Workbook
Name _Hlk215568700: PSIC!$B$2
Name latent: #REF!
Name tube_test_press1_12: #REF!

Sheet Break Down CI
U4: 1
A5: INVOICE NO. : | D5: ='Commercial Invoice'!H5 -> OM4-DE-IS-0004 | F5: PLACE : | L5: ='Commercial Invoice'!G6 -> DATE: | M5: ='Commercial Invoice'!H6 -> 46171 | U5: 2
U6: 3
A7: SI. No. | B7: Package No. | C7: Vị trí | D7: COMMODITY/DESCRIPTION OF GOODS | E7: POSITION IN PRICE SCHEDULE | F7: POSITION IN THE MASTER LIST | G7: QUANTITY | H7: UNIT | I7: NET WEIGHT (KG) | J7: UNIT PRICE (USD) | K7: AMOUNT (USD) | L7: DWG No. | M7: Remark | U7: 4
A8: 1 | B8: OM4-MPW-GT1-TGO-0001 | C8: S1 | D8: EMBEDDED MATERIAL | E8: PS 1.1, Ⅰ, 1 | F8: N/A | G8: 13 | H8: SETS | I8: 163.13725 | J8: 65.06 | K8: 845.82 | L8: G4-90019(G1-X2490)-0 G1-X2217-03 | M8: G1
A9: 2 | B9: OM4-MPW-GT1-TGO-0001 | C9: S1 | D9: EMBEDDED MATERIAL | E9: PS 1.1, Ⅰ, 1 | F9: N/A | G9: 19 | H9: SETS | I9: 238.43137 | J9: 65.06 | K9: 1236.2 | L9: G4-90019(G1-X2490)-0 G1-X2217-05 | M9: G1
A10: 3 | B10: OM4-MPW-GT1-TGO-0001 | C10: S1 | D10: EMBEDDED MATERIAL | E10: PS 1.1, Ⅰ, 1 | F10: N/A | G10: 10 | H10: SETS | I10: 125.4902 | J10: 65.06 | K10: 650.63 | L10: G4-90019(G1-X2490)-0 G1-X2217-07 | M10: G1
A11: 4 | B11: OM4-MPW-GT1-TGO-0001 | C11: S1 | D11: EMBEDDED HARDWARE | E11: PS 1.1, Ⅰ, 1 | F11: N/A | G11: 4 | H11: SETS | I11: 50.196078 | J11: 65.06 | K11: 260.25 | L11: G4-90019(G1-X2982)-0 G1-X2983-03 | M11: G1
A12: 5 | B12: OM4-MPW-GT1-TGO-0001 | C12: S1 | D12: EMBEDDED HARDWARE | E12: PS 1.1, Ⅰ, 1 | F12: N/A | G12: 5 | H12: SETS | I12: 62.745098 | J12: 65.06 | K12: 325.32 | L12: G4-90019(G1-X2982)-0 G1-X2983-04 | M12: G1
A13: 6 | B13: OM4-MPW-GT1-TGO-0002 | C13: S1 | D13: EMBEDDED HARDWARE | E13: PS 1.1, Ⅰ, 1 | F13: N/A | G13: 29 | H13: SETS | I13: 470 | J13: 84.03 | K13: 2436.82 | L13: G4-90370(G1-X1744)-0 G2-71467-01 | M13: G1
A14: 7 | B14: OM4-MPW-GT1-TGO-0003 | C14: S1 | D14: EMBEDDED MATERIAL | E14: PS 1.1, Ⅰ, 1 | F14: N/A | G14: 38 | H14: SETS | I14: 639.5122 | J14: 87.26 | K14: 3315.7 | L14: G4-90019(G1-X2490)-0 G1-X2217-04 | M14: G1
A15: 8 | B15: OM4-MPW-GT1-TGO-0003 | C15: S1 | D15: EMBEDDED MATERIAL | E15: PS 1.1, Ⅰ, 1 | F15: N/A | G15: 3 | H15: SETS | I15: 50.487805 | J15: 87.26 | K15: 261.77 | L15: G4-90019(G1-X2490)-0 G1-X2217-06 | M15: G1
A16: 9 | B16: OM4-MPW-GT1-TGO-0004 | C16: S1 | D16: EMBEDDED HARDWARE | E16: PS 1.1, Ⅰ, 1 | F16: N/A | G16: 17 | H16: SETS | I16: 672.91667 | J16: 205.23 | K16: 3488.89 | L16: G4-90370(G1-X1739)-0 G2-71462-01 | M16: G1
A17: 10 | B17: OM4-MPW-GT1-TGO-0004 | C17: S1 | D17: EMBEDDED HARDWARE | E17: PS 1.1, Ⅰ, 1 | F17: N/A | G17: 7 | H17: SETS | I17: 277.08333 | J17: 205.23 | K17: 1436.6 | L17: G4-90370(G1-X1739)-0 G2-71462-02 | M17: G1
A18: 11 | B18: OM4-MPW-GT1-TGO-0005 | C18: S1 | D18: EMBEDDED HARDWARE | E18: PS 1.1, Ⅰ, 1 | F18: N/A | G18: 46 | H18: SETS | I18: 606.03175 | J18: 68.31 | K18: 3142.11 | L18: G4-90370(G1-X1743)-0 G2-71466-01 | M18: G1
A19: 12 | B19: OM4-MPW-GT1-TGO-0005 | C19: S1 | D19: EMBEDDED HARDWARE | E19: PS 1.1, Ⅰ, 1 | F19: N/A | G19: 17 | H19: SETS | I19: 223.96825 | J19: 68.31 | K19: 1161.22 | L19: G4-90370(G1-X1743)-0 G2-71466-02 | M19: G1
... A31: 24 | B31: OM4-MPW-GT1-TGO-0013 | C31: S1 | D31: EMBEDDED MATERIAL | E31: PS 1.1, Ⅰ, 1 | F31: N/A | G31: 32 | H31: SETS | I31: 1080 | J31: 174.98 | K31: 5599.51 | L31: G4-90019(G1-X2490)-0 G1-X2217-02 | M31: G1
A32: 25 | B32: OM4-MPW-GT1-TGO-0014 | C32: S1 | D32: EMBEDDED MATERIAL | E32: PS 1.1, Ⅰ, 1 | F32: N/A | G32: 34 | H32: SETS | I32: 1150 | J32: =ROUND(K32/G32,2) -> 197.74 | K32: 6723.28 | L32: G4-90019(G1-X2490)-0 G1-X2217-02 | M32: G1
A33: 26 | B33: OM4-MPW-GT1-TGO-0015 | C33: S1 | D33: EMBEDDED MATERIAL | E33: PS 1.1, Ⅰ, 1 | F33: N/A | G33: 36 | H33: SETS | I33: 1780 | J33: 256.36 | K33: 9228.82 | L33: G4-90019(G1-X2490)-0 G1-X2217-01 | M33: G1
A34: 27 | B34: OM4-MPW-GT1-TGO-0016 | C34: S1 | D34: EMBEDDED HARDWARE | E34: PS 1.1, Ⅰ, 1 | F34: N/A | G34: 1 | H34: SET | I34: 32.222222 | J34: 167.06 | K34: 167.06 | L34: G4-90019(G1-X2982)-0 G1-X2983-05 | M34: G1
A35: 28 | B35: OM4-MPW-GT1-TGO-0016 | C35: S1 | D35: EMBEDDED HARDWARE | E35: PS 1.1, Ⅰ, 1 | F35: N/A | G35: 1 | H35: SET | I35: 32.222222 | J35: 167.06 | K35: 167.06 | L35: G4-90019(G1-X2982)-0 G1-X2983-06 | M35: G1
A36: 29 | B36: OM4-MPW-GT1-TGO-0016 | C36: S1 | D36: EMBEDDED HARDWARE | E36: PS 1.1, Ⅰ, 1 | F36: N/A | G36: 1 | H36: SET | I36: 32.222222 | J36: 167.06 | K36: 167.06 | L36: G4-90019(G1-X2982)-0 G1-X2983-07 | M36: G1
A37: 30 | B37: OM4-MPW-GT1-TGO-0016 | C37: S1 | D37: EMBEDDED HARDWARE | E37: PS 1.1, Ⅰ, 1 | F37: N/A | G37: 2 | H37: SETS | I37: 64.444444 | J37: 167.07 | K37: 334.14 | L37: G4-90019(G1-X2982)-0 G1-X2983-08 | M37: G1
A38: 31 | B38: OM4-MPW-GT1-TGO-0016 | C38: S1 | D38: EMBEDDED HARDWARE | E38: PS 1.1, Ⅰ, 1 | F38: N/A | G38: 1 | H38: SET | I38: 32.222222 | J38: 167.06 | K38: 167.06 | L38: G4-90019(G1-X2982)-0 G1-X2983-09 | M38: G1
A39: 32 | B39: OM4-MPW-GT1-TGO-0016 | C39: S1 | D39: EMBEDDED HARDWARE | E39: PS 1.1, Ⅰ, 1 | F39: N/A | G39: 1 | H39: SET | I39: 32.222222 | J39: 167.06 | K39: 167.06 | L39: G4-90019(G1-X2982)-1 G1-X2983-10 | M39: G1
A40: 33 | B40: OM4-MPW-GT1-TGO-0016 | C40: S1 | D40: EMBEDDED HARDWARE | E40: PS 1.1, Ⅰ, 1 | F40: N/A | G40: 2 | H40: SETS | I40: 64.444444 | J40: 167.07 | K40: 334.13 | L40: G4-90019(G1-X3127)-0 G2-71943-01 | M40: G1
A41: 34 | B41: OM4-MPW-GT1-TGO-0017 | C41: S1 | D41: FOUNDATION BOLT M68X2000 | E41: PS 1.1, Ⅰ, 1 | F41: N/A | G41: 5 | H41: SETS | I41: 175 | J41: 181.47 | K41: 907.33 | L41: G4-90019(G1-X2489)-0 G1-X2216-01 | M41: G1
A42: 35 | B42: OM4-MPW-GT1-TGO-0017 | C42: S1 | D42: HEX. NUT M68 | E42: PS 1.1, Ⅰ, 1 | F42: N/A | G42: 5 | H42: PCS | I42: 175 | J42: 181.47 | K42: 907.33 | L42: G4-90019(G1-X2489)-0 G1-X2216-05 | M42: G1
A43: 36 | B43: OM4-MPW-GT1-TGO-0017 | C43: S1 | D43: PLAIN WASHER 68 | E43: PS 1.1, Ⅰ, 1 | F43: N/A | G43: 5 | H43: PCS | I43: 175 | J43: 181.47 | K43: 907.33 | L43: G4-90019(G1-X2489)-0 G1-X2216-07 | M43: G1
A44: 37 | B44: OM4-MPW-GT1-TGO-0017 | C44: S1 | D44: CAP | E44: PS 1.1, Ⅰ, 1 | F44: N/A | G44: 5 | H44: PCS | I44: 175 | J44: 181.47 | K44: 907.33 | L44: G4-90019(G1-X2489)-0 G1-X2216-11 | M44: G1
... A99: 92 | B99: OM4-MPW-GT1-TGO-0030 | C99: S1 | D99: PLAIN WASHER 36 | E99: PS 1.1, Ⅰ, 1 | F99: N/A | G99: 24 | H99: PCS | I99: 105.5 | J99: 22.79 | K99: 546.99 | L99: G1-X1597-- G2-71978-04 | M99: G1
A100: 93 | B100: OM4-MPW-GT1-TGO-0030 | C100: S2 | D100: BLIND PLATE T3.2 : OUTER DIA.95 | E100: PS 1.1, Ⅰ, 1 | F100: N/A | G100: 24 | H100: PCS | I100: 105.5 | J100: =ROUND(K100/G100,2) -> 4.56 | K100: 109.4 | L100: G1-X1597-- G2-71978-07 | M100: G1
A101: 94 | B101: OM4-MPW-GT1-TGO-0031 | C101: S1 | D101: FOUNDATION BOLT M36X700 | E101: PS 1.1, Ⅰ, 1 | F101: N/A | G101: 40 | H101: SETS | I101: 132.75 | J101: =ROUND(K101/G101,2) -> 17.21 | K101: 688.27 | L101: G4-90019(G1-X2489)-0 G1-X2216-02 | M101: G1
A102: 95 | B102: OM4-MPW-GT1-TGO-0031 | C102: S1 | D102: HEX. NUT M36 | E102: PS 1.1, Ⅰ, 1 | F102: N/A | G102: 40 | H102: PCS | I102: 132.75 | J102: =ROUND(K102/G102,2) -> 17.21 | K102: 688.27 | L102: G4-90019(G1-X2489)-0 G1-X2216-06 | M102: G1
A103: 96 | B103: OM4-MPW-GT1-TGO-0031 | C103: S1 | D103: PLAIN WASHER 36 | E103: PS 1.1, Ⅰ, 1 | F103: N/A | G103: 40 | H103: PCS | I103: 132.75 | J103: =ROUND(K103/G103,2) -> 17.21 | K103: 688.27 | L103: G4-90019(G1-X2489)-0 G1-X2216-08 | M103: G1
A104: 97 | B104: OM4-MPW-GT1-TGO-0031 | C104: S1 | D104: CAP | E104: PS 1.1, Ⅰ, 1 | F104: N/A | G104: 40 | H104: PCS | I104: 132.75 | J104: =ROUND(K104/G104,2) -> 17.21 | K104: 688.27 | L104: G4-90019(G1-X2489)-0 G1-X2216-12 | M104: G1
A105: 98 | B105: OM4-MPW-GT1-TGO-0032 | C105: S1 | D105: FOUNDATION BOLT M30X630 | E105: PS 1.1, Ⅰ, 1 | F105: N/A | G105: 11 | H105: SETS | I105: 38.966102 | J105: =ROUND(K105/G105,2) -> 3.67 | K105: 40.41 | L105: G4-90019(G1-X1149)-0 G2-71457-01 | M105: G1
A106: 99 | B106: OM4-MPW-GT1-TGO-0032 | C106: S1 | D106: HEX. NUT M30 | E106: PS 1.1, Ⅰ, 1 | F106: N/A | G106: 22 | H106: PCS | I106: 77.932203 | J106: =ROUND(K106/G106,2) -> 18.37 | K106: 404.06 | L106: G4-90019(G1-X1149)-0 G2-71457-03 | M106: G1
A107: 100 | B107: OM4-MPW-GT1-TGO-0032 | C107: S1 | D107: PLAIN WASHER 30 | E107: PS 1.1, Ⅰ, 1 | F107: N/A | G107: 11 | H107: PCS | I107: 38.966102 | J107: =ROUND(K107/G107,2) -> 3.67 | K107: 40.41 | L107: G4-90019(G1-X1149)-0 G2-71457-04 | M107: G1 | X107: Items Excluded from RCEP COO Application
A108: 101 | B108: OM4-MPW-GT1-TGO-0032 | C108: S1 | D108: CAP | E108: PS 1.1, Ⅰ, 1 | F108: N/A | G108: 11 | H108: PCS | I108: 38.966102 | J108: 18.37 | K108: 202.04 | L108: G4-90019(G1-X1149)-0 G2-71457-07 | M108: G1
...

Sheet Detailed PL
C3: PECC2 Innovation Hub, 45 Street No.2, Truong Tho Ward, Thu Duc City, HCMC, Vietnam Tel: +84-28-2221 6468 | Fax: +84-28-2221 0408
B4: DETAILED PACKING LIST
C5: PL No. | E5: ='PL(2_2)'!E5 -> OM4-DE-IS-0004 | Z5: 36 | AA5: 39 | AB5: 40 | AC5: 163 | AD5: 3 | AE5: 8 | AF5: 44 | AG5: 45 | AH5: 46 | AI5: 60 | AJ5: 66 | AK5: 68 | AL5: 69 | AM5: 70 | AN5: 71 | AO5: 170 | AP5: 110 | AQ5: 234 | AR5: 33 | AS5: 34 | AT5: 142 | AV5: 79 | AW5: 80 | AX5: 81 | AY5: 82
C6: Dated | E6: ='PL(2_2)'!E6 -> 46171 | J6: * Storage Classification | O6: ** Plant/Equipment/Materials for | Z6: =SUMIF(#REF!,Z5,#REF!) -> #REF! | AA6: =SUMIF(#REF!,AA5,#REF!) -> #REF! | AB6: =SUMIF(#REF!,AB5,#REF!) -> #REF! | AC6: =SUMIF(#REF!,AC5,#REF!) -> #REF! | AD6: =SUMIF(#REF!,AD5,#REF!) -> #REF! | AE6: =SUMIF(#REF!,AE5,#REF!) -> #REF! | AF6: =SUMIF(#REF!,AF5,#REF!) -> #REF! | AG6: =SUMIF(#REF!,AG5,#REF!) -> #REF! | ... AP6: =SUMIF(#REF!,AP5,#REF!) -> #REF! | AQ6: =SUMIF($AH$151:$AH$420,AQ5,$I$151:$I$420) -> 0 | AR6: =SUMIF($AH$151:$AH$420,AR5,$I$151:$I$420) -> 0 | AS6: =SUMIF($AH$151:$AH$420,AS5,$I$151:$I$420) -> 0 | AT6: =SUMIF(#REF!,AT5,#REF!) -> #REF! | AU6: =SUM(Z6:AT7) -> #REF! | AV6: =SUMIF(#REF!,AV5,#REF!) -> #REF! | AW6: =SUMIF(#REF!,AW5,#REF!) -> #REF! | AX6: =SUMIF($AH$151:$AH$420,AX5,$I$151:$I$420) -> 0 | AY6: =SUMIF($AH$151:$AH$420,AY5,$I$151:$I$420) -> 0
C7: Project | E7: ='PL(2_2)'!E7 -> O MON IV THERMAL POWER PLANT | J7: "A" | K7: : Indoor with Air conditioning | P7: HRSG | Q7: STG | R7: GTG | S7: BOP | AD7: 1 | AE7: 1 | AH7: 5 | AI7: 100 | AT7: 2 | AV7: 105
J8: "B" | K8: : Indoor without Air conditioning | O8: Unit 1 | P8: B1 | Q8: T1 | R8: G1 | S8: P2
J9: "C" | K9: : Hazardous Material | O9: Unit 2 | P9: B2 | Q9: T2 | R9: G2 | S9: P2
J10: "D" | K10: : Outdoor with waterproofing | O10: Common | P10: B0 | Q10: T0 | R10: G0 | S10: P0
J11: "E" | K11: : Outdoor without waterproofing
B13: SI. No. | C13: Package No. | E13: Description of Goods | F13: Manufacturer | G13: C/O of Goods | H13: Position in price schedule | I13: Quantity | K13: Package Type | L13: Measurement | P13: Net Weight (kg) | Q13: Gross Weight (kg) | R13: Hazardous Material | S13: Storage Classification (*) | T13: Tag No. | U13: DWG No. | V13: Remark (**)
I14: Nos | J14: Unit | L14: Length (cm) | M14: Width (cm) | N14: Height (cm) | O14: Volume (cbm)
B15: 1 | C15: OM4-MPW-GT1-TGO-0001 | D15: S1 | E15: EMBEDDED MATERIAL | F15: MPW | G15: JAPAN | H15: PS 1.1, Ⅰ, 1 | I15: 13 | J15: SETS | P15: 163.13725 | U15: G4-90019(G1-X2490)-0 G1-X2217-03 | V15: G1
B16: 2 | C16: OM4-MPW-GT1-TGO-0001 | D16: S1 | E16: EMBEDDED MATERIAL | F16: MPW | G16: JAPAN | H16: PS 1.1, Ⅰ, 1 | I16: 19 | J16: SETS | P16: 238.43137 | U16: G4-90019(G1-X2490)-0 G1-X2217-05 | V16: G1
B17: 3 | C17: OM4-MPW-GT1-TGO-0001 | D17: S1 | E17: EMBEDDED MATERIAL | F17: MPW | G17: JAPAN | H17: PS 1.1, Ⅰ, 1 | I17: 10 | J17: SETS | P17: 125.4902 | U17: G4-90019(G1-X2490)-0 G1-X2217-07 | V17: G1
B18: 4 | C18: OM4-MPW-GT1-TGO-0001 | D18: S1 | E18: EMBEDDED HARDWARE | F18: MPW | G18: JAPAN | H18: PS 1.1, Ⅰ, 1 | I18: 4 | J18: SETS | P18: 50.196078 | U18: G4-90019(G1-X2982)-0 G1-X2983-03 | V18: G1
B19: 5 | C19: OM4-MPW-GT1-TGO-0001 | D19: S1 | E19: EMBEDDED HARDWARE | F19: MPW | G19: JAPAN | H19: PS 1.1, Ⅰ, 1 | I19: 5 | J19: SETS | P19: 62.745098 | U19: G4-90019(G1-X2982)-0 G1-X2983-04 | V19: G1
B20: Sub-Total | K20: CASE | L20: 136 | M20: 136 | N20: 117 | O20: 2.164 | P20: 640 | Q20: 810 | R20: N | S20: B | Y20: =P20/51 -> 12.54902
B21: 6 | C21: OM4-MPW-GT1-TGO-0002 | D21: S1 | E21: EMBEDDED HARDWARE | F21: MPW | G21: JAPAN | H21: PS 1.1, Ⅰ, 1 | I21: 29 | J21: SETS | P21: 470 | U21: G4-90370(G1-X1744)-0 G2-71467-01 | V21: G1
B22: Sub-Total | K22: CASE | L22: 136 | M22: 136 | N22: 117 | O22: 2.164 | P22: 470 | Q22: 640 | R22: N | S22: B
B23: 7 | C23: OM4-MPW-GT1-TGO-0003 | D23: S1 | E23: EMBEDDED MATERIAL | F23: MPW | G23: JAPAN | H23: PS 1.1, Ⅰ, 1 | I23: 38 | J23: SETS | P23: 639.5122 | U23: G4-90019(G1-X2490)-0 G1-X2217-04 | V23: G1
B24: 8 | C24: OM4-MPW-GT1-TGO-0003 | D24: S1 | E24: EMBEDDED MATERIAL | F24: MPW | G24: JAPAN | H24: PS 1.1, Ⅰ, 1 | I24: 3 | J24: SETS | P24: 50.487805 | U24: G4-90019(G1-X2490)-0 G1-X2217-06 | V24: G1
B25: Sub-Total | K25: CASE | L25: 136 | M25: 136 | N25: 117 | O25: 2.164 | P25: 690 | Q25: 850 | R25: N | S25: B | Y25: =P25/41 -> 16.829268
B26: 9 | C26: OM4-MPW-GT1-TGO-0004 | D26: S1 | E26: EMBEDDED HARDWARE | F26: MPW | G26: JAPAN | H26: PS 1.1, Ⅰ, 1 | I26: 17 | J26: SETS | P26: 672.91667 | U26: G4-90370(G1-X1739)-0 G2-71462-01 | V26: G1
B27: 10 | C27: OM4-MPW-GT1-TGO-0004 | D27: S1 | E27: EMBEDDED HARDWARE | F27: MPW | G27: JAPAN | H27: PS 1.1, Ⅰ, 1 | I27: 7 | J27: SETS | P27: 277.08333 | U27: G4-90370(G1-X1739)-0 G2-71462-02 | V27: G1
B28: Sub-Total | K28: CASE | L28: 136 | M28: 136 | N28: 117 | O28: 2.164 | P28: 950 | Q28: 1110 | R28: N | S28: B | Y28: =P28/24 -> 39.583333
B29: 11 | C29: OM4-MPW-GT1-TGO-0005 | D29: S1 | E29: EMBEDDED HARDWARE | F29: MPW | G29: JAPAN | H29: PS 1.1, Ⅰ, 1 | I29: 46 | J29: SETS | P29: 606.03175 | U29: G4-90370(G1-X1743)-0 G2-71466-01 | V29: G1
B30: 12 | C30: OM4-MPW-GT1-TGO-0005 | D30: S1 | E30: EMBEDDED HARDWARE | F30: MPW | G30: JAPAN | H30: PS 1.1, Ⅰ, 1 | I30: 17 | J30: SETS | P30: 223.96825 | U30: G4-90370(G1-X1743)-0 G2-71466-02 | V30: G1
B31: Sub-Total | K31: CASE | L31: 136 | M31: 136 | N31: 117 | O31: 2.164 | P31: 830 | Q31: 990 | R31: N | S31: B | Y31: =P31/63 -> 13.174603
B32: 13 | C32: OM4-MPW-GT1-TGO-0006 | D32: S1 | E32: EMBEDDED HARDWARE | F32: MPW | G32: JAPAN | H32: PS 1.1, Ⅰ, 1 | I32: 6 | J32: SETS | P32: 37.894737 | U32: G4-90019(G1-X2982)-0 G1-X2983-01 | V32: G1
B33: 14 | C33: OM4-MPW-GT1-TGO-0006 | D33: S1 | E33: EMBEDDED HARDWARE | F33: MPW | G33: JAPAN | H33: PS 1.1, Ⅰ, 1 | I33: 10 | J33: SETS | P33: 63.157895 | U33: G4-90019(G1-X2982)-0 G1-X2983-02 | V33: G1
B34: 15 | C34: OM4-MPW-GT1-TGO-0006 | D34: S1 | E34: EMBEDDED HARDWARE | F34: MPW | G34: JAPAN | H34: PS 1.1, Ⅰ, 1 | I34: 22 | J34: SETS | P34: 138.94737 | U34: G4-90370(G1-X1744)-0 G2-71467-02 | V34: G1
B35: Sub-Total | K35: CASE | L35: 157 | M35: 123 | N35: 66 | O35: 1.275 | P35: 240 | Q35: 380 | R35: N | S35: B | Y35: =P35/38 -> 6.3157895
B36: 16 | C36: OM4-MPW-GT1-TGO-0007 | D36: S1 | E36: EMBEDDED HARDWARE | F36: MPW | G36: JAPAN | H36: PS 1.1, Ⅰ, 1 | I36: 32 | J36: SETS | P36: 1580 | U36: G4-90370(G1-X1740)-0 G2-71463-01 | V36: G1
B37: Sub-Total | K37: CASE | L37: 136 | M37: 136 | N37: 142 | O37: 2.626 | P37: 1580 | Q37: 1730 | R37: N | S37: B
B38: 17 | C38: OM4-MPW-GT1-TGO-0008 | D38: S1 | E38: EMBEDDED HARDWARE | F38: MPW | G38: JAPAN | H38: PS 1.1, Ⅰ, 1 | I38: 32 | J38: SETS | P38: 1580 | U38: G4-90370(G1-X1739)-0 G2-71462-01 | V38: G1
B39: Sub-Total | K39: CASE | L39: 136 | M39: 136 | N39: 142 | O39: 2.626 | P39: 1580 | Q39: 1750 | R39: N | S39: B
B40: 18 | C40: OM4-MPW-GT1-TGO-0009 | D40: S1 | E40: EMBEDDED HARDWARE | F40: MPW | G40: JAPAN | H40: PS 1.1, Ⅰ, 1 | I40: 25 | J40: SETS | P40: 1120.6897 | U40: G4-90370(G1-X1742)-0 G2-71465-01 | V40: G1
B41: 19 | C41: OM4-MPW-GT1-TGO-0009 | D41: S1 | E41: EMBEDDED HARDWARE | F41: MPW | G41: JAPAN | H41: PS 1.1, Ⅰ, 1 | I41: 4 | J41: SETS | P41: 179.31034 | U41: G4-90370(G1-X1742)-0 G2-71465-02 | V41: G1
B42: Sub-Total | K42: CASE | L42: 136 | M42: 136 | N42: 142 | O42: 2.626 | P42: 1300 | Q42: 1490 | R42: N | S42: B | Y42: =P42/29 -> 44.827586
B43: 20 | C43: OM4-MPW-GT1-TGO-0010 | D43: S1 | E43: EMBEDDED HARDWARE | F43: MPW | G43: JAPAN | H43: PS 1.1, Ⅰ, 1 | I43: 17 | J43: SETS | P43: 595 | U43: G4-90370(G1-X1741)-0 G2-71464-01 | V43: G1
...

Sheet PL(2_2)
C3: PECC2 Innovation Hub, 45 Street No.2, Truong Tho Ward, Thu Duc City, HCMC, Vietnam Tel: +84-28-2221 6468 | Fax: +84-28-2221 0408
B4: PACKING LIST(2/2)
C5: P/L No. | E5: ='Packing List (1_2)'!H5 -> OM4-DE-IS-0004
C6: Dated | E6: ='Packing List (1_2)'!H6 -> 46171 | H6: * Storage Classification | P6: ** Plant/Equipment/Materials for
C7: Project | E7: O MON IV THERMAL POWER PLANT | H7: "A" | I7: : Indoor with Air conditioning | Q7: HRSG | R7: STG | S7: GTG | T7: BOP
H8: "B" | I8: : Indoor without Air conditioning | P8: Unit 1 | Q8: B1 | R8: T1 | S8: G1 | T8: P2
H9: "C" | I9: : Hazardous Material | P9: Unit 2 | Q9: B2 | R9: T2 | S9: G2 | T9: P2
H10: "D" | I10: : Outdoor with waterproofing | P10: Common | Q10: B0 | R10: T0 | S10: G0 | T10: P0
H11: "E" | I11: : Outdoor without waterproofing
B13: SI. No. | C13: Package No. | E13: Description of Goods | F13: Position in price schedule | G13: Quantity | I13: Package Type | J13: Measurement | N13: Net Weight (kg) | O13: Gross Weight (kg) | P13: Hazardous Material | Q13: COG Marked (Y/N) | R13: Sling Point Marked (Y/N) | S13: Handle with care Marked (Y/N) | T13: Storage Classification (*) | U13: Remark (**)
D14: Vị Trí | G14: Nos | H14: Unit | J14: Length (cm) | K14: Width (cm) | L14: Height (cm) | M14: Volume (cbm)
B15: 1 | C15: OM4-DE-IS-0004-001 | D15: S1 | E15: EMBEDDED MATERIAL ASS'Y | F15: PS 1.1, Ⅰ, 1 | G15: 1 | I15: CASE | J15: 136 | K15: 136 | L15: 117 | M15: 2.164 | N15: 640 | O15: 810 | P15: N | Q15: Y | R15: Y | S15: Y | T15: B | U15: G1
B16: 2 | C16: OM4-DE-IS-0004-002 | D16: S1 | E16: EMBEDDED HARDWARE | F16: PS 1.1, Ⅰ, 1 | G16: 1 | I16: CASE | J16: 136 | K16: 136 | L16: 117 | M16: 2.164 | N16: 470 | O16: 640 | P16: N | Q16: Y | R16: Y | S16: Y | T16: B | U16: G1
B17: 3 | C17: OM4-DE-IS-0004-003 | D17: S1 | E17: EMBEDDED MATERIAL ASS'Y | F17: PS 1.1, Ⅰ, 1 | G17: 1 | I17: CASE | J17: 136 | K17: 136 | L17: 117 | M17: 2.164 | N17: 690 | O17: 850 | P17: N | Q17: Y | R17: Y | S17: Y | T17: B | U17: G1
B18: 4 | C18: OM4-DE-IS-0004-004 | D18: S1 | E18: EMBEDDED HARDWARE | F18: PS 1.1, Ⅰ, 1 | G18: 1 | I18: CASE | J18: 136 | K18: 136 | L18: 117 | M18: 2.164 | N18: 950 | O18: 1110 | P18: N | Q18: Y | R18: Y | S18: Y | T18: B | U18: G1
B19: 5 | C19: OM4-DE-IS-0004-005 | D19: S1 | E19: EMBEDDED HARDWARE | F19: PS 1.1, Ⅰ, 1 | G19: 1 | I19: CASE | J19: 136 | K19: 136 | L19: 117 | M19: 2.164 | N19: 830 | O19: 990 | P19: N | Q19: Y | R19: Y | S19: Y | T19: B | U19: G1
B20: 6 | C20: OM4-DE-IS-0004-006 | D20: S1 | E20: EMBEDDED HARDWARE | F20: PS 1.1, Ⅰ, 1 | G20: 1 | I20: CASE | J20: 157 | K20: 123 | L20: 66 | M20: 1.275 | N20: 240 | O20: 380 | P20: N | Q20: Y | R20: Y | S20: Y | T20: B | U20: G1
B21: 7 | C21: OM4-DE-IS-0004-007 | D21: S1 | E21: EMBEDDED HARDWARE | F21: PS 1.1, Ⅰ, 1 | G21: 1 | I21: CASE | J21: 136 | K21: 136 | L21: 142 | M21: 2.626 | N21: 1580 | O21: 1730 | P21: N | Q21: Y | R21: Y | S21: Y | T21: B | U21: G1
B22: 8 | C22: OM4-DE-IS-0004-008 | D22: S1 | E22: EMBEDDED HARDWARE | F22: PS 1.1, Ⅰ, 1 | G22: 1 | I22: CASE | J22: 136 | K22: 136 | L22: 142 | M22: 2.626 | N22: 1580 | O22: 1750 | P22: N | Q22: Y | R22: Y | S22: Y | T22: B | U22: G1
B23: 9 | C23: OM4-DE-IS-0004-009 | D23: S1 | E23: EMBEDDED HARDWARE | F23: PS 1.1, Ⅰ, 1 | G23: 1 | I23: CASE | J23: 136 | K23: 136 | L23: 142 | M23: 2.626 | N23: 1300 | O23: 1490 | P23: N | Q23: Y | R23: Y | S23: Y | T23: B | U23: G1
B24: 10 | C24: OM4-DE-IS-0004-010 | D24: S1 | E24: EMBEDDED HARDWARE | F24: PS 1.1, Ⅰ, 1 | G24: 1 | I24: CASE | J24: 136 | K24: 136 | L24: 142 | M24: 2.626 | N24: 1050 | O24: 1240 | P24: N | Q24: Y | R24: Y | S24: Y | T24: B | U24: G1
B25: 11 | C25: OM4-DE-IS-0004-011 | D25: S1 | E25: EMBEDDED MATERIAL ASS'Y | F25: PS 1.1, Ⅰ, 1 | G25: 1 | I25: CASE | J25: 136 | K25: 136 | L25: 158 | M25: 2.922 | N25: 1730 | O25: 1890 | P25: N | Q25: Y | R25: Y | S25: Y | T25: B | U25: G1
B26: 12 | C26: OM4-DE-IS-0004-012 | D26: S1 | E26: EMBEDDED MATERIAL ASS'Y | F26: PS 1.1, Ⅰ, 1 | G26: 1 | I26: CASE | J26: 136 | K26: 136 | L26: 158 | M26: 2.922 | N26: 1780 | O26: 1940 | P26: N | Q26: Y | R26: Y | S26: Y | T26: B | U26: G1
... B47: 33 | C47: OM4-DE-IS-0004-033 | D47: S1 | E47: EMBEDDED HARDWARE | F47: PS 1.1, Ⅰ, 1 | G47: 1 | I47: CASE | J47: 287 | K47: 40 | L47: 46 | M47: 0.528 | N47: 23 | O47: 100 | P47: N | Q47: Y | R47: Y | S47: Y | T47: B | U47: G1
B48: Grand Total | M48: =SUM(M15:M47) -> 72.697 | N48: =SUM(N15:N47) -> 27300 | O48: =SUM(O15:O47) -> 32465

Sheet Commercial Invoice (Rev1)
A4: COMMERCIAL INVOICE
A5: SHIPPER: | G5: INVOICE NO. : | H5: OM4-DE-IS-0004
B6: Doosan Enerbility Co., Ltd. 22 DoosanVolvo-ro, Seongsan-gu, Chang-won-si, Gyeongsangnam-do 51711, Republic of Korea | G6: DATE: | H6: 46219
G7: CONTRACT NO. | H7: 06/2025/HĐ-PVN/OM4-06
G8: DATE: | H8: 45814
A9: CONSIGNEE : | G9: SHIPPING MARK
B10: Cty Doosan Enerbility Co.,Ltd HQ-Nha thau TH CV thuoc Goi thau so OM4-EPC-HHO-06 cho NMND O Mon IV Thoi Loi Area, Phuoc Thoi Ward, Can Tho City, Vietnam T : (+84) 367 566 167 F : (+84 243) 624 8485 | G10: O MON IV THERMAL POWER PLANT
A13: NOTIFY PARTY :
B14: Cty Doosan Enerbility Co.,Ltd HQ-Nha thau TH CV thuoc Goi thau so OM4-EPC-HHO-06 cho NMND O Mon IV Thoi Loi Area, Phươc Thoi Ward, Can Tho City, Vietnam T : (+84) 367 566 167 F : (+84 243) 624 8485 BRANCH OF KWANGJIN VIET NAM IN DUNG QUAT Co.,Ltd Dung Quat Economic Zone, Van Tuong Commune, Quang Ngai Province, Vietnam T : (+84) 28 3825 6330 Attn: Mr. Phuoc / Email: phuoc@kjtc.co.kr
G15: SHIPMENT NO. : | H15: OM4-DE-IS-0004
G17: TERM OF DELIVERY : | H17: CIF Ho Chi Minh City Port, Vietnam
A18: VESSEL NAME : | C18: ETD :
B19: ASL TAIPEI / 2629S | D19: 46222 | G19: QUALITY | H19: 100% BRAND NEW
A20: PORT OF LOADING : | C20: PORT OF DISCHARGE : | G20: PAYMENT TERMS: | H20: T/T
B21: KOBE, JAPAN | C21: HO CHI MINH, VIET NAM
A22: BILL OF LADING/ AIRWAY BILL NO. : | C22: B/L DATE :
B23: SITKBSG2611906 | D23: 46222
A24: FINAL DESTINATION : | G24: *Remark
B25: O MON IV THERMAL POWER PLANT | G25: - PO No. : 2025012890
B26: Address: O Mon Power Complex at Phuoc Thoi wards, Can Tho city | G26: - Sub-Vendor : MPW
G27: - OEM's Inv No. : OM4-T-001-JPN
A28: COMMODITY/DESCRIPTION OF GOODS | H28: UNIT | I28: QUANTITY | J28: UNIT PRICE (USD) | K28: AMOUNT (USD)
B29: PLANT/ EQUIPMENT AND MATERIALS FOR O MON IV THERMAL POWER PLANT (Contract No. OM4-PO-DE-001)
A31: Gas Turbine set and its auxiliaries #1 - Embedded materials
H32: LOT | I32: 1 | K32: 141543.19
B35: DETAILS ARE AS PER ATTACHED SHEET
B38: TOTAL AMOUNT AT THIS SHIPMENT : | K38: =SUM(K31:K37) -> 141543.19
G45: Signed by
H46: Jinho. Lee / Deputy Project Director

Sheet Break Down CI (Rve1)
AA4: 1
A5: INVOICE NO. : | D5: ='Commercial Invoice'!H5 -> OM4-DE-IS-0004 | H5: PLACE : | R5: ='Commercial Invoice'!G6 -> DATE: | S5: 46219 | AA5: 2
AA6: 3
A7: SI. No. | B7: Package No. | C7: Vị trí | D7: COMMODITY/DESCRIPTION OF GOODS | E7: Tên hàng tiếng việt | F7: Hs code | G7: POSITION IN PRICE SCHEDULE | H7: POSITION IN THE MASTER LIST | I7: QUANTITY | J7: UNIT | N7: NET WEIGHT (KG) | O7: NET WEIGHT (KG) | P7: UNIT PRICE (USD) | Q7: AMOUNT (USD) | R7: DWG No. | S7: Remark | AA7: 4
A8: 1 | B8: OM4-MPW-GT1-TGO-0001 | C8: S1 | D8: EMBEDDED MATERIAL | E8: Tấm nền móng, bằng thép, đặt sẵn, đã được gia công để dùng làm kết cấu, dùng cho hệ thống tuabin khí số #1, (13SETS=163.14kg), số DWG No.: G4-90019(G1-X2490)-0 G1-X2217-03, mới 100%- EMBEDDED MATERIAL | F8: 73089099 | G8: PS 1.1, Ⅰ, 1 | H8: N/A | I8: 13 | J8: SETS | N8: 163.13725 | O8: 163.13725 | P8: 65.06 | Q8: 845.82 | R8: G4-90019(G1-X2490)-0 G1-X2217-03 | S8: G1
A9: 2 | B9: OM4-MPW-GT1-TGO-0001 | C9: S1 | D9: EMBEDDED MATERIAL | E9: Tấm nền móng, bằng thép, đặt sẵn, đã được gia công để dùng làm kết cấu, dùng cho hệ thống tuabin khí số #1, (19SETS=238.43kg), số DWG No.: G4-90019(G1-X2490)-0 G1-X2217-05, mới 100%- EMBEDDED MATERIAL | F9: 73089099 | G9: PS 1.1, Ⅰ, 1 | H9: N/A | I9: 19 | J9: SETS | N9: 238.43137 | O9: 238.43137 | P9: 65.06 | Q9: 1236.2 | R9: G4-90019(G1-X2490)-0 G1-X2217-05 | S9: G1
A10: 3 | B10: OM4-MPW-GT1-TGO-0001 | C10: S1 | D10: EMBEDDED MATERIAL | E10: Tấm nền móng, bằng thép, đặt sẵn, đã được gia công để dùng làm kết cấu, dùng cho hệ thống tuabin khí số #1, (10SETS=125.49kg), số DWG No.: G4-90019(G1-X2490)-0 G1-X2217-07, mới 100%- EMBEDDED MATERIAL | F10: 73089099 | G10: PS 1.1, Ⅰ, 1 | H10: N/A | I10: 10 | J10: SETS | N10: 125.4902 | O10: 125.4902 | P10: 65.06 | Q10: 650.63 | R10: G4-90019(G1-X2490)-0 G1-X2217-07 | S10: G1
A11: 4 | B11: OM4-MPW-GT1-TGO-0001 | C11: S1 | D11: EMBEDDED HARDWARE | E11: Tấm nền móng, bằng thép, đặt sẵn, đã được gia công để dùng làm kết cấu, dùng cho hệ thống tuabin khí số #1, (4SETS=50.2kg), số DWG No.: G4-90019(G1-X2982)-0 G1-X2983-03, mới 100%- EMBEDDED HARDWARE | F11: 73089099 | G11: PS 1.1, Ⅰ, 1 | H11: N/A | I11: 4 | J11: SETS | N11: 50.196078 | O11: 50.196078 | P11: 65.06 | Q11: 260.25 | R11: G4-90019(G1-X2982)-0 G1-X2983-03 | S11: G1
A12: 5 | B12: OM4-MPW-GT1-TGO-0001 | C12: S1 | D12: EMBEDDED HARDWARE | E12: Tấm nền móng, bằng thép, đặt sẵn, đã được gia công để dùng làm kết cấu, dùng cho hệ thống tuabin khí số #1, (5SETS=62.75kg), số DWG No.: G4-90019(G1-X2982)-0 G1-X2983-04, mới 100%- EMBEDDED HARDWARE | F12: 73089099 | G12: PS 1.1, Ⅰ, 1 | H12: N/A | I12: 5 | J12: SETS | N12: 62.745098 | O12: 62.745098 | P12: 65.06 | Q12: 325.32 | R12: G4-90019(G1-X2982)-0 G1-X2983-04 | S12: G1
A13: 6 | B13: OM4-MPW-GT1-TGO-0002 | C13: S1 | D13: EMBEDDED HARDWARE | E13: Tấm nền móng, bằng thép, đặt sẵn, đã được gia công để dùng làm kết cấu, dùng cho hệ thống tuabin khí số #1, (29SETS=470kg), số DWG No.: G4-90370(G1-X1744)-0 G2-71467-01, mới 100%- EMBEDDED HARDWARE | F13: 73089099 | G13: PS 1.1, Ⅰ, 1 | H13: N/A | I13: 29 | J13: SETS | N13: 470 | O13: 470 | P13: 84.03 | Q13: 2436.82 | R13: G4-90370(G1-X1744)-0 G2-71467-01 | S13: G1
A14: 7 | B14: OM4-MPW-GT1-TGO-0003 | C14: S1 | D14: EMBEDDED MATERIAL | E14: Tấm nền móng, bằng thép, đặt sẵn, đã được gia công để dùng làm kết cấu, dùng cho hệ thống tuabin khí số #1, (38SETS=639.51kg), số DWG No.: G4-90019(G1-X2490)-0 G1-X2217-04, mới 100%- EMBEDDED MATERIAL | F14: 73089099 | G14: PS 1.1, Ⅰ, 1 | H14: N/A | I14: 38 | J14: SETS | N14: 639.5122 | O14: 639.5122 | P14: 87.26 | Q14: 3315.7 | R14: G4-90019(G1-X2490)-0 G1-X2217-04 | S14: G1
A15: 8 | B15: OM4-MPW-GT1-TGO-0003 | C15: S1 | D15: EMBEDDED MATERIAL | E15: Tấm nền móng, bằng thép, đặt sẵn, đã được gia công để dùng làm kết cấu, dùng cho hệ thống tuabin khí số #1, (3SETS=50.49kg), số DWG No.: G4-90019(G1-X2490)-0 G1-X2217-06, mới 100%- EMBEDDED MATERIAL | F15: 73089099 | G15: PS 1.1, Ⅰ, 1 | H15: N/A | I15: 3 | J15: SETS | N15: 50.487805 | O15: 50.487805 | P15: 87.26 | Q15: 261.77 | R15: G4-90019(G1-X2490)-0 G1-X2217-06 | S15: G1
A16: 9 | B16: OM4-MPW-GT1-TGO-0004 | C16: S1 | D16: EMBEDDED HARDWARE | E16: Tấm nền móng, bằng thép, đặt sẵn, đã được gia công để dùng làm kết cấu, dùng cho hệ thống tuabin khí số #1, (17SETS=672.92kg), số DWG No.: G4-90370(G1-X1739)-0 G2-71462-01, mới 100%- EMBEDDED HARDWARE | F16: 73089099 | G16: PS 1.1, Ⅰ, 1 | H16: N/A | I16: 17 | J16: SETS | N16: 672.91667 | O16: 672.91667 | P16: 205.23 | Q16: 3488.89 | R16: G4-90370(G1-X1739)-0 G2-71462-01 | S16: G1
A17: 10 | B17: OM4-MPW-GT1-TGO-0004 | C17: S1 | D17: EMBEDDED HARDWARE | E17: Tấm nền móng, bằng thép, đặt sẵn, đã được gia công để dùng làm kết cấu, dùng cho hệ thống tuabin khí số #1, (7SETS=277.08kg), số DWG No.: G4-90370(G1-X1739)-0 G2-71462-02, mới 100%- EMBEDDED HARDWARE | F17: 73089099 | G17: PS 1.1, Ⅰ, 1 | H17: N/A | I17: 7 | J17: SETS | N17: 277.08333 | O17: 277.08333 | P17: 205.23 | Q17: 1436.6 | R17: G4-90370(G1-X1739)-0 G2-71462-02 | S17: G1
A18: 11 | B18: OM4-MPW-GT1-TGO-0005 | C18: S1 | D18: EMBEDDED HARDWARE | E18: Tấm nền móng, bằng thép, đặt sẵn, đã được gia công để dùng làm kết cấu, dùng cho hệ thống tuabin khí số #1, (46SETS=606.03kg), số DWG No.: G4-90370(G1-X1743)-0 G2-71466-01, mới 100%- EMBEDDED HARDWARE | F18: 73089099 | G18: PS 1.1, Ⅰ, 1 | H18: N/A | I18: 46 | J18: SETS | N18: 606.03175 | O18: 606.03175 | P18: 68.31 | Q18: 3142.11 | R18: G4-90370(G1-X1743)-0 G2-71466-01 | S18: G1
A19: 12 | B19: OM4-MPW-GT1-TGO-0005 | C19: S1 | D19: EMBEDDED HARDWARE | E19: Tấm nền móng, bằng thép, đặt sẵn, đã được gia công để dùng làm kết cấu, dùng cho hệ thống tuabin khí số #1, (17SETS=223.97kg), số DWG No.: G4-90370(G1-X1743)-0 G2-71466-02, mới 100%- EMBEDDED HARDWARE | F19: 73089099 | G19: PS 1.1, Ⅰ, 1 | H19: N/A | I19: 17 | J19: SETS | N19: 223.96825 | O19: 223.96825 | P19: 68.31 | Q19: 1161.22 | R19: G4-90370(G1-X1743)-0 G2-71466-02 | S19: G1
... A31: 24 | B31: OM4-MPW-GT1-TGO-0013 | C31: S1 | D31: EMBEDDED MATERIAL | E31: Tấm nền móng, bằng thép, đặt sẵn, đã được gia công để dùng làm kết cấu, dùng cho hệ thống tuabin khí số #1, (32SETS=1080kg), số DWG No.: G4-90019(G1-X2490)-0 G1-X2217-02, mới 100%- EMBEDDED MATERIAL | F31: 73089099 | G31: PS 1.1, Ⅰ, 1 | H31: N/A | I31: 32 | J31: SETS | N31: 1080 | O31: 1080 | P31: 174.98 | Q31: 5599.51 | R31: G4-90019(G1-X2490)-0 G1-X2217-02 | S31: G1
A32: 25 | B32: OM4-MPW-GT1-TGO-0014 | C32: S1 | D32: EMBEDDED MATERIAL | E32: Tấm nền móng, bằng thép, đặt sẵn, đã được gia công để dùng làm kết cấu, dùng cho hệ thống tuabin khí số #1, (34SETS=1150kg), số DWG No.: G4-90019(G1-X2490)-0 G1-X2217-02, mới 100%- EMBEDDED MATERIAL | F32: 73089099 | G32: PS 1.1, Ⅰ, 1 | H32: N/A | I32: 34 | J32: SETS | N32: 1150 | O32: 1150 | P32: =ROUND(Q32/I32,2) -> 197.74 | Q32: 6723.28 | R32: G4-90019(G1-X2490)-0 G1-X2217-02 | S32: G1
A33: 26 | B33: OM4-MPW-GT1-TGO-0015 | C33: S1 | D33: EMBEDDED MATERIAL | E33: Tấm nền móng, bằng thép, đặt sẵn, đã được gia công để dùng làm kết cấu, dùng cho hệ thống tuabin khí số #1, (36SETS=1780kg), số DWG No.: G4-90019(G1-X2490)-0 G1-X2217-01, mới 100%- EMBEDDED MATERIAL | F33: 73089099 | G33: PS 1.1, Ⅰ, 1 | H33: N/A | I33: 36 | J33: SETS | N33: 1780 | O33: 1780 | P33: 256.36 | Q33: 9228.82 | R33: G4-90019(G1-X2490)-0 G1-X2217-01 | S33: G1
A34: 27 | B34: OM4-MPW-GT1-TGO-0016 | C34: S1 | D34: EMBEDDED HARDWARE | E34: Tấm nền móng, bằng thép, đặt sẵn, đã được gia công để dùng làm kết cấu, dùng cho hệ thống tuabin khí số #1, (1SET=32.22kg), số DWG No.: G4-90019(G1-X2982)-0 G1-X2983-05, mới 100%- EMBEDDED HARDWARE | F34: 73089099 | G34: PS 1.1, Ⅰ, 1 | H34: N/A | I34: 1 | J34: SET | N34: 32.222222 | O34: 32.222222 | P34: 167.06 | Q34: 167.06 | R34: G4-90019(G1-X2982)-0 G1-X2983-05 | S34: G1
A35: 28 | B35: OM4-MPW-GT1-TGO-0016 | C35: S1 | D35: EMBEDDED HARDWARE | E35: Tấm nền móng, bằng thép, đặt sẵn, đã được gia công để dùng làm kết cấu, dùng cho hệ thống tuabin khí số #1, (1SET=32.22kg), số DWG No.: G4-90019(G1-X2982)-0 G1-X2983-06, mới 100%- EMBEDDED HARDWARE | F35: 73089099 | G35: PS 1.1, Ⅰ, 1 | H35: N/A | I35: 1 | J35: SET | N35: 32.222222 | O35: 32.222222 | P35: 167.06 | Q35: 167.06 | R35: G4-90019(G1-X2982)-0 G1-X2983-06 | S35: G1
A36: 29 | B36: OM4-MPW-GT1-TGO-0016 | C36: S1 | D36: EMBEDDED HARDWARE | E36: Tấm nền móng, bằng thép, đặt sẵn, đã được gia công để dùng làm kết cấu, dùng cho hệ thống tuabin khí số #1, (1SET=32.22kg), số DWG No.: G4-90019(G1-X2982)-0 G1-X2983-07, mới 100%- EMBEDDED HARDWARE | F36: 73089099 | G36: PS 1.1, Ⅰ, 1 | H36: N/A | I36: 1 | J36: SET | N36: 32.222222 | O36: 32.222222 | P36: 167.06 | Q36: 167.06 | R36: G4-90019(G1-X2982)-0 G1-X2983-07 | S36: G1
A37: 30 | B37: OM4-MPW-GT1-TGO-0016 | C37: S1 | D37: EMBEDDED HARDWARE | E37: Tấm nền móng, bằng thép, đặt sẵn, đã được gia công để dùng làm kết cấu, dùng cho hệ thống tuabin khí số #1, (2SETS=64.44kg), số DWG No.: G4-90019(G1-X2982)-0 G1-X2983-08, mới 100%- EMBEDDED HARDWARE | F37: 73089099 | G37: PS 1.1, Ⅰ, 1 | H37: N/A | I37: 2 | J37: SETS | N37: 64.444444 | O37: 64.444444 | P37: 167.07 | Q37: 334.14 | R37: G4-90019(G1-X2982)-0 G1-X2983-08 | S37: G1
A38: 31 | B38: OM4-MPW-GT1-TGO-0016 | C38: S1 | D38: EMBEDDED HARDWARE | E38: Tấm nền móng, bằng thép, đặt sẵn, đã được gia công để dùng làm kết cấu, dùng cho hệ thống tuabin khí số #1, (1SET=32.22kg), số DWG No.: G4-90019(G1-X2982)-0 G1-X2983-09, mới 100%- EMBEDDED HARDWARE | F38: 73089099 | G38: PS 1.1, Ⅰ, 1 | H38: N/A | I38: 1 | J38: SET | N38: 32.222222 | O38: 32.222222 | P38: 167.06 | Q38: 167.06 | R38: G4-90019(G1-X2982)-0 G1-X2983-09 | S38: G1
A39: 32 | B39: OM4-MPW-GT1-TGO-0016 | C39: S1 | D39: EMBEDDED HARDWARE | E39: Tấm nền móng, bằng thép, đặt sẵn, đã được gia công để dùng làm kết cấu, dùng cho hệ thống tuabin khí số #1, (1SET=32.22kg), số DWG No.: G4-90019(G1-X2982)-1 G1-X2983-10, mới 100%- EMBEDDED HARDWARE | F39: 73089099 | G39: PS 1.1, Ⅰ, 1 | H39: N/A | I39: 1 | J39: SET | N39: 32.222222 | O39: 32.222222 | P39: 167.06 | Q39: 167.06 | R39: G4-90019(G1-X2982)-1 G1-X2983-10 | S39: G1
A40: 33 | B40: OM4-MPW-GT1-TGO-0016 | C40: S1 | D40: EMBEDDED HARDWARE | E40: Tấm nền móng, bằng thép, đặt sẵn, đã được gia công để dùng làm kết cấu, dùng cho hệ thống tuabin khí số #1, (2SETS=64.44kg), số DWG No.: G4-90019(G1-X3127)-0 G2-71943-01, mới 100%- EMBEDDED HARDWARE | F40: 73089099 | G40: PS 1.1, Ⅰ, 1 | H40: N/A | I40: 2 | J40: SETS | N40: 64.444444 | O40: 64.444444 | P40: 167.07 | Q40: 334.13 | R40: G4-90019(G1-X3127)-0 G2-71943-01 | S40: G1
A41: 34 | B41: OM4-MPW-GT1-TGO-0017 | C41: S1 | D41: FOUNDATION BOLT M68X2000 | E41: Bộ bu lông móng bằng thép (bộ gồm: 1 bu lông, 2 đai ốc, 2 vòng đệm), loại có ren, có đường kính ngoài của thân: 68mm (M68X2000), hàng mới 100% - FOUNDATION BOLT M68X2000 | F41: 73181590 | G41: PS 1.1, Ⅰ, 1 | H41: N/A | I41: 5 | J41: SETS | K41: 57 | L41: =I41*K41 -> 285 | M41: 663.1 | N41: 663.1 | O41: 175 | P41: 181.47 | Q41: 907.33 | R41: G4-90019(G1-X2489)-0 G1-X2216-01 | S41: G1
A42: 35 | B42: OM4-MPW-GT1-TGO-0017 | C42: S1 | D42: HEX. NUT M68 | E42: Đai ốc bằng thép, loại có ren, dùng cho bu lông móng có đường kính ngoài của thân: 68mm (M68), hàng mới 100% - HEX. NUT M68 | F42: 73181690 | G42: PS 1.1, Ⅰ, 1 | H42: N/A | I42: 5 | J42: PCS | K42: 2.2 | L42: =I42*K42 -> 11 | M42: 25.59 | N42: 25.59 | O42: 175 | P42: 181.47 | Q42: 907.33 | R42: G4-90019(G1-X2489)-0 G1-X2216-05 | S42: G1
A43: 36 | B43: OM4-MPW-GT1-TGO-0017 | C43: S1 | D43: PLAIN WASHER 68 | E43: Vòng đệm bằng thép, không ren, dùng cho bu lông móng, có đường kính: 68mm, hàng mới 100% - PLAIN WASHER 68 | F43: 73182200 | G43: PS 1.1, Ⅰ, 1 | H43: N/A | I43: 5 | J43: PCS | K43: 0.6 | L43: =I43*K43 -> 3 | M43: 6.99 | N43: 6.99 | O43: 175 | P43: 181.47 | Q43: 907.33 | R43: G4-90019(G1-X2489)-0 G1-X2216-07 | S43: G1
A44: 37 | B44: OM4-MPW-GT1-TGO-0017 | C44: S1 | D44: CAP | E44: Nắp chèn kín bằng thép, đã được gia công cơ khí qua nhiều công đoạn để tạo ra 1 sản phẩm hoàn chỉnh, kích thước: 155x74x3.2t mm, hàng mới 100% - CAP | F44: 73269099 | G44: PS 1.1, Ⅰ, 1 | H44: N/A | I44: 5 | J44: PCS | K44: 0.37 | L44: =I44*K44 -> 1.85 | M44: 4.32 | N44: 4.32 | O44: 175 | P44: 181.47 | Q44: 907.33 | R44: G4-90019(G1-X2489)-0 G1-X2216-11 | S44: G1
A45: 38 | B45: OM4-MPW-GT1-TGO-0018 | C45: S1 | D45: FOUNDATION BOLT M68X2000 | E45: Bộ bu lông móng bằng thép (bộ gồm: 1 bu lông, 2 đai ốc, 2 vòng đệm), loại có ren, có đường kính ngoài của thân: 68mm (M68X2000), hàng mới 100% - FOUNDATION BOLT M68X2000 | F45: 73181590 | G45: PS 1.1, Ⅰ, 1 | H45: N/A | I45: 5 | J45: SETS | K45: 57 | L45: =I45*K45 -> 285 | M45: 663.1 | N45: 663.1 | O45: 175 | P45: 181.47 | Q45: 907.33 | R45: G4-90019(G1-X2489)-0 G1-X2216-01 | S45: G1
A46: 39 | B46: OM4-MPW-GT1-TGO-0018 | C46: S1 | D46: HEX. NUT M68 | E46: Đai ốc bằng thép, loại có ren, dùng cho bu lông móng có đường kính ngoài của thân: 68mm (M68), hàng mới 100% - HEX. NUT M68 | F46: 73181690 | G46: PS 1.1, Ⅰ, 1 | H46: N/A | I46: 5 | J46: PCS | K46: 2.2 | L46: =I46*K46 -> 11 | M46: 25.59 | N46: 25.59 | O46: 175 | P46: 181.47 | Q46: 907.33 | R46: G4-90019(G1-X2489)-0 G1-X2216-05 | S46: G1
A47: 40 | B47: OM4-MPW-GT1-TGO-0018 | C47: S1 | D47: PLAIN WASHER 68 | E47: Vòng đệm bằng thép, không ren, dùng cho bu lông móng, có đường kính: 68mm, hàng mới 100% - PLAIN WASHER 68 | F47: 73182200 | G47: PS 1.1, Ⅰ, 1 | H47: N/A | I47: 5 | J47: PCS | K47: 0.6 | L47: =I47*K47 -> 3 | M47: 6.99 | N47: 6.99 | O47: 175 | P47: 181.47 | Q47: 907.33 | R47: G4-90019(G1-X2489)-0 G1-X2216-07 | S47: G1
A48: 41 | B48: OM4-MPW-GT1-TGO-0018 | C48: S1 | D48: CAP | E48: Nắp chèn kín bằng thép, đã được gia công cơ khí qua nhiều công đoạn để tạo ra 1 sản phẩm hoàn chỉnh, kích thước: 155x74x3.2t mm, hàng mới 100% - CAP | F48: 73269099 | G48: PS 1.1, Ⅰ, 1 | H48: N/A | I48: 5 | J48: PCS | K48: 0.37 | L48: =I48*K48 -> 1.85 | M48: 4.32 | N48: 4.32 | O48: 175 | P48: 181.47 | Q48: 907.33 | R48: G4-90019(G1-X2489)-0 G1-X2216-11 | S48: G1
A49: 42 | B49: OM4-MPW-GT1-TGO-0019 | C49: S1 | D49: FOUNDATION BOLT M68X2000 | E49: Bộ bu lông móng bằng thép (bộ gồm: 1 bu lông, 2 đai ốc, 2 vòng đệm), loại có ren, có đường kính ngoài của thân: 68mm (M68X2000), hàng mới 100% - FOUNDATION BOLT M68X2000 | F49: 73181590 | G49: PS 1.1, Ⅰ, 1 | H49: N/A | I49: 5 | J49: SETS | K49: 57 | L49: =I49*K49 -> 285 | M49: 663.1 | N49: 663.1 | O49: 175 | P49: 181.47 | Q49: 907.33 | R49: G4-90019(G1-X2489)-0 G1-X2216-01 | S49: G1
A50: 43 | B50: OM4-MPW-GT1-TGO-0019 | C50: S1 | D50: HEX. NUT M68 | E50: Đai ốc bằng thép, loại có ren, dùng cho bu lông móng có đường kính ngoài của thân: 68mm (M68), hàng mới 100% - HEX. NUT M68 | F50: 73181690 | G50: PS 1.1, Ⅰ, 1 | H50: N/A | I50: 5 | J50: PCS | K50: 2.2 | L50: =I50*K50 -> 11 | M50: 25.59 | N50: 25.59 | O50: 175 | P50: 181.47 | Q50: 907.33 | R50: G4-90019(G1-X2489)-0 G1-X2216-05 | S50: G1
A51: 44 | B51: OM4-MPW-GT1-TGO-0019 | C51: S1 | D51: PLAIN WASHER 68 | E51: Vòng đệm bằng thép, không ren, dùng cho bu lông móng, có đường kính: 68mm, hàng mới 100% - PLAIN WASHER 68 | F51: 73182200 | G51: PS 1.1, Ⅰ, 1 | H51: N/A | I51: 5 | J51: PCS | K51: 0.6 | L51: =I51*K51 -> 3 | M51: 6.99 | N51: 6.99 | O51: 175 | P51: 181.47 | Q51: 907.33 | R51: G4-90019(G1-X2489)-0 G1-X2216-07 | S51: G1
A52: 45 | B52: OM4-MPW-GT1-TGO-0019 | C52: S1 | D52: CAP | E52: Nắp chèn kín bằng thép, đã được gia công cơ khí qua nhiều công đoạn để tạo ra 1 sản phẩm hoàn chỉnh, kích thước: 155x74x3.2t mm, hàng mới 100% - CAP | F52: 73269099 | G52: PS 1.1, Ⅰ, 1 | H52: N/A | I52: 5 | J52: PCS | K52: 0.37 | L52: =I52*K52 -> 1.85 | M52: 4.32 | N52: 4.32 | O52: 175 | P52: 181.47 | Q52: 907.33 | R52: G4-90019(G1-X2489)-0 G1-X2216-11 | S52: G1
... A96: 89 | B96: OM4-MPW-GT1-TGO-0029 | C96: S1 | D96: CAP | E96: Nắp chèn kín bằng thép, đã được gia công cơ khí qua nhiều công đoạn để tạo ra 1 sản phẩm hoàn chỉnh, kích thước: 155x74x3.2t mm, hàng mới 100% - CAP | F96: 73269099 | G96: PS 1.1, Ⅰ, 1 | H96: N/A | I96: 3 | J96: PCS | K96: 0.37 | L96: =I96*K96 -> 1.11 | M96: 2.5 | N96: 2.5 | O96: 101.25 | P96: 174.98 | Q96: 524.95 | R96: G4-90019(G1-X2489)-1 G1-X2216-11 | S96: G1
A97: 90 | B97: OM4-MPW-GT1-TGO-0030 | C97: S1 | D97: FOUNDATION BOLT M36 X 760 | E97: Bộ bu lông móng bằng thép (bộ gồm: 1 bu lông, 2 đai ốc), loại có ren, có đường kính ngoài của thân: 36mm (M36X760), hàng mới 100% - FOUNDATION BOLT M36 X 760 | F97: 73181590 | G97: PS 1.1, Ⅰ, 1 | H97: N/A | I97: 24 | J97: SETS | L97: =M101/I101 -> 10.85475 | M97: 356.46 | N97: 356.46 | O97: 105.5 | P97: 22.79 | Q97: 546.99 | R97: G1-X1597-- G2-71978-01 | S97: G1
...

Sheet Commercial Invoice
B3: PECC2 Innovation Hub, 45 Street No.2, Truong Tho Ward, Thu Duc City, HCMC, Vietnam Tel: +84-28-2221 6468 | Fax: +84-28-2221 0408
A4: COMMERCIAL INVOICE
A5: SHIPPER: | G5: INVOICE NO. : | H5: OM4-DE-IS-0004
B6: Doosan Enerbility Co., Ltd. 22 DoosanVolvo-ro, Seongsan-gu, Chang-won-si, Gyeongsangnam-do 51711, Republic of Korea | G6: DATE: | H6: 46171
G7: CONTRACT NO. | H7: 06/2025/HĐ-PVN/OM4-06
G8: DATE: | H8: 45814
A9: CONSIGNEE : | G9: SHIPPING MARK
B10: Cty Doosan Enerbility Co.,Ltd HQ-Nha thau TH CV thuoc Goi thau so OM4-EPC-HHO-06 cho NMND O Mon IV Thoi Loi Area, Phuoc Thoi Ward, Can Tho City, Vietnam T : (+84) 367 566 167 F : (+84 243) 624 8485 | G10: O MON IV THERMAL POWER PLANT
A13: NOTIFY PARTY :
B14: Cty Doosan Enerbility Co.,Ltd HQ-Nha thau TH CV thuoc Goi thau so OM4-EPC-HHO-06 cho NMND O Mon IV Thoi Loi Area, Phươc Thoi Ward, Can Tho City, Vietnam T : (+84) 367 566 167 F : (+84 243) 624 8485 BRANCH OF KWANGJIN VIET NAM IN DUNG QUAT Co.,Ltd Dung Quat Economic Zone, Van Tuong Commune, Quang Ngai Province, Vietnam T : (+84) 28 3825 6330 Attn: Mr. Phuoc / Email: phuoc@kjtc.co.kr
G15: SHIPMENT NO. : | H15: OM4-DE-IS-0004
G17: TERM OF DELIVERY : | H17: CIF Ho Chi Minh City Port, Vietnam
A18: VESSEL NAME : | C18: ETD :
B19: ASL TAIPEI / 2629S | D19: 46223 | G19: QUALITY | H19: 100% BRAND NEW
A20: PORT OF LOADING : | C20: PORT OF DISCHARGE : | G20: PAYMENT TERMS: | H20: T/T
B21: KOBE, JAPAN | D21: Ho Chi Minh City Port, Vietnam
A22: BILL OF LADING/ AIRWAY BILL NO. : | C22: B/L DATE :
B23: SITKBSG2611906 | D23: 46222
A24: FINAL DESTINATION : | G24: *Remark
B25: O MON IV THERMAL POWER PLANT | G25: - PO No. : 2025012890
B26: Address: O Mon Power Complex at Phuoc Thoi wards, Can Tho city | G26: - Sub-Vendor : MPW
G27: - OEM's Inv No. : OM4-T-001-JPN
A28: COMMODITY/DESCRIPTION OF GOODS | H28: UNIT | I28: QUANTITY | J28: UNIT PRICE (USD) | K28: AMOUNT (USD)
B29: PLANT/ EQUIPMENT AND MATERIALS FOR O MON IV THERMAL POWER PLANT (Contract No. OM4-PO-DE-001)
A31: Gas Turbine set and its auxiliaries #1 - Embedded materials
H32: CASE | I32: 33 | J32: =ROUND(K32/I32,2) -> 4289.19 | K32: ='Break Down CI'!K111 -> 141543.19
B35: DETAILS ARE AS PER ATTACHED SHEET
B38: TOTAL AMOUNT AT THIS SHIPMENT : | K38: =SUM(K31:K37) -> 141543.19
G45: Signed by
H46: Jinho. Lee / Deputy Project Director

Sheet Packing List (1_2)
B3: PECC2 Innovation Hub, 45 Street No.2, Truong Tho Ward, Thu Duc City, HCMC, Vietnam Tel: +84-28-2221 6468 | Fax: +84-28-2221 0408
A4: PACKING LIST(1/2)
A5: SHIPPER: | G5: P/L No. | H5: ='Commercial Invoice'!H5 -> OM4-DE-IS-0004
B6: Doosan Enerbility Co., Ltd. 22 DoosanVolvo-ro, Seongsan-gu, Chang-won-si, Gyeongsangnam-do 51711, Republic of Korea | G6: DATE: | H6: ='Commercial Invoice'!H6 -> 46171
G7: CONTRACT NO. | H7: 06/2025/HĐ-PVN/OM4-06
G8: DATE: | H8: ='Commercial Invoice'!H8 -> 45814
A9: CONSIGNEE : | G9: SHIPPING MARK
B10: Cty Doosan Enerbility Co.,Ltd HQ-Nha thau TH CV thuoc Goi thau so OM4-EPC-HHO-06 cho NMND O Mon IV Thoi Loi Area, Phuoc Thoi Ward, Can Tho City, Vietnam T : (+84) 367 566 167 F : (+84 243) 624 8485 | G10: O MON IV THERMAL POWER PLANT
A13: NOTIFY PARTY :
B14: Cty Doosan Enerbility Co.,Ltd HQ-Nha thau TH CV thuoc Goi thau so OM4-EPC-HHO-06 cho NMND O Mon IV Thoi Loi Area, Phươc Thoi Ward, Can Tho City, Vietnam T : (+84) 367 566 167 F : (+84 243) 624 8485 BRANCH OF KWANGJIN VIET NAM IN DUNG QUAT Co.,Ltd Dung Quat Economic Zone, Van Tuong Commune, Quang Ngai Province, Vietnam T : (+84) 28 3825 6330 Attn: Mr. Phuoc / Email: phuoc@kjtc.co.kr
G15: SHIPMENT NO. : | H15: ='Commercial Invoice'!H15:K16 -> OM4-DE-IS-0004
G17: TERM OF DELIVERY : | H17: CIF Ho Chi Minh City Port, Vietnam
A18: VESSEL NAME : | C18: ETD :
B19: ASL TAIPEI / 2629S | D19: 46223 | G19: QUALITY | H19: 100% BRAND NEW
A20: PORT OF LOADING : | C20: PORT OF DISCHARGE :
B21: KOBE, JAPAN | D21: Ho Chi Minh City Port, Vietnam
A22: BILL OF LADING/ AIRWAY BILL NO. : | C22: B/L DATE :
B23: SITKBSG2611906 | D23: 46222
A24: FINAL DESTINATION : | G24: *Remark
B25: O MON IV THERMAL POWER PLANT | G25: - PO No. : 2025012890
B26: Address: O Mon Power Complex at Phuoc Thoi wards, Can Tho city | G26: - Sub-Vendor : MPW
G27: - OEM's Inv No. : OM4-T-001-JPN
A28: COMMODITY/DESCRIPTION OF GOODS | G28: UNIT | H28: QUANTITY | I28: NET WEIGHT (KG) | J28: GROSS WEIGHT (KG) | K28: MEASUREMENT (CBM)
B29: PLANT/ EQUIPMENT AND MATERIALS FOR O MON IV THERMAL POWER PLANT (Contract No. OM4-PO-DE-001)
B32: Gas Turbine set and its auxiliaries #1 - Embedded materials | G32: CASE | H32: 10 | I32: 8313 | J32: 9830 | K32: 19.866 | M32: EMBEDDED HARDWARE
G33: CASE | H33: 7 | I33: 8850 | J33: 10030 | K33: 18.938 | M33: EMBEDDED MATERIAL ASS'Y
G34: CASE | H34: 1 | I34: 422 | J34: 550 | K34: 2.215 | M34: FOUNDATION BOLT ASS'Y:M36 X 760
G35: CASE | H35: 1 | I35: 209 | J35: 340 | K35: 2.215 | M35: FOUNDATION BOLT M30X3X630
G36: CASE | H36: 1 | I36: 531 | J36: 660 | K36: 2.215 | M36: FOUNDATION BOLT M36X700
G37: CASE | H37: 13 | I37: 8975 | J37: 11055 | K37: 27.248
B38: Number of packages: | D38: 33 | E38: PKGS
G41: TOTAL | I41: =SUM(I29:I40) -> 27300 | J41: =SUM(J29:J40) -> 32465 | K41: =SUM(K29:K40) -> 72.697
G47: Signed by
H48: Jinho. Lee / Deputy Project Director

Sheet SHIPPING MARK(1)
A1: SHIPPING MARK
A2: O MON IV THERMAL POWER PLANT
A3: Address: O Mon Power Complex at Phuoc Thoi wards, O Mon district, Can Tho city
A4: SHIPPER | B4: : | C4: Doosan Enerbility Co., Ltd.
A5: ADDRESS | B5: : | C5: 22 DoosanVolvo-ro, Seongsan-gu, Chang-won-si, Gyeongsangnam-do 51711, Republic of Korea
A6: CONSIGNEE | B6: : | C6: Cty Doosan Enerbility Co.,Ltd HQ-Nha thau TH CV thuoc Goi thau so OM4-EPC-HHO-06 cho NMND O Mon IV Thoi Loi Area, Phuoc Thoi Ward, Can Tho City, Vietnam T : (+84) 367 566 167 F : (+84 243) 624 8485
A7: NOTIFY PARTY | B7: : | C7: Cty Doosan Enerbility Co.,Ltd HQ-Nha thau TH CV thuoc Goi thau so OM4-EPC-HHO-06 cho NMND O Mon IV Thoi Loi Area, Phươc Thoi Ward, Can Tho City, Vietnam T : (+84) 367 566 167 F : (+84 243) 624 8485 BRANCH OF KWANGJIN VIET NAM IN DUNG QUAT Co.,Ltd Dung Quat Economic Zone, Van Tuong Commune, Quang Ngai Province, Vietnam T : (+84) 28 3825 6330 Attn: Mr. Phuoc / Email: phuoc@kjtc.co.kr
A8: CONTRACT NO. | B8: : | C8: 06/2025/HĐ-PVN/OM4-06
A9: SHIPMENT NO. | B9: : | C9: OM4-DE-IS-0004
A10: EQUIPMENT DESCRIPTION | B10: : | C10: PLANT/ EQUIPMENT AND MATERIALS FOR O MON IV THERMAL
A11: DESCRIPTION OF GOODS | B11: : | L11: PL(2_2) Sheet 내 내용 반영 필요
A12: CONSIGNOR. | B12: : | C12: MPW
A13: PACKAGE NO. | B13: : | C13: ='PL(2_2)'!C15 -> OM4-DE-IS-0004-001 | L13: PL(2_2) Sheet 내 PKG 별 숫자 반영 필요
A14: NET WEIGHT | B14: : | C14: ='PL(2_2)'!N15 -> 640 | D14: KG
A15: GROSS WEIGHT | B15: : | C15: ='PL(2_2)'!O15 -> 810 | D15: KG
A16: - MEASUREMENT | B16: : | C16: ='PL(2_2)'!J15 -> 136 | D16: cm(L) X | E16: ='PL(2_2)'!K15 -> 136 | F16: cm (W) X | G16: ='PL(2_2)'!L15 -> 117 | H16: cm (H) | I16: ='PL(2_2)'!M15 -> 2.164 | J16: CBM
A17: LOADING PORT | B17: : | C17: KOBE, JAPAN
A18: PORT OF DESTINATION | B18: : | C18: Ho Chi Minh City Port, Vietnam
A19: COUNTRY OF ORIGIN | B19: : | C19: JAPAN
A20: QUALITY | B20: : | C20: 100% BRAND NEW

Sheet SHIPPING MARK(2)
A1: SHIPPING MARK
A2: O MON IV THERMAL POWER PLANT
A3: Address: O Mon Power Complex at Phuoc Thoi wards, O Mon district, Can Tho city
A4: SHIPPER | B4: : | C4: Doosan Enerbility Co., Ltd.
A5: ADDRESS | B5: : | C5: 22 DoosanVolvo-ro, Seongsan-gu, Chang-won-si, Gyeongsangnam-do 51711, Republic of Korea
A6: CONSIGNEE | B6: : | C6: Cty Doosan Enerbility Co.,Ltd HQ-Nha thau TH CV thuoc Goi thau so OM4-EPC-HHO-06 cho NMND O Mon IV Thoi Loi Area, Phuoc Thoi Ward, Can Tho City, Vietnam T : (+84) 367 566 167 F : (+84 243) 624 8485
A7: NOTIFY PARTY | B7: : | C7: Cty Doosan Enerbility Co.,Ltd HQ-Nha thau TH CV thuoc Goi thau so OM4-EPC-HHO-06 cho NMND O Mon IV Thoi Loi Area, Phươc Thoi Ward, Can Tho City, Vietnam T : (+84) 367 566 167 F : (+84 243) 624 8485 BRANCH OF KWANGJIN VIET NAM IN DUNG QUAT Co.,Ltd Dung Quat Economic Zone, Van Tuong Commune, Quang Ngai Province, Vietnam T : (+84) 28 3825 6330 Attn: Mr. Phuoc / Email: phuoc@kjtc.co.kr
A8: CONTRACT NO. | B8: : | C8: 06/2025/HĐ-PVN/OM4-06
A9: SHIPMENT NO. | B9: : | C9: OM4-DE-IS-0004
A10: EQUIPMENT DESCRIPTION | B10: : | C10: PLANT/ EQUIPMENT AND MATERIALS FOR O MON IV THERMAL
A11: DESCRIPTION OF GOODS | B11: : | L11: PL(2_2) Sheet 내 내용 반영 필요
A12: CONSIGNOR. | B12: : | C12: MPW
A13: PACKAGE NO. | B13: : | C13: ='PL(2_2)'!C16 -> OM4-DE-IS-0004-002 | L13: PL(2_2) Sheet 내 PKG 별 숫자 반영 필요
A14: NET WEIGHT | B14: : | C14: ='PL(2_2)'!N16 -> 470 | D14: KG
A15: GROSS WEIGHT | B15: : | C15: ='PL(2_2)'!O16 -> 640 | D15: KG
A16: - MEASUREMENT | B16: : | C16: ='PL(2_2)'!J16 -> 136 | D16: cm(L) X | E16: ='PL(2_2)'!K16 -> 136 | F16: cm (W) X | G16: ='PL(2_2)'!L16 -> 117 | H16: cm (H) | I16: ='PL(2_2)'!M16 -> 2.164 | J16: CBM
A17: LOADING PORT | B17: : | C17: KOBE, JAPAN
A18: PORT OF DESTINATION | B18: : | C18: Ho Chi Minh City Port, Vietnam
A19: COUNTRY OF ORIGIN | B19: : | C19: JAPAN
A20: QUALITY | B20: : | C20: 100% BRAND NEW

Sheet SHIPPING MARK(3)
A1: SHIPPING MARK
A2: O MON IV THERMAL POWER PLANT
A3: Address: O Mon Power Complex at Phuoc Thoi wards, O Mon district, Can Tho city
A4: SHIPPER | B4: : | C4: Doosan Enerbility Co., Ltd.
A5: ADDRESS | B5: : | C5: 22 DoosanVolvo-ro, Seongsan-gu, Chang-won-si, Gyeongsangnam-do 51711, Republic of Korea
A6: CONSIGNEE | B6: : | C6: Cty Doosan Enerbility Co.,Ltd HQ-Nha thau TH CV thuoc Goi thau so OM4-EPC-HHO-06 cho NMND O Mon IV Thoi Loi Area, Phuoc Thoi Ward, Can Tho City, Vietnam T : (+84) 367 566 167 F : (+84 243) 624 8485
A7: NOTIFY PARTY | B7: : | C7: Cty Doosan Enerbility Co.,Ltd HQ-Nha thau TH CV thuoc Goi thau so OM4-EPC-HHO-06 cho NMND O Mon IV Thoi Loi Area, Phươc Thoi Ward, Can Tho City, Vietnam T : (+84) 367 566 167 F : (+84 243) 624 8485 BRANCH OF KWANGJIN VIET NAM IN DUNG QUAT Co.,Ltd Dung Quat Economic Zone, Van Tuong Commune, Quang Ngai Province, Vietnam T : (+84) 28 3825 6330 Attn: Mr. Phuoc / Email: phuoc@kjtc.co.kr
A8: CONTRACT NO. | B8: : | C8: 06/2025/HĐ-PVN/OM4-06
A9: SHIPMENT NO. | B9: : | C9: OM4-DE-IS-0004
A10: EQUIPMENT DESCRIPTION | B10: : | C10: PLANT/ EQUIPMENT AND MATERIALS FOR O MON IV THERMAL
A11: DESCRIPTION OF GOODS | B11: : | L11: PL(2_2) Sheet 내 내용 반영 필요
A12: CONSIGNOR. | B12: : | C12: MPW
A13: PACKAGE NO. | B13: : | C13: ='PL(2_2)'!C17 -> OM4-DE-IS-0004-003 | L13: PL(2_2) Sheet 내 PKG 별 숫자 반영 필요
A14: NET WEIGHT | B14: : | C14: ='PL(2_2)'!N17 -> 690 | D14: KG
A15: GROSS WEIGHT | B15: : | C15: ='PL(2_2)'!O17 -> 850 | D15: KG
A16: - MEASUREMENT | B16: : | C16: ='PL(2_2)'!J17 -> 136 | D16: cm(L) X | E16: ='PL(2_2)'!K17 -> 136 | F16: cm (W) X | G16: ='PL(2_2)'!L17 -> 117 | H16: cm (H) | I16: ='PL(2_2)'!M17 -> 2.164 | J16: CBM
A17: LOADING PORT | B17: : | C17: KOBE, JAPAN
A18: PORT OF DESTINATION | B18: : | C18: Ho Chi Minh City Port, Vietnam
A19: COUNTRY OF ORIGIN | B19: : | C19: JAPAN
A20: QUALITY | B20: : | C20: 100% BRAND NEW

Sheet SHIPPING MARK(4)
A1: SHIPPING MARK
A2: O MON IV THERMAL POWER PLANT
A3: Address: O Mon Power Complex at Phuoc Thoi wards, O Mon district, Can Tho city
A4: SHIPPER | B4: : | C4: Doosan Enerbility Co., Ltd.
A5: ADDRESS | B5: : | C5: 22 DoosanVolvo-ro, Seongsan-gu, Chang-won-si, Gyeongsangnam-do 51711, Republic of Korea
A6: CONSIGNEE | B6: : | C6: Cty Doosan Enerbility Co.,Ltd HQ-Nha thau TH CV thuoc Goi thau so OM4-EPC-HHO-06 cho NMND O Mon IV Thoi Loi Area, Phuoc Thoi Ward, Can Tho City, Vietnam T : (+84) 367 566 167 F : (+84 243) 624 8485
A7: NOTIFY PARTY | B7: : | C7: Cty Doosan Enerbility Co.,Ltd HQ-Nha thau TH CV thuoc Goi thau so OM4-EPC-HHO-06 cho NMND O Mon IV Thoi Loi Area, Phươc Thoi Ward, Can Tho City, Vietnam T : (+84) 367 566 167 F : (+84 243) 624 8485 BRANCH OF KWANGJIN VIET NAM IN DUNG QUAT Co.,Ltd Dung Quat Economic Zone, Van Tuong Commune, Quang Ngai Province, Vietnam T : (+84) 28 3825 6330 Attn: Mr. Phuoc / Email: phuoc@kjtc.co.kr
A8: CONTRACT NO. | B8: : | C8: 06/2025/HĐ-PVN/OM4-06
A9: SHIPMENT NO. | B9: : | C9: OM4-DE-IS-0004
A10: EQUIPMENT DESCRIPTION | B10: : | C10: PLANT/ EQUIPMENT AND MATERIALS FOR O MON IV THERMAL
A11: DESCRIPTION OF GOODS | B11: : | L11: PL(2_2) Sheet 내 내용 반영 필요
A12: CONSIGNOR. | B12: : | C12: MPW
A13: PACKAGE NO. | B13: : | C13: ='PL(2_2)'!C18 -> OM4-DE-IS-0004-004 | L13: PL(2_2) Sheet 내 PKG 별 숫자 반영 필요
A14: NET WEIGHT | B14: : | C14: ='PL(2_2)'!N18 -> 950 | D14: KG
A15: GROSS WEIGHT | B15: : | C15: ='PL(2_2)'!O18 -> 1110 | D15: KG
A16: - MEASUREMENT | B16: : | C16: ='PL(2_2)'!J18 -> 136 | D16: cm(L) X | E16: ='PL(2_2)'!K18 -> 136 | F16: cm (W) X | G16: ='PL(2_2)'!L18 -> 117 | H16: cm (H) | I16: ='PL(2_2)'!M18 -> 2.164 | J16: CBM
A17: LOADING PORT | B17: : | C17: KOBE, JAPAN
A18: PORT OF DESTINATION | B18: : | C18: Ho Chi Minh City Port, Vietnam
A19: COUNTRY OF ORIGIN | B19: : | C19: JAPAN
A20: QUALITY | B20: : | C20: 100% BRAND NEW

Sheet SHIPPING MARK(5)
A1: SHIPPING MARK
A2: O MON IV THERMAL POWER PLANT
A3: Address: O Mon Power Complex at Phuoc Thoi wards, O Mon district, Can Tho city
A4: SHIPPER | B4: : | C4: Doosan Enerbility Co., Ltd.
A5: ADDRESS | B5: : | C5: 22 DoosanVolvo-ro, Seongsan-gu, Chang-won-si, Gyeongsangnam-do 51711, Republic of Korea
A6: CONSIGNEE | B6: : | C6: Cty Doosan Enerbility Co.,Ltd HQ-Nha thau TH CV thuoc Goi thau so OM4-EPC-HHO-06 cho NMND O Mon IV Thoi Loi Area, Phuoc Thoi Ward, Can Tho City, Vietnam T : (+84) 367 566 167 F : (+84 243) 624 8485
A7: NOTIFY PARTY | B7: : | C7: Cty Doosan Enerbility Co.,Ltd HQ-Nha thau TH CV thuoc Goi thau so OM4-EPC-HHO-06 cho NMND O Mon IV Thoi Loi Area, Phươc Thoi Ward, Can Tho City, Vietnam T : (+84) 367 566 167 F : (+84 243) 624 8485 BRANCH OF KWANGJIN VIET NAM IN DUNG QUAT Co.,Ltd Dung Quat Economic Zone, Van Tuong Commune, Quang Ngai Province, Vietnam T : (+84) 28 3825 6330 Attn: Mr. Phuoc / Email: phuoc@kjtc.co.kr
A8: CONTRACT NO. | B8: : | C8: 06/2025/HĐ-PVN/OM4-06
A9: SHIPMENT NO. | B9: : | C9: OM4-DE-IS-0004
A10: EQUIPMENT DESCRIPTION | B10: : | C10: PLANT/ EQUIPMENT AND MATERIALS FOR O MON IV THERMAL
A11: DESCRIPTION OF GOODS | B11: : | L11: PL(2_2) Sheet 내 내용 반영 필요
A12: CONSIGNOR. | B12: : | C12: MPW
A13: PACKAGE NO. | B13: : | C13: ='PL(2_2)'!C19 -> OM4-DE-IS-0004-005 | L13: PL(2_2) Sheet 내 PKG 별 숫자 반영 필요
A14: NET WEIGHT | B14: : | C14: ='PL(2_2)'!N19 -> 830 | D14: KG
A15: GROSS WEIGHT | B15: : | C15: ='PL(2_2)'!O19 -> 990 | D15: KG
A16: - MEASUREMENT | B16: : | C16: ='PL(2_2)'!J19 -> 136 | D16: cm(L) X | E16: ='PL(2_2)'!K19 -> 136 | F16: cm (W) X | G16: ='PL(2_2)'!L19 -> 117 | H16: cm (H) | I16: ='PL(2_2)'!M19 -> 2.164 | J16: CBM
A17: LOADING PORT | B17: : | C17: KOBE, JAPAN
A18: PORT OF DESTINATION | B18: : | C18: Ho Chi Minh City Port, Vietnam
A19: COUNTRY OF ORIGIN | B19: : | C19: JAPAN
A20: QUALITY | B20: : | C20: 100% BRAND NEW

Sheet SHIPPING MARK(6)
A1: SHIPPING MARK
A2: O MON IV THERMAL POWER PLANT
A3: Address: O Mon Power Complex at Phuoc Thoi wards, O Mon district, Can Tho city
A4: SHIPPER | B4: : | C4: Doosan Enerbility Co., Ltd.
A5: ADDRESS | B5: : | C5: 22 DoosanVolvo-ro, Seongsan-gu, Chang-won-si, Gyeongsangnam-do 51711, Republic of Korea
A6: CONSIGNEE | B6: : | C6: Cty Doosan Enerbility Co.,Ltd HQ-Nha thau TH CV thuoc Goi thau so OM4-EPC-HHO-06 cho NMND O Mon IV Thoi Loi Area, Phuoc Thoi Ward, Can Tho City, Vietnam T : (+84) 367 566 167 F : (+84 243) 624 8485
A7: NOTIFY PARTY | B7: : | C7: Cty Doosan Enerbility Co.,Ltd HQ-Nha thau TH CV thuoc Goi thau so OM4-EPC-HHO-06 cho NMND O Mon IV Thoi Loi Area, Phươc Thoi Ward, Can Tho City, Vietnam T : (+84) 367 566 167 F : (+84 243) 624 8485 BRANCH OF KWANGJIN VIET NAM IN DUNG QUAT Co.,Ltd Dung Quat Economic Zone, Van Tuong Commune, Quang Ngai Province, Vietnam T : (+84) 28 3825 6330 Attn: Mr. Phuoc / Email: phuoc@kjtc.co.kr
A8: CONTRACT NO. | B8: : | C8: 06/2025/HĐ-PVN/OM4-06
A9: SHIPMENT NO. | B9: : | C9: OM4-DE-IS-0004
A10: EQUIPMENT DESCRIPTION | B10: : | C10: PLANT/ EQUIPMENT AND MATERIALS FOR O MON IV THERMAL
A11: DESCRIPTION OF GOODS | B11: : | L11: PL(2_2) Sheet 내 내용 반영 필요
A12: CONSIGNOR. | B12: : | C12: MPW
A13: PACKAGE NO. | B13: : | C13: ='PL(2_2)'!C20 -> OM4-DE-IS-0004-006 | L13: PL(2_2) Sheet 내 PKG 별 숫자 반영 필요
A14: NET WEIGHT | B14: : | C14: ='PL(2_2)'!N20 -> 240 | D14: KG
A15: GROSS WEIGHT | B15: : | C15: ='PL(2_2)'!O20 -> 380 | D15: KG
A16: - MEASUREMENT | B16: : | C16: ='PL(2_2)'!J20 -> 157 | D16: cm(L) X | E16: ='PL(2_2)'!K20 -> 123 | F16: cm (W) X | G16: ='PL(2_2)'!L20 -> 66 | H16: cm (H) | I16: ='PL(2_2)'!M20 -> 1.275 | J16: CBM
A17: LOADING PORT | B17: : | C17: KOBE, JAPAN
A18: PORT OF DESTINATION | B18: : | C18: Ho Chi Minh City Port, Vietnam
A19: COUNTRY OF ORIGIN | B19: : | C19: JAPAN
A20: QUALITY | B20: : | C20: 100% BRAND NEW

Sheet SHIPPING MARK(7)
A1: SHIPPING MARK
A2: O MON IV THERMAL POWER PLANT
A3: Address: O Mon Power Complex at Phuoc Thoi wards, O Mon district, Can Tho city
A4: SHIPPER | B4: : | C4: Doosan Enerbility Co., Ltd.
A5: ADDRESS | B5: : | C5: 22 DoosanVolvo-ro, Seongsan-gu, Chang-won-si, Gyeongsangnam-do 51711, Republic of Korea
A6: CONSIGNEE | B6: : | C6: Cty Doosan Enerbility Co.,Ltd HQ-Nha thau TH CV thuoc Goi thau so OM4-EPC-HHO-06 cho NMND O Mon IV Thoi Loi Area, Phuoc Thoi Ward, Can Tho City, Vietnam T : (+84) 367 566 167 F : (+84 243) 624 8485
A7: NOTIFY PARTY | B7: : | C7: Cty Doosan Enerbility Co.,Ltd HQ-Nha thau TH CV thuoc Goi thau so OM4-EPC-HHO-06 cho NMND O Mon IV Thoi Loi Area, Phươc Thoi Ward, Can Tho City, Vietnam T : (+84) 367 566 167 F : (+84 243) 624 8485 BRANCH OF KWANGJIN VIET NAM IN DUNG QUAT Co.,Ltd Dung Quat Economic Zone, Van Tuong Commune, Quang Ngai Province, Vietnam T : (+84) 28 3825 6330 Attn: Mr. Phuoc / Email: phuoc@kjtc.co.kr
A8: CONTRACT NO. | B8: : | C8: 06/2025/HĐ-PVN/OM4-06
A9: SHIPMENT NO. | B9: : | C9: OM4-DE-IS-0004
A10: EQUIPMENT DESCRIPTION | B10: : | C10: PLANT/ EQUIPMENT AND MATERIALS FOR O MON IV THERMAL
A11: DESCRIPTION OF GOODS | B11: : | L11: PL(2_2) Sheet 내 내용 반영 필요
A12: CONSIGNOR. | B12: : | C12: MPW
A13: PACKAGE NO. | B13: : | C13: ='PL(2_2)'!C21 -> OM4-DE-IS-0004-007 | L13: PL(2_2) Sheet 내 PKG 별 숫자 반영 필요
A14: NET WEIGHT | B14: : | C14: ='PL(2_2)'!N21 -> 1580 | D14: KG
A15: GROSS WEIGHT | B15: : | C15: ='PL(2_2)'!O21 -> 1730 | D15: KG
A16: - MEASUREMENT | B16: : | C16: ='PL(2_2)'!J21 -> 136 | D16: cm(L) X | E16: ='PL(2_2)'!K21 -> 136 | F16: cm (W) X | G16: ='PL(2_2)'!L21 -> 142 | H16: cm (H) | I16: ='PL(2_2)'!M21 -> 2.626 | J16: CBM
A17: LOADING PORT | B17: : | C17: KOBE, JAPAN
A18: PORT OF DESTINATION | B18: : | C18: Ho Chi Minh City Port, Vietnam
A19: COUNTRY OF ORIGIN | B19: : | C19: JAPAN
A20: QUALITY | B20: : | C20: 100% BRAND NEW

Sheet SHIPPING MARK(8)
A1: SHIPPING MARK
A2: O MON IV THERMAL POWER PLANT
A3: Address: O Mon Power Complex at Phuoc Thoi wards, O Mon district, Can Tho city
A4: SHIPPER | B4: : | C4: Doosan Enerbility Co., Ltd.
A5: ADDRESS | B5: : | C5: 22 DoosanVolvo-ro, Seongsan-gu, Chang-won-si, Gyeongsangnam-do 51711, Republic of Korea
A6: CONSIGNEE | B6: : | C6: Cty Doosan Enerbility Co.,Ltd HQ-Nha thau TH CV thuoc Goi thau so OM4-EPC-HHO-06 cho NMND O Mon IV Thoi Loi Area, Phuoc Thoi Ward, Can Tho City, Vietnam T : (+84) 367 566 167 F : (+84 243) 624 8485
A7: NOTIFY PARTY | B7: : | C7: Cty Doosan Enerbility Co.,Ltd HQ-Nha thau TH CV thuoc Goi thau so OM4-EPC-HHO-06 cho NMND O Mon IV Thoi Loi Area, Phươc Thoi Ward, Can Tho City, Vietnam T : (+84) 367 566 167 F : (+84 243) 624 8485 BRANCH OF KWANGJIN VIET NAM IN DUNG QUAT Co.,Ltd Dung Quat Economic Zone, Van Tuong Commune, Quang Ngai Province, Vietnam T : (+84) 28 3825 6330 Attn: Mr. Phuoc / Email: phuoc@kjtc.co.kr
A8: CONTRACT NO. | B8: : | C8: 06/2025/HĐ-PVN/OM4-06
A9: SHIPMENT NO. | B9: : | C9: OM4-DE-IS-0004
A10: EQUIPMENT DESCRIPTION | B10: : | C10: PLANT/ EQUIPMENT AND MATERIALS FOR O MON IV THERMAL
A11: DESCRIPTION OF GOODS | B11: : | L11: PL(2_2) Sheet 내 내용 반영 필요
A12: CONSIGNOR. | B12: : | C12: MPW
A13: PACKAGE NO. | B13: : | C13: ='PL(2_2)'!C22 -> OM4-DE-IS-0004-008 | L13: PL(2_2) Sheet 내 PKG 별 숫자 반영 필요
A14: NET WEIGHT | B14: : | C14: ='PL(2_2)'!N22 -> 1580 | D14: KG
A15: GROSS WEIGHT | B15: : | C15: ='PL(2_2)'!O22 -> 1750 | D15: KG
A16: - MEASUREMENT | B16: : | C16: ='PL(2_2)'!J22 -> 136 | D16: cm(L) X | E16: ='PL(2_2)'!K22 -> 136 | F16: cm (W) X | G16: ='PL(2_2)'!L22 -> 142 | H16: cm (H) | I16: ='PL(2_2)'!M22 -> 2.626 | J16: CBM
A17: LOADING PORT | B17: : | C17: KOBE, JAPAN
A18: PORT OF DESTINATION | B18: : | C18: Ho Chi Minh City Port, Vietnam
A19: COUNTRY OF ORIGIN | B19: : | C19: JAPAN
A20: QUALITY | B20: : | C20: 100% BRAND NEW

Sheet SHIPPING MARK(9)
A1: SHIPPING MARK
A2: O MON IV THERMAL POWER PLANT
