Workbook
Name _Hlk215568700: PSIC!$B$2
Name latent: #REF!
Name tube_test_press1_12: #REF!

Sheet Break Down CI (Rve1)
X4: 1 | Y4: 15750
A5: INVOICE NO. : | D5: ='Commercial Invoice'!H5 -> OM4-DE-IS-0005 | H5: PLACE : | O5: ='Commercial Invoice'!G6 -> DATE: | P5: 46219 | X5: 2 | Y5: 9817.5
X6: 3 | Y6: 14280
A7: SI. No. | B7: Package No. | C7: Vị trí | D7: COMMODITY/DESCRIPTION OF GOODS | E7: Tên hàng (mô tả chi tiết) | F7: Mã HS | G7: POSITION IN PRICE SCHEDULE | H7: POSITION IN THE MASTER LIST | I7: QUANTITY | J7: UNIT | K7: NET WEIGHT (KG) | L7: UNIT PRICE (USD) | M7: AMOUNT (USD) | N7: DWG No. | O7: ASSEMBLY D.W.G NO. | P7: Remark (**) | X7: 4 | Y7: 12495
A8: 1 | B8: OM4-MG-GEN1-KOB-0001 | C8: S1 | D8: GROUT RETAINER | E8: Khung cố định chân đế, bằng thép, đặt sẵn, đã được gia công để dùng làm kết cấu, dùng cho hệ thống máy phát điện tuabin khí số #1, số DWG No.: A13C454 -G01, hàng mới 100% - GROUT RETAINER | F8: 73089099 | G8: PS 1.1, Ⅰ, 2 | H8: N/A | I8: 4 | J8: PCS | K8: 300 | L8: =ROUND(M8/I8,2) -> 2423.5 | M8: 9693.98 | N8: A13C454 -G01 | P8: G1
A9: 2 | B9: OM4-MG-GEN1-KOB-0002 | C9: S1 | D9: GROUT RETAINER | E9: Khung cố định chân đế, bằng thép, đặt sẵn, đã được gia công để dùng làm kết cấu, dùng cho hệ thống máy phát điện tuabin khí số #1, số DWG No.: A13C454 -G02, hàng mới 100% - GROUT RETAINER | F9: 73089099 | G9: PS 1.1, Ⅰ, 2 | H9: N/A | I9: 1 | J9: PCE | K9: 55.555556 | L9: =ROUND(M9/I9,2) -> 4350.94 | M9: 4350.94 | N9: A13C454 -G02 | P9: G1
A10: 3 | B10: OM4-MG-GEN1-KOB-0002 | C10: S1 | D10: GROUT RETAINER | E10: Khung cố định chân đế, bằng thép, đặt sẵn, đã được gia công để dùng làm kết cấu, dùng cho hệ thống máy phát điện tuabin khí số #1, số DWG No.: A13C454 -G03, hàng mới 100% - GROUT RETAINER | F10: 73089099 | G10: PS 1.1, Ⅰ, 2 | H10: N/A | I10: 1 | J10: PCE | K10: 55.555556 | L10: =ROUND(M10/I10,2) -> 4350.94 | M10: 4350.94 | N10: A13C454 -G03 | P10: G1
A11: 4 | B11: OM4-MG-GEN1-KOB-0002 | C11: S1 | D11: GROUT RETAINER | E11: Khung cố định chân đế, bằng thép, đặt sẵn, đã được gia công để dùng làm kết cấu, dùng cho hệ thống máy phát điện tuabin khí số #1, số DWG No.: A13C454 -G04, hàng mới 100% - GROUT RETAINER | F11: 73089099 | G11: PS 1.1, Ⅰ, 2 | H11: N/A | I11: 1 | J11: PCE | K11: 55.555556 | L11: =ROUND(M11/I11,2) -> 4350.94 | M11: 4350.94 | N11: A13C454 -G04 | P11: G1
A12: 5 | B12: OM4-MG-GEN1-KOB-0002 | C12: S1 | D12: GROUT RETAINER | E12: Khung cố định chân đế, bằng thép, đặt sẵn, đã được gia công để dùng làm kết cấu, dùng cho hệ thống máy phát điện tuabin khí số #1, số DWG No.: A13C454 -G05, hàng mới 100% - GROUT RETAINER | F12: 73089099 | G12: PS 1.1, Ⅰ, 2 | H12: N/A | I12: 1 | J12: PCE | K12: 55.555556 | L12: =ROUND(M12/I12,2) -> 4350.94 | M12: 4350.94 | N12: A13C454 -G05 | P12: G1
A13: 6 | B13: OM4-MG-GEN1-KOB-0002 | C13: S1 | D13: GROUT RETAINER | E13: Khung cố định chân đế, bằng thép, đặt sẵn, đã được gia công để dùng làm kết cấu, dùng cho hệ thống máy phát điện tuabin khí số #1, số DWG No.: A13C454 -G06, hàng mới 100% - GROUT RETAINER | F13: 73089099 | G13: PS 1.1, Ⅰ, 2 | H13: N/A | I13: 2 | J13: PCS | K13: 111.11111 | L13: =ROUND(M13/I13,2) -> 2782.64 | M13: 5565.27 | N13: A13C454 -G06 | P13: G1
A14: 7 | B14: OM4-MG-GEN1-KOB-0002 | C14: S1 | D14: GROUT RETAINER | E14: Khung cố định chân đế, bằng thép, đặt sẵn, đã được gia công để dùng làm kết cấu, dùng cho hệ thống máy phát điện tuabin khí số #1, số DWG No.: A13C454 -G07, hàng mới 100% - GROUT RETAINER | F14: 73089099 | G14: PS 1.1, Ⅰ, 2 | H14: N/A | I14: 2 | J14: PCS | K14: 111.11111 | L14: =ROUND(M14/I14,2) -> 2782.64 | M14: 5565.27 | N14: A13C454 -G07 | P14: G1
A15: 8 | B15: OM4-MG-GEN1-KOB-0002 | C15: S1 | D15: GROUT RETAINER | E15: Khung cố định chân đế, bằng thép, đặt sẵn, đã được gia công để dùng làm kết cấu, dùng cho hệ thống máy phát điện tuabin khí số #1, số DWG No.: A13C454 -G08, hàng mới 100% - GROUT RETAINER | F15: 73089099 | G15: PS 1.1, Ⅰ, 2 | H15: N/A | I15: 1 | J15: PCE | K15: 55.555556 | L15: =ROUND(M15/I15,2) -> 4350.94 | M15: 4350.94 | N15: A13C454 -G08 | P15: G1
A16: 9 | B16: OM4-MG-GEN1-KOB-0004 | C16: S1 | D16: ANCHOR BLOCK | E16: Tấm khóa cố định chân đế, bằng thép, đặt sẵn, đã được gia công để dùng làm kết cấu, dùng cho hệ thống máy phát điện tuabin khí số #1, số DWG No.: AS29212 -G03, hàng mới 100% - ANCHOR BLOCK | F16: 73089099 | G16: PS 1.1, Ⅰ, 2 | H16: N/A | I16: 1 | J16: PCE | K16: 447 | L16: =ROUND(M16/I16,2) -> 9770.49 | M16: 9770.49 | N16: AS29212 -G03 | O16: EB102586 | P16: G1
A17: 10 | B17: OM4-MG-GEN1-KOB-0005 | C17: S1 | D17: ANCHOR BLOCK | E17: Tấm khóa cố định chân đế, bằng thép, đặt sẵn, đã được gia công để dùng làm kết cấu, dùng cho hệ thống máy phát điện tuabin khí số #1, số DWG No.: AS29643 -G03, hàng mới 100% - ANCHOR BLOCK | F17: 73089099 | G17: PS 1.1, Ⅰ, 2 | H17: N/A | I17: 1 | J17: PCE | K17: 676 | L17: =ROUND(M17/I17,2) -> 14775.95 | M17: 14775.95 | N17: AS29643 -G03 | O17: EB102586 | P17: G1
A18: 11 | B18: OM4-MG-GEN1-KOB-0006 | C18: S1 | D18: BOX 1/4 | E18: Hộp gia cố chân đế, bằng thép, đặt sẵn, đã được gia công để dùng làm kết cấu, dùng cho hệ thống máy phát điện tuabin khí số #1, số DWG No.: A12R049 -G01, hàng mới 100% - BOX 1/4 | F18: 73089099 | G18: PS 1.1, Ⅰ, 2 | H18: N/A | I18: 2 | J18: PCS | K18: 540 | L18: =ROUND(M18/I18,2) -> 5901.64 | M18: 11803.27 | N18: A12R049 -G01 | O18: EB102585 | P18: G1
A19: 12 | B19: OM4-MG-GEN1-KOB-0007 | C19: S1 | D19: BOX 2/4 | E19: Hộp gia cố chân đế, bằng thép, đặt sẵn, đã được gia công để dùng làm kết cấu, dùng cho hệ thống máy phát điện tuabin khí số #1, số DWG No.: A12R049 -G01, hàng mới 100% - BOX 2/4 | F19: 73089099 | G19: PS 1.1, Ⅰ, 2 | H19: N/A | I19: 2 | J19: PCS | K19: 540 | L19: =ROUND(M19/I19,2) -> 5901.64 | M19: 11803.27 | N19: A12R049 -G01 | O19: EB102585 | P19: G1
A20: 13 | B20: OM4-MG-GEN1-KOB-0008 | C20: S1 | D20: BOX 3/4 | E20: Hộp gia cố chân đế, bằng thép, đặt sẵn, đã được gia công để dùng làm kết cấu, dùng cho hệ thống máy phát điện tuabin khí số #1, số DWG No.: A12R049 -G01, hàng mới 100% - BOX 3/4 | F20: 73089099 | G20: PS 1.1, Ⅰ, 2 | H20: N/A | I20: 2 | J20: PCS | K20: 540 | L20: =ROUND(M20/I20,2) -> 5901.64 | M20: 11803.27 | N20: A12R049 -G01 | O20: EB102585 | P20: G1
A21: 14 | B21: OM4-MG-GEN1-KOB-0009 | C21: S1 | D21: BOX 4/4 | E21: Hộp gia cố chân đế, bằng thép, đặt sẵn, đã được gia công để dùng làm kết cấu, dùng cho hệ thống máy phát điện tuabin khí số #1, số DWG No.: A12R049 -G01, hàng mới 100% - BOX 4/4 | F21: 73089099 | G21: PS 1.1, Ⅰ, 2 | H21: N/A | I21: 2 | J21: PCS | K21: 540 | L21: =ROUND(M21/I21,2) -> 5901.64 | M21: 11803.27 | N21: A12R049 -G01 | O21: EB102585 | P21: G1
A22: 15 | B22: OM4-MG-GEN1-KOB-0010 | C22: S1 | D22: COVER | E22: Tấm che hộp gia cố chân đế, bằng thép, đặt sẵn, đã được gia công để dùng làm kết cấu, dùng cho hệ thống máy phát điện tuabin khí số #1, số DWG No.: A12R049 -G02, hàng mới 100% - COVER | F22: 73089099 | G22: PS 1.1, Ⅰ, 2 | H22: N/A | I22: 8 | J22: PCS | K22: 55 | L22: =ROUND(M22/I22,2) -> 150.27 | M22: 1202.19 | N22: A12R049 -G02 | O22: EB102585 | P22: G1
A23: 16 | B23: OM4-MG-GEN1-MAR-0001 | C23: S1 | D23: EMBEDDED METAL-1 (Fe) 200X500X159 | E23: Tấm nền móng, bằng thép, đặt sẵn, đã được gia công để dùng làm kết cấu, dùng cho hệ thống máy phát điện tuabin khí số #1, kích thước: 200X500X159mm, hàng mới 100% - EMBEDDED METAL-1 (Fe) 200X500X159 | F23: 73089099 | G23: PS 1.1, Ⅰ, 2 | H23: N/A | I23: 3 | J23: PCS | K23: 18.333333 | L23: =ROUND(M23/I23,2) -> 133.58 | M23: 400.73 | O23: OM4-DE-XB02-P0MKC-EL-230144 (EBT3-EAY-EG12) | P23: G1
A24: 17 | B24: OM4-MG-GEN1-MAR-0001 | C24: S1 | D24: EMBEDDED METAL-2 (Fe) 200X200X159 | E24: Tấm nền móng, bằng thép, đặt sẵn, đã được gia công để dùng làm kết cấu, dùng cho hệ thống máy phát điện tuabin khí số #1, kích thước: 200X200X159mm, hàng mới 100% - EMBEDDED METAL-2 (Fe) 200X200X159 | F24: 73089099 | G24: PS 1.1, Ⅰ, 2 | H24: N/A | I24: 4 | J24: PCS | K24: 24.444444 | L24: =ROUND(M24/I24,2) -> 133.58 | M24: 534.3 | O24: OM4-DE-XB02-P0MKC-EL-230144 (EBT3-EAY-EG12) | P24: G1
A25: 18 | B25: OM4-MG-GEN1-MAR-0001 | C25: S1 | D25: EMBEDDED METAL-1 (Fe) 200X500X159 | E25: Tấm nền móng, bằng thép, đặt sẵn, đã được gia công để dùng làm kết cấu, dùng cho hệ thống máy phát điện tuabin khí số #1, kích thước: 200x500x159mm, hàng mới 100% - EMBEDDED METAL-1 (Fe) 200X500X159 | F25: 73089099 | G25: PS 1.1, Ⅰ, 2 | H25: N/A | I25: 1 | J25: PCE | K25: 6.1111111 | L25: =ROUND(M25/I25,2) -> 133.58 | M25: 133.58 | O25: OM4-DE-XB02-P0MKC-EL-230144 (EBT3-EAY-EG12) | P25: G1
A26: 19 | B26: OM4-MG-GEN1-MAR-0001 | C26: S1 | D26: EMBEDDED METAL-2 (Fe) 200X200X159 | E26: Tấm nền móng, bằng thép, đặt sẵn, đã được gia công để dùng làm kết cấu, dùng cho hệ thống máy phát điện tuabin khí số #1, kích thước: 200x200x159mm, hàng mới 100% - EMBEDDED METAL-2 (Fe) 200X200X159 | F26: 73089099 | G26: PS 1.1, Ⅰ, 2 | H26: N/A | I26: 1 | J26: PCE | K26: 6.1111111 | L26: =ROUND(M26/I26,2) -> 133.58 | M26: 133.58 | O26: OM4-DE-XB02-P0MKC-EL-230144 (EBT3-EAY-EG12) | P26: G1
A27: 20 | B27: OM4-MG-GEN2-KOB-0001 | C27: S1 | D27: GROUT RETAINER | E27: Khung cố định chân đế, bằng thép, đặt sẵn, đã được gia công để dùng làm kết cấu, dùng cho hệ thống máy phát điện tuabin khí số #2, số DWG No.: A13C454 -G01, hàng mới 100% - GROUT RETAINER | F27: 73089099 | G27: PS 1.1, Ⅰ, 4 | H27: N/A | I27: 4 | J27: PCS | K27: 300 | L27: =ROUND(M27/I27,2) -> 2423.5 | M27: 9693.98 | N27: A13C454 -G01 | P27: G2
A28: 21 | B28: OM4-MG-GEN2-KOB-0002 | C28: S1 | D28: GROUT RETAINER | E28: Khung cố định chân đế, bằng thép, đặt sẵn, đã được gia công để dùng làm kết cấu, dùng cho hệ thống máy phát điện tuabin khí số #2, số DWG No.: A13C454 -G02, hàng mới 100% - GROUT RETAINER | F28: 73089099 | G28: PS 1.1, Ⅰ, 4 | H28: N/A | I28: 1 | J28: PCE | K28: 55.555556 | L28: =ROUND(M28/I28,2) -> 4350.94 | M28: 4350.94 | N28: A13C454 -G02 | P28: G2
A29: 22 | B29: OM4-MG-GEN2-KOB-0002 | C29: S1 | D29: GROUT RETAINER | E29: Khung cố định chân đế, bằng thép, đặt sẵn, đã được gia công để dùng làm kết cấu, dùng cho hệ thống máy phát điện tuabin khí số #2, số DWG No.: A13C454 -G03, hàng mới 100% - GROUT RETAINER | F29: 73089099 | G29: PS 1.1, Ⅰ, 4 | H29: N/A | I29: 1 | J29: PCE | K29: 55.555556 | L29: =ROUND(M29/I29,2) -> 4350.94 | M29: 4350.94 | N29: A13C454 -G03 | P29: G2
A30: 23 | B30: OM4-MG-GEN2-KOB-0002 | C30: S1 | D30: GROUT RETAINER | E30: Khung cố định chân đế, bằng thép, đặt sẵn, đã được gia công để dùng làm kết cấu, dùng cho hệ thống máy phát điện tuabin khí số #2, số DWG No.: A13C454 -G04, hàng mới 100% - GROUT RETAINER | F30: 73089099 | G30: PS 1.1, Ⅰ, 4 | H30: N/A | I30: 1 | J30: PCE | K30: 55.555556 | L30: =ROUND(M30/I30,2) -> 4350.94 | M30: 4350.94 | N30: A13C454 -G04 | P30: G2
A31: 24 | B31: OM4-MG-GEN2-KOB-0002 | C31: S1 | D31: GROUT RETAINER | E31: Khung cố định chân đế, bằng thép, đặt sẵn, đã được gia công để dùng làm kết cấu, dùng cho hệ thống máy phát điện tuabin khí số #2, số DWG No.: A13C454 -G05 -GROUT RETAINER | F31: 73089099 | G31: PS 1.1, Ⅰ, 4 | H31: N/A | I31: 1 | J31: PCE | K31: 55.555556 | L31: =ROUND(M31/I31,2) -> 4350.94 | M31: 4350.94 | N31: A13C454 -G05 | P31: G2
A32: 25 | B32: OM4-MG-GEN2-KOB-0002 | C32: S1 | D32: GROUT RETAINER | E32: Khung cố định chân đế, bằng thép, đặt sẵn, đã được gia công để dùng làm kết cấu, dùng cho hệ thống máy phát điện tuabin khí số #2, số DWG No.: A13C454 -G06, hàng mới 100% - GROUT RETAINER | F32: 73089099 | G32: PS 1.1, Ⅰ, 4 | H32: N/A | I32: 2 | J32: PCS | K32: 111.11111 | L32: =ROUND(M32/I32,2) -> 2782.64 | M32: 5565.27 | N32: A13C454 -G06 | P32: G2
A33: 26 | B33: OM4-MG-GEN2-KOB-0002 | C33: S1 | D33: GROUT RETAINER | E33: Khung cố định chân đế, bằng thép, đặt sẵn, đã được gia công để dùng làm kết cấu, dùng cho hệ thống máy phát điện tuabin khí số #2, số DWG No.: A13C454 -G07, hàng mới 100% - GROUT RETAINER | F33: 73089099 | G33: PS 1.1, Ⅰ, 4 | H33: N/A | I33: 2 | J33: PCS | K33: 111.11111 | L33: =ROUND(M33/I33,2) -> 2782.64 | M33: 5565.27 | N33: A13C454 -G07 | P33: G2
A34: 27 | B34: OM4-MG-GEN2-KOB-0002 | C34: S1 | D34: GROUT RETAINER | E34: Khung cố định chân đế, bằng thép, đặt sẵn, đã được gia công để dùng làm kết cấu, dùng cho hệ thống máy phát điện tuabin khí số #2, số DWG No.: A13C454 -G08, hàng mới 100% - GROUT RETAINER | F34: 73089099 | G34: PS 1.1, Ⅰ, 4 | H34: N/A | I34: 1 | J34: PCE | K34: 55.555556 | L34: =ROUND(M34/I34,2) -> 4350.94 | M34: 4350.94 | N34: A13C454 -G08 | P34: G2
A35: 28 | B35: OM4-MG-GEN2-KOB-0004 | C35: S1 | D35: ANCHOR BLOCK | E35: Tấm khóa cố định chân đế, bằng thép, đặt sẵn, đã được gia công để dùng làm kết cấu, dùng cho hệ thống máy phát điện tuabin khí số #2, số DWG No.: AS29212 -G03, hàng mới 100% - ANCHOR BLOCK | F35: 73089099 | G35: PS 1.1, Ⅰ, 4 | H35: N/A | I35: 1 | J35: PCE | K35: 447 | L35: =ROUND(M35/I35,2) -> 9770.49 | M35: 9770.49 | N35: AS29212 -G03 | O35: EB102586 | P35: G2
A36: 29 | B36: OM4-MG-GEN2-KOB-0005 | C36: S1 | D36: ANCHOR BLOCK | E36: Tấm khóa cố định chân đế, bằng thép, đặt sẵn, đã được gia công để dùng làm kết cấu, dùng cho hệ thống máy phát điện tuabin khí số #2, số DWG No.: AS29643 -G03, hàng mới 100% - ANCHOR BLOCK | F36: 73089099 | G36: PS 1.1, Ⅰ, 4 | H36: N/A | I36: 1 | J36: PCE | K36: 676 | L36: =ROUND(M36/I36,2) -> 14775.95 | M36: 14775.95 | N36: AS29643 -G03 | O36: EB102586 | P36: G2
A37: 30 | B37: OM4-MG-GEN2-KOB-0006 | C37: S1 | D37: BOX 1/4 | E37: Hộp gia cố chân đế, bằng thép, đặt sẵn, đã được gia công để dùng làm kết cấu, dùng cho hệ thống máy phát điện tuabin khí số #2, số DWG No.: A12R049 -G01, hàng mới 100% - BOX 1/4 | F37: 73089099 | G37: PS 1.1, Ⅰ, 4 | H37: N/A | I37: 2 | J37: PCS | K37: 540 | L37: =ROUND(M37/I37,2) -> 5901.64 | M37: 11803.27 | N37: A12R049 -G01 | O37: EB102585 | P37: G2
A38: 31 | B38: OM4-MG-GEN2-KOB-0007 | C38: S1 | D38: BOX 2/4 | E38: Hộp gia cố chân đế, bằng thép, đặt sẵn, đã được gia công để dùng làm kết cấu, dùng cho hệ thống máy phát điện tuabin khí số #2, số DWG No.: A12R049 -G01, hàng mới 100% - BOX 2/4 | F38: 73089099 | G38: PS 1.1, Ⅰ, 4 | H38: N/A | I38: 2 | J38: PCS | K38: 540 | L38: =ROUND(M38/I38,2) -> 5901.64 | M38: 11803.27 | N38: A12R049 -G01 | O38: EB102585 | P38: G2
A39: 32 | B39: OM4-MG-GEN2-KOB-0008 | C39: S1 | D39: BOX 3/4 | E39: Hộp gia cố chân đế, bằng thép, đặt sẵn, đã được gia công để dùng làm kết cấu, dùng cho hệ thống máy phát điện tuabin khí số #2, số DWG No.: A12R049 -G01, hàng mới 100% - BOX 3/4 | F39: 73089099 | G39: PS 1.1, Ⅰ, 4 | H39: N/A | I39: 2 | J39: PCS | K39: 540 | L39: =ROUND(M39/I39,2) -> 5901.64 | M39: 11803.27 | N39: A12R049 -G01 | O39: EB102585 | P39: G2
A40: 33 | B40: OM4-MG-GEN2-KOB-0009 | C40: S1 | D40: BOX 4/4 | E40: Hộp gia cố chân đế, bằng thép, đặt sẵn, đã được gia công để dùng làm kết cấu, dùng cho hệ thống máy phát điện tuabin khí số #2, số DWG No.: A12R049 -G01, hàng mới 100% - BOX 4/4 | F40: 73089099 | G40: PS 1.1, Ⅰ, 4 | H40: N/A | I40: 2 | J40: PCS | K40: 540 | L40: =ROUND(M40/I40,2) -> 5901.64 | M40: 11803.27 | N40: A12R049 -G01 | O40: EB102585 | P40: G2
A41: 34 | B41: OM4-MG-GEN2-KOB-0010 | C41: S1 | D41: COVER | E41: Tấm che hộp gia cố chân đế, bằng thép, đặt sẵn, đã được gia công để dùng làm kết cấu, dùng cho hệ thống máy phát điện tuabin khí số #1, số DWG No.: A12R049 -G02, hàng mới 100% - COVER | F41: 73089099 | G41: PS 1.1, Ⅰ, 4 | H41: N/A | I41: 8 | J41: PCS | K41: 55 | L41: =ROUND(M41/I41,2) -> 150.27 | M41: 1202.19 | N41: A12R049 -G02 | O41: EB102585 | P41: G2
A42: 35 | B42: OM4-MG-GEN2-MAR-0001 | C42: S1 | D42: EMBEDDED METAL-1 (Fe) 200X500X159 | E42: Tấm nền móng, bằng thép, đặt sẵn, đã được gia công để dùng làm kết cấu, dùng cho hệ thống máy phát điện tuabin khí số #2, kích thước: 200x500x159mm, hàng mới 100% - EMBEDDED METAL-1 (Fe) 200X500X159 | F42: 73089099 | G42: PS 1.1, Ⅰ, 4 | H42: N/A | I42: 3 | J42: PCS | K42: 18.333333 | L42: =ROUND(M42/I42,2) -> 133.58 | M42: 400.73 | O42: OM4-DE-XB02-P0MKC-EL-230144 (EBT3-EAY-EG12) | P42: G2
A43: 36 | B43: OM4-MG-GEN2-MAR-0001 | C43: S1 | D43: EMBEDDED METAL-2 (Fe) 200X200X159 | E43: Tấm nền móng, bằng thép, đặt sẵn, đã được gia công để dùng làm kết cấu, dùng cho hệ thống máy phát điện tuabin khí số #2, kích thước: 200x200x159mm, hàng mới 100% - EMBEDDED METAL-2 (Fe) 200X200X159 | F43: 73089099 | G43: PS 1.1, Ⅰ, 4 | H43: N/A | I43: 4 | J43: PCS | K43: 24.444444 | L43: =ROUND(M43/I43,2) -> 133.58 | M43: 534.3 | O43: OM4-DE-XB02-P0MKC-EL-230144 (EBT3-EAY-EG12) | P43: G2
...

Sheet book
W4: 1 | X4: 15750
A5: INVOICE NO. : | C5: ='Commercial Invoice'!H5 -> OM4-DE-IS-0005 | G5: PLACE : | N5: ='Commercial Invoice'!G6 -> DATE: | O5: ='Commercial Invoice'!H6 -> 46171 | W5: 2 | X5: 9817.5
W6: 3 | X6: 14280
A7: SI. No. | B7: Package No. | C7: COMMODITY/DESCRIPTION OF GOODS | F7: POSITION IN PRICE SCHEDULE | G7: POSITION IN THE MASTER LIST | H7: QUANTITY | I7: UNIT | J7: NET WEIGHT (KG) | K7: UNIT PRICE (USD) | L7: AMOUNT (USD) | M7: DWG No. | N7: ASSEMBLY D.W.G NO. | O7: Remark (**) | W7: 4 | X7: 12495
A8: 1 | B8: OM4-MG-GEN1-KOB-0001 | C8: GROUT RETAINER | D8: Khung cố định chân đế, bằng thép, đặt sẵn, đã được gia công để dùng làm kết cấu, dùng cho hệ thống máy phát điện tuabin khí số #1, số DWG No.: A13C454 -G01 -GROUT RETAINER | E8: 73089099 | F8: PS 1.1, Ⅰ, 2 | G8: N/A | H8: 4 | I8: PCS | J8: 300 | K8: 2423.5 | L8: 9693.98 | M8: A13C454 -G01 | O8: G1
A9: 2 | B9: OM4-MG-GEN1-KOB-0002 | C9: GROUT RETAINER | D9: Khung cố định chân đế, bằng thép, đặt sẵn, đã được gia công để dùng làm kết cấu, dùng cho hệ thống máy phát điện tuabin khí số #1, số DWG No.: A13C454 -G02 -GROUT RETAINER | E9: 73089099 | F9: PS 1.1, Ⅰ, 2 | G9: N/A | H9: 1 | I9: PCE | J9: 55.555556 | K9: 4350.94 | L9: 4350.94 | M9: A13C454 -G02 | O9: G1
A10: 3 | B10: OM4-MG-GEN1-KOB-0002 | C10: GROUT RETAINER | D10: Khung cố định chân đế, bằng thép, đặt sẵn, đã được gia công để dùng làm kết cấu, dùng cho hệ thống máy phát điện tuabin khí số #1, số DWG No.: A13C454 -G03 -GROUT RETAINER | E10: 73089099 | F10: PS 1.1, Ⅰ, 2 | G10: N/A | H10: 1 | I10: PCE | J10: 55.555556 | K10: 4350.94 | L10: 4350.94 | M10: A13C454 -G03 | O10: G1
A11: 4 | B11: OM4-MG-GEN1-KOB-0002 | C11: GROUT RETAINER | D11: Khung cố định chân đế, bằng thép, đặt sẵn, đã được gia công để dùng làm kết cấu, dùng cho hệ thống máy phát điện tuabin khí số #1, số DWG No.: A13C454 -G04 -GROUT RETAINER | E11: 73089099 | F11: PS 1.1, Ⅰ, 2 | G11: N/A | H11: 1 | I11: PCE | J11: 55.555556 | K11: 4350.94 | L11: 4350.94 | M11: A13C454 -G04 | O11: G1
A12: 5 | B12: OM4-MG-GEN1-KOB-0002 | C12: GROUT RETAINER | D12: Khung cố định chân đế, bằng thép, đặt sẵn, đã được gia công để dùng làm kết cấu, dùng cho hệ thống máy phát điện tuabin khí số #1, số DWG No.: A13C454 -G05 -GROUT RETAINER | E12: 73089099 | F12: PS 1.1, Ⅰ, 2 | G12: N/A | H12: 1 | I12: PCE | J12: 55.555556 | K12: 4350.94 | L12: 4350.94 | M12: A13C454 -G05 | O12: G1
A13: 6 | B13: OM4-MG-GEN1-KOB-0002 | C13: GROUT RETAINER | D13: Khung cố định chân đế, bằng thép, đặt sẵn, đã được gia công để dùng làm kết cấu, dùng cho hệ thống máy phát điện tuabin khí số #1, số DWG No.: A13C454 -G06 -GROUT RETAINER | E13: 73089099 | F13: PS 1.1, Ⅰ, 2 | G13: N/A | H13: 2 | I13: PCS | J13: 111.11111 | K13: 2782.64 | L13: 5565.27 | M13: A13C454 -G06 | O13: G1
A14: 7 | B14: OM4-MG-GEN1-KOB-0002 | C14: GROUT RETAINER | D14: Khung cố định chân đế, bằng thép, đặt sẵn, đã được gia công để dùng làm kết cấu, dùng cho hệ thống máy phát điện tuabin khí số #1, số DWG No.: A13C454 -G07 -GROUT RETAINER | E14: 73089099 | F14: PS 1.1, Ⅰ, 2 | G14: N/A | H14: 2 | I14: PCS | J14: 111.11111 | K14: 2782.64 | L14: 5565.27 | M14: A13C454 -G07 | O14: G1
A15: 8 | B15: OM4-MG-GEN1-KOB-0002 | C15: GROUT RETAINER | D15: Khung cố định chân đế, bằng thép, đặt sẵn, đã được gia công để dùng làm kết cấu, dùng cho hệ thống máy phát điện tuabin khí số #1, số DWG No.: A13C454 -G08 -GROUT RETAINER | E15: 73089099 | F15: PS 1.1, Ⅰ, 2 | G15: N/A | H15: 1 | I15: PCE | J15: 55.555556 | K15: 4350.94 | L15: 4350.94 | M15: A13C454 -G08 | O15: G1
A16: 13 | B16: OM4-MG-GEN1-KOB-0004 | C16: ANCHOR BLOCK | D16: Tấm khóa cố định chân đế, bằng thép, đặt sẵn, đã được gia công để dùng làm kết cấu, dùng cho hệ thống máy phát điện tuabin khí số #1, số DWG No.: AS29212 -G03 -ANCHOR BLOCK | E16: 73089099 | F16: PS 1.1, Ⅰ, 2 | G16: N/A | H16: 1 | I16: PCE | J16: 447 | K16: 9770.49 | L16: 9770.49 | M16: AS29212 -G03 | N16: EB102586 | O16: G1
A17: 14 | B17: OM4-MG-GEN1-KOB-0005 | C17: ANCHOR BLOCK | D17: Tấm khóa cố định chân đế, bằng thép, đặt sẵn, đã được gia công để dùng làm kết cấu, dùng cho hệ thống máy phát điện tuabin khí số #1, số DWG No.: AS29643 -G03 -ANCHOR BLOCK | E17: 73089099 | F17: PS 1.1, Ⅰ, 2 | G17: N/A | H17: 1 | I17: PCE | J17: 676 | K17: 14775.95 | L17: 14775.95 | M17: AS29643 -G03 | N17: EB102586 | O17: G1
A18: 15 | B18: OM4-MG-GEN1-KOB-0006 | C18: BOX 1/4 | D18: Hộp gia cố chân đế, bằng thép, đặt sẵn, đã được gia công để dùng làm kết cấu, dùng cho hệ thống máy phát điện tuabin khí số #1, số DWG No.: A12R049 -G01 -BOX 1/4 | E18: 73089099 | F18: PS 1.1, Ⅰ, 2 | G18: N/A | H18: 2 | I18: PCS | J18: 540 | K18: 5901.64 | L18: 11803.27 | M18: A12R049 -G01 | N18: EB102585 | O18: G1
A19: 16 | B19: OM4-MG-GEN1-KOB-0007 | C19: BOX 2/4 | D19: Hộp gia cố chân đế, bằng thép, đặt sẵn, đã được gia công để dùng làm kết cấu, dùng cho hệ thống máy phát điện tuabin khí số #1, số DWG No.: A12R049 -G01 -BOX 2/4 | E19: 73089099 | F19: PS 1.1, Ⅰ, 2 | G19: N/A | H19: 2 | I19: PCS | J19: 540 | K19: 5901.64 | L19: 11803.27 | M19: A12R049 -G01 | N19: EB102585 | O19: G1
A20: 17 | B20: OM4-MG-GEN1-KOB-0008 | C20: BOX 3/4 | D20: Hộp gia cố chân đế, bằng thép, đặt sẵn, đã được gia công để dùng làm kết cấu, dùng cho hệ thống máy phát điện tuabin khí số #1, số DWG No.: A12R049 -G01 -BOX 3/4 | E20: 73089099 | F20: PS 1.1, Ⅰ, 2 | G20: N/A | H20: 2 | I20: PCS | J20: 540 | K20: 5901.64 | L20: 11803.27 | M20: A12R049 -G01 | N20: EB102585 | O20: G1
A21: 18 | B21: OM4-MG-GEN1-KOB-0009 | C21: BOX 4/4 | D21: Hộp gia cố chân đế, bằng thép, đặt sẵn, đã được gia công để dùng làm kết cấu, dùng cho hệ thống máy phát điện tuabin khí số #1, số DWG No.: A12R049 -G01 -BOX 4/4 | E21: 73089099 | F21: PS 1.1, Ⅰ, 2 | G21: N/A | H21: 2 | I21: PCS | J21: 540 | K21: 5901.64 | L21: 11803.27 | M21: A12R049 -G01 | N21: EB102585 | O21: G1
A22: 19 | B22: OM4-MG-GEN1-KOB-0010 | C22: COVER | D22: Tấm che hộp gia cố chân đế, bằng thép, đặt sẵn, đã được gia công để dùng làm kết cấu, dùng cho hệ thống máy phát điện tuabin khí số #1, kích thước: 750x1600mm, số DWG No.: A12R049 -G02 -COVER | E22: 73089099 | F22: PS 1.1, Ⅰ, 2 | G22: N/A | H22: 8 | I22: PCS | J22: 55 | K22: 150.27 | L22: 1202.19 | M22: A12R049 -G02 | N22: EB102585 | O22: G1
A23: 22 | B23: OM4-MG-GEN1-MAR-0001 | C23: EMBEDDED METAL-1 (Fe) 200×500×159 | D23: Tấm nền móng, bằng thép, đặt sẵn, đã được gia công để dùng làm kết cấu, dùng cho hệ thống máy phát điện tuabin khí số #1, kích thước: 200X500X159mm -EMBEDDED METAL-1 (Fe) 200X500X159 | E23: 73089099 | F23: PS 1.1, Ⅰ, 2 | G23: N/A | H23: 3 | I23: PCS | J23: 18.333333 | K23: 133.58 | L23: 400.73 | N23: OM4-DE-XB02-P0MKC-EL-230144 (EBT3-EAY-EG12) | O23: G1
A24: 23 | B24: OM4-MG-GEN1-MAR-0001 | C24: EMBEDDED METAL-2 (Fe) 200×200×159 | D24: Tấm nền móng, bằng thép, đặt sẵn, đã được gia công để dùng làm kết cấu, dùng cho hệ thống máy phát điện tuabin khí số #1, kích thước: 200X200X159mm -EMBEDDED METAL-2 (Fe) 200X200X159 | E24: 73089099 | F24: PS 1.1, Ⅰ, 2 | G24: N/A | H24: 4 | I24: PCS | J24: 24.444444 | K24: 133.58 | L24: 534.3 | N24: OM4-DE-XB02-P0MKC-EL-230144 (EBT3-EAY-EG12) | O24: G1
A25: 24 | B25: OM4-MG-GEN1-MAR-0001 | C25: EMBEDDED METAL-1 (Fe) 200×500×159 | D25: Tấm nền móng, bằng thép, đặt sẵn, đã được gia công để dùng làm kết cấu, dùng cho hệ thống máy phát điện tuabin khí số #1, kích thước: 200x500x159mm -EMBEDDED METAL-1 (Fe) 200X500X159 | E25: 73089099 | F25: PS 1.1, Ⅰ, 2 | G25: N/A | H25: 1 | I25: PCE | J25: 6.1111111 | K25: 133.58 | L25: 133.58 | N25: OM4-DE-XB02-P0MKC-EL-230144 (EBT3-EAY-EG12) | O25: G1
A26: 25 | B26: OM4-MG-GEN1-MAR-0001 | C26: EMBEDDED METAL-2 (Fe) 200×200×159 | D26: Tấm nền móng, bằng thép, đặt sẵn, đã được gia công để dùng làm kết cấu, dùng cho hệ thống máy phát điện tuabin khí số #1, kích thước: 200x200x159mm -EMBEDDED METAL-2 (Fe) 200X200X159 | E26: 73089099 | F26: PS 1.1, Ⅰ, 2 | G26: N/A | H26: 1 | I26: PCE | J26: 6.1111111 | K26: 133.58 | L26: 133.58 | N26: OM4-DE-XB02-P0MKC-EL-230144 (EBT3-EAY-EG12) | O26: G1
A27: 26 | B27: OM4-MG-GEN2-KOB-0001 | C27: GROUT RETAINER | D27: Khung cố định chân đế, bằng thép, đặt sẵn, đã được gia công để dùng làm kết cấu, dùng cho hệ thống máy phát điện tuabin khí số #2, số DWG No.: A13C454 -G01 -GROUT RETAINER | E27: 73089099 | F27: PS 1.1, Ⅰ, 4 | G27: N/A | H27: 4 | I27: PCS | J27: 300 | K27: 2423.5 | L27: 9693.98 | M27: A13C454 -G01 | O27: G2
A28: 27 | B28: OM4-MG-GEN2-KOB-0002 | C28: GROUT RETAINER | D28: Khung cố định chân đế, bằng thép, đặt sẵn, đã được gia công để dùng làm kết cấu, dùng cho hệ thống máy phát điện tuabin khí số #2, số DWG No.: A13C454 -G02 -GROUT RETAINER | E28: 73089099 | F28: PS 1.1, Ⅰ, 4 | G28: N/A | H28: 1 | I28: PCE | J28: 55.555556 | K28: 4350.94 | L28: 4350.94 | M28: A13C454 -G02 | O28: G2
A29: 28 | B29: OM4-MG-GEN2-KOB-0002 | C29: GROUT RETAINER | D29: Khung cố định chân đế, bằng thép, đặt sẵn, đã được gia công để dùng làm kết cấu, dùng cho hệ thống máy phát điện tuabin khí số #2, số DWG No.: A13C454 -G03 -GROUT RETAINER | E29: 73089099 | F29: PS 1.1, Ⅰ, 4 | G29: N/A | H29: 1 | I29: PCE | J29: 55.555556 | K29: 4350.94 | L29: 4350.94 | M29: A13C454 -G03 | O29: G2
A30: 29 | B30: OM4-MG-GEN2-KOB-0002 | C30: GROUT RETAINER | D30: Khung cố định chân đế, bằng thép, đặt sẵn, đã được gia công để dùng làm kết cấu, dùng cho hệ thống máy phát điện tuabin khí số #2, số DWG No.: A13C454 -G04 -GROUT RETAINER | E30: 73089099 | F30: PS 1.1, Ⅰ, 4 | G30: N/A | H30: 1 | I30: PCE | J30: 55.555556 | K30: 4350.94 | L30: 4350.94 | M30: A13C454 -G04 | O30: G2
A31: 30 | B31: OM4-MG-GEN2-KOB-0002 | C31: GROUT RETAINER | D31: Khung cố định chân đế, bằng thép, đặt sẵn, đã được gia công để dùng làm kết cấu, dùng cho hệ thống máy phát điện tuabin khí số #2, số DWG No.: A13C454 -G05 -GROUT RETAINER | E31: 73089099 | F31: PS 1.1, Ⅰ, 4 | G31: N/A | H31: 1 | I31: PCE | J31: 55.555556 | K31: 4350.94 | L31: 4350.94 | M31: A13C454 -G05 | O31: G2
A32: 31 | B32: OM4-MG-GEN2-KOB-0002 | C32: GROUT RETAINER | D32: Khung cố định chân đế, bằng thép, đặt sẵn, đã được gia công để dùng làm kết cấu, dùng cho hệ thống máy phát điện tuabin khí số #2, số DWG No.: A13C454 -G06 -GROUT RETAINER | E32: 73089099 | F32: PS 1.1, Ⅰ, 4 | G32: N/A | H32: 2 | I32: PCS | J32: 111.11111 | K32: 2782.64 | L32: 5565.27 | M32: A13C454 -G06 | O32: G2
A33: 32 | B33: OM4-MG-GEN2-KOB-0002 | C33: GROUT RETAINER | D33: Khung cố định chân đế, bằng thép, đặt sẵn, đã được gia công để dùng làm kết cấu, dùng cho hệ thống máy phát điện tuabin khí số #2, số DWG No.: A13C454 -G07 -GROUT RETAINER | E33: 73089099 | F33: PS 1.1, Ⅰ, 4 | G33: N/A | H33: 2 | I33: PCS | J33: 111.11111 | K33: 2782.64 | L33: 5565.27 | M33: A13C454 -G07 | O33: G2
A34: 33 | B34: OM4-MG-GEN2-KOB-0002 | C34: GROUT RETAINER | D34: Khung cố định chân đế, bằng thép, đặt sẵn, đã được gia công để dùng làm kết cấu, dùng cho hệ thống máy phát điện tuabin khí số #2, số DWG No.: A13C454 -G08 -GROUT RETAINER | E34: 73089099 | F34: PS 1.1, Ⅰ, 4 | G34: N/A | H34: 1 | I34: PCE | J34: 55.555556 | K34: 4350.94 | L34: 4350.94 | M34: A13C454 -G08 | O34: G2
A35: 38 | B35: OM4-MG-GEN2-KOB-0004 | C35: ANCHOR BLOCK | D35: Tấm khóa cố định chân đế, bằng thép, đặt sẵn, đã được gia công để dùng làm kết cấu, dùng cho hệ thống máy phát điện tuabin khí số #2, số DWG No.: AS29212 -G03 -ANCHOR BLOCK | E35: 73089099 | F35: PS 1.1, Ⅰ, 4 | G35: N/A | H35: 1 | I35: PCE | J35: 447 | K35: 9770.49 | L35: 9770.49 | M35: AS29212 -G03 | N35: EB102586 | O35: G2
A36: 39 | B36: OM4-MG-GEN2-KOB-0005 | C36: ANCHOR BLOCK | D36: Tấm khóa cố định chân đế, bằng thép, đặt sẵn, đã được gia công để dùng làm kết cấu, dùng cho hệ thống máy phát điện tuabin khí số #2, số DWG No.: AS29643 -G03 -ANCHOR BLOCK | E36: 73089099 | F36: PS 1.1, Ⅰ, 4 | G36: N/A | H36: 1 | I36: PCE | J36: 676 | K36: 14775.95 | L36: 14775.95 | M36: AS29643 -G03 | N36: EB102586 | O36: G2
A37: 40 | B37: OM4-MG-GEN2-KOB-0006 | C37: BOX 1/4 | D37: Hộp gia cố chân đế, bằng thép, đặt sẵn, đã được gia công để dùng làm kết cấu, dùng cho hệ thống máy phát điện tuabin khí số #2, số DWG No.: A12R049 -G01 -BOX 1/4 | E37: 73089099 | F37: PS 1.1, Ⅰ, 4 | G37: N/A | H37: 2 | I37: PCS | J37: 540 | K37: 5901.64 | L37: 11803.27 | M37: A12R049 -G01 | N37: EB102585 | O37: G2
A38: 41 | B38: OM4-MG-GEN2-KOB-0007 | C38: BOX 2/4 | D38: Hộp gia cố chân đế, bằng thép, đặt sẵn, đã được gia công để dùng làm kết cấu, dùng cho hệ thống máy phát điện tuabin khí số #2, số DWG No.: A12R049 -G01 -BOX 2/4 | E38: 73089099 | F38: PS 1.1, Ⅰ, 4 | G38: N/A | H38: 2 | I38: PCS | J38: 540 | K38: 5901.64 | L38: 11803.27 | M38: A12R049 -G01 | N38: EB102585 | O38: G2
A39: 42 | B39: OM4-MG-GEN2-KOB-0008 | C39: BOX 3/4 | D39: Hộp gia cố chân đế, bằng thép, đặt sẵn, đã được gia công để dùng làm kết cấu, dùng cho hệ thống máy phát điện tuabin khí số #2, số DWG No.: A12R049 -G01 -BOX 3/4 | E39: 73089099 | F39: PS 1.1, Ⅰ, 4 | G39: N/A | H39: 2 | I39: PCS | J39: 540 | K39: 5901.64 | L39: 11803.27 | M39: A12R049 -G01 | N39: EB102585 | O39: G2
A40: 43 | B40: OM4-MG-GEN2-KOB-0009 | C40: BOX 4/4 | D40: Hộp gia cố chân đế, bằng thép, đặt sẵn, đã được gia công để dùng làm kết cấu, dùng cho hệ thống máy phát điện tuabin khí số #2, số DWG No.: A12R049 -G01 -BOX 4/4 | E40: 73089099 | F40: PS 1.1, Ⅰ, 4 | G40: N/A | H40: 2 | I40: PCS | J40: 540 | K40: 5901.64 | L40: 11803.27 | M40: A12R049 -G01 | N40: EB102585 | O40: G2
A41: 44 | B41: OM4-MG-GEN2-KOB-0010 | C41: COVER | D41: Tấm che hộp gia cố chân đế, bằng thép, đặt sẵn, đã được gia công để dùng làm kết cấu, dùng cho hệ thống máy phát điện tuabin khí số #1, kích thước: 750 x 1600mm, số DWG No.: A12R049 -G02 -COVER | E41: 73089099 | F41: PS 1.1, Ⅰ, 4 | G41: N/A | H41: 8 | I41: PCS | J41: 55 | K41: 150.27 | L41: 1202.19 | M41: A12R049 -G02 | N41: EB102585 | O41: G2
A42: 47 | B42: OM4-MG-GEN2-MAR-0001 | C42: EMBEDDED METAL-1 (Fe) 200×500×159 | D42: Tấm nền móng, bằng thép, đặt sẵn, đã được gia công để dùng làm kết cấu, dùng cho hệ thống máy phát điện tuabin khí số #2, kích thước: 200x500x159mm -EMBEDDED METAL-1 (Fe) 200X500X159 | E42: 73089099 | F42: PS 1.1, Ⅰ, 4 | G42: N/A | H42: 3 | I42: PCS | J42: 18.333333 | K42: 133.58 | L42: 400.73 | N42: OM4-DE-XB02-P0MKC-EL-230144 (EBT3-EAY-EG12) | O42: G2
A43: 48 | B43: OM4-MG-GEN2-MAR-0001 | C43: EMBEDDED METAL-2 (Fe) 200×200×159 | D43: Tấm nền móng, bằng thép, đặt sẵn, đã được gia công để dùng làm kết cấu, dùng cho hệ thống máy phát điện tuabin khí số #2, kích thước: 200x200x159mm -EMBEDDED METAL-2 (Fe) 200X200X159 | E43: 73089099 | F43: PS 1.1, Ⅰ, 4 | G43: N/A | H43: 4 | I43: PCS | J43: 24.444444 | K43: 133.58 | L43: 534.3 | N43: OM4-DE-XB02-P0MKC-EL-230144 (EBT3-EAY-EG12) | O43: G2
...

Sheet Detailed PL
C3: PECC2 Innovation Hub, 45 Street No.2, Truong Tho Ward, Thu Duc City, HCMC, Vietnam Tel: +84-28-2221 6468 | Fax: +84-28-2221 0408
B4: DETAILED PACKING LIST
C5: PL No. | D5: ='PL(2_2)'!D5 -> OM4-DE-IS-0005 | Z5: 36 | AA5: 39 | AB5: 40 | AC5: 163 | AD5: 3 | AE5: 8 | AF5: 44 | AG5: 45 | AH5: 46 | AI5: 60 | AJ5: 66 | AK5: 68 | AL5: 69 | AM5: 70 | AN5: 71 | AO5: 170 | AP5: 110 | AQ5: 234 | AR5: 33 | AS5: 34 | AT5: 142 | AV5: 79 | AW5: 80 | AX5: 81 | AY5: 82
C6: Dated | D6: ='PL(2_2)'!D6 -> 46171 | J6: * Storage Classification | Q6: ** Plant/Equipment/Materials for | Z6: =SUMIF(#REF!,Z5,#REF!) -> #REF! | AA6: =SUMIF(#REF!,AA5,#REF!) -> #REF! | AB6: =SUMIF(#REF!,AB5,#REF!) -> #REF! | AC6: =SUMIF(#REF!,AC5,#REF!) -> #REF! | AD6: =SUMIF(#REF!,AD5,#REF!) -> #REF! | AE6: =SUMIF(#REF!,AE5,#REF!) -> #REF! | AF6: =SUMIF(#REF!,AF5,#REF!) -> #REF! | AG6: =SUMIF(#REF!,AG5,#REF!) -> #REF! | ... AP6: =SUMIF(#REF!,AP5,#REF!) -> #REF! | AQ6: =SUMIF($AH$89:$AH$358,AQ5,$I$89:$I$358) -> 0 | AR6: =SUMIF($AH$89:$AH$358,AR5,$I$89:$I$358) -> 0 | AS6: =SUMIF($AH$89:$AH$358,AS5,$I$89:$I$358) -> 0 | AT6: =SUMIF(#REF!,AT5,#REF!) -> #REF! | AU6: =SUM(Z6:AT7) -> #REF! | AV6: =SUMIF(#REF!,AV5,#REF!) -> #REF! | AW6: =SUMIF(#REF!,AW5,#REF!) -> #REF! | AX6: =SUMIF($AH$89:$AH$358,AX5,$I$89:$I$358) -> 0 | AY6: =SUMIF($AH$89:$AH$358,AY5,$I$89:$I$358) -> 0
C7: Project | D7: ='PL(2_2)'!D7 -> O MON IV THERMAL POWER PLANT | J7: "A" | K7: : Indoor with Air conditioning | R7: HRSG | S7: STG | T7: GTG | U7: BOP | AD7: 1 | AE7: 1 | AH7: 5 | AI7: 100 | AT7: 2 | AV7: 105
C8: Referenced DWG No. | J8: "B" | K8: : Indoor without Air conditioning | Q8: Unit 1 | R8: B1 | S8: T1 | T8: G1 | U8: P2
J9: "C" | K9: : Hazardous Material | Q9: Unit 2 | R9: B2 | S9: T2 | T9: G2 | U9: P2
J10: "D" | K10: : Outdoor with waterproofing | Q10: Common | R10: B0 | S10: T0 | T10: G0 | U10: P0
J11: "E" | K11: : Outdoor without waterproofing
B13: SI. No. | C13: Package No. | D13: Description of Goods | F13: Manufacturer | G13: C/O of Goods | H13: Position in price schedule | I13: Quantity | K13: Package Type | L13: Measurement | P13: Net Weight (kg) | Q13: Gross Weight (kg) | R13: Hazardous Material | S13: Storage Classification (*) | T13: Tag No. | U13: DWG No. | V13: ASSEMBLY D.W.G NO. | W13: Remark (**)
I14: Nos | J14: Unit | L14: Length (cm) | M14: Width (cm) | N14: Height (cm) | O14: Volume (cbm)
B15: 1 | C15: OM4-MG-GEN1-KOB-0001 | D15: GROUT RETAINER | F15: MG | G15: JAPAN | H15: PS 1.1, Ⅰ, 2 | I15: 4 | J15: PCS | P15: 300 | U15: A13C454 -G01 | W15: G1
B16: Sub-Total | K16: CASE | L16: 608 | M16: 158 | N16: 60 | O16: 5.764 | P16: 300 | Q16: 930 | R16: N | S16: B
B17: 2 | C17: OM4-MG-GEN1-KOB-0002 | D17: GROUT RETAINER | F17: MG | G17: JAPAN | H17: PS 1.1, Ⅰ, 2 | I17: 1 | J17: PCE | P17: 55.555556 | U17: A13C454 -G02 | W17: G1
B18: 3 | C18: OM4-MG-GEN1-KOB-0002 | D18: GROUT RETAINER | F18: MG | G18: JAPAN | H18: PS 1.1, Ⅰ, 2 | I18: 1 | J18: PCE | P18: 55.555556 | U18: A13C454 -G03 | W18: G1
B19: 4 | C19: OM4-MG-GEN1-KOB-0002 | D19: GROUT RETAINER | F19: MG | G19: JAPAN | H19: PS 1.1, Ⅰ, 2 | I19: 1 | J19: PCE | P19: 55.555556 | U19: A13C454 -G04 | W19: G1
B20: 5 | C20: OM4-MG-GEN1-KOB-0002 | D20: GROUT RETAINER | F20: MG | G20: JAPAN | H20: PS 1.1, Ⅰ, 2 | I20: 1 | J20: PCE | P20: 55.555556 | U20: A13C454 -G05 | W20: G1
B21: 6 | C21: OM4-MG-GEN1-KOB-0002 | D21: GROUT RETAINER | F21: MG | G21: JAPAN | H21: PS 1.1, Ⅰ, 2 | I21: 2 | J21: PCS | P21: 111.11111 | U21: A13C454 -G06 | W21: G1
B22: 7 | C22: OM4-MG-GEN1-KOB-0002 | D22: GROUT RETAINER | F22: MG | G22: JAPAN | H22: PS 1.1, Ⅰ, 2 | I22: 2 | J22: PCS | P22: 111.11111 | U22: A13C454 -G07 | W22: G1
B23: 8 | C23: OM4-MG-GEN1-KOB-0002 | D23: GROUT RETAINER | F23: MG | G23: JAPAN | H23: PS 1.1, Ⅰ, 2 | I23: 1 | J23: PCE | P23: 55.555556 | U23: A13C454 -G08 | W23: G1
B24: Sub-Total | K24: CASE | L24: 354 | M24: 204 | N24: 100 | O24: 7.222 | P24: 500 | Q24: 1030 | R24: N | S24: B
B25: 9 | C25: OM4-MG-GEN1-KOB-0003 | D25: EMBEDDED PLATE 500X100Xt6 EB402263-1 | F25: MG | G25: JAPAN | H25: PS 1.1, Ⅰ, 2 | I25: 27 | J25: PCS | P25: 273.375 | U25: EB402263-1 | V25: EBABH-W0624 | W25: G1
B26: 10 | C26: OM4-MG-GEN1-KOB-0003 | D26: EMBEDDED PLATE 1000X100Xt6 EB402263-2 | F26: MG | G26: JAPAN | H26: PS 1.1, Ⅰ, 2 | I26: 42 | J26: PCS | P26: 425.25 | U26: EB402263-2 | V26: EBABH-W0624 | W26: G1
B27: 11 | C27: OM4-MG-GEN1-KOB-0003 | D27: EMBEDDED PLATE 1500X100Xt6 EB4022_x000D_ 63-3 | F27: MG | G27: JAPAN | H27: PS 1.1, Ⅰ, 2 | I27: 9 | J27: PCS | P27: 91.125 | U27: EB402263-3 | V27: EBABH-W0624 | W27: G1
B28: 12 | C28: OM4-MG-GEN1-KOB-0003 | D28: EMBEDDED PLATE 1500X200Xt9 EB4022_x000D_ 63-4 | F28: MG | G28: JAPAN | H28: PS 1.1, Ⅰ, 2 | I28: 2 | J28: PCS | P28: 20.25 | U28: EB402263-4 | V28: EBABH-W0624 | W28: G1
B29: Sub-Total | K29: CASE | L29: 340 | M29: 208 | N29: 138 | O29: 9.759 | P29: 810 | Q29: 1350 | R29: N | S29: B
B30: 13 | C30: OM4-MG-GEN1-KOB-0004 | D30: ANCHOR BLOCK | F30: MG | G30: JAPAN | H30: PS 1.1, Ⅰ, 2 | I30: 1 | J30: PCE | P30: 447 | U30: AS29212 -G03 | V30: EB102586 | W30: G1
B31: Sub-Total | K31: CASE | L31: 115 | M31: 94 | N31: 85 | O31: 0.919 | P31: 447 | Q31: 540 | R31: N | S31: B
B32: 14 | C32: OM4-MG-GEN1-KOB-0005 | D32: ANCHOR BLOCK | F32: MG | G32: JAPAN | H32: PS 1.1, Ⅰ, 2 | I32: 1 | J32: PCE | P32: 676 | U32: AS29643 -G03 | V32: EB102586 | W32: G1
B33: Sub-Total | K33: CASE | L33: 168 | M33: 115 | N33: 77 | O33: 1.488 | P33: 676 | Q33: 812 | R33: N | S33: B
B34: 15 | C34: OM4-MG-GEN1-KOB-0006 | D34: BOX 1/4 | F34: MG | G34: JAPAN | H34: PS 1.1, Ⅰ, 2 | I34: 2 | J34: PCS | P34: 540 | U34: A12R049 -G01 | V34: EB102585 | W34: G1
B35: Sub-Total | K35: CASE | L35: 125 | M35: 117 | N35: 114 | O35: 1.667 | P35: 540 | Q35: 683 | R35: N | S35: B
B36: 16 | C36: OM4-MG-GEN1-KOB-0007 | D36: BOX 2/4 | F36: MG | G36: JAPAN | H36: PS 1.1, Ⅰ, 2 | I36: 2 | J36: PCS | P36: 540 | U36: A12R049 -G01 | V36: EB102585 | W36: G1
B37: Sub-Total | K37: CASE | L37: 125 | M37: 117 | N37: 114 | O37: 1.667 | P37: 540 | Q37: 683 | R37: N | S37: B
B38: 17 | C38: OM4-MG-GEN1-KOB-0008 | D38: BOX 3/4 | F38: MG | G38: JAPAN | H38: PS 1.1, Ⅰ, 2 | I38: 2 | J38: PCS | P38: 540 | U38: A12R049 -G01 | V38: EB102585 | W38: G1
B39: Sub-Total | K39: CASE | L39: 125 | M39: 117 | N39: 114 | O39: 1.667 | P39: 540 | Q39: 683 | R39: N | S39: B
B40: 18 | C40: OM4-MG-GEN1-KOB-0009 | D40: BOX 4/4 | F40: MG | G40: JAPAN | H40: PS 1.1, Ⅰ, 2 | I40: 2 | J40: PCS | P40: 540 | U40: A12R049 -G01 | V40: EB102585 | W40: G1
B41: Sub-Total | K41: CASE | L41: 125 | M41: 117 | N41: 114 | O41: 1.667 | P41: 540 | Q41: 683 | R41: N | S41: B
B42: 19 | C42: OM4-MG-GEN1-KOB-0010 | D42: COVER | F42: MG | G42: JAPAN | H42: PS 1.1, Ⅰ, 2 | I42: 8 | J42: PCS | P42: 55 | U42: A12R049 -G02 | V42: EB102585 | W42: G1
B43: Sub-Total | K43: CASE | L43: 100 | M43: 80 | N43: 63 | O43: 0.504 | P43: 55 | Q43: 100 | R43: N | S43: B
...

Sheet Commercial Invoice (Rve1)
A4: COMMERCIAL INVOICE
A5: SHIPPER: | G5: INVOICE NO. : | H5: OM4-DE-IS-0005
B6: Doosan Enerbility Co., Ltd. 22 DoosanVolvo-ro, Seongsan-gu, Chang-won-si, Gyeongsangnam-do 51711, Republic of Korea | G6: DATE: | H6: 46219
G7: CONTRACT NO. | H7: 06/2025/HĐ-PVN/OM4-06
G8: DATE: | H8: 45814
A9: CONSIGNEE : | G9: SHIPPING MARK
B10: Cty Doosan Enerbility Co.,Ltd HQ-Nha thau TH CV thuoc Goi thau so OM4-EPC-HHO-06 cho NMND O Mon IV Thoi Loi Area, Phuoc Thoi Ward, Can Tho City, Vietnam T : (+84) 367 566 167 F : (+84 243) 624 8485 | G10: O MON IV THERMAL POWER PLANT
A13: NOTIFY PARTY :
B14: Cty Doosan Enerbility Co.,Ltd HQ-Nha thau TH CV thuoc Goi thau so OM4-EPC-HHO-06 cho NMND O Mon IV Thoi Loi Area, Phươc Thoi Ward, Can Tho City, Vietnam T : (+84) 367 566 167 F : (+84 243) 624 8485 BRANCH OF KWANGJIN VIET NAM IN DUNG QUAT Co.,Ltd Dung Quat Economic Zone, Van Tuong Commune, Quang Ngai Province, Vietnam T : (+84) 28 3825 6330 Attn: Mr. Phuoc / Email: phuoc@kjtc.co.kr
G15: SHIPMENT NO. : | H15: OM4-DE-IS-0005
G17: TERM OF DELIVERY : | H17: CIF Ho Chi Minh City Port, Vietnam
A18: VESSEL NAME : | C18: ETD :
B19: ASL TAIPEI / 2629S | D19: 46222 | G19: QUALITY | H19: 100% BRAND NEW
A20: PORT OF LOADING : | C20: PORT OF DISCHARGE : | G20: PAYMENT TERMS: | H20: T/T
B21: KOBE, JAPAN | D21: HO CHI MINH, VIET NAM
A22: BILL OF LADING/ AIRWAY BILL NO. : | C22: B/L DATE :
B23: SITKBSG2612069 | D23: 46222
A24: FINAL DESTINATION : | G24: *Remark
B25: O MON IV THERMAL POWER PLANT | G25: - PO No. : 2025012890
B26: Address: O Mon Power Complex at Phuoc Thoi wards, Can Tho city | G26: - Sub-Vendor : MG
G27: - OEM's Inv No. : OM4-M-001-JPN
A28: COMMODITY/DESCRIPTION OF GOODS | H28: UNIT | I28: QUANTITY | J28: UNIT PRICE (USD) | K28: AMOUNT (USD)
B29: PLANT/ EQUIPMENT AND MATERIALS FOR O MON IV THERMAL POWER PLANT (Contract No. OM4-PO-DE-001)
A30: Gas Turbine Generator set and its auxiliaries #1 & #2 - Embedded materials
H31: LOT | I31: 1 | K31: 246032.64
B35: DETAILS ARE AS PER ATTACHED SHEET
B37: TOTAL AMOUNT AT THIS SHIPMENT : | K37: =SUM(K30:K36) -> 246032.64
G44: Signed by
H45: Jinho. Lee / Deputy Project Director

Sheet Commercial Invoice
B3: PECC2 Innovation Hub, 45 Street No.2, Truong Tho Ward, Thu Duc City, HCMC, Vietnam Tel: +84-28-2221 6468 | Fax: +84-28-2221 0408
A4: COMMERCIAL INVOICE
A5: SHIPPER: | G5: INVOICE NO. : | H5: OM4-DE-IS-0005
B6: Doosan Enerbility Co., Ltd. 22 DoosanVolvo-ro, Seongsan-gu, Chang-won-si, Gyeongsangnam-do 51711, Republic of Korea | G6: DATE: | H6: 46171
G7: CONTRACT NO. | H7: 06/2025/HĐ-PVN/OM4-06
G8: DATE: | H8: 45814
A9: CONSIGNEE : | G9: SHIPPING MARK
B10: Cty Doosan Enerbility Co.,Ltd HQ-Nha thau TH CV thuoc Goi thau so OM4-EPC-HHO-06 cho NMND O Mon IV Thoi Loi Area, Phuoc Thoi Ward, Can Tho City, Vietnam T : (+84) 367 566 167 F : (+84 243) 624 8485 | G10: O MON IV THERMAL POWER PLANT
A13: NOTIFY PARTY :
B14: Cty Doosan Enerbility Co.,Ltd HQ-Nha thau TH CV thuoc Goi thau so OM4-EPC-HHO-06 cho NMND O Mon IV Thoi Loi Area, Phươc Thoi Ward, Can Tho City, Vietnam T : (+84) 367 566 167 F : (+84 243) 624 8485 BRANCH OF KWANGJIN VIET NAM IN DUNG QUAT Co.,Ltd Dung Quat Economic Zone, Van Tuong Commune, Quang Ngai Province, Vietnam T : (+84) 28 3825 6330 Attn: Mr. Phuoc / Email: phuoc@kjtc.co.kr
G15: SHIPMENT NO. : | H15: OM4-DE-IS-0005
G17: TERM OF DELIVERY : | H17: CIF Ho Chi Minh City Port, Vietnam
A18: VESSEL NAME : | C18: ETD :
B19: ASL TAIPEI / 2629S | D19: 46223 | G19: QUALITY | H19: 100% BRAND NEW
A20: PORT OF LOADING : | C20: PORT OF DISCHARGE : | G20: PAYMENT TERMS: | H20: T/T
B21: KOBE, JAPAN | D21: Ho Chi Minh City Port, Vietnam
A22: BILL OF LADING/ AIRWAY BILL NO. : | C22: B/L DATE :
B23: SITKBSG2612069 | D23: 46222
A24: FINAL DESTINATION : | G24: *Remark
B25: O MON IV THERMAL POWER PLANT | G25: - PO No. : 2025012890
B26: Address: O Mon Power Complex at Phuoc Thoi wards, Can Tho city | G26: - Sub-Vendor : MG
G27: - OEM's Inv No. : OM4-M-001-JPN
A28: COMMODITY/DESCRIPTION OF GOODS | H28: UNIT | I28: QUANTITY | J28: UNIT PRICE (USD) | K28: AMOUNT (USD)
B29: PLANT/ EQUIPMENT AND MATERIALS FOR O MON IV THERMAL POWER PLANT (Contract No. OM4-PO-DE-001)
A30: Gas Turbine Generator set and its auxiliaries #1 & #2 - Embedded materials
H31: CASE | I31: 24 | J31: =ROUND(K31/I31,2) -> 10251.36 | K31: ='Break Down CI'!K58 -> 246032.64
B35: DETAILS ARE AS PER ATTACHED SHEET
B37: TOTAL AMOUNT AT THIS SHIPMENT : | K37: =SUM(K30:K36) -> 246032.64
G44: Signed by
H45: Jinho. Lee / Deputy Project Director

Sheet Break Down CI
V4: 1 | W4: 15750
A5: INVOICE NO. : | C5: ='Commercial Invoice'!H5 -> OM4-DE-IS-0005 | F5: PLACE : | M5: ='Commercial Invoice'!G6 -> DATE: | N5: ='Commercial Invoice'!H6 -> 46171 | V5: 2 | W5: 9817.5
V6: 3 | W6: 14280
A7: SI. No. | B7: Package No. | C7: COMMODITY/DESCRIPTION OF GOODS | E7: POSITION IN PRICE SCHEDULE | F7: POSITION IN THE MASTER LIST | G7: QUANTITY | H7: UNIT | I7: NET WEIGHT (KG) | J7: UNIT PRICE (USD) | K7: AMOUNT (USD) | L7: DWG No. | M7: ASSEMBLY D.W.G NO. | N7: Remark (**) | V7: 4 | W7: 12495
A8: 1 | B8: OM4-MG-GEN1-KOB-0001 | C8: GROUT RETAINER | E8: PS 1.1, Ⅰ, 2 | F8: N/A | G8: 4 | H8: PCS | I8: 300 | J8: =ROUND(K8/G8,2) -> 2423.5 | K8: 9693.98 | L8: A13C454 -G01 | N8: G1
A9: 2 | B9: OM4-MG-GEN1-KOB-0002 | C9: GROUT RETAINER | E9: PS 1.1, Ⅰ, 2 | F9: N/A | G9: 1 | H9: PCE | I9: 55.555556 | J9: =ROUND(K9/G9,2) -> 4350.94 | K9: 4350.94 | L9: A13C454 -G02 | N9: G1
A10: 3 | B10: OM4-MG-GEN1-KOB-0002 | C10: GROUT RETAINER | E10: PS 1.1, Ⅰ, 2 | F10: N/A | G10: 1 | H10: PCE | I10: 55.555556 | J10: =ROUND(K10/G10,2) -> 4350.94 | K10: 4350.94 | L10: A13C454 -G03 | N10: G1
A11: 4 | B11: OM4-MG-GEN1-KOB-0002 | C11: GROUT RETAINER | E11: PS 1.1, Ⅰ, 2 | F11: N/A | G11: 1 | H11: PCE | I11: 55.555556 | J11: =ROUND(K11/G11,2) -> 4350.94 | K11: 4350.94 | L11: A13C454 -G04 | N11: G1
A12: 5 | B12: OM4-MG-GEN1-KOB-0002 | C12: GROUT RETAINER | E12: PS 1.1, Ⅰ, 2 | F12: N/A | G12: 1 | H12: PCE | I12: 55.555556 | J12: =ROUND(K12/G12,2) -> 4350.94 | K12: 4350.94 | L12: A13C454 -G05 | N12: G1
A13: 6 | B13: OM4-MG-GEN1-KOB-0002 | C13: GROUT RETAINER | E13: PS 1.1, Ⅰ, 2 | F13: N/A | G13: 2 | H13: PCS | I13: 111.11111 | J13: =ROUND(K13/G13,2) -> 2782.64 | K13: 5565.27 | L13: A13C454 -G06 | N13: G1
A14: 7 | B14: OM4-MG-GEN1-KOB-0002 | C14: GROUT RETAINER | E14: PS 1.1, Ⅰ, 2 | F14: N/A | G14: 2 | H14: PCS | I14: 111.11111 | J14: =ROUND(K14/G14,2) -> 2782.64 | K14: 5565.27 | L14: A13C454 -G07 | N14: G1
A15: 8 | B15: OM4-MG-GEN1-KOB-0002 | C15: GROUT RETAINER | E15: PS 1.1, Ⅰ, 2 | F15: N/A | G15: 1 | H15: PCE | I15: 55.555556 | J15: =ROUND(K15/G15,2) -> 4350.94 | K15: 4350.94 | L15: A13C454 -G08 | N15: G1
A16: 9 | B16: OM4-MG-GEN1-KOB-0003 | C16: EMBEDDED PLATE 500X100Xt6 EB402263-1 | E16: PS 1.1, Ⅰ, 2 | F16: N/A | G16: 27 | H16: PCS | I16: 273.375 | J16: =ROUND(K16/G16,2) -> 41.26 | K16: 1113.935 | L16: EB402263-1 | M16: EBABH-W0624 | N16: G1 | Z16: Items Excluded from RCEP COO Application
A17: 10 | B17: OM4-MG-GEN1-KOB-0003 | C17: EMBEDDED PLATE 1000X100Xt6 EB402263-2 | E17: PS 1.1, Ⅰ, 2 | F17: N/A | G17: 42 | H17: PCS | I17: 425.25 | J17: =ROUND(K17/G17,2) -> 41.26 | K17: 1732.79 | L17: EB402263-2 | M17: EBABH-W0624 | N17: G1 | Z17: Items Excluded from RCEP COO Application
A18: 11 | B18: OM4-MG-GEN1-KOB-0003 | C18: EMBEDDED PLATE 1500X100Xt6 EB4022_x000D_ 63-3 | E18: PS 1.1, Ⅰ, 2 | F18: N/A | G18: 9 | H18: PCS | I18: 91.125 | J18: =ROUND(K18/G18,2) -> 41.26 | K18: 371.31 | L18: EB402263-3 | M18: EBABH-W0624 | N18: G1 | Z18: Items Excluded from RCEP COO Application
A19: 12 | B19: OM4-MG-GEN1-KOB-0003 | C19: EMBEDDED PLATE 1500X200Xt9 EB4022_x000D_ 63-4 | E19: PS 1.1, Ⅰ, 2 | F19: N/A | G19: 2 | H19: PCS | I19: 20.25 | J19: =ROUND(K19/G19,2) -> 41.24 | K19: 82.485 | L19: EB402263-4 | M19: EBABH-W0624 | N19: G1 | Z19: Items Excluded from RCEP COO Application
A20: 13 | B20: OM4-MG-GEN1-KOB-0004 | C20: ANCHOR BLOCK | E20: PS 1.1, Ⅰ, 2 | F20: N/A | G20: 1 | H20: PCE | I20: 447 | J20: =ROUND(K20/G20,2) -> 9770.49 | K20: 9770.49 | L20: AS29212 -G03 | M20: EB102586 | N20: G1
A21: 14 | B21: OM4-MG-GEN1-KOB-0005 | C21: ANCHOR BLOCK | E21: PS 1.1, Ⅰ, 2 | F21: N/A | G21: 1 | H21: PCE | I21: 676 | J21: =ROUND(K21/G21,2) -> 14775.95 | K21: 14775.95 | L21: AS29643 -G03 | M21: EB102586 | N21: G1
A22: 15 | B22: OM4-MG-GEN1-KOB-0006 | C22: BOX 1/4 | E22: PS 1.1, Ⅰ, 2 | F22: N/A | G22: 2 | H22: PCS | I22: 540 | J22: =ROUND(K22/G22,2) -> 5901.64 | K22: 11803.27 | L22: A12R049 -G01 | M22: EB102585 | N22: G1
A23: 16 | B23: OM4-MG-GEN1-KOB-0007 | C23: BOX 2/4 | E23: PS 1.1, Ⅰ, 2 | F23: N/A | G23: 2 | H23: PCS | I23: 540 | J23: =ROUND(K23/G23,2) -> 5901.64 | K23: 11803.27 | L23: A12R049 -G01 | M23: EB102585 | N23: G1
A24: 17 | B24: OM4-MG-GEN1-KOB-0008 | C24: BOX 3/4 | E24: PS 1.1, Ⅰ, 2 | F24: N/A | G24: 2 | H24: PCS | I24: 540 | J24: =ROUND(K24/G24,2) -> 5901.64 | K24: 11803.27 | L24: A12R049 -G01 | M24: EB102585 | N24: G1
A25: 18 | B25: OM4-MG-GEN1-KOB-0009 | C25: BOX 4/4 | E25: PS 1.1, Ⅰ, 2 | F25: N/A | G25: 2 | H25: PCS | I25: 540 | J25: =ROUND(K25/G25,2) -> 5901.64 | K25: 11803.27 | L25: A12R049 -G01 | M25: EB102585 | N25: G1
A26: 19 | B26: OM4-MG-GEN1-KOB-0010 | C26: COVER | E26: PS 1.1, Ⅰ, 2 | F26: N/A | G26: 8 | H26: PCS | I26: 55 | J26: =ROUND(K26/G26,2) -> 150.27 | K26: 1202.19 | L26: A12R049 -G02 | M26: EB102585 | N26: G1
A27: 20 | B27: OM4-MG-GEN1-KOB-0011 | C27: FOUNDATION BOLT M36 A36P470-5 | E27: PS 1.1, Ⅰ, 2 | F27: N/A | G27: 36 | H27: PCS | I27: 556.36364 | J27: =ROUND(K27/G27,2) -> 67.56 | K27: 2432.19 | L27: A36P470-5 | M27: EB102585 | N27: G1 | Z27: Items Excluded from RCEP COO Application
A28: 21 | B28: OM4-MG-GEN1-KOB-0011 | C28: FOUNDATION BOLT M30 A36P470-7 | E28: PS 1.1, Ⅰ, 2 | F28: N/A | G28: 8 | H28: PCS | I28: 123.63636 | J28: =ROUND(K28/G28,2) -> 67.56 | K28: 540.49 | L28: A36P470-7 | M28: EB102585 | N28: G1 | Z28: Items Excluded from RCEP COO Application
A29: 22 | B29: OM4-MG-GEN1-MAR-0001 | C29: EMBEDDED METAL-1 (Fe)200×500×159 | E29: PS 1.1, Ⅰ, 2 | F29: N/A | G29: 3 | H29: PCS | I29: 18.333333 | J29: =ROUND(K29/G29,2) -> 133.58 | K29: 400.73 | M29: OM4-DE-XB02-P0MKC-EL-230144 (EBT3-EAY-EG12) | N29: G1
A30: 23 | B30: OM4-MG-GEN1-MAR-0001 | C30: EMBEDDED METAL-2 (Fe)200×200×159 | E30: PS 1.1, Ⅰ, 2 | F30: N/A | G30: 4 | H30: PCS | I30: 24.444444 | J30: =ROUND(K30/G30,2) -> 133.58 | K30: 534.3 | M30: OM4-DE-XB02-P0MKC-EL-230144 (EBT3-EAY-EG12) | N30: G1
A31: 24 | B31: OM4-MG-GEN1-MAR-0001 | C31: EMBEDDED METAL-1 (Fe)200×500×159 | E31: PS 1.1, Ⅰ, 2 | F31: N/A | G31: 1 | H31: PCE | I31: 6.1111111 | J31: =ROUND(K31/G31,2) -> 133.58 | K31: 133.58 | M31: OM4-DE-XB02-P0MKC-EL-230144 (EBT3-EAY-EG12) | N31: G1
A32: 25 | B32: OM4-MG-GEN1-MAR-0001 | C32: EMBEDDED METAL-2 (Fe)200×200×159 | E32: PS 1.1, Ⅰ, 2 | F32: N/A | G32: 1 | H32: PCE | I32: 6.1111111 | J32: =ROUND(K32/G32,2) -> 133.58 | K32: 133.58 | M32: OM4-DE-XB02-P0MKC-EL-230144 (EBT3-EAY-EG12) | N32: G1
A33: 26 | B33: OM4-MG-GEN2-KOB-0001 | C33: GROUT RETAINER | E33: PS 1.1, Ⅰ, 4 | F33: N/A | G33: 4 | H33: PCS | I33: 300 | J33: =ROUND(K33/G33,2) -> 2423.5 | K33: 9693.98 | L33: A13C454 -G01 | N33: G2
A34: 27 | B34: OM4-MG-GEN2-KOB-0002 | C34: GROUT RETAINER | E34: PS 1.1, Ⅰ, 4 | F34: N/A | G34: 1 | H34: PCE | I34: 55.555556 | J34: =ROUND(K34/G34,2) -> 4350.94 | K34: 4350.94 | L34: A13C454 -G02 | N34: G2
A35: 28 | B35: OM4-MG-GEN2-KOB-0002 | C35: GROUT RETAINER | E35: PS 1.1, Ⅰ, 4 | F35: N/A | G35: 1 | H35: PCE | I35: 55.555556 | J35: =ROUND(K35/G35,2) -> 4350.94 | K35: 4350.94 | L35: A13C454 -G03 | N35: G2
A36: 29 | B36: OM4-MG-GEN2-KOB-0002 | C36: GROUT RETAINER | E36: PS 1.1, Ⅰ, 4 | F36: N/A | G36: 1 | H36: PCE | I36: 55.555556 | J36: =ROUND(K36/G36,2) -> 4350.94 | K36: 4350.94 | L36: A13C454 -G04 | N36: G2
A37: 30 | B37: OM4-MG-GEN2-KOB-0002 | C37: GROUT RETAINER | E37: PS 1.1, Ⅰ, 4 | F37: N/A | G37: 1 | H37: PCE | I37: 55.555556 | J37: =ROUND(K37/G37,2) -> 4350.94 | K37: 4350.94 | L37: A13C454 -G05 | N37: G2
A38: 31 | B38: OM4-MG-GEN2-KOB-0002 | C38: GROUT RETAINER | E38: PS 1.1, Ⅰ, 4 | F38: N/A | G38: 2 | H38: PCS | I38: 111.11111 | J38: =ROUND(K38/G38,2) -> 2782.64 | K38: 5565.27 | L38: A13C454 -G06 | N38: G2
A39: 32 | B39: OM4-MG-GEN2-KOB-0002 | C39: GROUT RETAINER | E39: PS 1.1, Ⅰ, 4 | F39: N/A | G39: 2 | H39: PCS | I39: 111.11111 | J39: =ROUND(K39/G39,2) -> 2782.64 | K39: 5565.27 | L39: A13C454 -G07 | N39: G2
A40: 33 | B40: OM4-MG-GEN2-KOB-0002 | C40: GROUT RETAINER | E40: PS 1.1, Ⅰ, 4 | F40: N/A | G40: 1 | H40: PCE | I40: 55.555556 | J40: =ROUND(K40/G40,2) -> 4350.94 | K40: 4350.94 | L40: A13C454 -G08 | N40: G2
A41: 34 | B41: OM4-MG-GEN2-KOB-0003 | C41: EMBEDDED PLATE 1000X100Xt6 EB402263-1 | E41: PS 1.1, Ⅰ, 4 | F41: N/A | G41: 27 | H41: PCS | I41: 236.25 | J41: =ROUND(K41/G41,2) -> 41.26 | K41: 1113.935 | L41: EB402263-1 | M41: EBABH-W0624 | N41: G2 | Z41: Items Excluded from RCEP COO Application
A42: 35 | B42: OM4-MG-GEN2-KOB-0003 | C42: EMBEDDED PLATE 1000X100Xt6 EB402263-2 | E42: PS 1.1, Ⅰ, 4 | F42: N/A | G42: 42 | H42: PCS | I42: 367.5 | J42: =ROUND(K42/G42,2) -> 41.26 | K42: 1732.79 | L42: EB402263-2 | M42: EBABH-W0624 | N42: G2 | Z42: Items Excluded from RCEP COO Application
A43: 36 | B43: OM4-MG-GEN2-KOB-0003 | C43: EMBEDDED PLATE 1500X100Xt6 EB402263-3 | E43: PS 1.1, Ⅰ, 4 | F43: N/A | G43: 9 | H43: PCS | I43: 78.75 | J43: =ROUND(K43/G43,2) -> 41.26 | K43: 371.31 | L43: EB402263-3 | M43: EBABH-W0624 | N43: G2 | Z43: Items Excluded from RCEP COO Application
...

Sheet Packing List (1_2)
B3: PECC2 Innovation Hub, 45 Street No.2, Truong Tho Ward, Thu Duc City, HCMC, Vietnam Tel: +84-28-2221 6468 | Fax: +84-28-2221 0408
A4: PACKING LIST(1/2)
A5: SHIPPER: | G5: P/L No. | H5: ='Commercial Invoice'!H5 -> OM4-DE-IS-0005
B6: Doosan Enerbility Co., Ltd. 22 DoosanVolvo-ro, Seongsan-gu, Chang-won-si, Gyeongsangnam-do 51711, Republic of Korea | G6: DATE: | H6: ='Commercial Invoice'!H6 -> 46171
G7: CONTRACT NO. | H7: 06/2025/HĐ-PVN/OM4-06
G8: DATE: | H8: ='Commercial Invoice'!H8 -> 45814
A9: CONSIGNEE : | G9: SHIPPING MARK
B10: Cty Doosan Enerbility Co.,Ltd HQ-Nha thau TH CV thuoc Goi thau so OM4-EPC-HHO-06 cho NMND O Mon IV Thoi Loi Area, Phuoc Thoi Ward, Can Tho City, Vietnam T : (+84) 367 566 167 F : (+84 243) 624 8485 | G10: O MON IV THERMAL POWER PLANT
A13: NOTIFY PARTY :
B14: Cty Doosan Enerbility Co.,Ltd HQ-Nha thau TH CV thuoc Goi thau so OM4-EPC-HHO-06 cho NMND O Mon IV Thoi Loi Area, Phươc Thoi Ward, Can Tho City, Vietnam T : (+84) 367 566 167 F : (+84 243) 624 8485 BRANCH OF KWANGJIN VIET NAM IN DUNG QUAT Co.,Ltd Dung Quat Economic Zone, Van Tuong Commune, Quang Ngai Province, Vietnam T : (+84) 28 3825 6330 Attn: Mr. Phuoc / Email: phuoc@kjtc.co.kr
G15: SHIPMENT NO. : | H15: ='Commercial Invoice'!H15:K16 -> OM4-DE-IS-0005
G17: TERM OF DELIVERY : | H17: CIF Ho Chi Minh City Port, Vietnam
A18: VESSEL NAME : | C18: ETD :
B19: ASL TAIPEI / 2629S | D19: 46223 | G19: QUALITY | H19: 100% BRAND NEW
A20: PORT OF LOADING : | C20: PORT OF DISCHARGE :
B21: KOBE, JAPAN | D21: Ho Chi Minh City Port, Vietnam
A22: BILL OF LADING/ AIRWAY BILL NO. : | C22: B/L DATE :
B23: SITKBSG2612069 | D23: 46222
A24: FINAL DESTINATION : | G24: *Remark
B25: O MON IV THERMAL POWER PLANT | G25: - PO No. : 2025012890
B26: Address: O Mon Power Complex at Phuoc Thoi wards, Can Tho city | G26: - Sub-Vendor : MG
G27: - OEM's Inv No. : OM4-M-001-JPN
A28: COMMODITY/DESCRIPTION OF GOODS | G28: UNIT | H28: QUANTITY | I28: NET WEIGHT (KG) | J28: GROSS WEIGHT (KG) | K28: MEASUREMENT (CBM)
B29: PLANT/ EQUIPMENT AND MATERIALS FOR O MON IV THERMAL POWER PLANT (Contract No. OM4-PO-DE-001)
B31: Gas Turbine Generator set and its auxiliaries #1 & #2 - Embedded materials | G31: CASE | H31: 4 | I31: 2246 | J31: 2704 | K31: 4.814 | M31: ANCHOR BLOCK
G32: CASE | H32: 2 | I32: 1080 | J32: 1366 | K32: 3.334 | M32: BOX 1/4
G33: CASE | H33: 2 | I33: 1080 | J33: 1366 | K33: 3.334 | M33: BOX 2/4
G34: CASE | H34: 2 | I34: 1080 | J34: 1366 | K34: =1.667*2 -> 3.334 | M34: BOX 3/4
G35: CASE | H35: 2 | I35: 1080 | J35: 1366 | K35: =1.667*2 -> 3.334 | M35: BOX 4/4
G36: CASE | H36: 2 | I36: 110 | J36: 200 | K36: 1.008 | M36: COVER
G37: CASE | H37: 2 | I37: 110 | J37: 200 | K37: 1.024 | M37: EMBEDDED METAL-1 (Fe)200×500×159
B38: Number of packages: | D38: 24 | E38: PKGS | G38: CASE | H38: 2 | I38: 1510 | J38: 2330 | K38: 16.598 | M38: EMBEDDED PLATE 500X100Xt6 EB40226_x000D_ 3-1
G39: CASE | H39: 2 | I39: 1360 | J39: 1700 | K39: =1.961*2 -> 3.922 | M39: FOUNDATION BOLT M36 A36P470-5
G40: CASE | H40: 4 | I40: 1600 | J40: 3920 | K40: 25.972 | M40: GROUT RETAINER
G42: TOTAL | I42: =SUM(I29:I41) -> 11256 | J42: =SUM(J29:J41) -> 16518 | K42: =SUM(K29:K41) -> 66.674
G48: Signed by
H49: Jinho. Lee / Deputy Project Director

Sheet PL(2_2)
C3: PECC2 Innovation Hub, 45 Street No.2, Truong Tho Ward, Thu Duc City, HCMC, Vietnam Tel: +84-28-2221 6468 | Fax: +84-28-2221 0408
B4: PACKING LIST(2/2)
C5: P/L No. | D5: ='Packing List (1_2)'!H5 -> OM4-DE-IS-0005
C6: Dated | D6: ='Packing List (1_2)'!H6 -> 46171 | G6: * Storage Classification | O6: ** Plant/Equipment/Materials for
C7: Project | D7: O MON IV THERMAL POWER PLANT | G7: "A" | H7: : Indoor with Air conditioning | P7: GTG | Q7: TBN | R7: GEN | S7: BOP
G8: "B" | H8: : Indoor without Air conditioning | O8: Unit 1 | P8: B1 | Q8: T1 | R8: G1 | S8: P2
G9: "C" | H9: : Hazardous Material | O9: Unit 2 | P9: B2 | Q9: T2 | R9: G2 | S9: P2
G10: "D" | H10: : Outdoor with waterproofing | O10: Common | P10: B0 | Q10: T0 | R10: G0 | S10: P0
G11: "E" | H11: : Outdoor without waterproofing
B13: SI. No. | C13: Package No. | D13: Description of Goods | E13: Position in price schedule | F13: Quantity | H13: Package Type | I13: Measurement | M13: Net Weight (kg) | N13: Gross Weight (kg) | O13: Hazardous Material | P13: COG Marked (Y/N) | Q13: Sling Point Marked (Y/N) | R13: Handle with care Marked (Y/N) | S13: Storage Classification (*) | T13: Remark (**)
F14: Nos | G14: Unit | I14: Length (cm) | J14: Width (cm) | K14: Height (cm) | L14: Volume (cbm)
B15: 1 | C15: OM4-MG-GEN1-KOB-0001 | D15: GROUT RETAINER | E15: PS 1.1, Ⅰ, 2 | F15: 1 | H15: CASE | I15: 608 | J15: 158 | K15: 60 | L15: 5.764 | M15: 300 | N15: 930 | O15: N | P15: Y | Q15: Y | R15: Y | S15: B | T15: G1
B16: 2 | C16: OM4-MG-GEN1-KOB-0002 | D16: GROUT RETAINER | E16: PS 1.1, Ⅰ, 2 | F16: 1 | H16: CASE | I16: 354 | J16: 204 | K16: 100 | L16: 7.222 | M16: 500 | N16: 1030 | O16: N | P16: Y | Q16: Y | R16: Y | S16: B | T16: G1
B17: 3 | C17: OM4-MG-GEN1-KOB-0003 | D17: EMBEDDED PLATE 500X100Xt6 EB40226 3-1 | E17: PS 1.1, Ⅰ, 2 | F17: 1 | H17: CASE | I17: 340 | J17: 208 | K17: 138 | L17: 9.759 | M17: 810 | N17: 1350 | O17: N | P17: Y | Q17: Y | R17: Y | S17: B | T17: G1
B18: 4 | C18: OM4-MG-GEN1-KOB-0004 | D18: ANCHOR BLOCK | E18: PS 1.1, Ⅰ, 2 | F18: 1 | H18: CASE | I18: 115 | J18: 94 | K18: 85 | L18: 0.919 | M18: 447 | N18: 540 | O18: N | P18: Y | Q18: Y | R18: Y | S18: B | T18: G1
B19: 5 | C19: OM4-MG-GEN1-KOB-0005 | D19: ANCHOR BLOCK | E19: PS 1.1, Ⅰ, 2 | F19: 1 | H19: CASE | I19: 168 | J19: 115 | K19: 77 | L19: 1.488 | M19: 676 | N19: 812 | O19: N | P19: Y | Q19: Y | R19: Y | S19: B | T19: G1
B20: 6 | C20: OM4-MG-GEN1-KOB-0006 | D20: BOX 1/4 | E20: PS 1.1, Ⅰ, 2 | F20: 1 | H20: CASE | I20: 125 | J20: 117 | K20: 114 | L20: 1.667 | M20: 540 | N20: 683 | O20: N | P20: Y | Q20: Y | R20: Y | S20: B | T20: G1
B21: 7 | C21: OM4-MG-GEN1-KOB-0007 | D21: BOX 2/4 | E21: PS 1.1, Ⅰ, 2 | F21: 1 | H21: CASE | I21: 125 | J21: 117 | K21: 114 | L21: 1.667 | M21: 540 | N21: 683 | O21: N | P21: Y | Q21: Y | R21: Y | S21: B | T21: G1
B22: 8 | C22: OM4-MG-GEN1-KOB-0008 | D22: BOX 3/4 | E22: PS 1.1, Ⅰ, 2 | F22: 1 | H22: CASE | I22: 125 | J22: 117 | K22: 114 | L22: 1.667 | M22: 540 | N22: 683 | O22: N | P22: Y | Q22: Y | R22: Y | S22: B | T22: G1
B23: 9 | C23: OM4-MG-GEN1-KOB-0009 | D23: BOX 4/4 | E23: PS 1.1, Ⅰ, 2 | F23: 1 | H23: CASE | I23: 125 | J23: 117 | K23: 114 | L23: 1.667 | M23: 540 | N23: 683 | O23: N | P23: Y | Q23: Y | R23: Y | S23: B | T23: G1
B24: 10 | C24: OM4-MG-GEN1-KOB-0010 | D24: COVER | E24: PS 1.1, Ⅰ, 2 | F24: 1 | H24: CASE | I24: 100 | J24: 80 | K24: 63 | L24: 0.504 | M24: 55 | N24: 100 | O24: N | P24: Y | Q24: Y | R24: Y | S24: B | T24: G1
B25: 11 | C25: OM4-MG-GEN1-KOB-0011 | D25: FOUNDATION BOLT M36 A36P470-5 | E25: PS 1.1, Ⅰ, 2 | F25: 1 | H25: CASE | I25: 148 | J25: 138 | K25: 96 | L25: 1.961 | M25: 680 | N25: 850 | O25: N | P25: Y | Q25: Y | R25: Y | S25: B | T25: G1
B26: 12 | C26: OM4-MG-GEN1-MAR-0001 | D26: EMBEDDED METAL-1 (Fe)200×500×159 | E26: PS 1.1, Ⅰ, 2 | F26: 1 | H26: CASE | I26: 80 | J26: 80 | K26: 80 | L26: 0.512 | M26: 55 | N26: 100 | O26: N | P26: N | Q26: N | R26: Y | S26: B | T26: G1
... B38: 24 | C38: OM4-MG-GEN2-MAR-0001 | D38: EMBEDDED METAL-1 (Fe)200×500×159 | E38: PS 1.1, Ⅰ, 4 | F38: 1 | H38: CASE | I38: 80 | J38: 80 | K38: 80 | L38: 0.512 | M38: 55 | N38: 100 | O38: N | P38: N | Q38: N | R38: Y | S38: B | T38: G2
B39: Grand Total | L39: =SUM(L15:L38) -> 66.674 | M39: =SUM(M14:M38) -> 11256 | N39: =SUM(N14:N38) -> 16518

Sheet SHIPPING MARK(1)
A1: SHIPPING MARK
A2: O MON IV THERMAL POWER PLANT
A3: Address: O Mon Power Complex at Phuoc Thoi wards, O Mon district, Can Tho city
A4: SHIPPER | B4: : | C4: Doosan Enerbility Co., Ltd.
A5: ADDRESS | B5: : | C5: 22 DoosanVolvo-ro, Seongsan-gu, Chang-won-si, Gyeongsangnam-do 51711, Republic of Korea
A6: CONSIGNEE | B6: : | C6: Cty Doosan Enerbility Co.,Ltd HQ-Nha thau TH CV thuoc Goi thau so OM4-EPC-HHO-06 cho NMND O Mon IV Thoi Loi Area, Phuoc Thoi Ward, Can Tho City, Vietnam T : (+84) 367 566 167 F : (+84 243) 624 8485
A7: NOTIFY PARTY | B7: : | C7: Cty Doosan Enerbility Co.,Ltd HQ-Nha thau TH CV thuoc Goi thau so OM4-EPC-HHO-06 cho NMND O Mon IV Thoi Loi Area, Phươc Thoi Ward, Can Tho City, Vietnam T : (+84) 367 566 167 F : (+84 243) 624 8485 BRANCH OF KWANGJIN VIET NAM IN DUNG QUAT Co.,Ltd Dung Quat Economic Zone, Van Tuong Commune, Quang Ngai Province, Vietnam T : (+84) 28 3825 6330 Attn: Mr. Phuoc / Email: phuoc@kjtc.co.kr
A8: CONTRACT NO. | B8: : | C8: 06/2025/HĐ-PVN/OM4-06
A9: SHIPMENT NO. | B9: : | C9: OM4-DE-IS-0005
A10: EQUIPMENT DESCRIPTION | B10: : | C10: PLANT/ EQUIPMENT AND MATERIALS FOR O MON IV THERMAL
