Workbook
Name latent: #REF!
Name tube_test_press1_12: #REF!

Sheet Breakdown CI
B4: BREAK DOWN of COMMERCIAL INVOICE
B6: INVOICE NO. : | D6: OM4-DE-IS-0002 | E6: PLACE : | I6: DATE : | J6: =#REF! -> #REF! | R6: 2 | S6: 9817.5
B8: SI. No. | C8: Package No. | D8: Description of Goods | F8: C/O of Goods | G8: Position in price schedule | H8: Quantity | J8: Package Type | K8: NET WEIGHT (KG) | L8: UNIT PRICE (USD) | M8: AMOUNT (USD) | N8: Remark (**)
H9: Nos | I9: Unit | Q9: HS CODE
B10: 1 | C10: OM4-DE-IS-0002-001 | D10: TEMPLATE(TP-1)_10T*374*374 | F10: Republic of Korea | G10: PS 1.1, Ⅱ, 2 | H10: 20 | I10: EA | J10: Wooden Box | K10: 190 | L10: 60 | M10: 1200 | N10: B2 | Q10: 7326.90-9000
B11: 2 | C11: OM4-DE-IS-0002-001 | D11: TEMPLATE(TP-2)_10T*450*900 | F11: Republic of Korea | G11: PS 1.1, Ⅱ, 2 | H11: 40 | I11: EA | J11: Wooden Box | K11: 916 | L11: 144.75 | M11: 5790 | N11: B2 | Q11: 7326.90-9000
B12: 3 | C12: OM4-DE-IS-0002-001 | D12: TEMPLATE(TP-3)_10T*270*320 | F12: Republic of Korea | G12: PS 1.1, Ⅱ, 2 | H12: 8 | I12: EA | J12: Wooden Box | K12: 45.6 | L12: 36 | M12: 288 | N12: B2 | Q12: 7326.90-9000
B13: 4 | C13: OM4-DE-IS-0002-001 | D13: TEMPLATE(STP-1)_15T*250*3801 | F13: Republic of Korea | G13: PS 1.1, Ⅱ, 2 | H13: 6 | I13: EA | J13: Wooden Box | K13: 663 | L13: 698.5 | M13: 4191 | N13: B2 | Q13: 7326.90-9000
B14: 5 | C14: OM4-DE-IS-0002-001 | D14: TEMPLATE(STP-2)_10T*60*250 | F14: Republic of Korea | G14: PS 1.1, Ⅱ, 2 | H14: 6 | I14: EA | J14: Wooden Box | K14: 7.2 | L14: 7.5 | M14: 45 | N14: B2 | Q14: 7326.90-9000
B15: 6 | C15: OM4-DE-IS-0002-001 | D15: TEMPLATE(STP-3)_15T*250*3801 | F15: Republic of Korea | G15: PS 1.1, Ⅱ, 2 | H15: 6 | I15: EA | J15: Wooden Box | K15: 663 | L15: 698.5 | M15: 4191 | N15: B2 | Q15: 7326.90-9000
B16: 7 | C16: OM4-DE-IS-0002-001 | D16: TEMPLATE(STP-4)_10T*60*250 | F16: Republic of Korea | G16: PS 1.1, Ⅱ, 2 | H16: 6 | I16: EA | J16: Wooden Box | K16: 7.2 | L16: 7.5 | M16: 45 | N16: B2 | Q16: 7326.90-9000
B17: 8 | C17: OM4-DE-IS-0002-002 | D17: Anchor Bolt M56X1,515L | F17: Republic of Korea | G17: PS 1.1, Ⅱ, 2 | H17: 40 | I17: EA | J17: Wooden Box | K17: 1060 | L17: 35.0625 | M17: 1402.5 | N17: B2 | Q17: 7318.15-2000
B18: 9 | C18: OM4-DE-IS-0002-002 | D18: Nut M56 | F18: Republic of Korea | G18: PS 1.1, Ⅱ, 2 | H18: 160 | I18: EA | J18: Wooden Box | K18: 288 | L18: 35.0625 | M18: 5610 | N18: B2 | Q18: 7318.16-0000
B19: 10 | C19: OM4-DE-IS-0002-002 | D19: Anchor Bolt M42X1,110L | F19: Republic of Korea | G19: PS 1.1, Ⅱ, 2 | H19: 16 | I19: EA | J19: Wooden Box | K19: 175 | L19: 35.0625 | M19: 561 | N19: B2 | Q19: 7318.15-2000
B20: 11 | C20: OM4-DE-IS-0002-002 | D20: Nut M42 | F20: Republic of Korea | G20: PS 1.1, Ⅱ, 2 | H20: 64 | I20: EA | J20: Wooden Box | K20: 45 | L20: 35.0625 | M20: 2244 | N20: B2 | Q20: 7318.16-0000
B21: 12 | C21: OM4-DE-IS-0002-003 | D21: Anchor Bolt M60X1,560L | F21: Republic of Korea | G21: PS 1.1, Ⅱ, 2 | H21: 53 | I21: EA | J21: Wooden Box | K21: 1654 | L21: 49.0875 | M21: 2601.6375 | N21: B2 | Q21: 7318.15-2000
... B50: 41 | C50: OM4-DE-IS-0002-009 | D50: Square Washer 120X120X16T | F50: Republic of Korea | G50: PS 1.1, Ⅱ, 2 | H50: 5 | I50: EA | J50: Wooden Box | K50: 9 | L50: 10.857143 | M50: 54.285714 | N50: B2 | Q50: 7318.22-0000
B51: Grand-Total | M51: 105000

Sheet PL(2_2)
C3: PECC2 Innovation Hub, 45 Street No.2, Truong Tho Ward, Thu Duc City, HCMC, Vietnam Tel: +84-28-2221 6468 | Fax: +84-28-2221 0408
B4: PACKING LIST(2/2)
C5: P/L No. | D5: =#REF! -> #REF!
C6: Dated | D6: =#REF! -> #REF! | G6: * Storage Classification | L6: ** Plant/Equipment/Materials for
C7: Project | D7: O MON IV THERMAL POWER PLANT | G7: "A" | H7: : Indoor with Air conditioning | M7: HRSG | N7: STG | O7: GTG | P7: BOP
G8: "B" | H8: : Indoor without Air conditioning | L8: Unit 1 | M8: B1 | N8: T1 | O8: G1 | P8: P2
G9: "C" | H9: : Hazardous Material | L9: Unit 2 | M9: B2 | N9: T2 | O9: G2 | P9: P2
G10: "D" | H10: : Outdoor with waterproofing | L10: Common | M10: B0 | N10: T0 | O10: G0 | P10: P0
G11: "E" | H11: : Outdoor without waterproofing
B13: SI. No. | C13: Package No. | D13: Description of Goods | E13: Position in price schedule | F13: Quantity | H13: Package Type | I13: Measurement | M13: Net Weight (kg) | N13: Gross Weight (kg) | O13: Hazardous Material | P13: COG Marked (Y/N) | Q13: Sling Point Marked (Y/N) | R13: Handle with care Marked (Y/N) | S13: Storage Classification (*) | T13: Remark (**)
F14: Nos | G14: Unit | I14: Length (cm) | J14: Width (cm) | K14: Height (cm) | L14: Volume (cbm)
B15: 1 | C15: ='Detailed PL'!C15 -> OM4-DE-IS-0002-001 | D15: HRSG Embeded Material (Template) | E15: PS 1.1, Ⅱ, 2 | F15: 1 | G15: PKG | H15: Wooden Box | I15: 410 | J15: 150 | K15: 83 | L15: 5.1045 | M15: 2492 | N15: 2772 | O15: N | P15: Y | Q15: Y | R15: Y | S15: B | T15: B2
B16: 2 | C16: ='Detailed PL'!C23 -> OM4-DE-IS-0002-002 | D16: HRSG Embeded Material (Anchor Bolt/Nut/Washer) | E16: PS 1.1, Ⅱ, 2 | F16: 1 | G16: PKG | H16: Wooden Box | I16: 170 | J16: 115 | K16: 85 | L16: 1.66175 | M16: 1568 | N16: 1668 | O16: N | P16: Y | Q16: Y | R16: Y | S16: B | T16: B2
B17: 3 | C17: ='Detailed PL'!C28 -> OM4-DE-IS-0002-003 | D17: HRSG Embeded Material (Anchor Bolt/Nut/Washer) | E17: PS 1.1, Ⅱ, 2 | F17: 1 | G17: PKG | H17: Wooden Box | I17: 175 | J17: 115 | K17: 105 | L17: 2.113125 | M17: 2120 | N17: 2240 | O17: N | P17: Y | Q17: Y | R17: Y | S17: B | T17: B2
B18: 4 | C18: ='Detailed PL'!C31 -> OM4-DE-IS-0002-004 | D18: HRSG Embeded Material (Anchor Bolt/Nut/Washer) | E18: PS 1.1, Ⅱ, 2 | F18: 1 | G18: PKG | H18: Wooden Box | I18: 175 | J18: 115 | K18: 105 | L18: 2.113125 | M18: 2120 | N18: 2240 | O18: N | P18: Y | Q18: Y | R18: Y | S18: B | T18: B2
B19: 5 | C19: ='Detailed PL'!C34 -> OM4-DE-IS-0002-005 | D19: HRSG Embeded Material (Anchor Bolt/Nut/Washer) | E19: PS 1.1, Ⅱ, 2 | F19: 1 | G19: PKG | H19: Wooden Box | I19: 175 | J19: 115 | K19: 105 | L19: 2.113125 | M19: 2160 | N19: 2280 | O19: N | P19: Y | Q19: Y | R19: Y | S19: B | T19: B2
B20: 6 | C20: ='Detailed PL'!C37 -> OM4-DE-IS-0002-006 | D20: HRSG Embeded Material (Anchor Bolt/Nut/Washer) | E20: PS 1.1, Ⅱ, 2 | F20: 1 | G20: PKG | H20: Wooden Box | I20: 215 | J20: 115 | K20: 85 | L20: 2.101625 | M20: 2376 | N20: 2516 | O20: N | P20: Y | Q20: Y | R20: Y | S20: B | T20: B2
B21: 7 | C21: ='Detailed PL'!C40 -> OM4-DE-IS-0002-007 | D21: HRSG Embeded Material (Anchor Bolt/Nut/Washer) | E21: PS 1.1, Ⅱ, 2 | F21: 1 | G21: PKG | H21: Wooden Box | I21: 115 | J21: 115 | K21: 80 | L21: 1.058 | M21: 1567 | N21: 1627 | O21: N | P21: Y | Q21: Y | R21: Y | S21: B | T21: B2
B22: 8 | C22: ='Detailed PL'!C52 -> OM4-DE-IS-0002-008 | D22: HRSG Embeded Material (Anchor Bolt/Nut/Washer) | E22: PS 1.1, Ⅱ, 2 | F22: 1 | G22: PKG | H22: Wooden Box | I22: 245 | J22: 115 | K22: 120 | L22: 3.38 | M22: 2640 | N22: 2790 | O22: N | P22: Y | Q22: Y | R22: Y | S22: B | T22: B2
B23: 9 | C23: ='Detailed PL'!C56 -> OM4-DE-IS-0002-009 | D23: HRSG Embeded Material (Spare) | E23: PS 1.1, Ⅱ, 2 | F23: 1 | G23: PKG | H23: Wooden Box | I23: 90 | J23: 90 | K23: 60 | L23: 0.486 | M23: 155 | N23: 195 | O23: N | P23: Y | Q23: Y | R23: Y | S23: B | T23: B2
B24: Grand Total | L24: =SUM(L15:L23) -> 20.13125 | M24: =SUM(M15:M23) -> 17198 | N24: =SUM(N15:N23) -> 18328

Sheet Detailed PL
C3: PECC2 Innovation Hub, 45 Street No.2, Truong Tho Ward, Thu Duc City, HCMC, Vietnam Tel: +84-28-2221 6468 | Fax: +84-28-2221 0408
B4: DETAILED PACKING LIST
C5: PL No. | D5: ='PL(2_2)'!D5 -> #REF! | Y5: 36 | Z5: 39 | AA5: 40 | AB5: 163 | AC5: 3 | AD5: 8 | AE5: 44 | AF5: 45 | AG5: 46 | AH5: 60 | AI5: 66 | AJ5: 68 | AK5: 69 | AL5: 70 | AM5: 71 | AN5: 170 | AO5: 110 | AP5: 234 | AQ5: 33 | AR5: 34 | AS5: 142 | AU5: 79 | AV5: 80 | AW5: 81 | AX5: 82
C6: Dated | D6: ='PL(2_2)'!D6 -> #REF! | J6: * Storage Classification | O6: ** Plant/Equipment/Materials for | Y6: =SUMIF($AG$65:$AG$65,Y5,$I$65:$I$65) -> 0 | Z6: =SUMIF($AG$65:$AG$65,Z5,$I$65:$I$65) -> 0 | AA6: =SUMIF($AG$65:$AG$65,AA5,$I$65:$I$65) -> 0 | AB6: =SUMIF($AG$65:$AG$65,AB5,$I$65:$I$65) -> 0 | AC6: =SUMIF($AG$65:$AG$65,AC5,$I$65:$I$65) -> 0 | AD6: =SUMIF($AG$65:$AG$65,AD5,$I$65:$I$65) -> 0 | AE6: =SUMIF($AG$65:$AG$65,AE5,$I$65:$I$65) -> 0 | AF6: =SUMIF($AG$65:$AG$65,AF5,$I$65:$I$65) -> 0 | ... AO6: =SUMIF($AG$65:$AG$65,AO5,$I$65:$I$65) -> 0 | AP6: =SUMIF($AG$65:$AG$335,AP5,$I$65:$I$335) -> 0 | AQ6: =SUMIF($AG$65:$AG$335,AQ5,$I$65:$I$335) -> 0 | AR6: =SUMIF($AG$65:$AG$335,AR5,$I$65:$I$335) -> 0 | AS6: =SUMIF($AG$65:$AG$65,AS5,$I$65:$I$65) -> 0 | AT6: =SUM(Y6:AS7) -> 109 | AU6: =SUMIF($AG$65:$AG$65,AU5,$I$65:$I$65) -> 0 | AV6: =SUMIF($AG$65:$AG$65,AV5,$I$65:$I$65) -> 0 | AW6: =SUMIF($AG$65:$AG$335,AW5,$I$65:$I$335) -> 0 | AX6: =SUMIF($AG$65:$AG$335,AX5,$I$65:$I$335) -> 0
C7: Project | D7: ='PL(2_2)'!D7 -> O MON IV THERMAL POWER PLANT | J7: "A" | K7: : Indoor with Air conditioning | P7: HRSG | Q7: TBN | R7: GEN | S7: BOP | AC7: 1 | AD7: 1 | AG7: 5 | AH7: 100 | AS7: 2 | AU7: 105
C8: Referenced DWG No. | D8: OM4-DE-XW03-P1HBA-CI-330003 | J8: "B" | K8: : Indoor without Air conditioning | O8: Unit 1 | P8: B1 | Q8: T1 | R8: G1 | S8: P2
D9: OM4-DE-XW03-P1HBA-CI-330004 | J9: "C" | K9: : Hazardous Material | O9: Unit 2 | P9: B2 | Q9: T2 | R9: G2 | S9: P2
J10: "D" | K10: : Outdoor with waterproofing | O10: Common | P10: B0 | Q10: T0 | R10: G0 | S10: P0
J11: "E" | K11: : Outdoor without waterproofing
B13: SI. No. | C13: Package No. | D13: Description of Goods | F13: Manufacturer | G13: C/O of Goods | H13: Position in price schedule | I13: Quantity | K13: Package Type | L13: Measurement | P13: Net Weight (kg) | Q13: Gross Weight (kg) | R13: Hazardous Material | S13: Storage Classification (*) | T13: Tag No. | U13: Remark (**)
I14: Nos | J14: Unit | L14: Length (cm) | M14: Width (cm) | N14: Height (cm) | O14: Volume (cbm)
B15: 1 | C15: OM4-DE-IS-0002-001 | D15: #2 HRSG Embeded Material | F15: BHI | G15: Republic of Korea | H15: PS 1.1, Ⅱ, 2 | I15: 1 | J15: PKG | K15: Wooden Box | L15: 410 | M15: 150 | N15: 83 | O15: =L15*M15*N15/1000000 -> 5.1045 | P15: 2492 | Q15: 2772 | R15: N | S15: B | U15: B2
C16: OM4-DE-IS-0002-001 | D16: TEMPLATE(TP-1)_10T*374*374 | F16: BHI | G16: Republic of Korea | H16: PS 1.1, Ⅱ, 2 | I16: 20 | J16: EA | P16: 190 | T16: TP-1
C17: OM4-DE-IS-0002-001 | D17: TEMPLATE(TP-2)_10T*450*900 | F17: BHI | G17: Republic of Korea | H17: PS 1.1, Ⅱ, 2 | I17: 40 | J17: EA | P17: 916 | T17: TP-2
C18: OM4-DE-IS-0002-001 | D18: TEMPLATE(TP-3)_10T*270*320 | F18: BHI | G18: Republic of Korea | H18: PS 1.1, Ⅱ, 2 | I18: 8 | J18: EA | P18: 45.6 | T18: TP-3
C19: OM4-DE-IS-0002-001 | D19: TEMPLATE(STP-1)_15T*250*3801 | F19: BHI | G19: Republic of Korea | H19: PS 1.1, Ⅱ, 2 | I19: 6 | J19: EA | P19: 663 | T19: STP-1
C20: OM4-DE-IS-0002-001 | D20: TEMPLATE(STP-2)_10T*60*250 | F20: BHI | G20: Republic of Korea | H20: PS 1.1, Ⅱ, 2 | I20: 6 | J20: EA | P20: 7.2 | T20: STP-2
C21: OM4-DE-IS-0002-001 | D21: TEMPLATE(STP-3)_15T*250*3801 | F21: BHI | G21: Republic of Korea | H21: PS 1.1, Ⅱ, 2 | I21: 6 | J21: EA | P21: 663 | T21: STP-3
C22: OM4-DE-IS-0002-001 | D22: TEMPLATE(STP-4)_10T*60*250 | F22: BHI | G22: Republic of Korea | H22: PS 1.1, Ⅱ, 2 | I22: 6 | J22: EA | P22: 7.2 | T22: STP-4
B23: 2 | C23: OM4-DE-IS-0002-002 | D23: HRSG Embeded Material | F23: BHI | G23: Republic of Korea | H23: PS 1.1, Ⅱ, 2 | I23: 1 | J23: PKG | K23: Wooden Box | L23: 170 | M23: 115 | N23: 85 | O23: =L23*M23*N23/1000000 -> 1.66175 | P23: 1568 | Q23: 1668 | R23: N | S23: B | U23: B2
C24: OM4-DE-IS-0002-002 | D24: Anchor Bolt M56X1,515L | F24: BHI | G24: Republic of Korea | H24: PS 1.1, Ⅱ, 2 | I24: 40 | J24: EA | P24: 1060 | T24: AB-1
C25: OM4-DE-IS-0002-002 | D25: Nut M56 | F25: BHI | G25: Republic of Korea | H25: PS 1.1, Ⅱ, 2 | I25: 160 | J25: EA | P25: 288 | T25: AB-1
C26: OM4-DE-IS-0002-002 | D26: Anchor Bolt M42X1,110L | F26: BHI | G26: Republic of Korea | H26: PS 1.1, Ⅱ, 2 | I26: 16 | J26: EA | P26: 175 | T26: AB-3
C27: OM4-DE-IS-0002-002 | D27: Nut M42 | F27: BHI | G27: Republic of Korea | H27: PS 1.1, Ⅱ, 2 | I27: 64 | J27: EA | P27: 45 | T27: AB-3
B28: 3 | C28: OM4-DE-IS-0002-003 | D28: HRSG Embeded Material | F28: BHI | G28: Republic of Korea | H28: PS 1.1, Ⅱ, 2 | I28: 1 | J28: PKG | K28: Wooden Box | L28: 175 | M28: 115 | N28: 105 | O28: =L28*M28*N28/1000000 -> 2.113125 | P28: 2120 | Q28: 2240 | R28: N | S28: B | U28: B2
C29: OM4-DE-IS-0002-003 | D29: Anchor Bolt M60X1,560L | F29: BHI | G29: Republic of Korea | H29: PS 1.1, Ⅱ, 2 | I29: 53 | J29: EA | P29: 1654 | T29: AB-2
C30: OM4-DE-IS-0002-003 | D30: Nut M60 | F30: BHI | G30: Republic of Korea | H30: PS 1.1, Ⅱ, 2 | I30: 212 | J30: EA | P30: 466 | T30: AB-2
B31: 4 | C31: OM4-DE-IS-0002-004 | D31: HRSG Embeded Material | F31: BHI | G31: Republic of Korea | H31: PS 1.1, Ⅱ, 2 | I31: 1 | J31: PKG | K31: Wooden Box | L31: 175 | M31: 115 | N31: 105 | O31: =L31*M31*N31/1000000 -> 2.113125 | P31: 2120 | Q31: 2240 | R31: N | S31: B | U31: B2
C32: OM4-DE-IS-0002-004 | D32: Anchor Bolt M60X1,560L | F32: BHI | G32: Republic of Korea | H32: PS 1.1, Ⅱ, 2 | I32: 53 | J32: EA | P32: 1654 | T32: AB-2
C33: OM4-DE-IS-0002-004 | D33: Nut M60 | F33: BHI | G33: Republic of Korea | H33: PS 1.1, Ⅱ, 2 | I33: 212 | J33: EA | P33: 466 | T33: AB-2
A34: I | B34: 5 | C34: OM4-DE-IS-0002-005 | D34: HRSG Embeded Material | F34: BHI | G34: Republic of Korea | H34: PS 1.1, Ⅱ, 2 | I34: 1 | J34: PKG | K34: Wooden Box | L34: 175 | M34: 115 | N34: 105 | O34: =L34*M34*N34/1000000 -> 2.113125 | P34: 2160 | Q34: 2280 | R34: N | S34: B | U34: B2
C35: OM4-DE-IS-0002-005 | D35: Anchor Bolt M60X1,560L | F35: BHI | G35: Republic of Korea | H35: PS 1.1, Ⅱ, 2 | I35: 54 | J35: EA | P35: 1685 | T35: AB-2
C36: OM4-DE-IS-0002-005 | D36: Nut M60 | F36: BHI | G36: Republic of Korea | H36: PS 1.1, Ⅱ, 2 | I36: 216 | J36: EA | P36: 475 | T36: AB-2
B37: 6 | C37: OM4-DE-IS-0002-006 | D37: HRSG Embeded Material | F37: BHI | G37: Republic of Korea | H37: PS 1.1, Ⅱ, 2 | I37: 1 | J37: PKG | K37: Wooden Box | L37: 215 | M37: 115 | N37: 85 | O37: =L37*M37*N37/1000000 -> 2.101625 | P37: 2376 | Q37: 2516 | R37: N | S37: B | U37: B2
C38: OM4-DE-IS-0002-006 | D38: Anchor Bolt M48X1,970L | F38: BHI | G38: Republic of Korea | H38: PS 1.1, Ⅱ, 2 | I38: 72 | J38: EA | P38: 2029 | T38: SAB-1
C39: OM4-DE-IS-0002-006 | D39: Nut M48 | F39: BHI | G39: Republic of Korea | H39: PS 1.1, Ⅱ, 2 | I39: 288 | J39: EA | P39: 347 | T39: SAB-1
B40: 7 | C40: OM4-DE-IS-0002-007 | D40: HRSG Embeded Material | F40: BHI | G40: Republic of Korea | H40: PS 1.1, Ⅱ, 2 | I40: 1 | J40: PKG | K40: Wooden Box | L40: 115 | M40: 115 | N40: 80 | O40: =L40*M40*N40/1000000 -> 1.058 | P40: 1567 | Q40: 1627 | R40: N | S40: B | U40: B2
C41: OM4-DE-IS-0002-007 | D41: Square Washer 130X160X20T | F41: BHI | G41: Republic of Korea | H41: PS 1.1, Ⅱ, 2 | I41: 40 | J41: EA | P41: 132 | T41: AB-1
C42: OM4-DE-IS-0002-007 | D42: Square Washer 130X130X20T | F42: BHI | G42: Republic of Korea | H42: PS 1.1, Ⅱ, 2 | I42: 160 | J42: EA | P42: 432 | T42: AB-2
C43: OM4-DE-IS-0002-007 | D43: Square Washer 100X100X15T | F43: BHI | G43: Republic of Korea | H43: PS 1.1, Ⅱ, 2 | I43: 16 | J43: EA | P43: 19 | T43: AB-3
...
