Workbook
Name _Hlk215568700: PSIC!$B$2
Name latent: #REF!
Name latent: '[4]steam table'!$N$5:$Q$102
Name tube_test_press1_12: #REF!

Sheet Break Down CI
B5: ='Commercial Invoice'!G5 -> INVOICE NO. : | C5: ='Commercial Invoice'!H5 -> OM4-DE-IS-0003 | M5: DATE : | O5: ='Commercial Invoice'!H6 -> 46157
A7: SI. No. | B7: Package No. | C7: COMMODITY/DESCRIPTION OF GOODS | D7: C/O of Goods | E7: POSITION IN PRICE SCHEDULE | F7: Quantity | H7: Package Type | I7: NET WEIGHT (KG) | J7: GROSS WEIGHT (KG) | K7: GROSS WEIGHT (KG) | M7: UNIT PRICE (USD) | N7: AMOUNT (USD) | O7: Remark (**)
F8: Nos | G8: Unit | Q8: HS CODE
A9: 1 | B9: OM4-DE-IS-0003-001 | C9: PVC Conduit 150mm (6") | D9: Republic of Korea | E9: PS 1.1, Ⅴ, 11 | F9: 150 | G9: EA | H9: SKID | I9: 3375 | J9: 3575 | K9: 3575 | L9: =J9-K9 -> 0 | M9: 34.02 | N9: =M9*F9 -> 5103 | O9: P0 | Q9: 3917.23-0000
A10: 2 | B10: OM4-DE-IS-0003-002 | C10: PVC Conduit 150mm (6") | D10: Republic of Korea | E10: PS 1.1, Ⅴ, 11 | F10: 150 | G10: EA | H10: SKID | I10: 3375 | J10: 3575 | K10: 3575 | L10: =J10-K10 -> 0 | M10: 34.02 | N10: =M10*F10 -> 5103 | O10: P0 | Q10: 3917.23-0000 | T10: =M9*F9 -> 5103
A11: 3 | B11: OM4-DE-IS-0003-003 | C11: PVC Conduit 150mm (6") | D11: Republic of Korea | E11: PS 1.1, Ⅴ, 11 | F11: 150 | G11: EA | H11: SKID | I11: 3375 | J11: 3575 | K11: 3575 | L11: =J11-K11 -> 0 | M11: 34.02 | N11: =M11*F11 -> 5103 | O11: P0 | Q11: 3917.23-0000 | T11: =M10*F10 -> 5103
A12: 4 | B12: OM4-DE-IS-0003-004 | C12: PVC Conduit 150mm (6") | D12: Republic of Korea | E12: PS 1.1, Ⅴ, 11 | F12: 150 | G12: EA | H12: SKID | I12: 3375 | J12: 3575 | K12: 3575 | L12: =J12-K12 -> 0 | M12: 34.02 | N12: =M12*F12 -> 5103 | O12: P0 | Q12: 3917.23-0000 | T12: =M11*F11 -> 5103
A13: 5 | B13: OM4-DE-IS-0003-005 | C13: PVC Conduit 150mm (6") | D13: Republic of Korea | E13: PS 1.1, Ⅴ, 11 | F13: 150 | G13: EA | H13: SKID | I13: 3375 | J13: 3575 | K13: 3575 | L13: =J13-K13 -> 0 | M13: 34.02 | N13: =M13*F13 -> 5103 | O13: P0 | Q13: 3917.23-0000 | T13: =M12*F12 -> 5103
A14: 6 | B14: OM4-DE-IS-0003-006 | C14: PVC Conduit 150mm (6") | D14: Republic of Korea | E14: PS 1.1, Ⅴ, 11 | F14: 150 | G14: EA | H14: SKID | I14: 3375 | J14: 3575 | K14: 3575 | L14: =J14-K14 -> 0 | M14: 34.02 | N14: =M14*F14 -> 5103 | O14: P0 | Q14: 3917.23-0000 | T14: =M13*F13 -> 5103
A15: 7 | B15: OM4-DE-IS-0003-007 | C15: PVC Conduit 150mm (6") | D15: Republic of Korea | E15: PS 1.1, Ⅴ, 11 | F15: 100 | G15: EA | H15: SKID | I15: 2250 | J15: 2450 | K15: 2450 | L15: =J15-K15 -> 0 | M15: 34.02 | N15: =M15*F15 -> 3402 | O15: P0 | Q15: 3917.23-0000 | T15: =M14*F14 -> 5103
A16: 8 | B16: OM4-DE-IS-0003-008 | C16: PVC Conduit 125mm (5") | D16: Republic of Korea | E16: PS 1.1, Ⅴ, 11 | F16: 100 | G16: EA | H16: SKID | I16: 1120 | J16: 1320 | K16: 1320 | L16: =J16-K16 -> 0 | M16: 19.44 | N16: =M16*F16 -> 1944 | O16: P0 | Q16: 3917.23-0000 | T16: =M15*F15 -> 3402
A17: 9 | B17: OM4-DE-IS-0003-009 | C17: PVC Conduit 28mm (1") | D17: Republic of Korea | E17: PS 1.1, Ⅴ, 11 | F17: 200 | G17: EA | H17: SKID | I17: 392 | J17: 425.33333 | K17: 425.33 | L17: =J17-K17 -> 0.0033333333 | M17: 7.78 | N17: =M17*F17 -> 1556 | O17: P0 | Q17: 3917.23-0000 | T17: =M16*F16 -> 1944
A18: 10 | B18: OM4-DE-IS-0003-009 | C18: PVC Conduit 36mm (1-1/4") | D18: Republic of Korea | E18: PS 1.1, Ⅴ, 11 | F18: 80 | G18: EA | H18: SKID | I18: 211.2 | J18: 244.53333 | K18: 244.53 | L18: =J18-K18 -> 0.0033333333 | M18: 7.78 | N18: =M18*F18 -> 622.4 | O18: P0 | Q18: 3917.23-0000 | T18: =M17*F17 -> 1556
A19: 11 | B19: OM4-DE-IS-0003-009 | C19: PVC Conduit 42mm (1-1/2") | D19: Republic of Korea | E19: PS 1.1, Ⅴ, 11 | F19: 100 | G19: EA | H19: SKID | I19: 316 | J19: 349.33333 | K19: 349.33 | L19: =J19-K19 -> 0.0033333333 | M19: 7.78 | N19: =M19*F19 -> 778 | O19: P0 | Q19: 3917.23-0000 | T19: =M18*F18 -> 622.4
A20: 12 | B20: OM4-DE-IS-0003-009 | C20: PVC Conduit 54mm (2") | D20: Republic of Korea | E20: PS 1.1, Ⅴ, 11 | F20: 70 | G20: EA | H20: SKID | I20: 296.8 | J20: 330.13333 | K20: 330.13 | L20: =J20-K20 -> 0.0033333333 | M20: 7.78 | N20: =M20*F20 -> 544.6 | O20: P0 | Q20: 3917.23-0000 | T20: =M19*F19 -> 778
A21: 13 | B21: OM4-DE-IS-0003-009 | C21: PVC Conduit 82mm (3") | D21: Republic of Korea | E21: PS 1.1, Ⅴ, 11 | F21: 50 | G21: EA | H21: SKID | I21: 436 | J21: 469.33333 | K21: 469.34 | L21: =J21-K21 -> -0.0066666667 | M21: 7.78 | N21: =M21*F21 -> 389 | O21: P0 | Q21: 3917.23-0000 | T21: =M20*F20 -> 544.6
... A97: 89 | B97: OM4-DE-IS-0003-014 | C97: Warning Tape (W150mm x 200m/Roll) | D97: Republic of Korea | E97: PS 1.1, Ⅴ, 11 | F97: 1 | G97: EA | H97: Wodden | I97: 2 | J97: 10.333333 | K97: 10.49 | L97: =J97-K97 -> -0.15666667 | M97: 2.55 | N97: =M97*F97 -> 2.55 | O97: P0 | Q97: 3920.10-0000 | T97: =M96*F96 -> 12.9
H98: TOTAL AMOUNT AT THIS SHIPMENT | N98: =SUM(N9:N97) -> 63122.44 | T98: =M97*F97 -> 2.55
T99: =SUM(T10:T98) -> 63122.44

Sheet Detailed PL
C3: PECC2 Innovation Hub, 45 Street No.2, Truong Tho Ward, Thu Duc City, HCMC, Vietnam Tel: +84-28-2221 6468 | Fax: +84-28-2221 0408
B4: DETAILED PACKING LIST
C5: PL No. | D5: ='PL(2_2)'!D5 -> OM4-DE-IS-0003
C6: Dated | D6: ='PL(2_2)'!D6 -> 46157 | J6: * Storage Classification | O6: ** Plant/Equipment/Materials for
C7: Project | D7: ='PL(2_2)'!D7 -> O MON IV THERMAL POWER PLANT | J7: "A" | K7: : Indoor with Air conditioning | P7: HRSG | Q7: STG | R7: GTG | S7: BOP
C8: Referenced DWG No. | J8: "B" | K8: : Indoor without Air conditioning | O8: Unit 1 | P8: B1 | Q8: T1 | R8: G1 | S8: P2
J9: "C" | K9: : Hazardous Material | O9: Unit 2 | P9: B2 | Q9: T2 | R9: G2 | S9: P2
J10: "D" | K10: : Outdoor with waterproofing | O10: Common | P10: B0 | Q10: T0 | R10: G0 | S10: P0
J11: "E" | K11: : Outdoor without waterproofing
B13: SI. No. | C13: Package No. | D13: Description of Goods | F13: Manufacturer | G13: C/O of Goods | H13: Position in price schedule | I13: Quantity | K13: Package Type | L13: Measurement | P13: Net Weight (kg) | Q13: Gross Weight (kg) | R13: Hazardous Material | S13: Storage Classification (*) | T13: Tag No. | U13: Remark (**)
I14: Nos | J14: Unit | L14: Length (cm) | M14: Width (cm) | N14: Height (cm) | O14: Volume (cbm)
B15: 1 | C15: OM4-DE-IS-0003-001 | D15: PVC Conduit | E15: 150mm (6") | F15: SAMSUNG E&L | G15: Republic of Korea | I15: 150 | J15: EA | P15: =W15*I15 -> 3375 | W15: =3.75*6 -> 22.5
B16: Sub-Total | I16: =SUM(I15) -> 150 | K16: SKID | L16: 620 | M16: 220 | N16: 235 | O16: =(L16*M16*N16)/10^6 -> 32.054 | P16: =P15 -> 3375 | Q16: =P16+200 -> 3575 | R16: N | S16: D | U16: P0
B17: 2 | C17: OM4-DE-IS-0003-002 | D17: PVC Conduit | E17: 150mm (6") | F17: SAMSUNG E&L | G17: Republic of Korea | I17: 150 | J17: EA | P17: =W17*I17 -> 3375 | W17: =3.75*6 -> 22.5
B18: Sub-Total | I18: =SUM(I17) -> 150 | K18: SKID | L18: 620 | M18: 220 | N18: 235 | O18: =(L18*M18*N18)/10^6 -> 32.054 | P18: =P17 -> 3375 | Q18: =P18+200 -> 3575 | R18: N | S18: D | U18: P0
B19: 3 | C19: OM4-DE-IS-0003-003 | D19: PVC Conduit | E19: 150mm (6") | F19: SAMSUNG E&L | G19: Republic of Korea | I19: 150 | J19: EA | P19: =W19*I19 -> 3375 | W19: =3.75*6 -> 22.5
B20: Sub-Total | I20: =SUM(I19) -> 150 | K20: SKID | L20: 620 | M20: 220 | N20: 235 | O20: =(L20*M20*N20)/10^6 -> 32.054 | P20: =P19 -> 3375 | Q20: =P20+200 -> 3575 | R20: N | S20: D | U20: P0
B21: 4 | C21: OM4-DE-IS-0003-004 | D21: PVC Conduit | E21: 150mm (6") | F21: SAMSUNG E&L | G21: Republic of Korea | I21: 150 | J21: EA | P21: =W21*I21 -> 3375 | W21: =3.75*6 -> 22.5
B22: Sub-Total | I22: =SUM(I21) -> 150 | K22: SKID | L22: 620 | M22: 220 | N22: 235 | O22: =(L22*M22*N22)/10^6 -> 32.054 | P22: =P21 -> 3375 | Q22: =P22+200 -> 3575 | R22: N | S22: D | U22: P0
B23: 5 | C23: OM4-DE-IS-0003-005 | D23: PVC Conduit | E23: 150mm (6") | F23: SAMSUNG E&L | G23: Republic of Korea | I23: 150 | J23: EA | P23: =W23*I23 -> 3375 | W23: =3.75*6 -> 22.5
B24: Sub-Total | I24: =SUM(I23) -> 150 | K24: SKID | L24: 620 | M24: 220 | N24: 235 | O24: =(L24*M24*N24)/10^6 -> 32.054 | P24: =P23 -> 3375 | Q24: =P24+200 -> 3575 | R24: N | S24: D | U24: P0
B25: 6 | C25: OM4-DE-IS-0003-006 | D25: PVC Conduit | E25: 150mm (6") | F25: SAMSUNG E&L | G25: Republic of Korea | I25: 150 | J25: EA | P25: =W25*I25 -> 3375 | W25: =3.75*6 -> 22.5
B26: Sub-Total | I26: =SUM(I25) -> 150 | K26: SKID | L26: 620 | M26: 220 | N26: 235 | O26: =(L26*M26*N26)/10^6 -> 32.054 | P26: =P25 -> 3375 | Q26: =P26+200 -> 3575 | R26: N | S26: D | U26: P0
B27: 7 | C27: OM4-DE-IS-0003-007 | D27: PVC Conduit | E27: 150mm (6") | F27: SAMSUNG E&L | G27: Republic of Korea | I27: 100 | J27: EA | P27: =W27*I27 -> 2250 | W27: =3.75*6 -> 22.5
B28: Sub-Total | I28: =SUM(I27) -> 100 | K28: SKID | L28: 620 | M28: 220 | N28: 180 | O28: =(L28*M28*N28)/10^6 -> 24.552 | P28: =P27 -> 2250 | Q28: =P28+200 -> 2450 | R28: N | S28: D | U28: P0
B29: 8 | C29: OM4-DE-IS-0003-008 | D29: PVC Conduit | E29: 125mm (5") | F29: SAMSUNG E&L | G29: Republic of Korea | I29: 100 | J29: EA | P29: =W29*I29 -> 1120 | W29: =2.8*4 -> 11.2
B30: Sub-Total | I30: =SUM(I29) -> 100 | K30: SKID | L30: 420 | M30: 220 | N30: 140 | O30: =(L30*M30*N30)/10^6 -> 12.936 | P30: =P29 -> 1120 | Q30: =P30+200 -> 1320 | R30: N | S30: D | U30: P0
B31: 9 | C31: OM4-DE-IS-0003-009 | D31: PVC Conduit | E31: 28mm (1") | F31: SAMSUNG E&L | G31: Republic of Korea | I31: 200 | J31: EA | P31: =W31*I31 -> 392 | W31: =0.49*4 -> 1.96
B32: 10 | C32: =C31 -> OM4-DE-IS-0003-009 | D32: PVC Conduit | E32: 36mm (1-1/4") | F32: SAMSUNG E&L | G32: Republic of Korea | I32: 80 | J32: EA | P32: =W32*I32 -> 211.2 | W32: =0.66*4 -> 2.64
B33: 11 | C33: =C32 -> OM4-DE-IS-0003-009 | D33: PVC Conduit | E33: 42mm (1-1/2") | F33: SAMSUNG E&L | G33: Republic of Korea | I33: 100 | J33: EA | P33: =W33*I33 -> 316 | W33: =0.79*4 -> 3.16
B34: 12 | C34: =C33 -> OM4-DE-IS-0003-009 | D34: PVC Conduit | E34: 54mm (2") | F34: SAMSUNG E&L | G34: Republic of Korea | I34: 70 | J34: EA | P34: =W34*I34 -> 296.8 | W34: =1.06*4 -> 4.24
B35: 13 | C35: =C34 -> OM4-DE-IS-0003-009 | D35: PVC Conduit | E35: 82mm (3") | F35: SAMSUNG E&L | G35: Republic of Korea | I35: 50 | J35: EA | P35: =W35*I35 -> 436 | W35: =2.18*4 -> 8.72
B36: 14 | C36: =C35 -> OM4-DE-IS-0003-009 | D36: PVC Conduit | E36: 104mm (4") | F36: SAMSUNG E&L | G36: Republic of Korea | I36: 50 | J36: EA | P36: =W36*I36 -> 620 | W36: =3.1*4 -> 12.4
B37: Sub-Total | I37: =SUM(I31:I36) -> 550 | K37: SKID | L37: 420 | M37: 220 | N37: 140 | O37: =(L37*M37*N37)/10^6 -> 12.936 | P37: =SUM(P31:P36) -> 2272 | Q37: =P37+200 -> 2472 | R37: N | S37: D | U37: P0
B38: 15 | C38: OM4-DE-IS-0003-010 | D38: Normal Bend for PVC Conduit | E38: 36mm (1-1/4") | F38: SAMSUNG E&L | G38: Republic of Korea | I38: 120 | J38: EA | P38: =W38*I38 -> 79.2 | W38: 0.66
B39: 16 | C39: =C38 -> OM4-DE-IS-0003-010 | D39: Normal Bend for PVC Conduit | E39: 42mm (1-1/2") | F39: SAMSUNG E&L | G39: Republic of Korea | I39: 60 | J39: EA | P39: =W39*I39 -> 47.4 | W39: 0.79
B40: 17 | C40: =C39 -> OM4-DE-IS-0003-010 | D40: Normal Bend for PVC Conduit | E40: 54mm (2") | F40: SAMSUNG E&L | G40: Republic of Korea | I40: 20 | J40: EA | P40: =W40*I40 -> 21.2 | W40: 1.06
B41: 18 | C41: =C40 -> OM4-DE-IS-0003-010 | D41: Normal Bend for PVC Conduit | E41: 82mm (3") | F41: SAMSUNG E&L | G41: Republic of Korea | I41: 30 | J41: EA | P41: =W41*I41 -> 65.4 | W41: 2.18
B42: 19 | C42: =C41 -> OM4-DE-IS-0003-010 | D42: Normal Bend for PVC Conduit | E42: 104mm (4") | F42: SAMSUNG E&L | G42: Republic of Korea | I42: 30 | J42: EA | P42: =W42*I42 -> 93 | W42: 3.1
B43: 20 | C43: =C42 -> OM4-DE-IS-0003-010 | D43: Normal Bend for PVC Conduit | E43: 125mm (5") | F43: SAMSUNG E&L | G43: Republic of Korea | I43: 30 | J43: EA | P43: =W43*I43 -> 84 | W43: =2.8 -> 2.8
...

Sheet Commercial Invoice
B3: PECC2 Innovation Hub, 45 Street No.2, Truong Tho Ward, Thu Duc City, HCMC, Vietnam Tel: +84-28-2221 6468 | Fax: +84-28-2221 0408
A4: COMMERCIAL INVOICE
A5: SHIPPER: | G5: INVOICE NO. : | H5: OM4-DE-IS-0003
B6: Doosan Enerbility Co., Ltd. 22 DoosanVolvo-ro, Seongsan-gu, Chang-won-si, Gyeongsangnam-do 51711, Republic of Korea | G6: DATE: | H6: 46157
G7: CONTRACT NO. | H7: 06/2025/HĐ-PVN/OM4-06
G8: DATE: | H8: 45814
A9: CONSIGNEE : | G9: SHIPPING MARK
B10: Cty Doosan Enerbility Co.,Ltd HQ-Nha thau TH CV thuoc Goi thau so OM4-EPC-HHO-06 cho NMND O Mon IV Thoi Loi Area, Phuoc Thoi Ward, Can Tho City, Vietnam T : (+84) 367 566 167 F : (+84 243) 624 8485 | G10: O MON IV THERMAL POWER PLANT
A13: NOTIFY PARTY :
B14: Cty Doosan Enerbility Co.,Ltd HQ-Nha thau TH CV thuoc Goi thau so OM4-EPC-HHO-06 cho NMND O Mon IV Thoi Loi Area, Phươc Thoi Ward, Can Tho City, Vietnam T : (+84) 367 566 167 F : (+84 243) 624 8485 BRANCH OF KWANGJIN VIET NAM IN DUNG QUAT Co.,Ltd Dung Quat Economic Zone, Van Tuong Commune, Quang Ngai Province, Vietnam T : (+84) 28 3825 6330 Attn: Mr. Phuoc / Email: phuoc@kjtc.co.kr
G15: SHIPMENT NO. : | H15: =H5 -> OM4-DE-IS-0003
G17: TERM OF DELIVERY : | H17: CIF, Ho Chi Minh City Port, Vietnam
A18: VESSEL NAME : | C18: ETD :
B19: HMM HARMONY 0022S | D19: 46169 | G19: QUALITY | H19: 100% BRAND NEW
A20: PORT OF LOADING : | C20: PORT OF DISCHARGE : | G20: PAYMENT TERMS: | H20: T/T
B21: Busan International Port, Korea | D21: Ho Chi Minh City Port, Vietnam
A22: BILL OF LADING/ AIRWAY BILL NO. : | C22: B/L DATE :
A24: FINAL DESTINATION :
B25: O MON IV THERMAL POWER PLANT
B26: Address: O Mon Power Complex at Phuoc Thoi wards, Can Tho city
A27: COMMODITY/DESCRIPTION OF GOODS | H27: UNIT | I27: QUANTITY | J27: UNIT PRICE (USD) | K27: AMOUNT (USD)
B28: PLANT/ EQUIPMENT AND MATERIALS FOR O MON IV THERMAL POWER PLANT (Contract No. OM4-PO-DE-001)
B30: Conduit & Accessories included I&C Conduit (PVC Conduit) | H30: EA | I30: 9808 | K30: ='Break Down CI'!N98 -> 63122.44
B38: Number of packages: | D38: 14 | E38: PKGS
B43: TOTAL AMOUNT AT THIS SHIPMENT : | K43: =SUM(K30:K37) -> 63122.44
G50: Signed by
H51: Jinho. Lee / Deputy Project Director

Sheet Packing List (1_2)
B3: PECC2 Innovation Hub, 45 Street No.2, Truong Tho Ward, Thu Duc City, HCMC, Vietnam Tel: +84-28-2221 6468 | Fax: +84-28-2221 0408
A4: PACKING LIST(1/2)
A5: SHIPPER: | G5: P/L No. | H5: OM4-DE-IS-0003
B6: Doosan Enerbility Co., Ltd. 22 DoosanVolvo-ro, Seongsan-gu, Chang-won-si, Gyeongsangnam-do 51711, Republic of Korea | G6: DATE: | H6: ='Commercial Invoice'!H6 -> 46157
G7: CONTRACT NO. | H7: 06/2025/HĐ-PVN/OM4-06
G8: DATE: | H8: ='Commercial Invoice'!H8 -> 45814
A9: CONSIGNEE : | G9: =[6]CI!G9 -> SHIPPING MARK
B10: Cty Doosan Enerbility Co.,Ltd HQ-Nha thau TH CV thuoc Goi thau so OM4-EPC-HHO-06 cho NMND O Mon IV Thoi Loi Area, Phuoc Thoi Ward, Can Tho City, Vietnam T : (+84) 367 566 167 F : (+84 243) 624 8485 | G10: O MON IV THERMAL POWER PLANT
A13: NOTIFY PARTY :
B14: Cty Doosan Enerbility Co.,Ltd HQ-Nha thau TH CV thuoc Goi thau so OM4-EPC-HHO-06 cho NMND O Mon IV Thoi Loi Area, Phươc Thoi Ward, Can Tho City, Vietnam T : (+84) 367 566 167 F : (+84 243) 624 8485 BRANCH OF KWANGJIN VIET NAM IN DUNG QUAT Co.,Ltd Dung Quat Economic Zone, Van Tuong Commune, Quang Ngai Province, Vietnam T : (+84) 28 3825 6330 Attn: Mr. Phuoc / Email: phuoc@kjtc.co.kr
G15: SHIPMENT NO. : | H15: =H5 -> OM4-DE-IS-0003
G17: TERM OF DELIVERY : | H17: CIF, Ho Chi Minh City Port, Vietnam
A18: VESSEL NAME : | C18: ETD :
B19: HMM HARMONY 0022S | D19: 46169 | G19: QUALITY | H19: 100% BRAND NEW
A20: PORT OF LOADING : | C20: PORT OF DISCHARGE :
B21: Busan International Port, Korea | D21: Ho Chi Minh City Port, Vietnam
A22: BILL OF LADING/ AIRWAY BILL NO. : | C22: B/L DATE :
A24: FINAL DESTINATION :
B25: O MON IV THERMAL POWER PLANT
B26: Address: O Mon Power Complex at Phuoc Thoi wards, Can Tho city
A27: COMMODITY/DESCRIPTION OF GOODS | G27: UNIT | H27: QUANTITY | I27: NET WEIGHT (KG) | J27: GROSS WEIGHT (KG) | K27: MEASUREMENT (CBM)
B28: PLANT/ EQUIPMENT AND MATERIALS FOR O MON IV THERMAL POWER PLANT (Contract No. OM4-PO-DE-001)
A30: Conduit & Accessories included I&C Conduit (PVC Conduit)
G31: EA | H31: 150 | I31: 3375 | J31: 3575 | K31: 32.054
G32: EA | H32: 150 | I32: 3375 | J32: 3575 | K32: 32.054
G33: EA | H33: 150 | I33: 3375 | J33: 3575 | K33: 32.054
G34: EA | H34: 150 | I34: 3375 | J34: 3575 | K34: 32.054
G35: EA | H35: 150 | I35: 3375 | J35: 3575 | K35: 32.054
G36: EA | H36: 150 | I36: 3375 | J36: 3575 | K36: 32.054
G37: EA | H37: 100 | I37: 2250 | J37: 2450 | K37: 24.552
G38: EA | H38: 100 | I38: 1120 | J38: 1320 | K38: 12.936
G39: EA | H39: 550 | I39: 2272 | J39: 2472 | K39: 12.936
G40: EA | H40: 1640 | I40: 710.5 | J40: 1010.5 | K40: 11.088
G41: EA | H41: 1300 | I41: 1300 | J41: 1600 | K41: 15.708
G42: EA | H42: 3805 | I42: 1860 | J42: 2160 | K42: 18.48
... G44: EA | H44: 1162 | I44: 603.455 | J44: 903.455 | K44: 6
B46: Number of packages: | D46: 14 | E46: PKGS
G50: TOTAL | I50: =SUM(I28:I49) -> 31353.235 | J50: =SUM(J28:J49) -> 34553.235 | K50: =SUM(K28:K49) -> 301.416
G58: Signed by
H59: Jinho. Lee / Deputy Project Director

Sheet PL(2_2)
C3: PECC2 Innovation Hub, 45 Street No.2, Truong Tho Ward, Thu Duc City, HCMC, Vietnam Tel: +84-28-2221 6468 | Fax: +84-28-2221 0408
B4: PACKING LIST(2/2)
C5: P/L No. | D5: ='Packing List (1_2)'!H5 -> OM4-DE-IS-0003
C6: Dated | D6: ='Packing List (1_2)'!H6 -> 46157 | I6: * Storage Classification | N6: ** Plant/Equipment/Materials for
C7: Project | D7: O MON IV THERMAL POWER PLANT | I7: "A" | J7: : Indoor with Air conditioning | O7: HRSG | P7: STG | Q7: GTG | R7: BOP
I8: "B" | J8: : Indoor without Air conditioning | N8: Unit 1 | O8: B1 | P8: T1 | Q8: G1 | R8: P2
I9: "C" | J9: : Hazardous Material | N9: Unit 2 | O9: B2 | P9: T2 | Q9: G2 | R9: P2
I10: "D" | J10: : Outdoor with waterproofing | N10: Common | O10: B0 | P10: T0 | Q10: G0 | R10: P0
I11: "E" | J11: : Outdoor without waterproofing
B13: SI. No. | C13: Package No. | D13: Description of Goods | E13: Position in price schedule | F13: Quantity | H13: Package Type | I13: Measurement | M13: Net Weight (kg) | N13: Gross Weight (kg) | O13: Hazardous Material | P13: COG Marked (Y/N) | Q13: Sling Point Marked (Y/N) | R13: Handle with care Marked (Y/N) | S13: Storage Classification (*) | T13: Remark (**)
F14: Nos | G14: Unit | I14: Length (cm) | J14: Width (cm) | K14: Height (cm) | L14: Volume (cbm)
B15: 1 | C15: ='Detailed PL'!C15 -> OM4-DE-IS-0003-001 | D15: PVC Conduit | F15: =SUM('Detailed PL'!I16) -> 150 | G15: EA | H15: ='Detailed PL'!K16 -> SKID | I15: ='Detailed PL'!L16 -> 620 | J15: ='Detailed PL'!M16 -> 220 | K15: ='Detailed PL'!N16 -> 235 | L15: ='Detailed PL'!O16 -> 32.054 | M15: ='Detailed PL'!P16 -> 3375 | N15: ='Detailed PL'!Q16 -> 3575 | O15: ='Detailed PL'!R16 -> N | P15: Y | Q15: Y | R15: N | S15: ='Detailed PL'!S16 -> D | T15: ='Detailed PL'!U16 -> P0
B16: 2 | C16: ='Detailed PL'!C17 -> OM4-DE-IS-0003-002 | D16: PVC Conduit | F16: =SUM('Detailed PL'!I18) -> 150 | G16: EA | H16: ='Detailed PL'!K18 -> SKID | I16: ='Detailed PL'!L18 -> 620 | J16: ='Detailed PL'!M18 -> 220 | K16: ='Detailed PL'!N18 -> 235 | L16: ='Detailed PL'!O18 -> 32.054 | M16: ='Detailed PL'!P18 -> 3375 | N16: ='Detailed PL'!Q18 -> 3575 | O16: ='Detailed PL'!R18 -> N | P16: Y | Q16: Y | R16: N | S16: ='Detailed PL'!S18 -> D | T16: ='Detailed PL'!U18 -> P0
B17: 3 | C17: ='Detailed PL'!C19 -> OM4-DE-IS-0003-003 | D17: PVC Conduit | F17: =SUM('Detailed PL'!I20) -> 150 | G17: EA | H17: ='Detailed PL'!K20 -> SKID | I17: ='Detailed PL'!L20 -> 620 | J17: ='Detailed PL'!M20 -> 220 | K17: ='Detailed PL'!N20 -> 235 | L17: ='Detailed PL'!O20 -> 32.054 | M17: ='Detailed PL'!P20 -> 3375 | N17: ='Detailed PL'!Q20 -> 3575 | O17: ='Detailed PL'!R20 -> N | P17: Y | Q17: Y | R17: N | S17: ='Detailed PL'!S20 -> D | T17: ='Detailed PL'!U20 -> P0
B18: 4 | C18: ='Detailed PL'!C21 -> OM4-DE-IS-0003-004 | D18: PVC Conduit | F18: =SUM('Detailed PL'!I22) -> 150 | G18: EA | H18: ='Detailed PL'!K22 -> SKID | I18: ='Detailed PL'!L22 -> 620 | J18: ='Detailed PL'!M22 -> 220 | K18: ='Detailed PL'!N22 -> 235 | L18: ='Detailed PL'!O22 -> 32.054 | M18: ='Detailed PL'!P22 -> 3375 | N18: ='Detailed PL'!Q22 -> 3575 | O18: ='Detailed PL'!R22 -> N | P18: Y | Q18: Y | R18: N | S18: ='Detailed PL'!S22 -> D | T18: ='Detailed PL'!U22 -> P0
B19: 5 | C19: ='Detailed PL'!C23 -> OM4-DE-IS-0003-005 | D19: PVC Conduit | F19: =SUM('Detailed PL'!I24) -> 150 | G19: EA | H19: ='Detailed PL'!K24 -> SKID | I19: ='Detailed PL'!L24 -> 620 | J19: ='Detailed PL'!M24 -> 220 | K19: ='Detailed PL'!N24 -> 235 | L19: ='Detailed PL'!O24 -> 32.054 | M19: ='Detailed PL'!P24 -> 3375 | N19: ='Detailed PL'!Q24 -> 3575 | O19: ='Detailed PL'!R24 -> N | P19: Y | Q19: Y | R19: N | S19: ='Detailed PL'!S24 -> D | T19: ='Detailed PL'!U24 -> P0
B20: 6 | C20: ='Detailed PL'!C25 -> OM4-DE-IS-0003-006 | D20: PVC Conduit | F20: =SUM('Detailed PL'!I26) -> 150 | G20: EA | H20: ='Detailed PL'!K26 -> SKID | I20: ='Detailed PL'!L26 -> 620 | J20: ='Detailed PL'!M26 -> 220 | K20: ='Detailed PL'!N26 -> 235 | L20: ='Detailed PL'!O26 -> 32.054 | M20: ='Detailed PL'!P26 -> 3375 | N20: ='Detailed PL'!Q26 -> 3575 | O20: ='Detailed PL'!R26 -> N | P20: Y | Q20: Y | R20: N | S20: ='Detailed PL'!S26 -> D | T20: ='Detailed PL'!U26 -> P0
B21: 7 | C21: ='Detailed PL'!C27 -> OM4-DE-IS-0003-007 | D21: PVC Conduit | F21: =SUM('Detailed PL'!I28) -> 100 | G21: EA | H21: ='Detailed PL'!K28 -> SKID | I21: ='Detailed PL'!L28 -> 620 | J21: ='Detailed PL'!M28 -> 220 | K21: ='Detailed PL'!N28 -> 180 | L21: ='Detailed PL'!O28 -> 24.552 | M21: ='Detailed PL'!P28 -> 2250 | N21: ='Detailed PL'!Q28 -> 2450 | O21: ='Detailed PL'!R28 -> N | P21: Y | Q21: Y | R21: N | S21: ='Detailed PL'!S28 -> D | T21: ='Detailed PL'!U28 -> P0
B22: 8 | C22: ='Detailed PL'!C29 -> OM4-DE-IS-0003-008 | D22: PVC Conduit | F22: =SUM('Detailed PL'!I30) -> 100 | G22: EA | H22: ='Detailed PL'!K30 -> SKID | I22: ='Detailed PL'!L30 -> 420 | J22: ='Detailed PL'!M30 -> 220 | K22: ='Detailed PL'!N30 -> 140 | L22: ='Detailed PL'!O30 -> 12.936 | M22: ='Detailed PL'!P30 -> 1120 | N22: ='Detailed PL'!Q30 -> 1320 | O22: ='Detailed PL'!R30 -> N | P22: Y | Q22: Y | R22: N | S22: ='Detailed PL'!S30 -> D | T22: ='Detailed PL'!U30 -> P0
B23: 9 | C23: ='Detailed PL'!C31 -> OM4-DE-IS-0003-009 | D23: PVC Conduit | F23: ='Detailed PL'!I37 -> 550 | G23: EA | H23: ='Detailed PL'!K37 -> SKID | I23: ='Detailed PL'!L37 -> 420 | J23: ='Detailed PL'!M37 -> 220 | K23: ='Detailed PL'!N37 -> 140 | L23: ='Detailed PL'!O37 -> 12.936 | M23: ='Detailed PL'!P37 -> 2272 | N23: ='Detailed PL'!Q37 -> 2472 | O23: ='Detailed PL'!R37 -> N | P23: Y | Q23: Y | R23: N | S23: ='Detailed PL'!S37 -> D | T23: ='Detailed PL'!U37 -> P0
B24: 10 | C24: ='Detailed PL'!C38 -> OM4-DE-IS-0003-010 | D24: CONDUIT FITTINGS (PVC Normal Bend, End bell, PVC COUPLING) | F24: ='Detailed PL'!I65 -> 1640 | G24: EA | H24: ='Detailed PL'!K65 -> Wodden | I24: ='Detailed PL'!L65 -> 420 | J24: ='Detailed PL'!M65 -> 220 | K24: ='Detailed PL'!N65 -> 120 | L24: ='Detailed PL'!O65 -> 11.088 | M24: ='Detailed PL'!P65 -> 710.5 | N24: ='Detailed PL'!Q65 -> 1010.5 | O24: ='Detailed PL'!R65 -> N | P24: Y | Q24: Y | R24: N | S24: ='Detailed PL'!S65 -> D | T24: ='Detailed PL'!U65 -> P0
B25: 11 | C25: ='Detailed PL'!C66 -> OM4-DE-IS-0003-011 | D25: CONDUIT FITTINGS (PVC COUPLING) | F25: ='Detailed PL'!I68 -> 1300 | G25: EA | H25: ='Detailed PL'!K68 -> Wodden | I25: ='Detailed PL'!L68 -> 420 | J25: ='Detailed PL'!M68 -> 220 | K25: ='Detailed PL'!N68 -> 170 | L25: ='Detailed PL'!O68 -> 15.708 | M25: ='Detailed PL'!P68 -> 1300 | N25: ='Detailed PL'!Q68 -> 1600 | O25: ='Detailed PL'!R68 -> N | P25: Y | Q25: Y | R25: N | S25: ='Detailed PL'!S68 -> D | T25: ='Detailed PL'!U68 -> P0
B26: 12 | C26: ='Detailed PL'!C69 -> OM4-DE-IS-0003-012 | D26: CONDUIT FITTINGS (PVC Spacer, End Bell, Warning Tape) | F26: ='Detailed PL'!I72 -> 3805 | G26: EA | H26: ='Detailed PL'!K72 -> Wodden | I26: ='Detailed PL'!L72 -> 420 | J26: ='Detailed PL'!M72 -> 220 | K26: ='Detailed PL'!N72 -> 200 | L26: ='Detailed PL'!O72 -> 18.48 | M26: ='Detailed PL'!P72 -> 1860 | N26: ='Detailed PL'!Q72 -> 2160 | O26: ='Detailed PL'!R72 -> N | P26: Y | Q26: Y | R26: N | S26: ='Detailed PL'!S72 -> D | T26: ='Detailed PL'!U72 -> P0
B27: 13 | C27: ='Detailed PL'!C73 -> OM4-DE-IS-0003-013 | D27: PVC Conduit | F27: ='Detailed PL'!I80 -> 251 | G27: EA | H27: ='Detailed PL'!K80 -> SKID | I27: ='Detailed PL'!L80 -> 420 | J27: ='Detailed PL'!M80 -> 220 | K27: ='Detailed PL'!N80 -> 80 | L27: ='Detailed PL'!O80 -> 7.392 | M27: ='Detailed PL'!P80 -> 987.28 | N27: ='Detailed PL'!Q80 -> 1187.28 | O27: ='Detailed PL'!R80 -> N | P27: Y | Q27: Y | R27: N | S27: ='Detailed PL'!S80 -> D | T27: ='Detailed PL'!U80 -> P0
B28: 14 | C28: ='Detailed PL'!C81 -> OM4-DE-IS-0003-014 | D28: CONDUIT FITTINGS | F28: ='Detailed PL'!I117 -> 1162 | G28: EA | H28: ='Detailed PL'!K117 -> Wodden | I28: ='Detailed PL'!L117 -> 200 | J28: ='Detailed PL'!M117 -> 200 | K28: ='Detailed PL'!N117 -> 150 | L28: ='Detailed PL'!O117 -> 6 | M28: ='Detailed PL'!P117 -> 603.455 | N28: ='Detailed PL'!Q117 -> 903.455 | O28: ='Detailed PL'!R117 -> N | P28: Y | Q28: Y | R28: N | S28: ='Detailed PL'!S117 -> D | T28: ='Detailed PL'!U117 -> P0
B29: Grand Total | L29: =SUM(L15:L28) -> 301.416 | M29: =SUM(M15:M28) -> 31353.235 | N29: =SUM(N15:N28) -> 34553.235

Sheet SHIPPING MARK (001)
A1: SHIPPING MARK
A2: O MON IV THERMAL POWER PLANT
A3: =[6]CI!B26 -> Address: O Mon Power Complex at Phuoc Thoi wards, O Mon district, Can Tho city
A5: SHIPPER | B5: : | C5: Doosan Enerbility Co., Ltd.
A6: ADDRESS | B6: : | C6: 22 DoosanVolvo-ro, Seongsan-gu, Chang-won-si, Gyeongsangnam-do 51711, Republic of Korea
A7: CONSIGNEE | B7: : | C7: Cty Doosan Enerbility Co.,Ltd HQ-Nha thau TH CV thuoc Goi thau so OM4-EPC-HHO-06 cho NMND O Mon IV Thoi Loi Area, Phuoc Thoi Ward, Can Tho City, Vietnam T : (+84) 367 566 167 F : (+84 243) 624 8485
A8: NOTIFY PARTY | B8: : | C8: Cty Doosan Enerbility Co.,Ltd HQ-Nha thau TH CV thuoc Goi thau so OM4-EPC-HHO-06 cho NMND O Mon IV Thoi Loi Area, Phươc Thoi Ward, Can Tho City, Vietnam T : (+84) 367 566 167 F : (+84 243) 624 8485 BRANCH OF KWANGJIN VIET NAM IN DUNG QUAT Co.,Ltd Dung Quat Economic Zone, Van Tuong Commune, Quang Ngai Province, Vietnam T : (+84) 28 3825 6330 Attn: Mr. Phuoc / Email: phuoc@kjtc.co.kr
A12: CONTRACT NO. | B12: : | C12: 06/2025/HĐ-PVN/OM4-06
A13: SHIPMENT NO. | B13: : | C13: OM4-DE-IS-0003
A14: EQUIPMENT DESCRIPTION | B14: : | C14: =[6]CI!B28 -> PLANT/ EQUIPMENT AND MATERIALS FOR O MON IV THERMAL
A15: DESCRIPTION OF GOODS | B15: : | C15: ='PL(2_2)'!D15 -> PVC Conduit | L15: PL(2_2) Sheet 내 내용 반영 필요
A16: CONSIGNOR. | B16: : | C16: SAMSUNG E&L
A17: PACKAGE NO. | B17: : | C17: ='PL(2_2)'!C15 -> OM4-DE-IS-0003-001
A18: NET WEIGHT | B18: : | C18: ='PL(2_2)'!M15 -> 3375 | D18: KG
A19: GROSS WEIGHT | B19: : | C19: ='PL(2_2)'!N15 -> 3575 | D19: KG
A20: - MEASUREMENT | B20: : | C20: ='PL(2_2)'!I15 -> 620 | D20: cm(L) X | E20: ='PL(2_2)'!J15 -> 220 | F20: cm (W) X | G20: ='PL(2_2)'!K15 -> 235 | H20: cm (H) | I20: ='PL(2_2)'!L15 -> 32.054 | J20: CBM
A21: LOADING PORT | B21: : | C21: ='Packing List (1_2)'!B21 -> Busan International Port, Korea
A22: PORT OF DESTINATION | B22: : | C22: Ho Chi Minh City Port, Vietnam
A23: COUNTRY OF ORIGIN | B23: : | C23: Republic of Korea
A24: QUALITY | B24: : | C24: 100% BRAND NEW

Sheet SHIPPING MARK (002)
A1: SHIPPING MARK
A2: O MON IV THERMAL POWER PLANT
A3: =[6]CI!B26 -> Address: O Mon Power Complex at Phuoc Thoi wards, O Mon district, Can Tho city
A5: SHIPPER | B5: : | C5: Doosan Enerbility Co., Ltd.
A6: ADDRESS | B6: : | C6: 22 DoosanVolvo-ro, Seongsan-gu, Chang-won-si, Gyeongsangnam-do 51711, Republic of Korea
A7: CONSIGNEE | B7: : | C7: Cty Doosan Enerbility Co.,Ltd HQ-Nha thau TH CV thuoc Goi thau so OM4-EPC-HHO-06 cho NMND O Mon IV Thoi Loi Area, Phuoc Thoi Ward, Can Tho City, Vietnam T : (+84) 367 566 167 F : (+84 243) 624 8485
A8: NOTIFY PARTY | B8: : | C8: Cty Doosan Enerbility Co.,Ltd HQ-Nha thau TH CV thuoc Goi thau so OM4-EPC-HHO-06 cho NMND O Mon IV Thoi Loi Area, Phươc Thoi Ward, Can Tho City, Vietnam T : (+84) 367 566 167 F : (+84 243) 624 8485 BRANCH OF KWANGJIN VIET NAM IN DUNG QUAT Co.,Ltd Dung Quat Economic Zone, Van Tuong Commune, Quang Ngai Province, Vietnam T : (+84) 28 3825 6330 Attn: Mr. Phuoc / Email: phuoc@kjtc.co.kr
A12: CONTRACT NO. | B12: : | C12: 06/2025/HĐ-PVN/OM4-06
A13: SHIPMENT NO. | B13: : | C13: OM4-DE-IS-0003
A14: EQUIPMENT DESCRIPTION | B14: : | C14: =[6]CI!B28 -> PLANT/ EQUIPMENT AND MATERIALS FOR O MON IV THERMAL
A15: DESCRIPTION OF GOODS | B15: : | C15: ='PL(2_2)'!D16 -> PVC Conduit | L15: PL(2_2) Sheet 내 내용 반영 필요
A16: CONSIGNOR. | B16: : | C16: SAMSUNG E&L
A17: PACKAGE NO. | B17: : | C17: ='PL(2_2)'!C16 -> OM4-DE-IS-0003-002
A18: NET WEIGHT | B18: : | C18: ='PL(2_2)'!M16 -> 3375 | D18: KG
A19: GROSS WEIGHT | B19: : | C19: ='PL(2_2)'!N16 -> 3575 | D19: KG
A20: - MEASUREMENT | B20: : | C20: ='PL(2_2)'!I16 -> 620 | D20: cm(L) X | E20: ='PL(2_2)'!J16 -> 220 | F20: cm (W) X | G20: ='PL(2_2)'!K16 -> 235 | H20: cm (H) | I20: ='PL(2_2)'!L16 -> 32.054 | J20: CBM
A21: LOADING PORT | B21: : | C21: ='Packing List (1_2)'!B21 -> Busan International Port, Korea
A22: PORT OF DESTINATION | B22: : | C22: Ho Chi Minh City Port, Vietnam
A23: COUNTRY OF ORIGIN | B23: : | C23: Republic of Korea
A24: QUALITY | B24: : | C24: 100% BRAND NEW

Sheet SHIPPING MARK (003)
A1: SHIPPING MARK
A2: O MON IV THERMAL POWER PLANT
A3: =[6]CI!B26 -> Address: O Mon Power Complex at Phuoc Thoi wards, O Mon district, Can Tho city
A5: SHIPPER | B5: : | C5: Doosan Enerbility Co., Ltd.
A6: ADDRESS | B6: : | C6: 22 DoosanVolvo-ro, Seongsan-gu, Chang-won-si, Gyeongsangnam-do 51711, Republic of Korea
A7: CONSIGNEE | B7: : | C7: Cty Doosan Enerbility Co.,Ltd HQ-Nha thau TH CV thuoc Goi thau so OM4-EPC-HHO-06 cho NMND O Mon IV Thoi Loi Area, Phuoc Thoi Ward, Can Tho City, Vietnam T : (+84) 367 566 167 F : (+84 243) 624 8485
A8: NOTIFY PARTY | B8: : | C8: Cty Doosan Enerbility Co.,Ltd HQ-Nha thau TH CV thuoc Goi thau so OM4-EPC-HHO-06 cho NMND O Mon IV Thoi Loi Area, Phươc Thoi Ward, Can Tho City, Vietnam T : (+84) 367 566 167 F : (+84 243) 624 8485 BRANCH OF KWANGJIN VIET NAM IN DUNG QUAT Co.,Ltd Dung Quat Economic Zone, Van Tuong Commune, Quang Ngai Province, Vietnam T : (+84) 28 3825 6330 Attn: Mr. Phuoc / Email: phuoc@kjtc.co.kr
A12: CONTRACT NO. | B12: : | C12: 06/2025/HĐ-PVN/OM4-06
A13: SHIPMENT NO. | B13: : | C13: OM4-DE-IS-0003
A14: EQUIPMENT DESCRIPTION | B14: : | C14: =[6]CI!B28 -> PLANT/ EQUIPMENT AND MATERIALS FOR O MON IV THERMAL
A15: DESCRIPTION OF GOODS | B15: : | C15: ='PL(2_2)'!D17 -> PVC Conduit | L15: PL(2_2) Sheet 내 내용 반영 필요
A16: CONSIGNOR. | B16: : | C16: SAMSUNG E&L
A17: PACKAGE NO. | B17: : | C17: ='PL(2_2)'!C17 -> OM4-DE-IS-0003-003
A18: NET WEIGHT | B18: : | C18: ='PL(2_2)'!M15 -> 3375 | D18: KG
A19: GROSS WEIGHT | B19: : | C19: ='PL(2_2)'!N15 -> 3575 | D19: KG
A20: - MEASUREMENT | B20: : | C20: ='PL(2_2)'!I15 -> 620 | D20: cm(L) X | E20: ='PL(2_2)'!J15 -> 220 | F20: cm (W) X | G20: ='PL(2_2)'!K15 -> 235 | H20: cm (H) | I20: ='PL(2_2)'!L15 -> 32.054 | J20: CBM
A21: LOADING PORT | B21: : | C21: ='Packing List (1_2)'!B21 -> Busan International Port, Korea
A22: PORT OF DESTINATION | B22: : | C22: Ho Chi Minh City Port, Vietnam
A23: COUNTRY OF ORIGIN | B23: : | C23: Republic of Korea
A24: QUALITY | B24: : | C24: 100% BRAND NEW

Sheet SHIPPING MARK (004)
A1: SHIPPING MARK
A2: O MON IV THERMAL POWER PLANT
A3: =[6]CI!B26 -> Address: O Mon Power Complex at Phuoc Thoi wards, O Mon district, Can Tho city
A5: SHIPPER | B5: : | C5: Doosan Enerbility Co., Ltd.
A6: ADDRESS | B6: : | C6: 22 DoosanVolvo-ro, Seongsan-gu, Chang-won-si, Gyeongsangnam-do 51711, Republic of Korea
A7: CONSIGNEE | B7: : | C7: Cty Doosan Enerbility Co.,Ltd HQ-Nha thau TH CV thuoc Goi thau so OM4-EPC-HHO-06 cho NMND O Mon IV Thoi Loi Area, Phuoc Thoi Ward, Can Tho City, Vietnam T : (+84) 367 566 167 F : (+84 243) 624 8485
A8: NOTIFY PARTY | B8: : | C8: Cty Doosan Enerbility Co.,Ltd HQ-Nha thau TH CV thuoc Goi thau so OM4-EPC-HHO-06 cho NMND O Mon IV Thoi Loi Area, Phươc Thoi Ward, Can Tho City, Vietnam T : (+84) 367 566 167 F : (+84 243) 624 8485 BRANCH OF KWANGJIN VIET NAM IN DUNG QUAT Co.,Ltd Dung Quat Economic Zone, Van Tuong Commune, Quang Ngai Province, Vietnam T : (+84) 28 3825 6330 Attn: Mr. Phuoc / Email: phuoc@kjtc.co.kr
A12: CONTRACT NO. | B12: : | C12: 06/2025/HĐ-PVN/OM4-06
A13: SHIPMENT NO. | B13: : | C13: OM4-DE-IS-0003
A14: EQUIPMENT DESCRIPTION | B14: : | C14: =[6]CI!B28 -> PLANT/ EQUIPMENT AND MATERIALS FOR O MON IV THERMAL
A15: DESCRIPTION OF GOODS | B15: : | C15: ='PL(2_2)'!D18 -> PVC Conduit | L15: PL(2_2) Sheet 내 내용 반영 필요
A16: CONSIGNOR. | B16: : | C16: SAMSUNG E&L
A17: PACKAGE NO. | B17: : | C17: ='PL(2_2)'!C18 -> OM4-DE-IS-0003-004
A18: NET WEIGHT | B18: : | C18: ='PL(2_2)'!M15 -> 3375 | D18: KG
A19: GROSS WEIGHT | B19: : | C19: ='PL(2_2)'!N15 -> 3575 | D19: KG
A20: - MEASUREMENT | B20: : | C20: ='PL(2_2)'!I15 -> 620 | D20: cm(L) X | E20: ='PL(2_2)'!J15 -> 220 | F20: cm (W) X | G20: ='PL(2_2)'!K15 -> 235 | H20: cm (H) | I20: ='PL(2_2)'!L15 -> 32.054 | J20: CBM
A21: LOADING PORT | B21: : | C21: ='Packing List (1_2)'!B21 -> Busan International Port, Korea
A22: PORT OF DESTINATION | B22: : | C22: Ho Chi Minh City Port, Vietnam
A23: COUNTRY OF ORIGIN | B23: : | C23: Republic of Korea
A24: QUALITY | B24: : | C24: 100% BRAND NEW

Sheet SHIPPING MARK (005)
A1: SHIPPING MARK
A2: O MON IV THERMAL POWER PLANT
A3: =[6]CI!B26 -> Address: O Mon Power Complex at Phuoc Thoi wards, O Mon district, Can Tho city
A5: SHIPPER | B5: : | C5: Doosan Enerbility Co., Ltd.
A6: ADDRESS | B6: : | C6: 22 DoosanVolvo-ro, Seongsan-gu, Chang-won-si, Gyeongsangnam-do 51711, Republic of Korea
A7: CONSIGNEE | B7: : | C7: Cty Doosan Enerbility Co.,Ltd HQ-Nha thau TH CV thuoc Goi thau so OM4-EPC-HHO-06 cho NMND O Mon IV Thoi Loi Area, Phuoc Thoi Ward, Can Tho City, Vietnam T : (+84) 367 566 167 F : (+84 243) 624 8485
A8: NOTIFY PARTY | B8: : | C8: Cty Doosan Enerbility Co.,Ltd HQ-Nha thau TH CV thuoc Goi thau so OM4-EPC-HHO-06 cho NMND O Mon IV Thoi Loi Area, Phươc Thoi Ward, Can Tho City, Vietnam T : (+84) 367 566 167 F : (+84 243) 624 8485 BRANCH OF KWANGJIN VIET NAM IN DUNG QUAT Co.,Ltd Dung Quat Economic Zone, Van Tuong Commune, Quang Ngai Province, Vietnam T : (+84) 28 3825 6330 Attn: Mr. Phuoc / Email: phuoc@kjtc.co.kr
A12: CONTRACT NO. | B12: : | C12: 06/2025/HĐ-PVN/OM4-06
A13: SHIPMENT NO. | B13: : | C13: OM4-DE-IS-0003
A14: EQUIPMENT DESCRIPTION | B14: : | C14: =[6]CI!B28 -> PLANT/ EQUIPMENT AND MATERIALS FOR O MON IV THERMAL
A15: DESCRIPTION OF GOODS | B15: : | C15: ='PL(2_2)'!D19 -> PVC Conduit | L15: PL(2_2) Sheet 내 내용 반영 필요
A16: CONSIGNOR. | B16: : | C16: SAMSUNG E&L
A17: PACKAGE NO. | B17: : | C17: ='PL(2_2)'!C19 -> OM4-DE-IS-0003-005
A18: NET WEIGHT | B18: : | C18: ='PL(2_2)'!M15 -> 3375 | D18: KG
A19: GROSS WEIGHT | B19: : | C19: ='PL(2_2)'!N15 -> 3575 | D19: KG
A20: - MEASUREMENT | B20: : | C20: ='PL(2_2)'!I15 -> 620 | D20: cm(L) X | E20: ='PL(2_2)'!J15 -> 220 | F20: cm (W) X | G20: ='PL(2_2)'!K15 -> 235 | H20: cm (H) | I20: ='PL(2_2)'!L15 -> 32.054 | J20: CBM
A21: LOADING PORT | B21: : | C21: ='Packing List (1_2)'!B21 -> Busan International Port, Korea
A22: PORT OF DESTINATION | B22: : | C22: Ho Chi Minh City Port, Vietnam
A23: COUNTRY OF ORIGIN | B23: : | C23: Republic of Korea
A24: QUALITY | B24: : | C24: 100% BRAND NEW

Sheet SHIPPING MARK (006)
A1: SHIPPING MARK
A2: O MON IV THERMAL POWER PLANT
A3: =[6]CI!B26 -> Address: O Mon Power Complex at Phuoc Thoi wards, O Mon district, Can Tho city
A5: SHIPPER | B5: : | C5: Doosan Enerbility Co., Ltd.
A6: ADDRESS | B6: : | C6: 22 DoosanVolvo-ro, Seongsan-gu, Chang-won-si, Gyeongsangnam-do 51711, Republic of Korea
A7: CONSIGNEE | B7: : | C7: Cty Doosan Enerbility Co.,Ltd HQ-Nha thau TH CV thuoc Goi thau so OM4-EPC-HHO-06 cho NMND O Mon IV Thoi Loi Area, Phuoc Thoi Ward, Can Tho City, Vietnam T : (+84) 367 566 167 F : (+84 243) 624 8485
A8: NOTIFY PARTY | B8: : | C8: Cty Doosan Enerbility Co.,Ltd HQ-Nha thau TH CV thuoc Goi thau so OM4-EPC-HHO-06 cho NMND O Mon IV Thoi Loi Area, Phươc Thoi Ward, Can Tho City, Vietnam T : (+84) 367 566 167 F : (+84 243) 624 8485 BRANCH OF KWANGJIN VIET NAM IN DUNG QUAT Co.,Ltd Dung Quat Economic Zone, Van Tuong Commune, Quang Ngai Province, Vietnam T : (+84) 28 3825 6330 Attn: Mr. Phuoc / Email: phuoc@kjtc.co.kr
A12: CONTRACT NO. | B12: : | C12: 06/2025/HĐ-PVN/OM4-06
A13: SHIPMENT NO. | B13: : | C13: OM4-DE-IS-0003
A14: EQUIPMENT DESCRIPTION | B14: : | C14: =[6]CI!B28 -> PLANT/ EQUIPMENT AND MATERIALS FOR O MON IV THERMAL
A15: DESCRIPTION OF GOODS | B15: : | C15: ='PL(2_2)'!D20 -> PVC Conduit | L15: PL(2_2) Sheet 내 내용 반영 필요
A16: CONSIGNOR. | B16: : | C16: SAMSUNG E&L
A17: PACKAGE NO. | B17: : | C17: ='PL(2_2)'!C20 -> OM4-DE-IS-0003-006
A18: NET WEIGHT | B18: : | C18: ='PL(2_2)'!M15 -> 3375 | D18: KG
A19: GROSS WEIGHT | B19: : | C19: ='PL(2_2)'!N15 -> 3575 | D19: KG
A20: - MEASUREMENT | B20: : | C20: ='PL(2_2)'!I15 -> 620 | D20: cm(L) X | E20: ='PL(2_2)'!J15 -> 220 | F20: cm (W) X | G20: ='PL(2_2)'!K15 -> 235 | H20: cm (H) | I20: ='PL(2_2)'!L15 -> 32.054 | J20: CBM
A21: LOADING PORT | B21: : | C21: ='Packing List (1_2)'!B21 -> Busan International Port, Korea
A22: PORT OF DESTINATION | B22: : | C22: Ho Chi Minh City Port, Vietnam
A23: COUNTRY OF ORIGIN | B23: : | C23: Republic of Korea
A24: QUALITY | B24: : | C24: 100% BRAND NEW

Sheet SHIPPING MARK (007)
A1: SHIPPING MARK
A2: O MON IV THERMAL POWER PLANT
A3: =[6]CI!B26 -> Address: O Mon Power Complex at Phuoc Thoi wards, O Mon district, Can Tho city
A5: SHIPPER | B5: : | C5: Doosan Enerbility Co., Ltd.
A6: ADDRESS | B6: : | C6: 22 DoosanVolvo-ro, Seongsan-gu, Chang-won-si, Gyeongsangnam-do 51711, Republic of Korea
A7: CONSIGNEE | B7: : | C7: Cty Doosan Enerbility Co.,Ltd HQ-Nha thau TH CV thuoc Goi thau so OM4-EPC-HHO-06 cho NMND O Mon IV Thoi Loi Area, Phuoc Thoi Ward, Can Tho City, Vietnam T : (+84) 367 566 167 F : (+84 243) 624 8485
A8: NOTIFY PARTY | B8: : | C8: Cty Doosan Enerbility Co.,Ltd HQ-Nha thau TH CV thuoc Goi thau so OM4-EPC-HHO-06 cho NMND O Mon IV Thoi Loi Area, Phươc Thoi Ward, Can Tho City, Vietnam T : (+84) 367 566 167 F : (+84 243) 624 8485 BRANCH OF KWANGJIN VIET NAM IN DUNG QUAT Co.,Ltd Dung Quat Economic Zone, Van Tuong Commune, Quang Ngai Province, Vietnam T : (+84) 28 3825 6330 Attn: Mr. Phuoc / Email: phuoc@kjtc.co.kr
A12: CONTRACT NO. | B12: : | C12: 06/2025/HĐ-PVN/OM4-06
A13: SHIPMENT NO. | B13: : | C13: OM4-DE-IS-0003
A14: EQUIPMENT DESCRIPTION | B14: : | C14: =[6]CI!B28 -> PLANT/ EQUIPMENT AND MATERIALS FOR O MON IV THERMAL
A15: DESCRIPTION OF GOODS | B15: : | C15: ='PL(2_2)'!D21 -> PVC Conduit | L15: PL(2_2) Sheet 내 내용 반영 필요
A16: CONSIGNOR. | B16: : | C16: SAMSUNG E&L
A17: PACKAGE NO. | B17: : | C17: ='PL(2_2)'!C21 -> OM4-DE-IS-0003-007
A18: NET WEIGHT | B18: : | C18: ='PL(2_2)'!M21 -> 2250 | D18: KG
A19: GROSS WEIGHT | B19: : | C19: ='PL(2_2)'!N21 -> 2450 | D19: KG
A20: - MEASUREMENT | B20: : | C20: ='PL(2_2)'!I21 -> 620 | D20: cm(L) X | E20: ='PL(2_2)'!J21 -> 220 | F20: cm (W) X | G20: ='PL(2_2)'!K21 -> 180 | H20: cm (H) | I20: ='PL(2_2)'!L21 -> 24.552 | J20: CBM
A21: LOADING PORT | B21: : | C21: ='Packing List (1_2)'!B21 -> Busan International Port, Korea
A22: PORT OF DESTINATION | B22: : | C22: Ho Chi Minh City Port, Vietnam
A23: COUNTRY OF ORIGIN | B23: : | C23: Republic of Korea
A24: QUALITY | B24: : | C24: 100% BRAND NEW

Sheet SHIPPING MARK (008)
A1: SHIPPING MARK
A2: O MON IV THERMAL POWER PLANT
A3: =[6]CI!B26 -> Address: O Mon Power Complex at Phuoc Thoi wards, O Mon district, Can Tho city
A5: SHIPPER | B5: : | C5: Doosan Enerbility Co., Ltd.
A6: ADDRESS | B6: : | C6: 22 DoosanVolvo-ro, Seongsan-gu, Chang-won-si, Gyeongsangnam-do 51711, Republic of Korea
A7: CONSIGNEE | B7: : | C7: Cty Doosan Enerbility Co.,Ltd HQ-Nha thau TH CV thuoc Goi thau so OM4-EPC-HHO-06 cho NMND O Mon IV Thoi Loi Area, Phuoc Thoi Ward, Can Tho City, Vietnam T : (+84) 367 566 167 F : (+84 243) 624 8485
A8: NOTIFY PARTY | B8: : | C8: Cty Doosan Enerbility Co.,Ltd HQ-Nha thau TH CV thuoc Goi thau so OM4-EPC-HHO-06 cho NMND O Mon IV Thoi Loi Area, Phươc Thoi Ward, Can Tho City, Vietnam T : (+84) 367 566 167 F : (+84 243) 624 8485 BRANCH OF KWANGJIN VIET NAM IN DUNG QUAT Co.,Ltd Dung Quat Economic Zone, Van Tuong Commune, Quang Ngai Province, Vietnam T : (+84) 28 3825 6330 Attn: Mr. Phuoc / Email: phuoc@kjtc.co.kr
A12: CONTRACT NO. | B12: : | C12: 06/2025/HĐ-PVN/OM4-06
A13: SHIPMENT NO. | B13: : | C13: OM4-DE-IS-0003
A14: EQUIPMENT DESCRIPTION | B14: : | C14: =[6]CI!B28 -> PLANT/ EQUIPMENT AND MATERIALS FOR O MON IV THERMAL
A15: DESCRIPTION OF GOODS | B15: : | C15: ='PL(2_2)'!D22 -> PVC Conduit | L15: PL(2_2) Sheet 내 내용 반영 필요
A16: CONSIGNOR. | B16: : | C16: SAMSUNG E&L
A17: PACKAGE NO. | B17: : | C17: ='PL(2_2)'!C22 -> OM4-DE-IS-0003-008
A18: NET WEIGHT | B18: : | C18: ='PL(2_2)'!M22 -> 1120 | D18: KG
A19: GROSS WEIGHT | B19: : | C19: ='PL(2_2)'!N22 -> 1320 | D19: KG
A20: - MEASUREMENT | B20: : | C20: ='PL(2_2)'!I22 -> 420 | D20: cm(L) X | E20: ='PL(2_2)'!J22 -> 220 | F20: cm (W) X | G20: ='PL(2_2)'!K22 -> 140 | H20: cm (H) | I20: ='PL(2_2)'!L22 -> 12.936 | J20: CBM
A21: LOADING PORT | B21: : | C21: ='Packing List (1_2)'!B21 -> Busan International Port, Korea
A22: PORT OF DESTINATION | B22: : | C22: Ho Chi Minh City Port, Vietnam
A23: COUNTRY OF ORIGIN | B23: : | C23: Republic of Korea
A24: QUALITY | B24: : | C24: 100% BRAND NEW

Sheet SHIPPING MARK (009)
A1: SHIPPING MARK
A2: O MON IV THERMAL POWER PLANT
A3: =[6]CI!B26 -> Address: O Mon Power Complex at Phuoc Thoi wards, O Mon district, Can Tho city
A5: SHIPPER | B5: : | C5: Doosan Enerbility Co., Ltd.
A6: ADDRESS | B6: : | C6: 22 DoosanVolvo-ro, Seongsan-gu, Chang-won-si, Gyeongsangnam-do 51711, Republic of Korea
A7: CONSIGNEE | B7: : | C7: Cty Doosan Enerbility Co.,Ltd HQ-Nha thau TH CV thuoc Goi thau so OM4-EPC-HHO-06 cho NMND O Mon IV Thoi Loi Area, Phuoc Thoi Ward, Can Tho City, Vietnam T : (+84) 367 566 167 F : (+84 243) 624 8485
A8: NOTIFY PARTY | B8: : | C8: Cty Doosan Enerbility Co.,Ltd HQ-Nha thau TH CV thuoc Goi thau so OM4-EPC-HHO-06 cho NMND O Mon IV Thoi Loi Area, Phươc Thoi Ward, Can Tho City, Vietnam T : (+84) 367 566 167 F : (+84 243) 624 8485 BRANCH OF KWANGJIN VIET NAM IN DUNG QUAT Co.,Ltd Dung Quat Economic Zone, Van Tuong Commune, Quang Ngai Province, Vietnam T : (+84) 28 3825 6330 Attn: Mr. Phuoc / Email: phuoc@kjtc.co.kr
A12: CONTRACT NO. | B12: : | C12: 06/2025/HĐ-PVN/OM4-06
A13: SHIPMENT NO. | B13: : | C13: OM4-DE-IS-0003
A14: EQUIPMENT DESCRIPTION | B14: : | C14: =[6]CI!B28 -> PLANT/ EQUIPMENT AND MATERIALS FOR O MON IV THERMAL
A15: DESCRIPTION OF GOODS | B15: : | C15: ='PL(2_2)'!D23 -> PVC Conduit | L15: PL(2_2) Sheet 내 내용 반영 필요
A16: CONSIGNOR. | B16: : | C16: SAMSUNG E&L
A17: PACKAGE NO. | B17: : | C17: ='PL(2_2)'!C23 -> OM4-DE-IS-0003-009
A18: NET WEIGHT | B18: : | C18: ='PL(2_2)'!M23 -> 2272 | D18: KG
A19: GROSS WEIGHT | B19: : | C19: ='PL(2_2)'!N23 -> 2472 | D19: KG
A20: - MEASUREMENT | B20: : | C20: ='PL(2_2)'!I23 -> 420 | D20: cm(L) X | E20: ='PL(2_2)'!J23 -> 220 | F20: cm (W) X | G20: ='PL(2_2)'!K23 -> 140 | H20: cm (H) | I20: ='PL(2_2)'!L23 -> 12.936 | J20: CBM
A21: LOADING PORT | B21: : | C21: ='Packing List (1_2)'!B21 -> Busan International Port, Korea
A22: PORT OF DESTINATION | B22: : | C22: Ho Chi Minh City Port, Vietnam
A23: COUNTRY OF ORIGIN | B23: : | C23: Republic of Korea
A24: QUALITY | B24: : | C24: 100% BRAND NEW

Sheet SHIPPING MARK (010)
A1: SHIPPING MARK
A2: O MON IV THERMAL POWER PLANT
A3: =[6]CI!B26 -> Address: O Mon Power Complex at Phuoc Thoi wards, O Mon district, Can Tho city
A5: SHIPPER | B5: : | C5: Doosan Enerbility Co., Ltd.
A6: ADDRESS | B6: : | C6: 22 DoosanVolvo-ro, Seongsan-gu, Chang-won-si, Gyeongsangnam-do 51711, Republic of Korea
A7: CONSIGNEE | B7: : | C7: Cty Doosan Enerbility Co.,Ltd HQ-Nha thau TH CV thuoc Goi thau so OM4-EPC-HHO-06 cho NMND O Mon IV Thoi Loi Area, Phuoc Thoi Ward, Can Tho City, Vietnam T : (+84) 367 566 167 F : (+84 243) 624 8485
A8: NOTIFY PARTY | B8: : | C8: Cty Doosan Enerbility Co.,Ltd HQ-Nha thau TH CV thuoc Goi thau so OM4-EPC-HHO-06 cho NMND O Mon IV Thoi Loi Area, Phươc Thoi Ward, Can Tho City, Vietnam T : (+84) 367 566 167 F : (+84 243) 624 8485 BRANCH OF KWANGJIN VIET NAM IN DUNG QUAT Co.,Ltd Dung Quat Economic Zone, Van Tuong Commune, Quang Ngai Province, Vietnam T : (+84) 28 3825 6330 Attn: Mr. Phuoc / Email: phuoc@kjtc.co.kr
A12: CONTRACT NO. | B12: : | C12: 06/2025/HĐ-PVN/OM4-06
A13: SHIPMENT NO. | B13: : | C13: OM4-DE-IS-0003
A14: EQUIPMENT DESCRIPTION | B14: : | C14: =[6]CI!B28 -> PLANT/ EQUIPMENT AND MATERIALS FOR O MON IV THERMAL
A15: DESCRIPTION OF GOODS | B15: : | C15: ='PL(2_2)'!D24 -> CONDUIT FITTINGS (PVC Normal Bend, End bell, PVC COUPLING) | L15: PL(2_2) Sheet 내 내용 반영 필요
A16: CONSIGNOR. | B16: : | C16: SAMSUNG E&L
A17: PACKAGE NO. | B17: : | C17: ='PL(2_2)'!C24 -> OM4-DE-IS-0003-010
A18: NET WEIGHT | B18: : | C18: ='PL(2_2)'!M24 -> 710.5 | D18: KG
A19: GROSS WEIGHT | B19: : | C19: ='PL(2_2)'!N24 -> 1010.5 | D19: KG
A20: - MEASUREMENT | B20: : | C20: ='PL(2_2)'!I24 -> 420 | D20: cm(L) X | E20: ='PL(2_2)'!J24 -> 220 | F20: cm (W) X | G20: ='PL(2_2)'!K24 -> 120 | H20: cm (H) | I20: ='PL(2_2)'!L24 -> 11.088 | J20: CBM
A21: LOADING PORT | B21: : | C21: ='Packing List (1_2)'!B21 -> Busan International Port, Korea
A22: PORT OF DESTINATION | B22: : | C22: Ho Chi Minh City Port, Vietnam
A23: COUNTRY OF ORIGIN | B23: : | C23: Republic of Korea
A24: QUALITY | B24: : | C24: 100% BRAND NEW

Sheet SHIPPING MARK (011)
A1: SHIPPING MARK
A2: O MON IV THERMAL POWER PLANT
A3: =[6]CI!B26 -> Address: O Mon Power Complex at Phuoc Thoi wards, O Mon district, Can Tho city
A5: SHIPPER | B5: : | C5: Doosan Enerbility Co., Ltd.
A6: ADDRESS | B6: : | C6: 22 DoosanVolvo-ro, Seongsan-gu, Chang-won-si, Gyeongsangnam-do 51711, Republic of Korea
A7: CONSIGNEE | B7: : | C7: Cty Doosan Enerbility Co.,Ltd HQ-Nha thau TH CV thuoc Goi thau so OM4-EPC-HHO-06 cho NMND O Mon IV Thoi Loi Area, Phuoc Thoi Ward, Can Tho City, Vietnam T : (+84) 367 566 167 F : (+84 243) 624 8485
A8: NOTIFY PARTY | B8: : | C8: Cty Doosan Enerbility Co.,Ltd HQ-Nha thau TH CV thuoc Goi thau so OM4-EPC-HHO-06 cho NMND O Mon IV Thoi Loi Area, Phươc Thoi Ward, Can Tho City, Vietnam T : (+84) 367 566 167 F : (+84 243) 624 8485 BRANCH OF KWANGJIN VIET NAM IN DUNG QUAT Co.,Ltd Dung Quat Economic Zone, Van Tuong Commune, Quang Ngai Province, Vietnam T : (+84) 28 3825 6330 Attn: Mr. Phuoc / Email: phuoc@kjtc.co.kr
A12: CONTRACT NO. | B12: : | C12: 06/2025/HĐ-PVN/OM4-06
A13: SHIPMENT NO. | B13: : | C13: OM4-DE-IS-0003
A14: EQUIPMENT DESCRIPTION | B14: : | C14: =[6]CI!B28 -> PLANT/ EQUIPMENT AND MATERIALS FOR O MON IV THERMAL
A15: DESCRIPTION OF GOODS | B15: : | C15: ='PL(2_2)'!D25 -> CONDUIT FITTINGS (PVC COUPLING) | L15: PL(2_2) Sheet 내 내용 반영 필요
A16: CONSIGNOR. | B16: : | C16: SAMSUNG E&L
A17: PACKAGE NO. | B17: : | C17: ='PL(2_2)'!C25 -> OM4-DE-IS-0003-011
A18: NET WEIGHT | B18: : | C18: ='PL(2_2)'!M25 -> 1300 | D18: KG
A19: GROSS WEIGHT | B19: : | C19: ='PL(2_2)'!N25 -> 1600 | D19: KG
A20: - MEASUREMENT | B20: : | C20: ='PL(2_2)'!I25 -> 420 | D20: cm(L) X | E20: ='PL(2_2)'!J25 -> 220 | F20: cm (W) X | G20: ='PL(2_2)'!K25 -> 170 | H20: cm (H) | I20: ='PL(2_2)'!L25 -> 15.708 | J20: CBM
A21: LOADING PORT | B21: : | C21: ='Packing List (1_2)'!B21 -> Busan International Port, Korea
A22: PORT OF DESTINATION | B22: : | C22: Ho Chi Minh City Port, Vietnam
A23: COUNTRY OF ORIGIN | B23: : | C23: Republic of Korea
A24: QUALITY | B24: : | C24: 100% BRAND NEW

Sheet SHIPPING MARK (012)
A1: SHIPPING MARK
A2: O MON IV THERMAL POWER PLANT
A3: =[6]CI!B26 -> Address: O Mon Power Complex at Phuoc Thoi wards, O Mon district, Can Tho city
A5: SHIPPER | B5: : | C5: Doosan Enerbility Co., Ltd.
A6: ADDRESS | B6: : | C6: 22 DoosanVolvo-ro, Seongsan-gu, Chang-won-si, Gyeongsangnam-do 51711, Republic of Korea
A7: CONSIGNEE | B7: : | C7: Cty Doosan Enerbility Co.,Ltd HQ-Nha thau TH CV thuoc Goi thau so OM4-EPC-HHO-06 cho NMND O Mon IV Thoi Loi Area, Phuoc Thoi Ward, Can Tho City, Vietnam T : (+84) 367 566 167 F : (+84 243) 624 8485
A8: NOTIFY PARTY | B8: : | C8: Cty Doosan Enerbility Co.,Ltd HQ-Nha thau TH CV thuoc Goi thau so OM4-EPC-HHO-06 cho NMND O Mon IV Thoi Loi Area, Phươc Thoi Ward, Can Tho City, Vietnam T : (+84) 367 566 167 F : (+84 243) 624 8485 BRANCH OF KWANGJIN VIET NAM IN DUNG QUAT Co.,Ltd Dung Quat Economic Zone, Van Tuong Commune, Quang Ngai Province, Vietnam T : (+84) 28 3825 6330 Attn: Mr. Phuoc / Email: phuoc@kjtc.co.kr
A12: CONTRACT NO. | B12: : | C12: 06/2025/HĐ-PVN/OM4-06
A13: SHIPMENT NO. | B13: : | C13: OM4-DE-IS-0003
A14: EQUIPMENT DESCRIPTION | B14: : | C14: =[6]CI!B28 -> PLANT/ EQUIPMENT AND MATERIALS FOR O MON IV THERMAL
A15: DESCRIPTION OF GOODS | B15: : | C15: ='PL(2_2)'!D26 -> CONDUIT FITTINGS (PVC Spacer, End Bell, Warning Tape) | L15: PL(2_2) Sheet 내 내용 반영 필요
A16: CONSIGNOR. | B16: : | C16: SAMSUNG E&L
A17: PACKAGE NO. | B17: : | C17: ='PL(2_2)'!C26 -> OM4-DE-IS-0003-012
A18: NET WEIGHT | B18: : | C18: ='PL(2_2)'!M26 -> 1860 | D18: KG
A19: GROSS WEIGHT | B19: : | C19: ='PL(2_2)'!N26 -> 2160 | D19: KG
A20: - MEASUREMENT | B20: : | C20: ='PL(2_2)'!I26 -> 420 | D20: cm(L) X | E20: ='PL(2_2)'!J26 -> 220 | F20: cm (W) X | G20: ='PL(2_2)'!K26 -> 200 | H20: cm (H) | I20: ='PL(2_2)'!L26 -> 18.48 | J20: CBM
A21: LOADING PORT | B21: : | C21: ='Packing List (1_2)'!B21 -> Busan International Port, Korea
A22: PORT OF DESTINATION | B22: : | C22: Ho Chi Minh City Port, Vietnam
A23: COUNTRY OF ORIGIN | B23: : | C23: Republic of Korea
A24: QUALITY | B24: : | C24: 100% BRAND NEW

Sheet SHIPPING MARK (013)
A1: SHIPPING MARK
A2: O MON IV THERMAL POWER PLANT
A3: =[6]CI!B26 -> Address: O Mon Power Complex at Phuoc Thoi wards, O Mon district, Can Tho city
A5: SHIPPER | B5: : | C5: Doosan Enerbility Co., Ltd.
A6: ADDRESS | B6: : | C6: 22 DoosanVolvo-ro, Seongsan-gu, Chang-won-si, Gyeongsangnam-do 51711, Republic of Korea
A7: CONSIGNEE | B7: : | C7: Cty Doosan Enerbility Co.,Ltd HQ-Nha thau TH CV thuoc Goi thau so OM4-EPC-HHO-06 cho NMND O Mon IV Thoi Loi Area, Phuoc Thoi Ward, Can Tho City, Vietnam T : (+84) 367 566 167 F : (+84 243) 624 8485
A8: NOTIFY PARTY | B8: : | C8: Cty Doosan Enerbility Co.,Ltd HQ-Nha thau TH CV thuoc Goi thau so OM4-EPC-HHO-06 cho NMND O Mon IV Thoi Loi Area, Phươc Thoi Ward, Can Tho City, Vietnam T : (+84) 367 566 167 F : (+84 243) 624 8485 BRANCH OF KWANGJIN VIET NAM IN DUNG QUAT Co.,Ltd Dung Quat Economic Zone, Van Tuong Commune, Quang Ngai Province, Vietnam T : (+84) 28 3825 6330 Attn: Mr. Phuoc / Email: phuoc@kjtc.co.kr
A12: CONTRACT NO. | B12: : | C12: 06/2025/HĐ-PVN/OM4-06
A13: SHIPMENT NO. | B13: : | C13: OM4-DE-IS-0003
A14: EQUIPMENT DESCRIPTION | B14: : | C14: =[6]CI!B28 -> PLANT/ EQUIPMENT AND MATERIALS FOR O MON IV THERMAL
A15: DESCRIPTION OF GOODS | B15: : | C15: ='PL(2_2)'!D27 -> PVC Conduit | L15: PL(2_2) Sheet 내 내용 반영 필요
A16: CONSIGNOR. | B16: : | C16: SAMSUNG E&L
A17: PACKAGE NO. | B17: : | C17: ='PL(2_2)'!C27 -> OM4-DE-IS-0003-013
A18: NET WEIGHT | B18: : | C18: ='PL(2_2)'!M27 -> 987.28 | D18: KG
A19: GROSS WEIGHT | B19: : | C19: ='PL(2_2)'!N27 -> 1187.28 | D19: KG
A20: - MEASUREMENT | B20: : | C20: ='PL(2_2)'!I27 -> 420 | D20: cm(L) X | E20: ='PL(2_2)'!J27 -> 220 | F20: cm (W) X | G20: ='PL(2_2)'!K27 -> 80 | H20: cm (H) | I20: ='PL(2_2)'!L27 -> 7.392 | J20: CBM
A21: LOADING PORT | B21: : | C21: ='Packing List (1_2)'!B21 -> Busan International Port, Korea
A22: PORT OF DESTINATION | B22: : | C22: Ho Chi Minh City Port, Vietnam
A23: COUNTRY OF ORIGIN | B23: : | C23: Republic of Korea
A24: QUALITY | B24: : | C24: 100% BRAND NEW

Sheet SHIPPING MARK (014)
A1: SHIPPING MARK
A2: O MON IV THERMAL POWER PLANT
A3: =[6]CI!B26 -> Address: O Mon Power Complex at Phuoc Thoi wards, O Mon district, Can Tho city
A5: SHIPPER | B5: : | C5: Doosan Enerbility Co., Ltd.
A6: ADDRESS | B6: : | C6: 22 DoosanVolvo-ro, Seongsan-gu, Chang-won-si, Gyeongsangnam-do 51711, Republic of Korea
A7: CONSIGNEE | B7: : | C7: Cty Doosan Enerbility Co.,Ltd HQ-Nha thau TH CV thuoc Goi thau so OM4-EPC-HHO-06 cho NMND O Mon IV Thoi Loi Area, Phuoc Thoi Ward, Can Tho City, Vietnam T : (+84) 367 566 167 F : (+84 243) 624 8485
A8: NOTIFY PARTY | B8: : | C8: Cty Doosan Enerbility Co.,Ltd HQ-Nha thau TH CV thuoc Goi thau so OM4-EPC-HHO-06 cho NMND O Mon IV Thoi Loi Area, Phươc Thoi Ward, Can Tho City, Vietnam T : (+84) 367 566 167 F : (+84 243) 624 8485 BRANCH OF KWANGJIN VIET NAM IN DUNG QUAT Co.,Ltd Dung Quat Economic Zone, Van Tuong Commune, Quang Ngai Province, Vietnam T : (+84) 28 3825 6330 Attn: Mr. Phuoc / Email: phuoc@kjtc.co.kr
A12: CONTRACT NO. | B12: : | C12: 06/2025/HĐ-PVN/OM4-06
A13: SHIPMENT NO. | B13: : | C13: OM4-DE-IS-0003
A14: EQUIPMENT DESCRIPTION | B14: : | C14: =[6]CI!B28 -> PLANT/ EQUIPMENT AND MATERIALS FOR O MON IV THERMAL
A15: DESCRIPTION OF GOODS | B15: : | C15: ='PL(2_2)'!D28 -> CONDUIT FITTINGS | L15: PL(2_2) Sheet 내 내용 반영 필요
A16: CONSIGNOR. | B16: : | C16: SAMSUNG E&L
A17: PACKAGE NO. | B17: : | C17: ='PL(2_2)'!C28 -> OM4-DE-IS-0003-014
A18: NET WEIGHT | B18: : | C18: ='PL(2_2)'!M28 -> 603.455 | D18: KG
A19: GROSS WEIGHT | B19: : | C19: ='PL(2_2)'!N28 -> 903.455 | D19: KG
A20: - MEASUREMENT | B20: : | C20: ='PL(2_2)'!I28 -> 200 | D20: cm(L) X | E20: ='PL(2_2)'!J28 -> 200 | F20: cm (W) X | G20: ='PL(2_2)'!K28 -> 150 | H20: cm (H) | I20: ='PL(2_2)'!L28 -> 6 | J20: CBM
A21: LOADING PORT | B21: : | C21: ='Packing List (1_2)'!B21 -> Busan International Port, Korea
A22: PORT OF DESTINATION | B22: : | C22: Ho Chi Minh City Port, Vietnam
A23: COUNTRY OF ORIGIN | B23: : | C23: Republic of Korea
A24: QUALITY | B24: : | C24: 100% BRAND NEW

Sheet Technical Description
A6: Technical Description
A7: Invoice no. | B7: ='Commercial Invoice'!H5 -> OM4-DE-IS-0003
A8: № | B8: Package No. | C8: Description of Goods | D8: Quantity | F8: Photo | H8: Technical specifications
D9: Nos | E9: Unit | F9: Before packing | G9: After packing
A10: 1 | B10: ='PL(2_2)'!C15 -> OM4-DE-IS-0003-001 | C10: ='PL(2_2)'!D15 -> PVC Conduit | D10: ='PL(2_2)'!F15 -> 150 | E10: ='PL(2_2)'!G15 -> EA
A11: 2 | B11: ='PL(2_2)'!C16 -> OM4-DE-IS-0003-002 | C11: ='PL(2_2)'!D16 -> PVC Conduit | D11: ='PL(2_2)'!F16 -> 150 | E11: ='PL(2_2)'!G16 -> EA
A12: 3 | B12: ='PL(2_2)'!C17 -> OM4-DE-IS-0003-003 | C12: ='PL(2_2)'!D17 -> PVC Conduit | D12: ='PL(2_2)'!F17 -> 150 | E12: ='PL(2_2)'!G17 -> EA
A13: 4 | B13: ='PL(2_2)'!C18 -> OM4-DE-IS-0003-004 | C13: ='PL(2_2)'!D18 -> PVC Conduit | D13: ='PL(2_2)'!F18 -> 150 | E13: ='PL(2_2)'!G18 -> EA
A14: 5 | B14: ='PL(2_2)'!C19 -> OM4-DE-IS-0003-005 | C14: ='PL(2_2)'!D19 -> PVC Conduit | D14: ='PL(2_2)'!F19 -> 150 | E14: ='PL(2_2)'!G19 -> EA
A15: 6 | B15: ='PL(2_2)'!C20 -> OM4-DE-IS-0003-006 | C15: ='PL(2_2)'!D20 -> PVC Conduit | D15: ='PL(2_2)'!F20 -> 150 | E15: ='PL(2_2)'!G20 -> EA
A16: 7 | B16: ='PL(2_2)'!C21 -> OM4-DE-IS-0003-007 | C16: ='PL(2_2)'!D21 -> PVC Conduit | D16: ='PL(2_2)'!F21 -> 100 | E16: ='PL(2_2)'!G21 -> EA
A17: 8 | B17: ='PL(2_2)'!C22 -> OM4-DE-IS-0003-008 | C17: ='PL(2_2)'!D22 -> PVC Conduit | D17: ='PL(2_2)'!F22 -> 100 | E17: ='PL(2_2)'!G22 -> EA
A18: 9 | B18: ='PL(2_2)'!C23 -> OM4-DE-IS-0003-009 | C18: ='PL(2_2)'!D23 -> PVC Conduit | D18: ='PL(2_2)'!F23 -> 550 | E18: ='PL(2_2)'!G23 -> EA
A19: 10 | B19: ='PL(2_2)'!C24 -> OM4-DE-IS-0003-010 | C19: ='PL(2_2)'!D24 -> CONDUIT FITTINGS (PVC Normal Bend, End bell, PVC COUPLING) | D19: ='PL(2_2)'!F24 -> 1640 | E19: ='PL(2_2)'!G24 -> EA
A20: 11 | B20: ='PL(2_2)'!C25 -> OM4-DE-IS-0003-011 | C20: ='PL(2_2)'!D25 -> CONDUIT FITTINGS (PVC COUPLING) | D20: ='PL(2_2)'!F25 -> 1300 | E20: ='PL(2_2)'!G25 -> EA
A21: 12 | B21: ='PL(2_2)'!C26 -> OM4-DE-IS-0003-012 | C21: ='PL(2_2)'!D26 -> CONDUIT FITTINGS (PVC Spacer, End Bell, Warning Tape) | D21: ='PL(2_2)'!F26 -> 3805 | E21: ='PL(2_2)'!G26 -> EA
... A23: 14 | B23: ='PL(2_2)'!C28 -> OM4-DE-IS-0003-014 | C23: ='PL(2_2)'!D28 -> CONDUIT FITTINGS | D23: ='PL(2_2)'!F28 -> 1162 | E23: ='PL(2_2)'!G28 -> EA

Sheet CO

Sheet CQ

Sheet BL
I3: - In the B/L Form, "Freight Prepaid" must be used according to the signed EPC regulations, "Freight payable" cannot be used as the form we are drafting. - According to EPC, the Contractor is required to bear the risks and losses until handover, and must insure all goods during transportation, so remove the content of the complicated limitation regulations below in the B/L Form.

Sheet PSIC
