Workbook
Name _Hlk215568700: PSIC!$B$2
Name latent: '[4]steam table'!$N$5:$Q$102
Name tube_test_press1_12: #REF!

Sheet Packing List (1_2)
B3: PECC2 Innovation Hub, 45 Street No.2, Truong Tho Ward, Thu Duc City, HCMC, Vietnam Tel: +84-28-2221 6468 | Fax: +84-28-2221 0408
A4: PACKING LIST(1/2)
A5: SHIPPER: | G5: P/L No. | H5: OM4-P2-LS-0002
B6: TRUONG NAM HAI ELECTROMECHANICS ENGINEERING CONSULTANT COMPANY LIMITED Address: 14 Street 20, Lake View City Urban Area, An Phu Ward, Thu Duc City, Ho Chi Minh City, Vietnam | G6: DATE: | H6: June 10th, 2026
G7: CONTRACT NO. | H7: 06/2025/HĐ-PVN/OM4-06
G8: DATE: | H8: June 6th, 2025
A9: CONSIGNEE : | G9: =[6]CI!G9 -> SHIPPING MARK
B10: Power Engineering Consulting Joint Stock Company 2 32 Ngo Thoi Nhiem Street, Xuan Hoa Ward, Ho Chi Minh City, Vietnam | G10: O MON IV THERMAL POWER PLANT
A13: NOTIFY PARTY :
B14: Same as consignee
G15: SHIPMENT NO. : | H15: =H5 -> OM4-P2-LS-0002
G16: TERM OF DELIVERY : | H16: Local shipment to site
A17: VESSEL NAME : | C17: ETD : | G17: QUALITY | H17: 100% BRAND NEW
A18: N/A | C18: N/A
A19: PORT OF LOADING : | C19: PORT OF DISCHARGE :
A20: N/A | C20: N/A
A21: BILL OF LADING/ AIRWAY BILL NO.: | C21: B/L DATE :
A22: N/A | C22: N/A
A23: FINAL DESTINATION :
B24: O MON IV THERMAL POWER PLANT
B25: Address: O Mon Power Complex at Phuoc Thoi wards, Can Tho city
A26: COMMODITY/DESCRIPTION OF GOODS | G26: UNIT | H26: QUANTITY | I26: NET WEIGHT (KG) | J26: GROSS WEIGHT (KG) | K26: MEASUREMENT (CBM)
B27: PLANT/ EQUIPMENT AND MATERIALS FOR O MON IV THERMAL POWER PLANT
B30: [Description of Goods]
B31: Earthing Material and accessories (2 nd shipment) | G31: 45 | H31: Package | I31: ='PL(2_2)'!N66 -> 15358 | J31: ='PL(2_2)'!O66 -> 16054 | K31: ='Detailed PL'!O66 -> 7.74
B36: Number of packages: | D36: 45 | E36: PKGS
G39: TOTAL | I39: =SUM(I27:I38) -> 15358 | J39: =SUM(J27:J38) -> 16054 | K39: =SUM(K27:K38) -> 7.74
G47: Signed by
H48: Factory Director

Sheet PL(2_2)
C3: PECC2 Innovation Hub, 45 Street No.2, Truong Tho Ward, Thu Duc City, HCMC, Vietnam Tel: +84-28-2221 6468 | Fax: +84-28-2221 0408
B4: PACKING LIST(2/2)
C5: P/L No. | D5: ='Packing List (1_2)'!H5 -> OM4-P2-LS-0002
C6: Dated | D6: ='Packing List (1_2)'!H6 -> June 10th, 2026 | I6: * Storage Classification | N6: ** Plant/Equipment/Materials for
C7: Project | D7: O MON IV THERMAL POWER PLANT | I7: "A" | J7: : Indoor with Air conditioning | O7: BLR | P7: TBN | Q7: GEN | R7: BOP
I8: "B" | J8: : Indoor without Air conditioning | N8: Unit 1 | O8: B1 | P8: T1 | Q8: G1 | R8: P2
I9: "C" | J9: : Hazardous Material | N9: Unit 2 | O9: B2 | P9: T2 | Q9: G2 | R9: P2
I10: "D" | J10: : Outdoor with waterproofing | N10: Common | O10: B0 | P10: T0 | Q10: G0 | R10: P0
I11: "E" | J11: : Outdoor without waterproofing
B13: SI. No. | C13: Package No. | D13: Description of Goods | E13: Position in price schedule | F13: Position in price schedule of PECC2 and Supplier (to hide when print out) | G13: Quantity | I13: Package Type | J13: Measurement | N13: Net Weight (kg) | O13: Gross Weight (kg) | P13: Hazardous Material | Q13: Storage Classification (*) | R13: Tag No | S13: Remark (**)
G14: Nos | H14: Unit | J14: Length (cm) | K14: Width (cm) | L14: Height (cm) | M14: Volume (cbm)
B15: 1 | C15: OM4-P2-LS-0002-001 | D15: Stranded Bare Copper Conductor 240 sq.mm (C-240) | E15: V.13 | F15: V.13 | G15: ='Detailed PL'!H15 -> 1000 | H15: m | I15: Roll | J15: ='Detailed PL'!L15 -> 1300 | K15: ='Detailed PL'!M15 -> 800 | L15: ='Detailed PL'!N15 -> 800 | M15: =ROUND(J15*K15*L15/1000000000,2) -> 0.83 | N15: ='Detailed PL'!P15 -> 2257 | O15: ='Detailed PL'!Q15 -> 2340 | P15: N/A | Q15: E | R15: C-240
B16: 2 | C16: OM4-P2-LS-0002-002 | D16: Stranded Bare Copper Conductor 240 sq.mm (C-240) | E16: V.13 | F16: V.13 | G16: ='Detailed PL'!H16 -> 1000 | H16: m | I16: Roll | J16: ='Detailed PL'!L16 -> 1300 | K16: ='Detailed PL'!M16 -> 800 | L16: ='Detailed PL'!N16 -> 800 | M16: =ROUND(J16*K16*L16/1000000000,2) -> 0.83 | N16: ='Detailed PL'!P16 -> 2257 | O16: ='Detailed PL'!Q16 -> 2340 | P16: N/A | Q16: E | R16: C-240
B17: 3 | C17: OM4-P2-LS-0002-003 | D17: Stranded Bare Copper Conductor 240 sq.mm (C-240) | E17: V.13 | F17: V.13 | G17: ='Detailed PL'!H17 -> 1000 | H17: m | I17: Roll | J17: ='Detailed PL'!L17 -> 1300 | K17: ='Detailed PL'!M17 -> 800 | L17: ='Detailed PL'!N17 -> 800 | M17: =ROUND(J17*K17*L17/1000000000,2) -> 0.83 | N17: ='Detailed PL'!P17 -> 2257 | O17: ='Detailed PL'!Q17 -> 2340 | P17: N/A | Q17: E | R17: C-240
B18: 4 | C18: OM4-P2-LS-0002-004 | D18: Stranded Bare Copper Conductor 240 sq.mm (C-240) | E18: V.13 | F18: V.13 | G18: ='Detailed PL'!H18 -> 1000 | H18: m | I18: Roll | J18: ='Detailed PL'!L18 -> 1300 | K18: ='Detailed PL'!M18 -> 800 | L18: ='Detailed PL'!N18 -> 800 | M18: =ROUND(J18*K18*L18/1000000000,2) -> 0.83 | N18: ='Detailed PL'!P18 -> 2257 | O18: ='Detailed PL'!Q18 -> 2340 | P18: N/A | Q18: E | R18: C-240
B19: 5 | C19: OM4-P2-LS-0002-005 | D19: Stranded Bare Copper Conductor 240 sq.mm (C-240) | E19: V.13 | F19: V.13 | G19: ='Detailed PL'!H19 -> 1300 | H19: m | I19: Roll | J19: ='Detailed PL'!L19 -> 1300 | K19: ='Detailed PL'!M19 -> 800 | L19: ='Detailed PL'!N19 -> 800 | M19: =ROUND(J19*K19*L19/1000000000,2) -> 0.83 | N19: ='Detailed PL'!P19 -> 2817 | O19: ='Detailed PL'!Q19 -> 2900 | P19: N/A | Q19: E | R19: C-240
B20: 6 | C20: OM4-P2-LS-0002-006 | D20: PVC Insulated Copper Conductor (Yellow and Green) - 240 sq.mm (CV 240, 0.6/1kV) | E20: V.13 | F20: V.13 | G20: ='Detailed PL'!H20 -> 500 | H20: m | I20: Roll | J20: ='Detailed PL'!L20 -> 1200 | K20: ='Detailed PL'!M20 -> 800 | L20: ='Detailed PL'!N20 -> 800 | M20: =ROUND(J20*K20*L20/1000000000,2) -> 0.77 | N20: ='Detailed PL'!P20 -> 1220 | O20: ='Detailed PL'!Q20 -> 1290 | P20: N/A | Q20: E | R20: CV 240, 0.6/1kV
B21: 7 | C21: OM4-P2-LS-0002-007 | D21: PVC Insulated Copper Conductor (Yellow and Green) - 150 sq.mm (CV 150, 0.6/1kV) | E21: V.13 | F21: I.1 | G21: ='Detailed PL'!H21 -> 500 | H21: m | I21: Roll | J21: ='Detailed PL'!L21 -> 1200 | K21: ='Detailed PL'!M21 -> 800 | L21: ='Detailed PL'!N21 -> 800 | M21: =ROUND(J21*K21*L21/1000000000,2) -> 0.77 | N21: ='Detailed PL'!P21 -> 733 | O21: ='Detailed PL'!Q21 -> 820 | P21: N/A | Q21: E | R21: CV 150, 0.6/1kV
B22: 8 | C22: OM4-P2-LS-0002-008 | D22: PVC Insulated Copper Conductor (Yellow and Green) - 95 sq.mm (CV 95, 0.6/1kV) | E22: V.13 | F22: I.2 | G22: ='Detailed PL'!H22 -> 500 | H22: m | I22: Roll | J22: ='Detailed PL'!L22 -> 1000 | K22: ='Detailed PL'!M22 -> 700 | L22: ='Detailed PL'!N22 -> 700 | M22: =ROUND(J22*K22*L22/1000000000,2) -> 0.49 | N22: ='Detailed PL'!P22 -> 493 | O22: ='Detailed PL'!Q22 -> 580 | P22: N/A | Q22: E | R22: CV 95, 0.6/1kV
B23: 9 | C23: OM4-P2-LS-0002-009 | D23: Welding mold D type (Cross connection cable 240x240 include: hand clamp, flint igniter, PVC & Steel brush). | E23: V.13 | F23: I.3 | G23: ='Detailed PL'!H23 -> 2 | H23: pcs | I23: Box | J23: 500 | K23: 500 | L23: 500 | M23: =ROUND(J23*K23*L23/1000000000,2) -> 0.13 | N23: ='Detailed PL'!P23 -> 80 | O23: ='Detailed PL'!Q23 -> 81 | P23: N/A | Q23: B | R23: CC4-D-240240
B24: 10 | D24: + Welding powder 250g/tube (include: Steel disk, starting powder). Using 2 tubes of 250g welding powder for each CC4-D-240240 cross-type welding joint/Vietnam | E24: V.13 | F24: I.3 | G24: ='Detailed PL'!H24 -> 400 | H24: pcs | Q24: B | R24: #250
B25: 11 | C25: OM4-P2-LS-0002-010 | D25: Welding mold D type (T connection cable 240 & cable 150 include: hand clamp, flint igniter, PVC & Steel brush). | E25: V.13 | F25: I.4 | G25: ='Detailed PL'!H25 -> 1 | H25: pcs | I25: Box | J25: 500 | K25: 500 | L25: 500 | M25: =ROUND(J25*K25*L25/1000000000,2) -> 0.13 | N25: ='Detailed PL'!P25 -> 30 | O25: ='Detailed PL'!Q25 -> 31 | P25: N/A | Q25: B | R25: CC2-D-240150
B26: 12 | D26: + Welding powder 200g/tube (include: Steel disk, starting powder). Using 1 tube of 200gram welding powder for each CC2-D-240150 T-type welding joint/Vietnam | E26: V.13 | F26: I.4 | G26: ='Detailed PL'!H26 -> 100 | H26: pcs | Q26: B | R26: #200
B27: 13 | C27: OM4-P2-LS-0002-011 | D27: Welding mold D type (T connection cable 240 & cable 95 include: hand clamp, flint igniter, PVC & Steel brush). | E27: V.13 | F27: I.5 | G27: ='Detailed PL'!H27 -> 1 | H27: pcs | I27: Box | J27: 500 | K27: 500 | L27: 500 | M27: =ROUND(J27*K27*L27/1000000000,2) -> 0.13 | N27: ='Detailed PL'!P27 -> 25 | O27: ='Detailed PL'!Q27 -> 26 | P27: N/A | Q27: B | R27: CC2-D-24095
B28: 14 | D28: + Welding powder 150g/tube (include: Steel disk, starting powder). Using 1 tube of 150gram welding powder for each CC2-D-24095 T-type welding joint/Vietnam | E28: V.13 | F28: I.5 | G28: ='Detailed PL'!H28 -> 100 | H28: pcs | Q28: B | R28: #150
B29: 15 | C29: OM4-P2-LS-0002-012 | D29: Welding mold C type (T connection cable 240 & cable 35 include: hand clamp, flint igniter, PVC & Steel brush). | E29: V.13 | F29: I.6 | G29: ='Detailed PL'!H29 -> 1 | H29: pcs | I29: Box | J29: 500 | K29: 500 | L29: 500 | M29: =ROUND(J29*K29*L29/1000000000,2) -> 0.13 | N29: ='Detailed PL'!P29 -> 10 | O29: ='Detailed PL'!Q29 -> 11 | P29: N/A | Q29: B | R29: CC2-C-24035
B30: 16 | D30: + Welding powder 90g/tube (include: Steel disk, starting powder). Using 1 tube of 90gram welding powder for each CC2-D-24035 T-type welding joint/Vietnam | E30: V.13 | F30: I.6 | G30: ='Detailed PL'!H30 -> 50 | H30: pcs | Q30: B | R30: #90
B31: 17 | C31: OM4-P2-LS-0002-013 | D31: Welding mold C type (T connection cable 240 & cable 16 include: hand clamp, flint igniter, PVC & Steel brush). | E31: V.13 | F31: I.7 | G31: ='Detailed PL'!H31 -> 1 | H31: pcs | I31: Box | J31: 500 | K31: 500 | L31: 500 | M31: =ROUND(J31*K31*L31/1000000000,2) -> 0.13 | N31: ='Detailed PL'!P31 -> 10 | O31: ='Detailed PL'!Q31 -> 11 | P31: N/A | Q31: B | R31: CC2-C-24016
B32: 18 | D32: '+ Welding powder 90g/tube (include: Steel disk, starting powder). Using 1 tube of 90gram welding powder for each CC2-D-24016 T-type welding joint/Vietnam | E32: V.13 | F32: I.7 | G32: ='Detailed PL'!H32 -> 50 | H32: pcs | Q32: B | R32: #90
B33: 19 | C33: OM4-P2-LS-0002-014 | D33: Welding mold D type (Horizontal cable 240 to rod Φ18 connection include: hand clamp, flint igniter, PVC & Steel brush). | E33: V.13 | F33: I.8 | G33: ='Detailed PL'!H33 -> 1 | H33: pcs | I33: Box | J33: 500 | K33: 500 | L33: 500 | M33: =ROUND(J33*K33*L33/1000000000,2) -> 0.13 | N33: ='Detailed PL'!P33 -> 12 | O33: ='Detailed PL'!Q33 -> 13 | P33: N/A | Q33: B | R33: CR1-D-18240
B34: 20 | D34: + Welding powder 200g/tube (include: Steel disk, starting powder). Using 1 tube of 200gram welding powder for each CR1-D-18240 240 sq.mm to Φ18 ground rod welding joint/Vietnam | E34: V.13 | F34: I.8 | G34: ='Detailed PL'!H34 -> 30 | H34: pcs | Q34: B | R34: #200
B35: 21 | C35: OM4-P2-LS-0002-015 | D35: Pure copper earth rod Φ18x3m, external thread both sides, factory tolerance. + Driving heads, internal thread for rod Φ18 (Black steel). + Driving tip, internal thread for rod Φ18 (Black steel). | E35: V.13 | F35: I.9 | G35: ='Detailed PL'!H35 -> 30 | H35: pcs | I35: Budle | J35: ='Detailed PL'!L35 -> 3000 | K35: ='Detailed PL'!M35 -> 300 | L35: ='Detailed PL'!N35 -> 200 | M35: =ROUND(J35*K35*L35/1000000000,2) -> 0.18 | N35: ='Detailed PL'!P35 -> 150 | O35: ='Detailed PL'!Q35 -> 151 | P35: N/A | Q35: E | R35: VA-CTD-1830
B36: 22 | C36: OM4-P2-LS-0002-016 | D36: Concrete eath pit (Dim: 310x310x170mm) + Copper earth bar 5 connection points Φ12, Dim: 50x5x300 c/w: SS304 bolds, nuts, spring & flat washers M12x40. | E36: V.13 | F36: I.10 | G36: ='Detailed PL'!H36 -> 1 | H36: pcs | I36: Budle | J36: ='Detailed PL'!L36 -> 350 | K36: ='Detailed PL'!M36 -> 350 | L36: ='Detailed PL'!N36 -> 200 | M36: =ROUND(J36*K36*L36/1000000000,2) -> 0.02 | N36: ='Detailed PL'!P36 -> 25 | O36: ='Detailed PL'!Q36 -> 26 | P36: N/A | Q36: E | R36: VA-HKT
B37: 23 | C37: OM4-P2-LS-0002-017 | D37: Concrete eath pit (Dim: 310x310x170mm) + Copper earth bar 5 connection points Φ12, Dim: 50x5x300 c/w: SS304 bolds, nuts, spring & flat washers M12x40. | E37: V.13 | F37: I.10 | G37: ='Detailed PL'!H37 -> 1 | H37: pcs | I37: Budle | J37: ='Detailed PL'!L37 -> 350 | K37: ='Detailed PL'!M37 -> 350 | L37: ='Detailed PL'!N37 -> 200 | M37: =ROUND(J37*K37*L37/1000000000,2) -> 0.02 | N37: ='Detailed PL'!P37 -> 25 | O37: ='Detailed PL'!Q37 -> 26 | P37: N/A | Q37: E | R37: VA-HKT
B38: 24 | C38: OM4-P2-LS-0002-018 | D38: Concrete eath pit (Dim: 310x310x170mm) + Copper earth bar 5 connection points Φ12, Dim: 50x5x300 c/w: SS304 bolds, nuts, spring & flat washers M12x40. | E38: V.13 | F38: I.10 | G38: ='Detailed PL'!H38 -> 1 | H38: pcs | I38: Budle | J38: ='Detailed PL'!L38 -> 350 | K38: ='Detailed PL'!M38 -> 350 | L38: ='Detailed PL'!N38 -> 200 | M38: =ROUND(J38*K38*L38/1000000000,2) -> 0.02 | N38: ='Detailed PL'!P38 -> 25 | O38: ='Detailed PL'!Q38 -> 26 | P38: N/A | Q38: E | R38: VA-HKT
B39: 25 | C39: OM4-P2-LS-0002-019 | D39: Concrete eath pit (Dim: 310x310x170mm) + Copper earth bar 5 connection points Φ12, Dim: 50x5x300 c/w: SS304 bolds, nuts, spring & flat washers M12x40. | E39: V.13 | F39: I.10 | G39: ='Detailed PL'!H39 -> 1 | H39: pcs | I39: Budle | J39: ='Detailed PL'!L39 -> 350 | K39: ='Detailed PL'!M39 -> 350 | L39: ='Detailed PL'!N39 -> 200 | M39: =ROUND(J39*K39*L39/1000000000,2) -> 0.02 | N39: ='Detailed PL'!P39 -> 25 | O39: ='Detailed PL'!Q39 -> 26 | P39: N/A | Q39: E | R39: VA-HKT
B40: 26 | C40: OM4-P2-LS-0002-020 | D40: Concrete eath pit (Dim: 310x310x170mm) + Copper earth bar 5 connection points Φ12, Dim: 50x5x300 c/w: SS304 bolds, nuts, spring & flat washers M12x40. | E40: V.13 | F40: I.10 | G40: ='Detailed PL'!H40 -> 1 | H40: pcs | I40: Budle | J40: ='Detailed PL'!L40 -> 350 | K40: ='Detailed PL'!M40 -> 350 | L40: ='Detailed PL'!N40 -> 200 | M40: =ROUND(J40*K40*L40/1000000000,2) -> 0.02 | N40: ='Detailed PL'!P40 -> 25 | O40: ='Detailed PL'!Q40 -> 26 | P40: N/A | Q40: E | R40: VA-HKT
B41: 27 | C41: OM4-P2-LS-0002-021 | D41: Concrete eath pit (Dim: 310x310x170mm) + Copper earth bar 5 connection points Φ12, Dim: 50x5x300 c/w: SS304 bolds, nuts, spring & flat washers M12x40. | E41: V.13 | F41: I.10 | G41: ='Detailed PL'!H41 -> 1 | H41: pcs | I41: Budle | J41: ='Detailed PL'!L41 -> 350 | K41: ='Detailed PL'!M41 -> 350 | L41: ='Detailed PL'!N41 -> 200 | M41: =ROUND(J41*K41*L41/1000000000,2) -> 0.02 | N41: ='Detailed PL'!P41 -> 25 | O41: ='Detailed PL'!Q41 -> 26 | P41: N/A | Q41: E | R41: VA-HKT
B42: 28 | C42: OM4-P2-LS-0002-022 | D42: Concrete eath pit (Dim: 310x310x170mm) + Copper earth bar 5 connection points Φ12, Dim: 50x5x300 c/w: SS304 bolds, nuts, spring & flat washers M12x40. | E42: V.13 | F42: I.10 | G42: ='Detailed PL'!H42 -> 1 | H42: pcs | I42: Budle | J42: ='Detailed PL'!L42 -> 350 | K42: ='Detailed PL'!M42 -> 350 | L42: ='Detailed PL'!N42 -> 200 | M42: =ROUND(J42*K42*L42/1000000000,2) -> 0.02 | N42: ='Detailed PL'!P42 -> 25 | O42: ='Detailed PL'!Q42 -> 26 | P42: N/A | Q42: E | R42: VA-HKT
B43: 29 | C43: OM4-P2-LS-0002-023 | D43: Concrete eath pit (Dim: 310x310x170mm) + Copper earth bar 5 connection points Φ12, Dim: 50x5x300 c/w: SS304 bolds, nuts, spring & flat washers M12x40. | E43: V.13 | F43: I.10 | G43: ='Detailed PL'!H43 -> 1 | H43: pcs | I43: Budle | J43: ='Detailed PL'!L43 -> 350 | K43: ='Detailed PL'!M43 -> 350 | L43: ='Detailed PL'!N43 -> 200 | M43: =ROUND(J43*K43*L43/1000000000,2) -> 0.02 | N43: ='Detailed PL'!P43 -> 25 | O43: ='Detailed PL'!Q43 -> 26 | P43: N/A | Q43: E | R43: VA-HKT
...

Sheet Detailed PL
C3: PECC2 Innovation Hub, 45 Street No.2, Truong Tho Ward, Thu Duc City, HCMC, Vietnam Tel: +84-28-2221 6468 | Fax: +84-28-2221 0408
B4: DETAILED PACKING LIST
C5: PL No. | D5: ='PL(2_2)'!D5 -> OM4-P2-LS-0002 | AA5: 36 | AB5: 39 | AC5: 40 | AD5: 163 | AE5: 3 | AF5: 8 | AG5: 44 | AH5: 45 | AI5: 46 | AJ5: 60 | AK5: 66 | AL5: 68 | AM5: 69 | AN5: 70 | AO5: 71 | AP5: 170 | AQ5: 110 | AR5: 234 | AS5: 33 | AT5: 34 | AU5: 142 | AW5: 79 | AX5: 80 | AY5: 81 | AZ5: 82
C6: Dated | D6: ='PL(2_2)'!D6 -> June 10th, 2026 | F6: * Storage Classification | M6: ** Plant/Equipment/Materials for | AA6: =SUMIF(#REF!,AA5,#REF!) -> #REF! | AB6: =SUMIF(#REF!,AB5,#REF!) -> #REF! | AC6: =SUMIF(#REF!,AC5,#REF!) -> #REF! | AD6: =SUMIF(#REF!,AD5,#REF!) -> #REF! | AE6: =SUMIF(#REF!,AE5,#REF!) -> #REF! | AF6: =SUMIF(#REF!,AF5,#REF!) -> #REF! | AG6: =SUMIF(#REF!,AG5,#REF!) -> #REF! | AH6: =SUMIF(#REF!,AH5,#REF!) -> #REF! | ... AQ6: =SUMIF(#REF!,AQ5,#REF!) -> #REF! | AR6: =SUMIF($AI$66:$AI$335,AR5,$H$66:$H$335) -> 0 | AS6: =SUMIF($AI$66:$AI$335,AS5,$H$66:$H$335) -> 0 | AT6: =SUMIF($AI$66:$AI$335,AT5,$H$66:$H$335) -> 0 | AU6: =SUMIF(#REF!,AU5,#REF!) -> #REF! | AV6: =SUM(AA6:AU7) -> #REF! | AW6: =SUMIF(#REF!,AW5,#REF!) -> #REF! | AX6: =SUMIF(#REF!,AX5,#REF!) -> #REF! | AY6: =SUMIF($AI$66:$AI$335,AY5,$H$66:$H$335) -> 0 | AZ6: =SUMIF($AI$66:$AI$335,AZ5,$H$66:$H$335) -> 0
C7: Project | D7: ='PL(2_2)'!D7 -> O MON IV THERMAL POWER PLANT | G7: "A" | H7: : Indoor with Air conditioning | N7: BLR | O7: TBN | P7: GEN | Q7: BOP | AC7: 1 | AD7: 1 | AG7: 5 | AH7: 100 | AS7: 2 | AU7: 105
C8: Referenced DWG No. | D8: 047.26. X021 | G8: "B" | H8: : Indoor without Air conditioning | M8: Unit 1 | N8: B1 | O8: T1 | P8: G1 | Q8: P2
G9: "C" | H9: : Hazardous Material | M9: Unit 2 | N9: B2 | O9: T2 | P9: G2 | Q9: P2
G10: "D" | H10: : Outdoor with waterproofing | M10: Common | N10: B0 | O10: T0 | P10: G0 | Q10: P0
G11: "E" | H11: : Outdoor without waterproofing
B13: SI. No. | C13: Package No. | D13: Description of Goods | E13: Supplier / Manufacturer | F13: C/O of Goods | G13: Position in price schedule | H13: Quantity | J13: kg | K13: Package Type | L13: Measurement | P13: Net Weight (kg) | Q13: Gross Weight (kg) | R13: Tag No./Model | S13: Remark (**)
H14: Nos | I14: Unit | L14: Length (mm) | M14: Width (mm) | N14: Height (mm) | O14: Volume (cbm)
B15: 1 | C15: OM4-P2-LS-0002-001 | D15: Stranded Bare Copper Conductor 240 sq.mm (C-240) | E15: Truong Nam Hai | F15: Vietnam | G15: V.13 | H15: 1000 | I15: m | J15: =2122+135 -> 2257 | K15: Roll | L15: 1300 | M15: 800 | N15: 800 | O15: =ROUND(L15*M15*N15/1000000000,2) -> 0.83 | P15: =1*J15 -> 2257 | Q15: =P15+83 -> 2340 | R15: C-240
B16: 2 | C16: OM4-P2-LS-0002-002 | D16: Stranded Bare Copper Conductor 240 sq.mm (C-240) | E16: Truong Nam Hai | F16: Vietnam | G16: V.13 | H16: 1000 | I16: m | J16: =2122+135 -> 2257 | K16: Roll | L16: 1300 | M16: 800 | N16: 800 | O16: =ROUND(L16*M16*N16/1000000000,2) -> 0.83 | P16: =1*J16 -> 2257 | Q16: =P16+83 -> 2340 | R16: C-240
B17: 3 | C17: OM4-P2-LS-0002-003 | D17: Stranded Bare Copper Conductor 240 sq.mm (C-240) | E17: Truong Nam Hai | F17: Vietnam | G17: V.13 | H17: 1000 | I17: m | J17: =2122+135 -> 2257 | K17: Roll | L17: 1300 | M17: 800 | N17: 800 | O17: =ROUND(L17*M17*N17/1000000000,2) -> 0.83 | P17: =1*J17 -> 2257 | Q17: =P17+83 -> 2340 | R17: C-240
B18: 4 | C18: OM4-P2-LS-0002-004 | D18: Stranded Bare Copper Conductor 240 sq.mm (C-240) | E18: Truong Nam Hai | F18: Vietnam | G18: V.13 | H18: 1000 | I18: m | J18: =2122+135 -> 2257 | K18: Roll | L18: 1300 | M18: 800 | N18: 800 | O18: =ROUND(L18*M18*N18/1000000000,2) -> 0.83 | P18: =1*J18 -> 2257 | Q18: =P18+83 -> 2340 | R18: C-240
B19: 5 | C19: OM4-P2-LS-0002-005 | D19: Stranded Bare Copper Conductor 240 sq.mm (C-240) | E19: Truong Nam Hai | F19: Vietnam | G19: V.13 | H19: 1300 | I19: m | J19: 2817 | K19: Roll | L19: 1300 | M19: 800 | N19: 800 | O19: =ROUND(L19*M19*N19/1000000000,2) -> 0.83 | P19: 2817 | Q19: =P19+83 -> 2900 | R19: C-240
B20: 6 | C20: OM4-P2-LS-0002-006 | D20: PVC Insulated Copper Conductor (Yellow and Green) - 240 sq.mm (CV 240, 0.6/1kV) | E20: Truong Nam Hai | F20: Vietnam | G20: V.13 | H20: 500 | I20: m | J20: 1220 | K20: Roll | L20: 1200 | M20: 800 | N20: 800 | O20: =ROUND(L20*M20*N20/1000000000,2) -> 0.77 | P20: 1220 | Q20: =P20+70 -> 1290 | R20: CV 240, 0.6/1kV
B21: 7 | C21: OM4-P2-LS-0002-007 | D21: PVC Insulated Copper Conductor (Yellow and Green) - 150 sq.mm (CV 150, 0.6/1kV) | E21: Truong Nam Hai | F21: Vietnam | G21: I.1 | H21: 500 | I21: m | J21: 733 | K21: Roll | L21: 1200 | M21: 800 | N21: 800 | O21: =ROUND(L21*M21*N21/1000000000,2) -> 0.77 | P21: 733 | Q21: =P21+87 -> 820 | R21: CV 150, 0.6/1kV
B22: 8 | C22: OM4-P2-LS-0002-008 | D22: PVC Insulated Copper Conductor (Yellow and Green) - 95 sq.mm (CV 95, 0.6/1kV) | E22: Truong Nam Hai | F22: Vietnam | G22: I.2 | H22: 500 | I22: m | J22: 493 | K22: Roll | L22: 1000 | M22: 700 | N22: 700 | O22: =ROUND(L22*M22*N22/1000000000,2) -> 0.49 | P22: 493 | Q22: =P22+87 -> 580 | R22: CV 95, 0.6/1kV
B23: 9 | C23: OM4-P2-LS-0002-009 | D23: Welding mold D type (Cross connection cable 240x240 include: hand clamp, flint igniter, PVC & Steel brush). | E23: Truong Nam Hai | F23: Vietnam | G23: I.3 | H23: 2 | I23: pcs | K23: Box | L23: 500 | M23: 500 | N23: 500 | O23: =ROUND(L23*M23*N23/1000000000,2) -> 0.13 | P23: =H24*J24 -> 80 | Q23: =P23+1 -> 81 | R23: CC4-D-240240
B24: 10 | D24: + Welding powder 250g/tube (include: Steel disk, starting powder). Using 2 tubes of 250g welding powder for each CC4-D-240240 cross-type welding joint/Vietnam | E24: Truong Nam Hai | F24: Vietnam | G24: I.3 | H24: 400 | I24: pcs | J24: 0.2 | R24: #250
B25: 11 | C25: OM4-P2-LS-0002-010 | D25: Welding mold D type (T connection cable 240 & cable 150 include: hand clamp, flint igniter, PVC & Steel brush). | E25: Truong Nam Hai | F25: Vietnam | G25: I.4 | H25: 1 | I25: pcs | K25: Box | L25: 500 | M25: 500 | N25: 500 | O25: =ROUND(L25*M25*N25/1000000000,2) -> 0.13 | P25: =H26*J26 -> 30 | Q25: =P25+1 -> 31 | R25: CC2-D-240150
B26: 12 | D26: + Welding powder 200g/tube (include: Steel disk, starting powder). Using 1 tube of 200gram welding powder for each CC2-D-240150 T-type welding joint/Vietnam | E26: Truong Nam Hai | F26: Vietnam | G26: I.4 | H26: 100 | I26: pcs | J26: 0.3 | R26: #200
B27: 13 | C27: OM4-P2-LS-0002-011 | D27: Welding mold D type (T connection cable 240 & cable 95 include: hand clamp, flint igniter, PVC & Steel brush). | E27: Truong Nam Hai | F27: Vietnam | G27: I.5 | H27: 1 | I27: pcs | K27: Box | L27: 500 | M27: 500 | N27: 500 | O27: =ROUND(L27*M27*N27/1000000000,2) -> 0.13 | P27: =H28*J28 -> 25 | Q27: =P27+1 -> 26 | R27: CC2-D-24095
B28: 14 | D28: '+ Welding powder 150g/tube (include: Steel disk, starting powder). Using 1 tube of 150gram welding powder for each CC2-D-24095 T-type welding joint/Vietnam | E28: Truong Nam Hai | F28: Vietnam | G28: I.5 | H28: 100 | I28: pcs | J28: 0.25 | R28: #150
B29: 15 | C29: OM4-P2-LS-0002-012 | D29: Welding mold C type (T connection cable 240 & cable 35 include: hand clamp, flint igniter, PVC & Steel brush). | E29: Truong Nam Hai | F29: Vietnam | G29: I.6 | H29: 1 | I29: pcs | K29: Box | L29: 500 | M29: 500 | N29: 500 | O29: =ROUND(L29*M29*N29/1000000000,2) -> 0.13 | P29: =H30*J30 -> 10 | Q29: =P29+1 -> 11 | R29: CC2-C-24035
B30: 16 | D30: + Welding powder 90g/tube (include: Steel disk, starting powder). Using 1 tube of 90gram welding powder for each CC2-D-24035 T-type welding joint/Vietnam | E30: Truong Nam Hai | F30: Vietnam | G30: I.6 | H30: 50 | I30: pcs | J30: 0.2 | R30: #90
B31: 17 | C31: OM4-P2-LS-0002-013 | D31: Welding mold C type (T connection cable 240 & cable 16 include: hand clamp, flint igniter, PVC & Steel brush). | E31: Truong Nam Hai | F31: Vietnam | G31: I.7 | H31: 1 | I31: pcs | K31: Box | L31: 500 | M31: 500 | N31: 500 | O31: =ROUND(L31*M31*N31/1000000000,2) -> 0.13 | P31: =H32*J32 -> 10 | Q31: =P31+1 -> 11 | R31: CC2-C-24016
B32: 18 | D32: '+ Welding powder 90g/tube (include: Steel disk, starting powder). Using 1 tube of 90gram welding powder for each CC2-D-24016 T-type welding joint/Vietnam | E32: Truong Nam Hai | F32: Vietnam | G32: I.7 | H32: 50 | I32: pcs | J32: 0.2 | R32: #90
B33: 19 | C33: OM4-P2-LS-0002-014 | D33: Welding mold D type (Horizontal cable 240 to rod Φ18 connection include: hand clamp, flint igniter, PVC & Steel brush). | E33: Truong Nam Hai | F33: Vietnam | G33: I.8 | H33: 1 | I33: pcs | K33: Box | L33: 500 | M33: 500 | N33: 500 | O33: =ROUND(L33*M33*N33/1000000000,2) -> 0.13 | P33: =H34*J34 -> 12 | Q33: =P33+1 -> 13 | R33: CR1-D-18240
B34: 20 | D34: + Welding powder 200g/tube (include: Steel disk, starting powder). Using 1 tube of 200gram welding powder for each CR1-D-18240 240 sq.mm to Φ18 ground rod welding joint/Vietnam | E34: Truong Nam Hai | F34: Vietnam | G34: I.8 | H34: 30 | I34: pcs | J34: 0.4 | R34: #200
B35: 21 | C35: OM4-P2-LS-0002-015 | D35: Pure copper earth rod Φ18x3m, external thread both sides, factory tolerance. + Driving heads, internal thread for rod Φ18 (Black steel). + Driving tip, internal thread for rod Φ18 (Black steel). | E35: Truong Nam Hai | F35: Vietnam | G35: I.9 | H35: 30 | I35: pcs | J35: 5 | K35: Budle | L35: 3000 | M35: 300 | N35: 200 | O35: =ROUND(L35*M35*N35/1000000000,2) -> 0.18 | P35: =H35*J35 -> 150 | Q35: =P35+1 -> 151 | R35: VA-CTD-1830
B36: 22 | C36: OM4-P2-LS-0002-016 | D36: Concrete eath pit (Dim: 310x310x170mm) + Copper earth bar 5 connection points Φ12, Dim: 50x5x300 c/w: SS304 bolds, nuts, spring & flat washers M12x40. | E36: Truong Nam Hai | F36: Vietnam | G36: I.10 | H36: 1 | I36: pcs | J36: 25 | K36: Budle | L36: 350 | M36: 350 | N36: 200 | O36: =ROUND(L36*M36*N36/1000000000,2) -> 0.02 | P36: =H36*J36 -> 25 | Q36: =P36+1 -> 26 | R36: VA-HKT
B37: 23 | C37: OM4-P2-LS-0002-017 | D37: Concrete eath pit (Dim: 310x310x170mm) + Copper earth bar 5 connection points Φ12, Dim: 50x5x300 c/w: SS304 bolds, nuts, spring & flat washers M12x40. | E37: Truong Nam Hai | F37: Vietnam | G37: I.10 | H37: 1 | I37: pcs | J37: 25 | K37: Budle | L37: 350 | M37: 350 | N37: 200 | O37: =ROUND(L37*M37*N37/1000000000,2) -> 0.02 | P37: =H37*J37 -> 25 | Q37: =P37+1 -> 26 | R37: VA-HKT
B38: 24 | C38: OM4-P2-LS-0002-018 | D38: Concrete eath pit (Dim: 310x310x170mm) + Copper earth bar 5 connection points Φ12, Dim: 50x5x300 c/w: SS304 bolds, nuts, spring & flat washers M12x40. | E38: Truong Nam Hai | F38: Vietnam | G38: I.10 | H38: 1 | I38: pcs | J38: 25 | K38: Budle | L38: 350 | M38: 350 | N38: 200 | O38: =ROUND(L38*M38*N38/1000000000,2) -> 0.02 | P38: =H38*J38 -> 25 | Q38: =P38+1 -> 26 | R38: VA-HKT
B39: 25 | C39: OM4-P2-LS-0002-019 | D39: Concrete eath pit (Dim: 310x310x170mm) + Copper earth bar 5 connection points Φ12, Dim: 50x5x300 c/w: SS304 bolds, nuts, spring & flat washers M12x40. | E39: Truong Nam Hai | F39: Vietnam | G39: I.10 | H39: 1 | I39: pcs | J39: 25 | K39: Budle | L39: 350 | M39: 350 | N39: 200 | O39: =ROUND(L39*M39*N39/1000000000,2) -> 0.02 | P39: =H39*J39 -> 25 | Q39: =P39+1 -> 26 | R39: VA-HKT
B40: 26 | C40: OM4-P2-LS-0002-020 | D40: Concrete eath pit (Dim: 310x310x170mm) + Copper earth bar 5 connection points Φ12, Dim: 50x5x300 c/w: SS304 bolds, nuts, spring & flat washers M12x40. | E40: Truong Nam Hai | F40: Vietnam | G40: I.10 | H40: 1 | I40: pcs | J40: 25 | K40: Budle | L40: 350 | M40: 350 | N40: 200 | O40: =ROUND(L40*M40*N40/1000000000,2) -> 0.02 | P40: =H40*J40 -> 25 | Q40: =P40+1 -> 26 | R40: VA-HKT
B41: 27 | C41: OM4-P2-LS-0002-021 | D41: Concrete eath pit (Dim: 310x310x170mm) + Copper earth bar 5 connection points Φ12, Dim: 50x5x300 c/w: SS304 bolds, nuts, spring & flat washers M12x40. | E41: Truong Nam Hai | F41: Vietnam | G41: I.10 | H41: 1 | I41: pcs | J41: 25 | K41: Budle | L41: 350 | M41: 350 | N41: 200 | O41: =ROUND(L41*M41*N41/1000000000,2) -> 0.02 | P41: =H41*J41 -> 25 | Q41: =P41+1 -> 26 | R41: VA-HKT
B42: 28 | C42: OM4-P2-LS-0002-022 | D42: Concrete eath pit (Dim: 310x310x170mm) + Copper earth bar 5 connection points Φ12, Dim: 50x5x300 c/w: SS304 bolds, nuts, spring & flat washers M12x40. | E42: Truong Nam Hai | F42: Vietnam | G42: I.10 | H42: 1 | I42: pcs | J42: 25 | K42: Budle | L42: 350 | M42: 350 | N42: 200 | O42: =ROUND(L42*M42*N42/1000000000,2) -> 0.02 | P42: =H42*J42 -> 25 | Q42: =P42+1 -> 26 | R42: VA-HKT
B43: 29 | C43: OM4-P2-LS-0002-023 | D43: Concrete eath pit (Dim: 310x310x170mm) + Copper earth bar 5 connection points Φ12, Dim: 50x5x300 c/w: SS304 bolds, nuts, spring & flat washers M12x40. | E43: Truong Nam Hai | F43: Vietnam | G43: I.10 | H43: 1 | I43: pcs | J43: 25 | K43: Budle | L43: 350 | M43: 350 | N43: 200 | O43: =ROUND(L43*M43*N43/1000000000,2) -> 0.02 | P43: =H43*J43 -> 25 | Q43: =P43+1 -> 26 | R43: VA-HKT
...

Sheet SHIPPING MARK
A1: SHIPPING MARK
A2: O MON IV THERMAL POWER PLANT
A3: =[6]CI!B26 -> Address: O Mon Power Complex at Phuoc Thoi wards, O Mon district, Can Tho city
A5: SHIPPER | B5: :
A6: ADDRESS | B6: :
A7: CONSIGNEE | B7: : | C7: As per the Contractor(Scope of Consortium)
A8: NOTIFY PARTY | B8: :
A12: CONTRACT NO. | B12: : | C12: 06/2025/HĐ-PVN/OM4-06 | H12: =[6]CI!G8 -> DATE:
A13: SHIPMENT NO. | B13: : | C13: Following shipment numbering
A14: EQUIPMENT DESCRIPTION | B14: : | C14: =[6]CI!B28 -> PLANT/ EQUIPMENT AND MATERIALS FOR O MON IV THERMAL
A15: CONSIGNOR. | B15: :
A16: PACKAGE NO. | B16: :
A17: NET WEIGHT | B17: : | D17: KG
A18: GROSS WEIGHT | B18: : | D18: KG
A19: - MEASUREMENT | B19: : | D19: cm(L) X | F19: cm (W) X | H19: cm (H) | J19: CBM
A20: LOADING PORT | B20: :
A21: PORT OF DESTINATION | B21: :
A22: COUNTRY OF ORIGIN | B22: :
A23: QUALITY | B23: : | C23: 100% BRAND NEW

Sheet CO

Sheet CQ

Sheet BL
I3: - In the B/L Form, "Freight Prepaid" must be used according to the signed EPC regulations, "Freight payable" cannot be used as the form we are drafting. - According to EPC, the Contractor is required to bear the risks and losses until handover, and must insure all goods during transportation, so remove the content of the complicated limitation regulations below in the B/L Form.

Sheet PSIC
