Workbook
Name _Hlk215568700: PSIC!$B$2
Name latent: #REF!
Name latent: '[4]steam table'!$N$5:$Q$102
Name tube_test_press1_12: #REF!

Sheet Detailed PL
C3: PECC2 Innovation Hub, 45 Street No.2, Truong Tho Ward, Thu Duc City, HCMC, Vietnam Tel: +84-28-2221 6468 | Fax: +84-28-2221 0408
B4: DETAILED PACKING LIST
C5: PL No. | D5: ='PL(2_2)'!D5 -> OM4-DE-IS-0009
C6: Dated | D6: ='PL(2_2)'!D6 -> 46177 | J6: * Storage Classification | O6: ** Plant/Equipment/Materials for
C7: Project | D7: ='PL(2_2)'!D7 -> O MON IV THERMAL POWER PLANT | J7: "A" | K7: : Indoor with Air conditioning | P7: HRSG | Q7: STG | R7: GTG | S7: BOP
C8: Referenced DWG No. | J8: "B" | K8: : Indoor without Air conditioning | O8: Unit 1 | P8: B1 | Q8: T1 | R8: G1 | S8: P2
J9: "C" | K9: : Hazardous Material | O9: Unit 2 | P9: B2 | Q9: T2 | R9: G2 | S9: P2
J10: "D" | K10: : Outdoor with waterproofing | O10: Common | P10: B0 | Q10: T0 | R10: G0 | S10: P0
J11: "E" | K11: : Outdoor without waterproofing
B13: SI. No. | C13: Package No. | D13: Description of Goods | F13: Manufacturer | G13: C/O of Goods | H13: Position in price schedule | I13: Quantity | K13: Package Type | L13: Measurement | P13: Net Weight (kg) | Q13: Gross Weight (kg) | R13: Hazardous Material | S13: Storage Classification (*) | T13: Tag No. | U13: Remark (**)
I14: Nos | J14: Unit | L14: Length (cm) | M14: Width (cm) | N14: Height (cm) | O14: Volume (cbm)
B15: 1 | C15: OM4-DE-IS-0009-001 | D15: HDG STEEL Conduit | E15: 125mm (5") | F15: SAMSUNG E&L | G15: Republic of Korea | I15: 32 | J15: EA | P15: =W15*I15 -> 1920 | W15: 60
B16: Sub-Total | I16: =SUM(I15) -> 32 | K16: Wooden | L16: 350 | M16: 120 | N16: 160 | O16: =(L16*M16*N16)/10^6 -> 6.72 | P16: =P15 -> 1920 | Q16: =P16+300 -> 2220 | R16: N | S16: D | U16: P0
B17: 2 | C17: OM4-DE-IS-0009-002 | D17: HDG STEEL Conduit | E17: 125mm (5") | F17: SAMSUNG E&L | G17: Republic of Korea | I17: 28 | J17: EA | P17: =W17*I17 -> 1680 | W17: 60
B18: Sub-Total | I18: =SUM(I17) -> 28 | K18: Wooden | L18: 350 | M18: 120 | N18: 130 | O18: =(L18*M18*N18)/10^6 -> 5.46 | P18: =P17 -> 1680 | Q18: =P18+300 -> 1980 | R18: N | S18: D | U18: P0
B19: 3 | C19: OM4-DE-IS-0009-003 | D19: Normal Bend for Steel Conduit | E19: 36mm (1-1/4") | F19: SAMSUNG E&L | G19: Republic of Korea | I19: 250 | J19: EA | P19: =W19*I19 -> 322.5 | W19: 1.29
B20: 4 | C20: =C19 -> OM4-DE-IS-0009-003 | D20: Normal Bend for Steel Conduit | E20: 42mm (1-1/2") | F20: SAMSUNG E&L | G20: Republic of Korea | I20: 100 | J20: EA | P20: =W20*I20 -> 187 | W20: 1.87
B21: 5 | C21: =C20 -> OM4-DE-IS-0009-003 | D21: Normal Bend for Steel Conduit | E21: 54mm (2") | F21: SAMSUNG E&L | G21: Republic of Korea | I21: 60 | J21: EA | P21: =W21*I21 -> 175.8 | W21: 2.93
B22: 6 | C22: =C21 -> OM4-DE-IS-0009-003 | D22: Coupling for Steel Conduit | E22: 28mm (1") | F22: SAMSUNG E&L | G22: Republic of Korea | I22: 180 | J22: EA | P22: =W22*I22 -> 21.6 | W22: 0.12
B23: 7 | C23: =C22 -> OM4-DE-IS-0009-003 | D23: Coupling for Steel Conduit | E23: 36mm (1-1/4") | F23: SAMSUNG E&L | G23: Republic of Korea | I23: 60 | J23: EA | P23: =W23*I23 -> 11.4 | W23: 0.19
B24: 8 | C24: =C23 -> OM4-DE-IS-0009-003 | D24: Coupling for Steel Conduit | E24: 42mm (1-1/2") | F24: SAMSUNG E&L | G24: Republic of Korea | I24: 30 | J24: EA | P24: =W24*I24 -> 6.6 | W24: 0.22
B25: 9 | C25: =C24 -> OM4-DE-IS-0009-003 | D25: Coupling for Steel Conduit | E25: 54mm (2") | F25: SAMSUNG E&L | G25: Republic of Korea | I25: 30 | J25: EA | P25: =W25*I25 -> 9.9 | W25: 0.33
B26: 10 | C26: =C25 -> OM4-DE-IS-0009-003 | D26: Coupling for Steel Conduit | E26: 82mm (3") | F26: SAMSUNG E&L | G26: Republic of Korea | I26: 40 | J26: EA | P26: =W26*I26 -> 39.2 | W26: 0.98
B27: 11 | C27: =C26 -> OM4-DE-IS-0009-003 | D27: Coupling for Steel Conduit | E27: 104mm (4") | F27: SAMSUNG E&L | G27: Republic of Korea | I27: 40 | J27: EA | P27: =W27*I27 -> 50 | W27: 1.25
B28: 12 | C28: =C27 -> OM4-DE-IS-0009-003 | D28: HI PVC to Steel Conduit Adaptor | E28: 28mm (1") | F28: SAMSUNG E&L | G28: Republic of Korea | I28: 80 | J28: EA | P28: =W28*I28 -> 9.6 | W28: 0.12
B29: 13 | C29: =C28 -> OM4-DE-IS-0009-003 | D29: HI PVC to Steel Conduit Adaptor | E29: 36mm (1-1/4") | F29: SAMSUNG E&L | G29: Republic of Korea | I29: 50 | J29: EA | P29: =W29*I29 -> 9.5 | W29: 0.19
B30: 14 | C30: =C29 -> OM4-DE-IS-0009-003 | D30: HI PVC to Steel Conduit Adaptor | E30: 42mm (1-1/2") | F30: SAMSUNG E&L | G30: Republic of Korea | I30: 30 | J30: EA | P30: =W30*I30 -> 6.6 | W30: 0.22
B31: 15 | C31: =C30 -> OM4-DE-IS-0009-003 | D31: HI PVC to Steel Conduit Adaptor | E31: 54mm (2") | F31: SAMSUNG E&L | G31: Republic of Korea | I31: 10 | J31: EA | P31: =W31*I31 -> 3.3 | W31: 0.33
... B34: 18 | C34: =C33 -> OM4-DE-IS-0009-003 | D34: HI PVC to Steel Conduit Adaptor | E34: 125mm (5") | F34: SAMSUNG E&L | G34: Republic of Korea | I34: 40 | J34: EA | P34: =W34*I34 -> 120 | W34: 3
B35: Sub-Total | I35: =SUM(I19:I34) -> 1060 | K35: Wooden | L35: 250 | M35: 150 | N35: 100 | O35: =(L35*M35*N35)/10^6 -> 3.75 | P35: =SUM(P19:P34) -> 1042.6 | Q35: =P35+300 -> 1342.6 | R35: N | S35: D | U35: P0
B36: 19 | C36: OM4-DE-IS-0009-004 | D36: Normal Bend for Steel Conduit | E36: 82mm (3") X 600Radius | F36: SAMSUNG E&L | G36: Republic of Korea | I36: 75 | J36: EA | P36: =W36*I36 -> 1162.5 | W36: 15.5
B37: Sub-Total | I37: =SUM(I36) -> 75 | K37: Wooden | L37: 240 | M37: 150 | N37: 90 | O37: =(L37*M37*N37)/10^6 -> 3.24 | P37: =P36 -> 1162.5 | Q37: =P37+300 -> 1462.5 | R37: N | S37: D | U37: P0
B38: 20 | C38: OM4-DE-IS-0009-005 | D38: Normal Bend for Steel Conduit | E38: 82mm (3") X 600Radius | F38: SAMSUNG E&L | G38: Republic of Korea | I38: 75 | J38: EA | P38: =W38*I38 -> 1162.5 | W38: 15.5
B39: Sub-Total | I39: =SUM(I38) -> 75 | K39: Wooden | L39: 240 | M39: 150 | N39: 90 | O39: =(L39*M39*N39)/10^6 -> 3.24 | P39: =P38 -> 1162.5 | Q39: =P39+300 -> 1462.5 | R39: N | S39: D | U39: P0
B40: 21 | C40: OM4-DE-IS-0009-006 | D40: Normal Bend for Steel Conduit | E40: 104mm (4") X 600Radius | F40: SAMSUNG E&L | G40: Republic of Korea | I40: 50 | J40: EA | P40: =W40*I40 -> 1102.5 | W40: 22.05
B41: Sub-Total | I41: =SUM(I40) -> 50 | K41: Wooden | L41: 200 | M41: 150 | N41: 120 | O41: =(L41*M41*N41)/10^6 -> 3.6 | P41: =P40 -> 1102.5 | Q41: =P41+300 -> 1402.5 | R41: N | S41: D | U41: P0
B42: 22 | C42: OM4-DE-IS-0009-007 | D42: Normal Bend for Steel Conduit | E42: 104mm (4") X 600Radius | F42: SAMSUNG E&L | G42: Republic of Korea | I42: 50 | J42: EA | P42: =W42*I42 -> 1102.5 | W42: 22.05
B43: Sub-Total | I43: =SUM(I42) -> 50 | K43: Wooden | L43: 200 | M43: 150 | N43: 120 | O43: =(L43*M43*N43)/10^6 -> 3.6 | P43: =P42 -> 1102.5 | Q43: =P43+300 -> 1402.5 | R43: N | S43: D | U43: P0
B44: 23 | C44: OM4-DE-IS-0009-008 | D44: Normal Bend for Steel Conduit | E44: 125mm (5") X 600Radius | F44: SAMSUNG E&L | G44: Republic of Korea | I44: 50 | J44: EA | P44: =W44*I44 -> 1500 | W44: 30
B45: Sub-Total | I45: =SUM(I44) -> 50 | K45: Wooden | L45: 250 | M45: 150 | N45: 115 | O45: =(L45*M45*N45)/10^6 -> 4.3125 | P45: =P44 -> 1500 | Q45: =P45+300 -> 1800 | R45: N | S45: D | U45: P0
...

Sheet Commercial Invoice
B3: PECC2 Innovation Hub, 45 Street No.2, Truong Tho Ward, Thu Duc City, HCMC, Vietnam Tel: +84-28-2221 6468 | Fax: +84-28-2221 0408
A4: COMMERCIAL INVOICE
A5: SHIPPER: | G5: INVOICE NO. : | H5: OM4-DE-IS-0009
B6: Doosan Enerbility Co., Ltd. 22 DoosanVolvo-ro, Seongsan-gu, Chang-won-si, Gyeongsangnam-do 51711, Republic of Korea | G6: DATE: | H6: 46177
G7: CONTRACT NO. | H7: 06/2025/HĐ-PVN/OM4-06
G8: DATE: | H8: 45814
A9: CONSIGNEE : | G9: SHIPPING MARK
B10: Cty Doosan Enerbility Co.,Ltd HQ-Nha thau TH CV thuoc Goi thau so OM4-EPC-HHO-06 cho NMND O Mon IV Thoi Loi Area, Phuoc Thoi Ward, Can Tho City, Vietnam T : (+84) 367 566 167 F : (+84 243) 624 8485 | G10: O MON IV THERMAL POWER PLANT
A13: NOTIFY PARTY :
B14: Cty Doosan Enerbility Co.,Ltd HQ-Nha thau TH CV thuoc Goi thau so OM4-EPC-HHO-06 cho NMND O Mon IV Thoi Loi Area, Phươc Thoi Ward, Can Tho City, Vietnam T : (+84) 367 566 167 F : (+84 243) 624 8485 BRANCH OF KWANGJIN VIET NAM IN DUNG QUAT Co.,Ltd Dung Quat Economic Zone, Van Tuong Commune, Quang Ngai Province, Vietnam T : (+84) 28 3825 6330 Attn: Mr. Phuoc / Email: phuoc@kjtc.co.kr
G15: SHIPMENT NO. : | H15: =H5 -> OM4-DE-IS-0009
G17: TERM OF DELIVERY : | H17: CIF, Ho Chi Minh City Port, Vietnam
A18: VESSEL NAME : | C18: ETD :
B19: HMM MIRACLE 0020S | D19: 46208 | G19: QUALITY | H19: 100% BRAND NEW
A20: PORT OF LOADING : | C20: PORT OF DISCHARGE : | G20: PAYMENT TERMS: | H20: T/T
B21: Busan International Port, Korea | D21: Ho Chi Minh City Port, Vietnam
A22: BILL OF LADING/ AIRWAY BILL NO. : | C22: B/L DATE :
A24: FINAL DESTINATION :
B25: O MON IV THERMAL POWER PLANT
B26: Address: O Mon Power Complex at Phuoc Thoi wards, Can Tho city
A27: COMMODITY/DESCRIPTION OF GOODS | H27: UNIT | I27: QUANTITY | J27: UNIT PRICE (USD) | K27: AMOUNT (USD)
B28: PLANT/ EQUIPMENT AND MATERIALS FOR O MON IV THERMAL POWER PLANT (Contract No. OM4-PO-DE-001)
B30: Conduit & Accessories included I&C Conduit (Steel Conduit) | H30: EA | I30: =SUM('Packing List (1_2)'!H30:H46) -> 31783 | J30: =ROUND(K30/I30,2) -> 3.89 | K30: ='Break Down CI'!O134 -> 123745.58 | M30: FOB (물품가액)
B33: Number of packages: | D33: 17 | E33: PKGS | M33: Freight | N33: 5108
M34: Insurance | N34: =K30*110%*0.1045% -> 142.24554
B38: TOTAL AMOUNT AT THIS SHIPMENT : | K38: =SUM(K30:K33) -> 123745.58
G45: Signed by
H46: Jinho. Lee / Deputy Project Director

Sheet Break Down CI
B5: ='Commercial Invoice'!G5 -> INVOICE NO. : | C5: ='Commercial Invoice'!H5 -> OM4-DE-IS-0009 | N5: DATE : | P5: ='Commercial Invoice'!H6 -> 46177
A7: SI. No. | B7: Package No. | C7: COMMODITY/DESCRIPTION OF GOODS | E7: C/O of Goods | F7: POSITION IN PRICE SCHEDULE | G7: Quantity | I7: Package Type | J7: NET WEIGHT (KG) | K7: GROSS WEIGHT (KG) | L7: GROSS WEIGHT (KG) | N7: UNIT PRICE (USD) | O7: AMOUNT (USD) | P7: Remark (**)
G8: Nos | H8: Unit | Z8: HS CODE
A9: 1 | B9: OM4-DE-IS-0009-001 | C9: HDG STEEL Conduit | D9: 125mm (5") | E9: Republic of Korea | F9: PS 1.1, Ⅴ, 11 | G9: ='Detailed PL'!I15 -> 32 | H9: EA | I9: Wooden | J9: ='Detailed PL'!P15 -> 1920 | K9: ='Detailed PL'!Q16 -> 2220 | L9: 2220 | M9: =K9-L9 -> 0 | N9: 213.69 | O9: 6838.08 | P9: P0 | R9: 6837.69 | T9: 213.69 | V9: =T9*G9 -> 6838.08 | X9: =R9-V9 -> -0.39 | Z9: 7306.30-2090
A10: 2 | B10: OM4-DE-IS-0009-002 | C10: HDG STEEL Conduit | D10: 125mm (5") | E10: Republic of Korea | F10: PS 1.1, Ⅴ, 11 | G10: ='Detailed PL'!I17 -> 28 | H10: EA | I10: Wooden | J10: ='Detailed PL'!P17 -> 1680 | K10: ='Detailed PL'!Q18 -> 1980 | L10: 1980 | M10: =K10-L10 -> 0 | N10: 213.69 | O10: 5983.32 | P10: P0 | R10: 5982.98 | T10: 213.69 | V10: =T10*G10 -> 5983.32 | X10: =R10-V10 -> -0.34 | Z10: 7306.30-2090
A11: 3 | B11: OM4-DE-IS-0009-003 | C11: Normal Bend for Steel Conduit | D11: 36mm (1-1/4") | E11: Republic of Korea | F11: PS 1.1, Ⅴ, 11 | G11: ='Detailed PL'!I19 -> 250 | H11: EA | I11: Wooden | J11: ='Detailed PL'!P19 -> 322.5 | K11: =J11+(0.29*G11) -> 395 | L11: 395 | M11: =K11-L11 -> 0 | N11: 3.95 | O11: 987.5 | P11: P0 | R11: 986.36 | T11: 3.95 | V11: =T11*G11 -> 987.5 | X11: =R11-V11 -> -1.14 | Z11: 7307.92-9000
A12: 4 | B12: OM4-DE-IS-0009-003 | C12: Normal Bend for Steel Conduit | D12: 42mm (1-1/2") | E12: Republic of Korea | F12: PS 1.1, Ⅴ, 11 | G12: ='Detailed PL'!I20 -> 100 | H12: EA | I12: Wooden | J12: ='Detailed PL'!P20 -> 187 | K12: =J12+(0.29*G12) -> 216 | L12: 216 | M12: =K12-L12 -> 0 | N12: 5.05 | O12: 505 | P12: P0 | R12: 504.69 | T12: 5.05 | V12: =T12*G12 -> 505 | X12: =R12-V12 -> -0.31 | Z12: 7307.92-9000
A13: 5 | B13: OM4-DE-IS-0009-003 | C13: Normal Bend for Steel Conduit | D13: 54mm (2") | E13: Republic of Korea | F13: PS 1.1, Ⅴ, 11 | G13: ='Detailed PL'!I21 -> 60 | H13: EA | I13: Wooden | J13: ='Detailed PL'!P21 -> 175.8 | K13: =J13+(0.29*G13) -> 193.2 | L13: 193.2 | M13: =K13-L13 -> 0 | N13: 7.55 | O13: 453 | P13: P0 | R13: 452.87 | T13: 7.55 | V13: =T13*G13 -> 453 | X13: =R13-V13 -> -0.13 | Z13: 7307.92-9000
A14: 6 | B14: OM4-DE-IS-0009-003 | C14: Coupling for Steel Conduit | D14: 28mm (1") | E14: Republic of Korea | F14: PS 1.1, Ⅴ, 11 | G14: ='Detailed PL'!I22 -> 180 | H14: EA | I14: Wooden | J14: ='Detailed PL'!P22 -> 21.6 | K14: =J14+(0.29*G14) -> 73.8 | L14: 73.8 | M14: =K14-L14 -> 0 | N14: 1.15 | O14: 207 | P14: P0 | R14: 206.39 | T14: 1.15 | V14: =T14*G14 -> 207 | X14: =R14-V14 -> -0.61 | Z14: 7307.92-9000
A15: 7 | B15: OM4-DE-IS-0009-003 | C15: Coupling for Steel Conduit | D15: 36mm (1-1/4") | E15: Republic of Korea | F15: PS 1.1, Ⅴ, 11 | G15: ='Detailed PL'!I23 -> 60 | H15: EA | I15: Wooden | J15: ='Detailed PL'!P23 -> 11.4 | K15: =J15+(0.29*G15) -> 28.8 | L15: 28.8 | M15: =K15-L15 -> 0 | N15: 1.43 | O15: 85.8 | P15: P0 | R15: 85.59 | T15: 1.43 | V15: =T15*G15 -> 85.8 | X15: =R15-V15 -> -0.21 | Z15: 7307.92-9000
A16: 8 | B16: OM4-DE-IS-0009-003 | C16: Coupling for Steel Conduit | D16: 42mm (1-1/2") | E16: Republic of Korea | F16: PS 1.1, Ⅴ, 11 | G16: ='Detailed PL'!I24 -> 30 | H16: EA | I16: Wooden | J16: ='Detailed PL'!P24 -> 6.6 | K16: =J16+(0.29*G16) -> 15.3 | L16: 15.3 | M16: =K16-L16 -> 0 | N16: 1.58 | O16: 47.4 | P16: P0 | R16: 47.67 | T16: 1.58 | V16: =T16*G16 -> 47.4 | X16: =R16-V16 -> 0.27 | Z16: 7307.92-9000
A17: 9 | B17: OM4-DE-IS-0009-003 | C17: Coupling for Steel Conduit | D17: 54mm (2") | E17: Republic of Korea | F17: PS 1.1, Ⅴ, 11 | G17: ='Detailed PL'!I25 -> 30 | H17: EA | I17: Wooden | J17: ='Detailed PL'!P25 -> 9.9 | K17: =J17+(0.29*G17) -> 18.6 | L17: 18.6 | M17: =K17-L17 -> 0 | N17: 2.34 | O17: 70.2 | P17: P0 | R17: 70.15 | T17: 2.34 | V17: =T17*G17 -> 70.2 | X17: =R17-V17 -> -0.05 | Z17: 7307.92-9000
A18: 10 | B18: OM4-DE-IS-0009-003 | C18: Coupling for Steel Conduit | D18: 82mm (3") | E18: Republic of Korea | F18: PS 1.1, Ⅴ, 11 | G18: ='Detailed PL'!I26 -> 40 | H18: EA | I18: Wooden | J18: ='Detailed PL'!P26 -> 39.2 | K18: =J18+(0.29*G18) -> 50.8 | L18: 50.8 | M18: =K18-L18 -> 0 | N18: 5.35 | O18: 214 | P18: P0 | R18: 213.8 | T18: 5.35 | V18: =T18*G18 -> 214 | X18: =R18-V18 -> -0.2 | Z18: 7307.92-9000
A19: 11 | B19: OM4-DE-IS-0009-003 | C19: Coupling for Steel Conduit | D19: 104mm (4") | E19: Republic of Korea | F19: PS 1.1, Ⅴ, 11 | G19: ='Detailed PL'!I27 -> 40 | H19: EA | I19: Wooden | J19: ='Detailed PL'!P27 -> 50 | K19: =J19+(0.29*G19) -> 61.6 | L19: 61.6 | M19: =K19-L19 -> 0 | N19: 7.19 | O19: 287.6 | P19: P0 | R19: 287.47 | T19: 7.19 | V19: =T19*G19 -> 287.6 | X19: =R19-V19 -> -0.13 | Z19: 7307.92-9000
A20: 12 | B20: OM4-DE-IS-0009-003 | C20: HI PVC to Steel Conduit Adaptor | D20: 28mm (1") | E20: Republic of Korea | F20: PS 1.1, Ⅴ, 11 | G20: ='Detailed PL'!I28 -> 80 | H20: EA | I20: Wooden | J20: ='Detailed PL'!P28 -> 9.6 | K20: =J20+(0.29*G20) -> 32.8 | L20: 31.74 | M20: =K20-L20 -> 1.06 | N20: 2.39 | O20: 191.2 | P20: P0 | R20: 191.4 | T20: 2.39 | V20: =T20*G20 -> 191.2 | X20: =R20-V20 -> 0.2 | Z20: 7307.92-9000
A21: 13 | B21: OM4-DE-IS-0009-003 | C21: HI PVC to Steel Conduit Adaptor | D21: 36mm (1-1/4") | E21: Republic of Korea | F21: PS 1.1, Ⅴ, 11 | G21: ='Detailed PL'!I29 -> 50 | H21: EA | I21: Wooden | J21: ='Detailed PL'!P29 -> 9.5 | K21: =J21+(0.29*G21) -> 24 | L21: 22.94 | M21: =K21-L21 -> 1.06 | N21: 3.38 | O21: 169 | P21: P0 | R21: 168.83 | T21: 3.38 | V21: =T21*G21 -> 169 | X21: =R21-V21 -> -0.17 | Z21: 7307.92-9000
A22: 14 | B22: OM4-DE-IS-0009-003 | C22: HI PVC to Steel Conduit Adaptor | D22: 42mm (1-1/2") | E22: Republic of Korea | F22: PS 1.1, Ⅴ, 11 | G22: ='Detailed PL'!I30 -> 30 | H22: EA | I22: Wooden | J22: ='Detailed PL'!P30 -> 6.6 | K22: =J22+(0.29*G22) -> 15.3 | L22: 14.24 | M22: =K22-L22 -> 1.06 | N22: 4.71 | O22: 141.3 | P22: P0 | R22: 141.39 | T22: 4.71 | V22: =T22*G22 -> 141.3 | X22: =R22-V22 -> 0.09 | Z22: 7307.92-9000
... A26: 18 | B26: OM4-DE-IS-0009-003 | C26: HI PVC to Steel Conduit Adaptor | D26: 125mm (5") | E26: Republic of Korea | F26: PS 1.1, Ⅴ, 11 | G26: ='Detailed PL'!I34 -> 40 | H26: EA | I26: Wooden | J26: ='Detailed PL'!P34 -> 120 | K26: =J26+(0.29*G26) -> 131.6 | L26: 130.55 | M26: =K26-L26 -> 1.05 | N26: 20.25 | O26: 810 | P26: P0 | R26: 810.04 | T26: 20.25 | V26: =T26*G26 -> 810 | X26: =R26-V26 -> 0.04 | Z26: 7307.92-9000
A27: 19 | B27: OM4-DE-IS-0009-004 | C27: Normal Bend for Steel Conduit | D27: 82mm (3") X 600Radius | E27: Republic of Korea | F27: PS 1.1, Ⅴ, 11 | G27: ='Detailed PL'!I36 -> 75 | H27: EA | I27: Wooden | J27: ='Detailed PL'!P36 -> 1162.5 | K27: ='Detailed PL'!Q37 -> 1462.5 | L27: 1462.5 | M27: =K27-L27 -> 0 | N27: 52.66 | O27: 3949.5 | P27: P0 | R27: 3948.39 | T27: 52.66 | V27: =T27*G27 -> 3949.5 | X27: =R27-V27 -> -1.11 | Z27: 7307.92-9000
A28: 20 | B28: OM4-DE-IS-0009-005 | C28: Normal Bend for Steel Conduit | D28: 82mm (3") X 600Radius | E28: Republic of Korea | F28: PS 1.1, Ⅴ, 11 | G28: ='Detailed PL'!I38 -> 75 | H28: EA | I28: Wooden | J28: ='Detailed PL'!P38 -> 1162.5 | K28: ='Detailed PL'!Q39 -> 1462.5 | L28: 1462.5 | M28: =K28-L28 -> 0 | N28: 52.65 | O28: 3948.75 | P28: P0 | R28: 3948.39 | T28: 52.65 | V28: =T28*G28 -> 3948.75 | X28: =R28-V28 -> -0.36 | Z28: 7307.92-9000
A29: 21 | B29: OM4-DE-IS-0009-006 | C29: Normal Bend for Steel Conduit | D29: 104mm (4") X 600Radius | E29: Republic of Korea | F29: PS 1.1, Ⅴ, 11 | G29: ='Detailed PL'!I40 -> 50 | H29: EA | I29: Wooden | J29: ='Detailed PL'!P40 -> 1102.5 | K29: ='Detailed PL'!Q41 -> 1402.5 | L29: 1402.5 | M29: =K29-L29 -> 0 | N29: 74.54 | O29: 3727 | P29: P0 | R29: 3726.97 | T29: 74.54 | V29: =T29*G29 -> 3727 | X29: =R29-V29 -> -0.03 | Z29: 7307.92-9000
A30: 22 | B30: OM4-DE-IS-0009-007 | C30: Normal Bend for Steel Conduit | D30: 104mm (4") X 600Radius | E30: Republic of Korea | F30: PS 1.1, Ⅴ, 11 | G30: ='Detailed PL'!I42 -> 50 | H30: EA | I30: Wooden | J30: ='Detailed PL'!P42 -> 1102.5 | K30: ='Detailed PL'!Q43 -> 1402.5 | L30: 1402.5 | M30: =K30-L30 -> 0 | N30: 74.54 | O30: 3727 | P30: P0 | R30: 3726.97 | T30: 74.54 | V30: =T30*G30 -> 3727 | X30: =R30-V30 -> -0.03 | Z30: 7307.92-9000
A31: 23 | B31: OM4-DE-IS-0009-008 | C31: Normal Bend for Steel Conduit | D31: 125mm (5") X 600Radius | E31: Republic of Korea | F31: PS 1.1, Ⅴ, 11 | G31: ='Detailed PL'!I44 -> 50 | H31: EA | I31: Wooden | J31: ='Detailed PL'!P44 -> 1500 | K31: ='Detailed PL'!Q45 -> 1800 | L31: 1800 | M31: =K31-L31 -> 0 | N31: 146.2 | O31: 7310 | P31: P0 | R31: 7309.93 | T31: 146.2 | V31: =T31*G31 -> 7310 | X31: =R31-V31 -> -0.07 | Z31: 7307.92-9000
A32: 24 | B32: OM4-DE-IS-0009-009 | C32: Normal Bend for Steel Conduit | D32: 125mm (5") X 600Radius | E32: Republic of Korea | F32: PS 1.1, Ⅴ, 11 | G32: ='Detailed PL'!I46 -> 50 | H32: EA | I32: Wooden | J32: ='Detailed PL'!P46 -> 1500 | K32: ='Detailed PL'!Q47 -> 1800 | L32: 1800 | M32: =K32-L32 -> 0 | N32: 146.2 | O32: 7310 | P32: P0 | R32: 7309.93 | T32: 146.2 | V32: =T32*G32 -> 7310 | X32: =R32-V32 -> -0.07 | Z32: 7307.92-9000
A33: 25 | B33: OM4-DE-IS-0009-010 | C33: Condulet ("LT" Type) | D33: 28mm (1") | E33: Republic of Korea | F33: PS 1.1, Ⅴ, 11 | G33: ='Detailed PL'!I48 -> 30 | H33: EA | I33: Wooden | J33: ='Detailed PL'!P48 -> 45 | K33: =J33+(0.08*G33) -> 47.4 | L33: 47.4 | M33: =K33-L33 -> 0 | N33: 3.86 | O33: 115.8 | P33: P0 | R33: 115.66 | T33: 3.86 | V33: =T33*G33 -> 115.8 | X33: =R33-V33 -> -0.14 | Z33: 7307.19-0000
A34: 26 | B34: OM4-DE-IS-0009-010 | C34: Condulet ("LT" Type) | D34: 36mm (1-1/4") | E34: Republic of Korea | F34: PS 1.1, Ⅴ, 11 | G34: ='Detailed PL'!I49 -> 30 | H34: EA | I34: Wooden | J34: ='Detailed PL'!P49 -> 54 | K34: =J34+(0.08*G34) -> 56.4 | L34: 56.4 | M34: =K34-L34 -> 0 | N34: 4.88 | O34: 146.4 | P34: P0 | R34: 146.26 | T34: 4.88 | V34: =T34*G34 -> 146.4 | X34: =R34-V34 -> -0.14 | Z34: 7307.19-0000
A35: 27 | B35: OM4-DE-IS-0009-010 | C35: Condulet ("LT" Type) | D35: 42mm (1-1/2") | E35: Republic of Korea | F35: PS 1.1, Ⅴ, 11 | G35: ='Detailed PL'!I50 -> 10 | H35: EA | I35: Wooden | J35: ='Detailed PL'!P50 -> 25 | K35: =J35+(0.08*G35) -> 25.8 | L35: 25.8 | M35: =K35-L35 -> 0 | N35: 6.38 | O35: 63.8 | P35: P0 | R35: 63.83 | T35: 6.38 | V35: =T35*G35 -> 63.8 | X35: =R35-V35 -> 0.03 | Z35: 7307.19-0000
A36: 28 | B36: OM4-DE-IS-0009-010 | C36: Condulet ("LT" Type) | D36: 54mm (2") | E36: Republic of Korea | F36: PS 1.1, Ⅴ, 11 | G36: ='Detailed PL'!I51 -> 15 | H36: EA | I36: Wooden | J36: ='Detailed PL'!P51 -> 52.5 | K36: =J36+(0.08*G36) -> 53.7 | L36: 53.7 | M36: =K36-L36 -> 0 | N36: 8.81 | O36: 132.15 | P36: P0 | R36: 132.18 | T36: 8.81 | V36: =T36*G36 -> 132.15 | X36: =R36-V36 -> 0.03 | Z36: 7307.19-0000
A37: 29 | B37: OM4-DE-IS-0009-010 | C37: Condulet ("LT" Type) | D37: 82mm (3") | E37: Republic of Korea | F37: PS 1.1, Ⅴ, 11 | G37: ='Detailed PL'!I52 -> 15 | H37: EA | I37: Wooden | J37: ='Detailed PL'!P52 -> 99 | K37: =J37+(0.08*G37) -> 100.2 | L37: 100.2 | M37: =K37-L37 -> 0 | N37: 25.1 | O37: 376.5 | P37: P0 | R37: 376.49 | T37: 25.1 | V37: =T37*G37 -> 376.5 | X37: =R37-V37 -> -0.01 | Z37: 7307.19-0000
A38: 30 | B38: OM4-DE-IS-0009-010 | C38: Condulet ("LT" Type) | D38: 104mm (4") | E38: Republic of Korea | F38: PS 1.1, Ⅴ, 11 | G38: ='Detailed PL'!I53 -> 10 | H38: EA | I38: Wooden | J38: ='Detailed PL'!P53 -> 98 | K38: =J38+(0.08*G38) -> 98.8 | L38: 98.8 | M38: =K38-L38 -> 0 | N38: 38.83 | O38: 388.3 | P38: P0 | R38: 388.32 | T38: 38.83 | V38: =T38*G38 -> 388.3 | X38: =R38-V38 -> 0.02 | Z38: 7307.19-0000
A39: 31 | B39: OM4-DE-IS-0009-010 | C39: Flexible Conduit Connector (Male Type) | D39: 28mm (1") | E39: Republic of Korea | F39: PS 1.1, Ⅴ, 11 | G39: ='Detailed PL'!I54 -> 420 | H39: EA | I39: Wooden | J39: ='Detailed PL'!P54 -> 42 | K39: =J39+(0.08*G39) -> 75.6 | L39: 75.6 | M39: =K39-L39 -> 0 | N39: 1.76 | O39: 739.2 | P39: P0 | R39: 739.44 | T39: 1.76 | V39: =T39*G39 -> 739.2 | X39: =R39-V39 -> 0.24 | Z39: 7907.00-2020
A40: 32 | B40: OM4-DE-IS-0009-010 | C40: Flexible Conduit Connector (Male Type) | D40: 36mm (1-1/4") | E40: Republic of Korea | F40: PS 1.1, Ⅴ, 11 | G40: ='Detailed PL'!I55 -> 150 | H40: EA | I40: Wooden | J40: ='Detailed PL'!P55 -> 22.5 | K40: =J40+(0.08*G40) -> 34.5 | L40: 34.5 | M40: =K40-L40 -> 0 | N40: 2.24 | O40: 336 | P40: P0 | R40: 335.86 | T40: 2.24 | V40: =T40*G40 -> 336 | X40: =R40-V40 -> -0.14 | Z40: 7907.00-2020
A41: 33 | B41: OM4-DE-IS-0009-010 | C41: Flexible Conduit Connector (Male Type) | D41: 42mm (1-1/2") | E41: Republic of Korea | F41: PS 1.1, Ⅴ, 11 | G41: ='Detailed PL'!I56 -> 50 | H41: EA | I41: Wooden | J41: ='Detailed PL'!P56 -> 9 | K41: =J41+(0.08*G41) -> 13 | L41: 13 | M41: =K41-L41 -> 0 | N41: 3.03 | O41: 151.5 | P41: P0 | R41: 151.68 | T41: 3.03 | V41: =T41*G41 -> 151.5 | X41: =R41-V41 -> 0.18 | Z41: 7907.00-2020
A42: 34 | B42: OM4-DE-IS-0009-010 | C42: Flexible Conduit Connector (Male Type) | D42: 54mm (2") | E42: Republic of Korea | F42: PS 1.1, Ⅴ, 11 | G42: ='Detailed PL'!I57 -> 30 | H42: EA | I42: Wooden | J42: ='Detailed PL'!P57 -> 8.1 | K42: =J42+(0.08*G42) -> 10.5 | L42: 10.5 | M42: =K42-L42 -> 0 | N42: 4.13 | O42: 123.9 | P42: P0 | R42: 123.78 | T42: 4.13 | V42: =T42*G42 -> 123.9 | X42: =R42-V42 -> -0.12 | Z42: 7907.00-2020
A43: 35 | B43: OM4-DE-IS-0009-010 | C43: Flexible Conduit Connector (Male Type) | D43: 82mm (3") | E43: Republic of Korea | F43: PS 1.1, Ⅴ, 11 | G43: ='Detailed PL'!I58 -> 80 | H43: EA | I43: Wooden | J43: ='Detailed PL'!P58 -> 64 | K43: =J43+(0.08*G43) -> 70.4 | L43: 70.4 | M43: =K43-L43 -> 0 | N43: 11.39 | O43: 911.2 | P43: P0 | R43: 911.52 | T43: 11.39 | V43: =T43*G43 -> 911.2 | X43: =R43-V43 -> 0.32 | Z43: 7907.00-2020
A44: 36 | B44: OM4-DE-IS-0009-010 | C44: Flexible Conduit Connector (Male Type) | D44: 104mm (4") | E44: Republic of Korea | F44: PS 1.1, Ⅴ, 11 | G44: ='Detailed PL'!I59 -> 50 | H44: EA | I44: Wooden | J44: ='Detailed PL'!P59 -> 70 | K44: =J44+(0.08*G44) -> 74 | L44: 74 | M44: =K44-L44 -> 0 | N44: 17.94 | O44: 897 | P44: P0 | R44: 896.98 | T44: 17.94 | V44: =T44*G44 -> 897 | X44: =R44-V44 -> -0.02 | Z44: 7907.00-2020
... A76: 68 | B76: OM4-DE-IS-0009-010 | C76: Flexible Conduit (Water proof type) | D76: 36mm (1-1/4") | E76: Republic of Korea | F76: PS 1.1, Ⅴ, 11 | G76: ='Detailed PL'!I91 -> 330 | H76: M | I76: Wooden | J76: ='Detailed PL'!P91 -> 320.1 | K76: =J76+(0.08*G76) -> 346.5 | L76: 346.5 | M76: =K76-L76 -> 0 | N76: 15.32 | O76: 5055.6 | P76: P0 | R76: 5056.06 | T76: 15.32 | V76: =T76*G76 -> 5055.6 | X76: =R76-V76 -> 0.46 | Z76: 8307.10-0000
A77: 69 | B77: OM4-DE-IS-0009-011 | C77: Flexible Conduit (Water proof type) | D77: 28mm (1") | E77: Republic of Korea | F77: PS 1.1, Ⅴ, 11 | G77: ='Detailed PL'!I93 -> 1000 | H77: M | I77: Wooden | J77: ='Detailed PL'!P93 -> 700 | K77: =J77+(0.23*G77) -> 930 | L77: 928.8 | M77: =K77-L77 -> 1.2 | N77: 1.58 | O77: 1580 | P77: P0 | R77: 1579.99 | T77: 1.58 | V77: =T77*G77 -> 1580 | X77: =R77-V77 -> -0.01 | Z77: 8307.10-0000
A78: 70 | B78: OM4-DE-IS-0009-011 | C78: Flexible Conduit (Water proof type) | D78: 82mm (3") | E78: Republic of Korea | F78: PS 1.1, Ⅴ, 11 | G78: ='Detailed PL'!I94 -> 200 | H78: M | I78: Wooden | J78: ='Detailed PL'!P94 -> 600 | K78: =J78+(0.23*G78) -> 646 | L78: 644.8 | M78: =K78-L78 -> 1.2 | N78: 9.07 | O78: 1814 | P78: P0 | R78: 1811.12 | T78: 9.07 | V78: =T78*G78 -> 1814 | X78: =R78-V78 -> -2.88 | Z78: 8307.10-0000
A79: 71 | B79: OM4-DE-IS-0009-011 | C79: Flexible Conduit (Water proof type) | D79: 104mm (4") | E79: Republic of Korea | F79: PS 1.1, Ⅴ, 11 | G79: ='Detailed PL'!I95 -> 120 | H79: M | I79: Wooden | J79: ='Detailed PL'!P95 -> 540 | K79: =J79+(0.23*G79) -> 567.6 | L79: 566.4 | M79: =K79-L79 -> 1.2 | N79: 11.53 | O79: 1383.6 | P79: P0 | R79: 1383.53 | T79: 11.53 | V79: =T79*G79 -> 1383.6 | X79: =R79-V79 -> -0.07 | Z79: 8307.10-0000
...

Sheet Packing List (1_2)
B3: PECC2 Innovation Hub, 45 Street No.2, Truong Tho Ward, Thu Duc City, HCMC, Vietnam Tel: +84-28-2221 6468 | Fax: +84-28-2221 0408
A4: PACKING LIST(1/2)
A5: SHIPPER: | G5: P/L No. | H5: OM4-DE-IS-0009
B6: Doosan Enerbility Co., Ltd. 22 DoosanVolvo-ro, Seongsan-gu, Chang-won-si, Gyeongsangnam-do 51711, Republic of Korea | G6: DATE: | H6: ='Commercial Invoice'!H6 -> 46177
G7: CONTRACT NO. | H7: 06/2025/HĐ-PVN/OM4-06
G8: DATE: | H8: ='Commercial Invoice'!H8 -> 45814
A9: CONSIGNEE : | G9: =[6]CI!G9 -> SHIPPING MARK
B10: Cty Doosan Enerbility Co.,Ltd HQ-Nha thau TH CV thuoc Goi thau so OM4-EPC-HHO-06 cho NMND O Mon IV Thoi Loi Area, Phuoc Thoi Ward, Can Tho City, Vietnam T : (+84) 367 566 167 F : (+84 243) 624 8485 | G10: O MON IV THERMAL POWER PLANT
A13: NOTIFY PARTY :
B14: Cty Doosan Enerbility Co.,Ltd HQ-Nha thau TH CV thuoc Goi thau so OM4-EPC-HHO-06 cho NMND O Mon IV Thoi Loi Area, Phươc Thoi Ward, Can Tho City, Vietnam T : (+84) 367 566 167 F : (+84 243) 624 8485 BRANCH OF KWANGJIN VIET NAM IN DUNG QUAT Co.,Ltd Dung Quat Economic Zone, Van Tuong Commune, Quang Ngai Province, Vietnam T : (+84) 28 3825 6330 Attn: Mr. Phuoc / Email: phuoc@kjtc.co.kr
G15: SHIPMENT NO. : | H15: =H5 -> OM4-DE-IS-0009
G17: TERM OF DELIVERY : | H17: CIF, Ho Chi Minh City Port, Vietnam
A18: VESSEL NAME : | C18: ETD :
B19: HMM MIRACLE 0020S | D19: 46208 | G19: QUALITY | H19: 100% BRAND NEW
A20: PORT OF LOADING : | C20: PORT OF DISCHARGE :
B21: Busan International Port, Korea | D21: Ho Chi Minh City Port, Vietnam
A22: BILL OF LADING/ AIRWAY BILL NO. : | C22: B/L DATE :
A24: FINAL DESTINATION :
B25: O MON IV THERMAL POWER PLANT
B26: Address: O Mon Power Complex at Phuoc Thoi wards, Can Tho city
A27: COMMODITY/DESCRIPTION OF GOODS | G27: UNIT | H27: QUANTITY | I27: NET WEIGHT (KG) | J27: GROSS WEIGHT (KG) | K27: MEASUREMENT (CBM)
B28: PLANT/ EQUIPMENT AND MATERIALS FOR O MON IV THERMAL POWER PLANT (Contract No. OM4-PO-DE-001)
A29: Conduit & Accessories included I&C Conduit (Steel Conduit)
G30: EA | H30: ='PL(2_2)'!F15 -> 32 | I30: ='PL(2_2)'!M15 -> 1920 | J30: ='PL(2_2)'!N15 -> 2220 | K30: ='PL(2_2)'!L15 -> 6.72
G31: EA | H31: ='PL(2_2)'!F16 -> 28 | I31: ='PL(2_2)'!M16 -> 1680 | J31: ='PL(2_2)'!N16 -> 1980 | K31: ='PL(2_2)'!L16 -> 5.46
G32: EA | H32: ='PL(2_2)'!F17 -> 1060 | I32: ='PL(2_2)'!M17 -> 1042.6 | J32: ='PL(2_2)'!N17 -> 1342.6 | K32: ='PL(2_2)'!L17 -> 3.75
G33: EA | H33: ='PL(2_2)'!F18 -> 75 | I33: ='PL(2_2)'!M18 -> 1162.5 | J33: ='PL(2_2)'!N18 -> 1462.5 | K33: ='PL(2_2)'!L18 -> 3.24
G34: EA | H34: ='PL(2_2)'!F19 -> 75 | I34: ='PL(2_2)'!M19 -> 1162.5 | J34: ='PL(2_2)'!N19 -> 1462.5 | K34: ='PL(2_2)'!L19 -> 3.24
G35: EA | H35: ='PL(2_2)'!F20 -> 50 | I35: ='PL(2_2)'!M20 -> 1102.5 | J35: ='PL(2_2)'!N20 -> 1402.5 | K35: ='PL(2_2)'!L20 -> 3.6
G36: EA | H36: ='PL(2_2)'!F21 -> 50 | I36: ='PL(2_2)'!M21 -> 1102.5 | J36: ='PL(2_2)'!N21 -> 1402.5 | K36: ='PL(2_2)'!L21 -> 3.6
G37: EA | H37: ='PL(2_2)'!F22 -> 50 | I37: ='PL(2_2)'!M22 -> 1500 | J37: ='PL(2_2)'!N22 -> 1800 | K37: ='PL(2_2)'!L22 -> 4.3125
G38: EA | H38: ='PL(2_2)'!F23 -> 50 | I38: ='PL(2_2)'!M23 -> 1500 | J38: ='PL(2_2)'!N23 -> 1800 | K38: ='PL(2_2)'!L23 -> 4.3125
G39: EA | H39: ='PL(2_2)'!F24 -> 3935 | I39: ='PL(2_2)'!M24 -> 1450.5 | J39: ='PL(2_2)'!N24 -> 1750.5 | K39: ='PL(2_2)'!L24 -> 5.6
G40: EA | H40: ='PL(2_2)'!F25 -> 1320 | I40: ='PL(2_2)'!M25 -> 1840 | J40: ='PL(2_2)'!N25 -> 2140 | K40: ='PL(2_2)'!L25 -> 17.556
G41: EA | H41: ='PL(2_2)'!F26 -> 22375 | I41: ='PL(2_2)'!M26 -> 2610.5 | J41: ='PL(2_2)'!N26 -> 2910.5 | K41: ='PL(2_2)'!L26 -> 4.8
... G43: EA | H43: ='PL(2_2)'!F28 -> 1800 | I43: ='PL(2_2)'!M28 -> 1530 | J43: ='PL(2_2)'!N28 -> 1830 | K43: ='PL(2_2)'!L28 -> 2.548
B44: Number of packages: | D44: 17 | E44: PKGS | G44: EA | H44: ='PL(2_2)'!F29 -> 500 | I44: ='PL(2_2)'!M29 -> 3450 | J44: ='PL(2_2)'!N29 -> 3750 | K44: ='PL(2_2)'!L29 -> 4.8
G45: EA | H45: ='PL(2_2)'!F30 -> 150 | I45: ='PL(2_2)'!M30 -> 600 | J45: ='PL(2_2)'!N30 -> 900 | K45: ='PL(2_2)'!L30 -> 2.688
G46: EA | H46: ='PL(2_2)'!F31 -> 153 | I46: ='PL(2_2)'!M31 -> 3931.59 | J46: ='PL(2_2)'!N31 -> 4231.59 | K46: ='PL(2_2)'!L31 -> 4.752
G48: TOTAL | I48: =SUM(I28:I47) -> 29079.24 | J48: =SUM(J28:J47) -> 34179.24 | K48: =SUM(K28:K47) -> 92.243
...

Sheet PL(2_2)
C3: PECC2 Innovation Hub, 45 Street No.2, Truong Tho Ward, Thu Duc City, HCMC, Vietnam Tel: +84-28-2221 6468 | Fax: +84-28-2221 0408
B4: PACKING LIST(2/2)
C5: P/L No. | D5: ='Packing List (1_2)'!H5 -> OM4-DE-IS-0009
C6: Dated | D6: ='Packing List (1_2)'!H6 -> 46177 | I6: * Storage Classification | N6: ** Plant/Equipment/Materials for
C7: Project | D7: O MON IV THERMAL POWER PLANT | I7: "A" | J7: : Indoor with Air conditioning | O7: HRSG | P7: STG | Q7: GTG | R7: BOP
I8: "B" | J8: : Indoor without Air conditioning | N8: Unit 1 | O8: B1 | P8: T1 | Q8: G1 | R8: P2
I9: "C" | J9: : Hazardous Material | N9: Unit 2 | O9: B2 | P9: T2 | Q9: G2 | R9: P2
I10: "D" | J10: : Outdoor with waterproofing | N10: Common | O10: B0 | P10: T0 | Q10: G0 | R10: P0
I11: "E" | J11: : Outdoor without waterproofing
B13: SI. No. | C13: Package No. | D13: Description of Goods | E13: Position in price schedule | F13: Quantity | H13: Package Type | I13: Measurement | M13: Net Weight (kg) | N13: Gross Weight (kg) | O13: Hazardous Material | P13: COG Marked (Y/N) | Q13: Sling Point Marked (Y/N) | R13: Handle with care Marked (Y/N) | S13: Storage Classification (*) | T13: Remark (**)
F14: Nos | G14: Unit | I14: Length (cm) | J14: Width (cm) | K14: Height (cm) | L14: Volume (cbm)
B15: 1 | C15: ='Detailed PL'!C15 -> OM4-DE-IS-0009-001 | D15: HDG STEEL Conduit | F15: ='Detailed PL'!I16 -> 32 | G15: EA | H15: ='Detailed PL'!K16 -> Wooden | I15: ='Detailed PL'!L16 -> 350 | J15: ='Detailed PL'!M16 -> 120 | K15: ='Detailed PL'!N16 -> 160 | L15: ='Detailed PL'!O16 -> 6.72 | M15: ='Detailed PL'!P16 -> 1920 | N15: ='Detailed PL'!Q16 -> 2220 | O15: N | P15: Y | Q15: Y | R15: N | S15: D | T15: P0
B16: 2 | C16: ='Detailed PL'!C17 -> OM4-DE-IS-0009-002 | D16: HDG STEEL Conduit | F16: ='Detailed PL'!I18 -> 28 | G16: EA | H16: ='Detailed PL'!K18 -> Wooden | I16: ='Detailed PL'!L18 -> 350 | J16: ='Detailed PL'!M18 -> 120 | K16: ='Detailed PL'!N18 -> 130 | L16: ='Detailed PL'!O18 -> 5.46 | M16: ='Detailed PL'!P18 -> 1680 | N16: ='Detailed PL'!Q18 -> 1980 | O16: N | P16: Y | Q16: Y | R16: N | S16: D | T16: P0
B17: 3 | C17: ='Detailed PL'!C19 -> OM4-DE-IS-0009-003 | D17: CONDUIT FITTINGS | F17: ='Detailed PL'!I35 -> 1060 | G17: EA | H17: ='Detailed PL'!K35 -> Wooden | I17: ='Detailed PL'!L35 -> 250 | J17: ='Detailed PL'!M35 -> 150 | K17: ='Detailed PL'!N35 -> 100 | L17: ='Detailed PL'!O35 -> 3.75 | M17: ='Detailed PL'!P35 -> 1042.6 | N17: ='Detailed PL'!Q35 -> 1342.6 | O17: N | P17: Y | Q17: Y | R17: N | S17: D | T17: P0
B18: 4 | C18: ='Detailed PL'!C36 -> OM4-DE-IS-0009-004 | D18: CONDUIT FITTINGS (Normal Bend) | F18: ='Detailed PL'!I37 -> 75 | G18: EA | H18: ='Detailed PL'!K37 -> Wooden | I18: ='Detailed PL'!L37 -> 240 | J18: ='Detailed PL'!M37 -> 150 | K18: ='Detailed PL'!N37 -> 90 | L18: ='Detailed PL'!O37 -> 3.24 | M18: ='Detailed PL'!P37 -> 1162.5 | N18: ='Detailed PL'!Q37 -> 1462.5 | O18: N | P18: Y | Q18: Y | R18: N | S18: D | T18: P0
B19: 5 | C19: ='Detailed PL'!C38 -> OM4-DE-IS-0009-005 | D19: CONDUIT FITTINGS (Normal Bend) | F19: ='Detailed PL'!I39 -> 75 | G19: EA | H19: ='Detailed PL'!K39 -> Wooden | I19: ='Detailed PL'!L39 -> 240 | J19: ='Detailed PL'!M39 -> 150 | K19: ='Detailed PL'!N39 -> 90 | L19: ='Detailed PL'!O39 -> 3.24 | M19: ='Detailed PL'!P39 -> 1162.5 | N19: ='Detailed PL'!Q39 -> 1462.5 | O19: N | P19: Y | Q19: Y | R19: N | S19: D | T19: P0
B20: 6 | C20: ='Detailed PL'!C40 -> OM4-DE-IS-0009-006 | D20: CONDUIT FITTINGS (Normal Bend) | F20: ='Detailed PL'!I41 -> 50 | G20: EA | H20: ='Detailed PL'!K41 -> Wooden | I20: ='Detailed PL'!L41 -> 200 | J20: ='Detailed PL'!M41 -> 150 | K20: ='Detailed PL'!N41 -> 120 | L20: ='Detailed PL'!O41 -> 3.6 | M20: ='Detailed PL'!P41 -> 1102.5 | N20: ='Detailed PL'!Q41 -> 1402.5 | O20: N | P20: Y | Q20: Y | R20: N | S20: D | T20: P0
B21: 7 | C21: ='Detailed PL'!C42 -> OM4-DE-IS-0009-007 | D21: CONDUIT FITTINGS (Normal Bend) | F21: ='Detailed PL'!I43 -> 50 | G21: EA | H21: ='Detailed PL'!K43 -> Wooden | I21: ='Detailed PL'!L43 -> 200 | J21: ='Detailed PL'!M43 -> 150 | K21: ='Detailed PL'!N43 -> 120 | L21: ='Detailed PL'!O43 -> 3.6 | M21: ='Detailed PL'!P43 -> 1102.5 | N21: ='Detailed PL'!Q43 -> 1402.5 | O21: N | P21: Y | Q21: Y | R21: N | S21: D | T21: P0
B22: 8 | C22: ='Detailed PL'!C44 -> OM4-DE-IS-0009-008 | D22: CONDUIT FITTINGS (Normal Bend) | F22: ='Detailed PL'!I45 -> 50 | G22: EA | H22: ='Detailed PL'!K45 -> Wooden | I22: ='Detailed PL'!L45 -> 250 | J22: ='Detailed PL'!M45 -> 150 | K22: ='Detailed PL'!N45 -> 115 | L22: ='Detailed PL'!O45 -> 4.3125 | M22: ='Detailed PL'!P45 -> 1500 | N22: ='Detailed PL'!Q45 -> 1800 | O22: N | P22: Y | Q22: Y | R22: N | S22: D | T22: P0
B23: 9 | C23: ='Detailed PL'!C46 -> OM4-DE-IS-0009-009 | D23: CONDUIT FITTINGS (Normal Bend) | F23: ='Detailed PL'!I47 -> 50 | G23: EA | H23: ='Detailed PL'!K47 -> Wooden | I23: ='Detailed PL'!L47 -> 250 | J23: ='Detailed PL'!M47 -> 150 | K23: ='Detailed PL'!N47 -> 115 | L23: ='Detailed PL'!O47 -> 4.3125 | M23: ='Detailed PL'!P47 -> 1500 | N23: ='Detailed PL'!Q47 -> 1800 | O23: N | P23: Y | Q23: Y | R23: N | S23: D | T23: P0
B24: 10 | C24: ='Detailed PL'!C48 -> OM4-DE-IS-0009-010 | D24: CONDUIT FITTINGS | F24: ='Detailed PL'!I92 -> 3935 | G24: EA | H24: ='Detailed PL'!K92 -> Wooden | I24: ='Detailed PL'!L92 -> 200 | J24: ='Detailed PL'!M92 -> 200 | K24: ='Detailed PL'!N92 -> 140 | L24: ='Detailed PL'!O92 -> 5.6 | M24: ='Detailed PL'!P92 -> 1450.5 | N24: ='Detailed PL'!Q92 -> 1750.5 | O24: N | P24: Y | Q24: Y | R24: N | S24: D | T24: P0
B25: 11 | C25: ='Detailed PL'!C93 -> OM4-DE-IS-0009-011 | D25: Flexible Conduit | F25: ='Detailed PL'!I96 -> 1320 | G25: EA | H25: ='Detailed PL'!K96 -> Wooden | I25: ='Detailed PL'!L96 -> 420 | J25: ='Detailed PL'!M96 -> 220 | K25: ='Detailed PL'!N96 -> 190 | L25: ='Detailed PL'!O96 -> 17.556 | M25: ='Detailed PL'!P96 -> 1840 | N25: ='Detailed PL'!Q96 -> 2140 | O25: N | P25: Y | Q25: Y | R25: N | S25: D | T25: P0
B26: 12 | C26: ='Detailed PL'!C97 -> OM4-DE-IS-0009-012 | D26: CONDUIT FITTINGS | F26: ='Detailed PL'!I137 -> 22375 | G26: EA | H26: ='Detailed PL'!K137 -> Wooden | I26: ='Detailed PL'!L137 -> 200 | J26: ='Detailed PL'!M137 -> 200 | K26: ='Detailed PL'!N137 -> 120 | L26: ='Detailed PL'!O137 -> 4.8 | M26: ='Detailed PL'!P137 -> 2610.5 | N26: ='Detailed PL'!Q137 -> 2910.5 | O26: N | P26: Y | Q26: Y | R26: N | S26: D | T26: P0
B27: 13 | C27: ='Detailed PL'!C138 -> OM4-DE-IS-0009-013 | D27: PULL BOX with C-COVER | F27: ='Detailed PL'!I144 -> 80 | G27: EA | H27: ='Detailed PL'!K144 -> Wooden | I27: ='Detailed PL'!L144 -> 320 | J27: ='Detailed PL'!M144 -> 220 | K27: ='Detailed PL'!N144 -> 160 | L27: ='Detailed PL'!O144 -> 11.264 | M27: ='Detailed PL'!P144 -> 1494.05 | N27: ='Detailed PL'!Q144 -> 1794.05 | O27: N | P27: Y | Q27: Y | R27: N | S27: D | T27: P0
B28: 14 | C28: ='Detailed PL'!C145 -> OM4-DE-IS-0009-014 | D28: Post Base single Channel | F28: ='Detailed PL'!I148 -> 1800 | G28: EA | H28: ='Detailed PL'!K148 -> Wooden | I28: ='Detailed PL'!L148 -> 140 | J28: ='Detailed PL'!M148 -> 140 | K28: ='Detailed PL'!N148 -> 130 | L28: ='Detailed PL'!O148 -> 2.548 | M28: ='Detailed PL'!P148 -> 1530 | N28: ='Detailed PL'!Q148 -> 1830 | O28: N | P28: Y | Q28: Y | R28: N | S28: D | T28: P0
B29: 15 | C29: ='Detailed PL'!C149 -> OM4-DE-IS-0009-015 | D29: Unistrut Channel Single | F29: ='Detailed PL'!I150 -> 500 | G29: EA | H29: ='Detailed PL'!K150 -> Wooden | I29: ='Detailed PL'!L150 -> 320 | J29: ='Detailed PL'!M150 -> 120 | K29: ='Detailed PL'!N150 -> 125 | L29: ='Detailed PL'!O150 -> 4.8 | M29: ='Detailed PL'!P150 -> 3450 | N29: ='Detailed PL'!Q150 -> 3750 | O29: N | P29: Y | Q29: Y | R29: N | S29: D | T29: P0
B30: 16 | C30: ='Detailed PL'!C151 -> OM4-DE-IS-0009-016 | D30: Uni-Struct Insert channel | F30: ='Detailed PL'!I153 -> 150 | G30: EA | H30: ='Detailed PL'!K153 -> Wooden | I30: ='Detailed PL'!L153 -> 320 | J30: ='Detailed PL'!M153 -> 120 | K30: ='Detailed PL'!N153 -> 70 | L30: ='Detailed PL'!O153 -> 2.688 | M30: ='Detailed PL'!P153 -> 600 | N30: ='Detailed PL'!Q153 -> 900 | O30: N | P30: Y | Q30: Y | R30: N | S30: D | T30: P0
B31: 17 | C31: ='Detailed PL'!C154 -> OM4-DE-IS-0009-017 | D31: C- Channel | F31: ='Detailed PL'!I156 -> 153 | G31: EA | H31: ='Detailed PL'!K156 -> Wooden | I31: ='Detailed PL'!L156 -> 360 | J31: ='Detailed PL'!M156 -> 120 | K31: ='Detailed PL'!N156 -> 110 | L31: ='Detailed PL'!O156 -> 4.752 | M31: ='Detailed PL'!P156 -> 3931.59 | N31: ='Detailed PL'!Q156 -> 4231.59 | O31: N | P31: Y | Q31: Y | R31: N | S31: D | T31: P0
B32: Grand Total | L32: =SUM(L15:L31) -> 92.243 | M32: =SUM(M15:M31) -> 29079.24 | N32: =SUM(N15:N31) -> 34179.24

Sheet SHIPPING MARK (001)
A1: SHIPPING MARK
A2: O MON IV THERMAL POWER PLANT
A3: =[6]CI!B26 -> Address: O Mon Power Complex at Phuoc Thoi wards, O Mon district, Can Tho city
A5: SHIPPER | B5: : | C5: Doosan Enerbility Co., Ltd.
A6: ADDRESS | B6: : | C6: 22 DoosanVolvo-ro, Seongsan-gu, Chang-won-si, Gyeongsangnam-do 51711, Republic of Korea
A7: CONSIGNEE | B7: : | C7: Cty Doosan Enerbility Co.,Ltd HQ-Nha thau TH CV thuoc Goi thau so OM4-EPC-HHO-06 cho NMND O Mon IV Thoi Loi Area, Phuoc Thoi Ward, Can Tho City, Vietnam T : (+84) 367 566 167 F : (+84 243) 624 8485
A8: NOTIFY PARTY | B8: : | C8: Cty Doosan Enerbility Co.,Ltd HQ-Nha thau TH CV thuoc Goi thau so OM4-EPC-HHO-06 cho NMND O Mon IV Thoi Loi Area, Phươc Thoi Ward, Can Tho City, Vietnam T : (+84) 367 566 167 F : (+84 243) 624 8485 BRANCH OF KWANGJIN VIET NAM IN DUNG QUAT Co.,Ltd Dung Quat Economic Zone, Van Tuong Commune, Quang Ngai Province, Vietnam T : (+84) 28 3825 6330 Attn: Mr. Phuoc / Email: phuoc@kjtc.co.kr
A12: CONTRACT NO. | B12: : | C12: 06/2025/HĐ-PVN/OM4-06
A13: SHIPMENT NO. | B13: : | C13: OM4-DE-IS-0009
A14: EQUIPMENT DESCRIPTION | B14: : | C14: =[6]CI!B28 -> PLANT/ EQUIPMENT AND MATERIALS FOR O MON IV THERMAL
A15: DESCRIPTION OF GOODS | B15: : | C15: ='PL(2_2)'!D15 -> HDG STEEL Conduit | L15: PL(2_2) Sheet 내 내용 반영 필요
A16: CONSIGNOR. | B16: : | C16: SAMSUNG E&L
A17: PACKAGE NO. | B17: : | C17: ='PL(2_2)'!C15 -> OM4-DE-IS-0009-001
A18: NET WEIGHT | B18: : | C18: ='PL(2_2)'!M15 -> 1920 | D18: KG
A19: GROSS WEIGHT | B19: : | C19: ='PL(2_2)'!N15 -> 2220 | D19: KG
A20: - MEASUREMENT | B20: : | C20: ='PL(2_2)'!I15 -> 350 | D20: cm(L) X | E20: ='PL(2_2)'!J15 -> 120 | F20: cm (W) X | G20: ='PL(2_2)'!K15 -> 160 | H20: cm (H) | I20: ='PL(2_2)'!L15 -> 6.72 | J20: CBM
A21: LOADING PORT | B21: : | C21: ='Packing List (1_2)'!B21 -> Busan International Port, Korea
A22: PORT OF DESTINATION | B22: : | C22: Ho Chi Minh City Port, Vietnam
A23: COUNTRY OF ORIGIN | B23: : | C23: Republic of Korea
A24: QUALITY | B24: : | C24: 100% BRAND NEW

Sheet SHIPPING MARK (002)
A1: SHIPPING MARK
A2: O MON IV THERMAL POWER PLANT
A3: =[6]CI!B26 -> Address: O Mon Power Complex at Phuoc Thoi wards, O Mon district, Can Tho city
A5: SHIPPER | B5: : | C5: Doosan Enerbility Co., Ltd.
A6: ADDRESS | B6: : | C6: 22 DoosanVolvo-ro, Seongsan-gu, Chang-won-si, Gyeongsangnam-do 51711, Republic of Korea
A7: CONSIGNEE | B7: : | C7: Cty Doosan Enerbility Co.,Ltd HQ-Nha thau TH CV thuoc Goi thau so OM4-EPC-HHO-06 cho NMND O Mon IV Thoi Loi Area, Phuoc Thoi Ward, Can Tho City, Vietnam T : (+84) 367 566 167 F : (+84 243) 624 8485
A8: NOTIFY PARTY | B8: : | C8: Cty Doosan Enerbility Co.,Ltd HQ-Nha thau TH CV thuoc Goi thau so OM4-EPC-HHO-06 cho NMND O Mon IV Thoi Loi Area, Phươc Thoi Ward, Can Tho City, Vietnam T : (+84) 367 566 167 F : (+84 243) 624 8485 BRANCH OF KWANGJIN VIET NAM IN DUNG QUAT Co.,Ltd Dung Quat Economic Zone, Van Tuong Commune, Quang Ngai Province, Vietnam T : (+84) 28 3825 6330 Attn: Mr. Phuoc / Email: phuoc@kjtc.co.kr
A12: CONTRACT NO. | B12: : | C12: 06/2025/HĐ-PVN/OM4-06
A13: SHIPMENT NO. | B13: : | C13: OM4-DE-IS-0009
A14: EQUIPMENT DESCRIPTION | B14: : | C14: =[6]CI!B28 -> PLANT/ EQUIPMENT AND MATERIALS FOR O MON IV THERMAL
A15: DESCRIPTION OF GOODS | B15: : | C15: ='PL(2_2)'!D16 -> HDG STEEL Conduit | L15: PL(2_2) Sheet 내 내용 반영 필요
A16: CONSIGNOR. | B16: : | C16: SAMSUNG E&L
A17: PACKAGE NO. | B17: : | C17: ='PL(2_2)'!C16 -> OM4-DE-IS-0009-002
A18: NET WEIGHT | B18: : | C18: ='PL(2_2)'!M16 -> 1680 | D18: KG
A19: GROSS WEIGHT | B19: : | C19: ='PL(2_2)'!N16 -> 1980 | D19: KG
A20: - MEASUREMENT | B20: : | C20: ='PL(2_2)'!I16 -> 350 | D20: cm(L) X | E20: ='PL(2_2)'!J16 -> 120 | F20: cm (W) X | G20: ='PL(2_2)'!K16 -> 130 | H20: cm (H) | I20: ='PL(2_2)'!L16 -> 5.46 | J20: CBM
A21: LOADING PORT | B21: : | C21: ='Packing List (1_2)'!B21 -> Busan International Port, Korea
A22: PORT OF DESTINATION | B22: : | C22: Ho Chi Minh City Port, Vietnam
A23: COUNTRY OF ORIGIN | B23: : | C23: Republic of Korea
A24: QUALITY | B24: : | C24: 100% BRAND NEW

Sheet SHIPPING MARK (003)
A1: SHIPPING MARK
A2: O MON IV THERMAL POWER PLANT
A3: =[6]CI!B26 -> Address: O Mon Power Complex at Phuoc Thoi wards, O Mon district, Can Tho city
A5: SHIPPER | B5: : | C5: Doosan Enerbility Co., Ltd.
A6: ADDRESS | B6: : | C6: 22 DoosanVolvo-ro, Seongsan-gu, Chang-won-si, Gyeongsangnam-do 51711, Republic of Korea
A7: CONSIGNEE | B7: : | C7: Cty Doosan Enerbility Co.,Ltd HQ-Nha thau TH CV thuoc Goi thau so OM4-EPC-HHO-06 cho NMND O Mon IV Thoi Loi Area, Phuoc Thoi Ward, Can Tho City, Vietnam T : (+84) 367 566 167 F : (+84 243) 624 8485
A8: NOTIFY PARTY | B8: : | C8: Cty Doosan Enerbility Co.,Ltd HQ-Nha thau TH CV thuoc Goi thau so OM4-EPC-HHO-06 cho NMND O Mon IV Thoi Loi Area, Phươc Thoi Ward, Can Tho City, Vietnam T : (+84) 367 566 167 F : (+84 243) 624 8485 BRANCH OF KWANGJIN VIET NAM IN DUNG QUAT Co.,Ltd Dung Quat Economic Zone, Van Tuong Commune, Quang Ngai Province, Vietnam T : (+84) 28 3825 6330 Attn: Mr. Phuoc / Email: phuoc@kjtc.co.kr
A12: CONTRACT NO. | B12: : | C12: 06/2025/HĐ-PVN/OM4-06
A13: SHIPMENT NO. | B13: : | C13: OM4-DE-IS-0009
A14: EQUIPMENT DESCRIPTION | B14: : | C14: =[6]CI!B28 -> PLANT/ EQUIPMENT AND MATERIALS FOR O MON IV THERMAL
A15: DESCRIPTION OF GOODS | B15: : | C15: ='PL(2_2)'!D17 -> CONDUIT FITTINGS | L15: PL(2_2) Sheet 내 내용 반영 필요
A16: CONSIGNOR. | B16: : | C16: SAMSUNG E&L
A17: PACKAGE NO. | B17: : | C17: ='PL(2_2)'!C17 -> OM4-DE-IS-0009-003
A18: NET WEIGHT | B18: : | C18: ='PL(2_2)'!M17 -> 1042.6 | D18: KG
A19: GROSS WEIGHT | B19: : | C19: ='PL(2_2)'!N17 -> 1342.6 | D19: KG
A20: - MEASUREMENT | B20: : | C20: ='PL(2_2)'!I17 -> 250 | D20: cm(L) X | E20: ='PL(2_2)'!J17 -> 150 | F20: cm (W) X | G20: ='PL(2_2)'!K17 -> 100 | H20: cm (H) | I20: ='PL(2_2)'!L17 -> 3.75 | J20: CBM
A21: LOADING PORT | B21: : | C21: ='Packing List (1_2)'!B21 -> Busan International Port, Korea
A22: PORT OF DESTINATION | B22: : | C22: Ho Chi Minh City Port, Vietnam
A23: COUNTRY OF ORIGIN | B23: : | C23: Republic of Korea
A24: QUALITY | B24: : | C24: 100% BRAND NEW

Sheet SHIPPING MARK (004)
A1: SHIPPING MARK
A2: O MON IV THERMAL POWER PLANT
A3: =[6]CI!B26 -> Address: O Mon Power Complex at Phuoc Thoi wards, O Mon district, Can Tho city
A5: SHIPPER | B5: : | C5: Doosan Enerbility Co., Ltd.
A6: ADDRESS | B6: : | C6: 22 DoosanVolvo-ro, Seongsan-gu, Chang-won-si, Gyeongsangnam-do 51711, Republic of Korea
A7: CONSIGNEE | B7: : | C7: Cty Doosan Enerbility Co.,Ltd HQ-Nha thau TH CV thuoc Goi thau so OM4-EPC-HHO-06 cho NMND O Mon IV Thoi Loi Area, Phuoc Thoi Ward, Can Tho City, Vietnam T : (+84) 367 566 167 F : (+84 243) 624 8485
A8: NOTIFY PARTY | B8: : | C8: Cty Doosan Enerbility Co.,Ltd HQ-Nha thau TH CV thuoc Goi thau so OM4-EPC-HHO-06 cho NMND O Mon IV Thoi Loi Area, Phươc Thoi Ward, Can Tho City, Vietnam T : (+84) 367 566 167 F : (+84 243) 624 8485 BRANCH OF KWANGJIN VIET NAM IN DUNG QUAT Co.,Ltd Dung Quat Economic Zone, Van Tuong Commune, Quang Ngai Province, Vietnam T : (+84) 28 3825 6330 Attn: Mr. Phuoc / Email: phuoc@kjtc.co.kr
A12: CONTRACT NO. | B12: : | C12: 06/2025/HĐ-PVN/OM4-06
A13: SHIPMENT NO. | B13: : | C13: OM4-DE-IS-0009
A14: EQUIPMENT DESCRIPTION | B14: : | C14: =[6]CI!B28 -> PLANT/ EQUIPMENT AND MATERIALS FOR O MON IV THERMAL
A15: DESCRIPTION OF GOODS | B15: : | C15: ='PL(2_2)'!D18 -> CONDUIT FITTINGS (Normal Bend) | L15: PL(2_2) Sheet 내 내용 반영 필요
A16: CONSIGNOR. | B16: : | C16: SAMSUNG E&L
A17: PACKAGE NO. | B17: : | C17: ='PL(2_2)'!C18 -> OM4-DE-IS-0009-004
A18: NET WEIGHT | B18: : | C18: ='PL(2_2)'!M18 -> 1162.5 | D18: KG
A19: GROSS WEIGHT | B19: : | C19: ='PL(2_2)'!N18 -> 1462.5 | D19: KG
A20: - MEASUREMENT | B20: : | C20: ='PL(2_2)'!I18 -> 240 | D20: cm(L) X | E20: ='PL(2_2)'!J18 -> 150 | F20: cm (W) X | G20: ='PL(2_2)'!K18 -> 90 | H20: cm (H) | I20: ='PL(2_2)'!L18 -> 3.24 | J20: CBM
A21: LOADING PORT | B21: : | C21: ='Packing List (1_2)'!B21 -> Busan International Port, Korea
A22: PORT OF DESTINATION | B22: : | C22: Ho Chi Minh City Port, Vietnam
A23: COUNTRY OF ORIGIN | B23: : | C23: Republic of Korea
A24: QUALITY | B24: : | C24: 100% BRAND NEW

Sheet SHIPPING MARK (005)
A1: SHIPPING MARK
A2: O MON IV THERMAL POWER PLANT
A3: =[6]CI!B26 -> Address: O Mon Power Complex at Phuoc Thoi wards, O Mon district, Can Tho city
A5: SHIPPER | B5: : | C5: Doosan Enerbility Co., Ltd.
A6: ADDRESS | B6: : | C6: 22 DoosanVolvo-ro, Seongsan-gu, Chang-won-si, Gyeongsangnam-do 51711, Republic of Korea
A7: CONSIGNEE | B7: : | C7: Cty Doosan Enerbility Co.,Ltd HQ-Nha thau TH CV thuoc Goi thau so OM4-EPC-HHO-06 cho NMND O Mon IV Thoi Loi Area, Phuoc Thoi Ward, Can Tho City, Vietnam T : (+84) 367 566 167 F : (+84 243) 624 8485
A8: NOTIFY PARTY | B8: : | C8: Cty Doosan Enerbility Co.,Ltd HQ-Nha thau TH CV thuoc Goi thau so OM4-EPC-HHO-06 cho NMND O Mon IV Thoi Loi Area, Phươc Thoi Ward, Can Tho City, Vietnam T : (+84) 367 566 167 F : (+84 243) 624 8485 BRANCH OF KWANGJIN VIET NAM IN DUNG QUAT Co.,Ltd Dung Quat Economic Zone, Van Tuong Commune, Quang Ngai Province, Vietnam T : (+84) 28 3825 6330 Attn: Mr. Phuoc / Email: phuoc@kjtc.co.kr
A12: CONTRACT NO. | B12: : | C12: 06/2025/HĐ-PVN/OM4-06
A13: SHIPMENT NO. | B13: : | C13: OM4-DE-IS-0009
A14: EQUIPMENT DESCRIPTION | B14: : | C14: =[6]CI!B28 -> PLANT/ EQUIPMENT AND MATERIALS FOR O MON IV THERMAL
A15: DESCRIPTION OF GOODS | B15: : | C15: ='PL(2_2)'!D19 -> CONDUIT FITTINGS (Normal Bend) | L15: PL(2_2) Sheet 내 내용 반영 필요
A16: CONSIGNOR. | B16: : | C16: SAMSUNG E&L
A17: PACKAGE NO. | B17: : | C17: ='PL(2_2)'!C19 -> OM4-DE-IS-0009-005
A18: NET WEIGHT | B18: : | C18: ='PL(2_2)'!M19 -> 1162.5 | D18: KG
A19: GROSS WEIGHT | B19: : | C19: ='PL(2_2)'!N19 -> 1462.5 | D19: KG
A20: - MEASUREMENT | B20: : | C20: ='PL(2_2)'!I19 -> 240 | D20: cm(L) X | E20: ='PL(2_2)'!J19 -> 150 | F20: cm (W) X | G20: ='PL(2_2)'!K19 -> 90 | H20: cm (H) | I20: ='PL(2_2)'!L19 -> 3.24 | J20: CBM
A21: LOADING PORT | B21: : | C21: ='Packing List (1_2)'!B21 -> Busan International Port, Korea
A22: PORT OF DESTINATION | B22: : | C22: Ho Chi Minh City Port, Vietnam
A23: COUNTRY OF ORIGIN | B23: : | C23: Republic of Korea
A24: QUALITY | B24: : | C24: 100% BRAND NEW

Sheet SHIPPING MARK (006)
A1: SHIPPING MARK
A2: O MON IV THERMAL POWER PLANT
A3: =[6]CI!B26 -> Address: O Mon Power Complex at Phuoc Thoi wards, O Mon district, Can Tho city
A5: SHIPPER | B5: : | C5: Doosan Enerbility Co., Ltd.
A6: ADDRESS | B6: : | C6: 22 DoosanVolvo-ro, Seongsan-gu, Chang-won-si, Gyeongsangnam-do 51711, Republic of Korea
A7: CONSIGNEE | B7: : | C7: Cty Doosan Enerbility Co.,Ltd HQ-Nha thau TH CV thuoc Goi thau so OM4-EPC-HHO-06 cho NMND O Mon IV Thoi Loi Area, Phuoc Thoi Ward, Can Tho City, Vietnam T : (+84) 367 566 167 F : (+84 243) 624 8485
A8: NOTIFY PARTY | B8: : | C8: Cty Doosan Enerbility Co.,Ltd HQ-Nha thau TH CV thuoc Goi thau so OM4-EPC-HHO-06 cho NMND O Mon IV Thoi Loi Area, Phươc Thoi Ward, Can Tho City, Vietnam T : (+84) 367 566 167 F : (+84 243) 624 8485 BRANCH OF KWANGJIN VIET NAM IN DUNG QUAT Co.,Ltd Dung Quat Economic Zone, Van Tuong Commune, Quang Ngai Province, Vietnam T : (+84) 28 3825 6330 Attn: Mr. Phuoc / Email: phuoc@kjtc.co.kr
A12: CONTRACT NO. | B12: : | C12: 06/2025/HĐ-PVN/OM4-06
A13: SHIPMENT NO. | B13: : | C13: OM4-DE-IS-0009
A14: EQUIPMENT DESCRIPTION | B14: : | C14: =[6]CI!B28 -> PLANT/ EQUIPMENT AND MATERIALS FOR O MON IV THERMAL
A15: DESCRIPTION OF GOODS | B15: : | C15: ='PL(2_2)'!D20 -> CONDUIT FITTINGS (Normal Bend) | L15: PL(2_2) Sheet 내 내용 반영 필요
A16: CONSIGNOR. | B16: : | C16: SAMSUNG E&L
A17: PACKAGE NO. | B17: : | C17: ='PL(2_2)'!C20 -> OM4-DE-IS-0009-006
A18: NET WEIGHT | B18: : | C18: ='PL(2_2)'!M20 -> 1102.5 | D18: KG
A19: GROSS WEIGHT | B19: : | C19: ='PL(2_2)'!N20 -> 1402.5 | D19: KG
A20: - MEASUREMENT | B20: : | C20: ='PL(2_2)'!I20 -> 200 | D20: cm(L) X | E20: ='PL(2_2)'!J20 -> 150 | F20: cm (W) X | G20: ='PL(2_2)'!K20 -> 120 | H20: cm (H) | I20: ='PL(2_2)'!L20 -> 3.6 | J20: CBM
A21: LOADING PORT | B21: : | C21: ='Packing List (1_2)'!B21 -> Busan International Port, Korea
A22: PORT OF DESTINATION | B22: : | C22: Ho Chi Minh City Port, Vietnam
A23: COUNTRY OF ORIGIN | B23: : | C23: Republic of Korea
A24: QUALITY | B24: : | C24: 100% BRAND NEW

Sheet SHIPPING MARK (007)
A1: SHIPPING MARK
A2: O MON IV THERMAL POWER PLANT
A3: =[6]CI!B26 -> Address: O Mon Power Complex at Phuoc Thoi wards, O Mon district, Can Tho city
A5: SHIPPER | B5: : | C5: Doosan Enerbility Co., Ltd.
A6: ADDRESS | B6: : | C6: 22 DoosanVolvo-ro, Seongsan-gu, Chang-won-si, Gyeongsangnam-do 51711, Republic of Korea
A7: CONSIGNEE | B7: : | C7: Cty Doosan Enerbility Co.,Ltd HQ-Nha thau TH CV thuoc Goi thau so OM4-EPC-HHO-06 cho NMND O Mon IV Thoi Loi Area, Phuoc Thoi Ward, Can Tho City, Vietnam T : (+84) 367 566 167 F : (+84 243) 624 8485
A8: NOTIFY PARTY | B8: : | C8: Cty Doosan Enerbility Co.,Ltd HQ-Nha thau TH CV thuoc Goi thau so OM4-EPC-HHO-06 cho NMND O Mon IV Thoi Loi Area, Phươc Thoi Ward, Can Tho City, Vietnam T : (+84) 367 566 167 F : (+84 243) 624 8485 BRANCH OF KWANGJIN VIET NAM IN DUNG QUAT Co.,Ltd Dung Quat Economic Zone, Van Tuong Commune, Quang Ngai Province, Vietnam T : (+84) 28 3825 6330 Attn: Mr. Phuoc / Email: phuoc@kjtc.co.kr
A12: CONTRACT NO. | B12: : | C12: 06/2025/HĐ-PVN/OM4-06
A13: SHIPMENT NO. | B13: : | C13: OM4-DE-IS-0009
A14: EQUIPMENT DESCRIPTION | B14: : | C14: =[6]CI!B28 -> PLANT/ EQUIPMENT AND MATERIALS FOR O MON IV THERMAL
A15: DESCRIPTION OF GOODS | B15: : | C15: ='PL(2_2)'!D21 -> CONDUIT FITTINGS (Normal Bend) | L15: PL(2_2) Sheet 내 내용 반영 필요
A16: CONSIGNOR. | B16: : | C16: SAMSUNG E&L
A17: PACKAGE NO. | B17: : | C17: ='PL(2_2)'!C21 -> OM4-DE-IS-0009-007
A18: NET WEIGHT | B18: : | C18: ='PL(2_2)'!M21 -> 1102.5 | D18: KG
A19: GROSS WEIGHT | B19: : | C19: ='PL(2_2)'!N21 -> 1402.5 | D19: KG
A20: - MEASUREMENT | B20: : | C20: ='PL(2_2)'!I21 -> 200 | D20: cm(L) X | E20: ='PL(2_2)'!J21 -> 150 | F20: cm (W) X | G20: ='PL(2_2)'!K21 -> 120 | H20: cm (H) | I20: ='PL(2_2)'!L21 -> 3.6 | J20: CBM
A21: LOADING PORT | B21: : | C21: ='Packing List (1_2)'!B21 -> Busan International Port, Korea
A22: PORT OF DESTINATION | B22: : | C22: Ho Chi Minh City Port, Vietnam
A23: COUNTRY OF ORIGIN | B23: : | C23: Republic of Korea
A24: QUALITY | B24: : | C24: 100% BRAND NEW

Sheet SHIPPING MARK (008)
A1: SHIPPING MARK
A2: O MON IV THERMAL POWER PLANT
A3: =[6]CI!B26 -> Address: O Mon Power Complex at Phuoc Thoi wards, O Mon district, Can Tho city
A5: SHIPPER | B5: : | C5: Doosan Enerbility Co., Ltd.
A6: ADDRESS | B6: : | C6: 22 DoosanVolvo-ro, Seongsan-gu, Chang-won-si, Gyeongsangnam-do 51711, Republic of Korea
A7: CONSIGNEE | B7: : | C7: Cty Doosan Enerbility Co.,Ltd HQ-Nha thau TH CV thuoc Goi thau so OM4-EPC-HHO-06 cho NMND O Mon IV Thoi Loi Area, Phuoc Thoi Ward, Can Tho City, Vietnam T : (+84) 367 566 167 F : (+84 243) 624 8485
A8: NOTIFY PARTY | B8: : | C8: Cty Doosan Enerbility Co.,Ltd HQ-Nha thau TH CV thuoc Goi thau so OM4-EPC-HHO-06 cho NMND O Mon IV Thoi Loi Area, Phươc Thoi Ward, Can Tho City, Vietnam T : (+84) 367 566 167 F : (+84 243) 624 8485 BRANCH OF KWANGJIN VIET NAM IN DUNG QUAT Co.,Ltd Dung Quat Economic Zone, Van Tuong Commune, Quang Ngai Province, Vietnam T : (+84) 28 3825 6330 Attn: Mr. Phuoc / Email: phuoc@kjtc.co.kr
A12: CONTRACT NO. | B12: : | C12: 06/2025/HĐ-PVN/OM4-06
A13: SHIPMENT NO. | B13: : | C13: OM4-DE-IS-0009
A14: EQUIPMENT DESCRIPTION | B14: : | C14: =[6]CI!B28 -> PLANT/ EQUIPMENT AND MATERIALS FOR O MON IV THERMAL
A15: DESCRIPTION OF GOODS | B15: : | C15: ='PL(2_2)'!D22 -> CONDUIT FITTINGS (Normal Bend) | L15: PL(2_2) Sheet 내 내용 반영 필요
A16: CONSIGNOR. | B16: : | C16: SAMSUNG E&L
A17: PACKAGE NO. | B17: : | C17: ='PL(2_2)'!C22 -> OM4-DE-IS-0009-008
A18: NET WEIGHT | B18: : | C18: ='PL(2_2)'!M22 -> 1500 | D18: KG
A19: GROSS WEIGHT | B19: : | C19: ='PL(2_2)'!N22 -> 1800 | D19: KG
A20: - MEASUREMENT | B20: : | C20: ='PL(2_2)'!I22 -> 250 | D20: cm(L) X | E20: ='PL(2_2)'!J22 -> 150 | F20: cm (W) X | G20: ='PL(2_2)'!K22 -> 115 | H20: cm (H) | I20: ='PL(2_2)'!L22 -> 4.3125 | J20: CBM
A21: LOADING PORT | B21: : | C21: ='Packing List (1_2)'!B21 -> Busan International Port, Korea
A22: PORT OF DESTINATION | B22: : | C22: Ho Chi Minh City Port, Vietnam
A23: COUNTRY OF ORIGIN | B23: : | C23: Republic of Korea
A24: QUALITY | B24: : | C24: 100% BRAND NEW

Sheet SHIPPING MARK (009)
A1: SHIPPING MARK
A2: O MON IV THERMAL POWER PLANT
A3: =[6]CI!B26 -> Address: O Mon Power Complex at Phuoc Thoi wards, O Mon district, Can Tho city
A5: SHIPPER | B5: : | C5: Doosan Enerbility Co., Ltd.
A6: ADDRESS | B6: : | C6: 22 DoosanVolvo-ro, Seongsan-gu, Chang-won-si, Gyeongsangnam-do 51711, Republic of Korea
A7: CONSIGNEE | B7: : | C7: Cty Doosan Enerbility Co.,Ltd HQ-Nha thau TH CV thuoc Goi thau so OM4-EPC-HHO-06 cho NMND O Mon IV Thoi Loi Area, Phuoc Thoi Ward, Can Tho City, Vietnam T : (+84) 367 566 167 F : (+84 243) 624 8485
A8: NOTIFY PARTY | B8: : | C8: Cty Doosan Enerbility Co.,Ltd HQ-Nha thau TH CV thuoc Goi thau so OM4-EPC-HHO-06 cho NMND O Mon IV Thoi Loi Area, Phươc Thoi Ward, Can Tho City, Vietnam T : (+84) 367 566 167 F : (+84 243) 624 8485 BRANCH OF KWANGJIN VIET NAM IN DUNG QUAT Co.,Ltd Dung Quat Economic Zone, Van Tuong Commune, Quang Ngai Province, Vietnam T : (+84) 28 3825 6330 Attn: Mr. Phuoc / Email: phuoc@kjtc.co.kr
A12: CONTRACT NO. | B12: : | C12: 06/2025/HĐ-PVN/OM4-06
A13: SHIPMENT NO. | B13: : | C13: OM4-DE-IS-0009
A14: EQUIPMENT DESCRIPTION | B14: : | C14: =[6]CI!B28 -> PLANT/ EQUIPMENT AND MATERIALS FOR O MON IV THERMAL
A15: DESCRIPTION OF GOODS | B15: : | C15: ='PL(2_2)'!D23 -> CONDUIT FITTINGS (Normal Bend) | L15: PL(2_2) Sheet 내 내용 반영 필요
A16: CONSIGNOR. | B16: : | C16: SAMSUNG E&L
A17: PACKAGE NO. | B17: : | C17: ='PL(2_2)'!C23 -> OM4-DE-IS-0009-009
A18: NET WEIGHT | B18: : | C18: ='PL(2_2)'!M23 -> 1500 | D18: KG
A19: GROSS WEIGHT | B19: : | C19: ='PL(2_2)'!N23 -> 1800 | D19: KG
A20: - MEASUREMENT | B20: : | C20: ='PL(2_2)'!I23 -> 250 | D20: cm(L) X | E20: ='PL(2_2)'!J23 -> 150 | F20: cm (W) X | G20: ='PL(2_2)'!K23 -> 115 | H20: cm (H) | I20: ='PL(2_2)'!L23 -> 4.3125 | J20: CBM
A21: LOADING PORT | B21: : | C21: ='Packing List (1_2)'!B21 -> Busan International Port, Korea
A22: PORT OF DESTINATION | B22: : | C22: Ho Chi Minh City Port, Vietnam
A23: COUNTRY OF ORIGIN | B23: : | C23: Republic of Korea
A24: QUALITY | B24: : | C24: 100% BRAND NEW

Sheet SHIPPING MARK (010)
A1: SHIPPING MARK
A2: O MON IV THERMAL POWER PLANT
A3: =[6]CI!B26 -> Address: O Mon Power Complex at Phuoc Thoi wards, O Mon district, Can Tho city
A5: SHIPPER | B5: : | C5: Doosan Enerbility Co., Ltd.
A6: ADDRESS | B6: : | C6: 22 DoosanVolvo-ro, Seongsan-gu, Chang-won-si, Gyeongsangnam-do 51711, Republic of Korea
A7: CONSIGNEE | B7: : | C7: Cty Doosan Enerbility Co.,Ltd HQ-Nha thau TH CV thuoc Goi thau so OM4-EPC-HHO-06 cho NMND O Mon IV Thoi Loi Area, Phuoc Thoi Ward, Can Tho City, Vietnam T : (+84) 367 566 167 F : (+84 243) 624 8485
A8: NOTIFY PARTY | B8: : | C8: Cty Doosan Enerbility Co.,Ltd HQ-Nha thau TH CV thuoc Goi thau so OM4-EPC-HHO-06 cho NMND O Mon IV Thoi Loi Area, Phươc Thoi Ward, Can Tho City, Vietnam T : (+84) 367 566 167 F : (+84 243) 624 8485 BRANCH OF KWANGJIN VIET NAM IN DUNG QUAT Co.,Ltd Dung Quat Economic Zone, Van Tuong Commune, Quang Ngai Province, Vietnam T : (+84) 28 3825 6330 Attn: Mr. Phuoc / Email: phuoc@kjtc.co.kr
A12: CONTRACT NO. | B12: : | C12: 06/2025/HĐ-PVN/OM4-06
A13: SHIPMENT NO. | B13: : | C13: OM4-DE-IS-0009
A14: EQUIPMENT DESCRIPTION | B14: : | C14: =[6]CI!B28 -> PLANT/ EQUIPMENT AND MATERIALS FOR O MON IV THERMAL
A15: DESCRIPTION OF GOODS | B15: : | C15: ='PL(2_2)'!D24 -> CONDUIT FITTINGS | L15: PL(2_2) Sheet 내 내용 반영 필요
A16: CONSIGNOR. | B16: : | C16: SAMSUNG E&L
A17: PACKAGE NO. | B17: : | C17: ='PL(2_2)'!C24 -> OM4-DE-IS-0009-010
A18: NET WEIGHT | B18: : | C18: ='PL(2_2)'!M24 -> 1450.5 | D18: KG
A19: GROSS WEIGHT | B19: : | C19: ='PL(2_2)'!N24 -> 1750.5 | D19: KG
A20: - MEASUREMENT | B20: : | C20: ='PL(2_2)'!I24 -> 200 | D20: cm(L) X | E20: ='PL(2_2)'!J24 -> 200 | F20: cm (W) X | G20: ='PL(2_2)'!K24 -> 140 | H20: cm (H) | I20: ='PL(2_2)'!L24 -> 5.6 | J20: CBM
A21: LOADING PORT | B21: : | C21: ='Packing List (1_2)'!B21 -> Busan International Port, Korea
A22: PORT OF DESTINATION | B22: : | C22: Ho Chi Minh City Port, Vietnam
A23: COUNTRY OF ORIGIN | B23: : | C23: Republic of Korea
A24: QUALITY | B24: : | C24: 100% BRAND NEW

Sheet SHIPPING MARK (011)
A1: SHIPPING MARK
A2: O MON IV THERMAL POWER PLANT
A3: =[6]CI!B26 -> Address: O Mon Power Complex at Phuoc Thoi wards, O Mon district, Can Tho city
A5: SHIPPER | B5: : | C5: Doosan Enerbility Co., Ltd.
A6: ADDRESS | B6: : | C6: 22 DoosanVolvo-ro, Seongsan-gu, Chang-won-si, Gyeongsangnam-do 51711, Republic of Korea
A7: CONSIGNEE | B7: : | C7: Cty Doosan Enerbility Co.,Ltd HQ-Nha thau TH CV thuoc Goi thau so OM4-EPC-HHO-06 cho NMND O Mon IV Thoi Loi Area, Phuoc Thoi Ward, Can Tho City, Vietnam T : (+84) 367 566 167 F : (+84 243) 624 8485
A8: NOTIFY PARTY | B8: : | C8: Cty Doosan Enerbility Co.,Ltd HQ-Nha thau TH CV thuoc Goi thau so OM4-EPC-HHO-06 cho NMND O Mon IV Thoi Loi Area, Phươc Thoi Ward, Can Tho City, Vietnam T : (+84) 367 566 167 F : (+84 243) 624 8485 BRANCH OF KWANGJIN VIET NAM IN DUNG QUAT Co.,Ltd Dung Quat Economic Zone, Van Tuong Commune, Quang Ngai Province, Vietnam T : (+84) 28 3825 6330 Attn: Mr. Phuoc / Email: phuoc@kjtc.co.kr
A12: CONTRACT NO. | B12: : | C12: 06/2025/HĐ-PVN/OM4-06
A13: SHIPMENT NO. | B13: : | C13: OM4-DE-IS-0009
A14: EQUIPMENT DESCRIPTION | B14: : | C14: =[6]CI!B28 -> PLANT/ EQUIPMENT AND MATERIALS FOR O MON IV THERMAL
